<?xml version="1.0"?>
<!-- =================================================================================== -->
<!-- |    This document is a hand edited version of the output                         | -->
<!-- |    autogenerated by xacro from j2s7s300_standalone.xacro                        | -->
<!-- =================================================================================== -->
<!-- j2s7s300 refers to jaco v2 7DOF spherical 3fingers -->
<robot name="j2s7s300_hand">
  <link name="hand_base">
    <visual>
      <geometry>
        <mesh filename="package://drake/manipulation/models/jaco_description/meshes/hand_3finger.obj"/>
      </geometry>
      <material name="carbon_fiber">
        <color rgba="0.792156862745098 0.819607843137255 0.933333333333333 1"/>
      </material>
    </visual>
    <visual>
      <geometry>
        <mesh filename="package://drake/manipulation/models/jaco_description/meshes/ring_small.obj"/>
      </geometry>
    </visual>
    <collision>
      <origin rpy="0 0 0" xyz="0 0 -0.03"/>
      <geometry>
        <sphere radius="0.045"/>
      </geometry>
    </collision>
    <collision>
      <origin rpy="0 0 0" xyz="0 0 -0.07"/>
      <geometry>
        <sphere radius="0.045"/>
      </geometry>
    </collision>
    <collision>
      <origin rpy="0 0 0" xyz="0 0.025 -0.07"/>
      <geometry>
        <sphere radius="0.03"/>
      </geometry>
    </collision>
    <collision>
      <origin rpy="0 0 0" xyz="0 0.025 -0.08"/>
      <geometry>
        <sphere radius="0.03"/>
      </geometry>
    </collision>
    <collision>
      <origin rpy="0 0 0" xyz="-0.02 -0.025 -0.07"/>
      <geometry>
        <sphere radius="0.03"/>
      </geometry>
    </collision>
    <collision>
      <origin rpy="0 0 0" xyz="-0.02 -0.025 -0.08"/>
      <geometry>
        <sphere radius="0.03"/>
      </geometry>
    </collision>
    <collision>
      <origin rpy="0 0 0" xyz="0.02 -0.025 -0.07"/>
      <geometry>
        <sphere radius="0.03"/>
      </geometry>
    </collision>
    <collision>
      <origin rpy="0 0 0" xyz="0.02 -0.025 -0.08"/>
      <geometry>
        <sphere radius="0.03"/>
      </geometry>
    </collision>
    <inertial>
      <mass value="0.727"/>
      <origin xyz="0 0 -0.06"/>
      <inertia ixx="0.0003453236187" ixy="0" ixz="0" iyy="0.0003453236187" iyz="0" izz="0.0005816"/>
    </inertial>
  </link>
  <link name="j2s7s300_end_effector">
    <visual>
      <geometry>
        <sphere radius="0"/>
      </geometry>
    </visual>
    <collision>
      <geometry>
        <sphere radius="0"/>
      </geometry>
    </collision>
  </link>
  <joint name="j2s7s300_joint_end_effector" type="fixed">
    <parent link="hand_base"/>
    <child link="j2s7s300_end_effector"/>
    <axis xyz="0 0 0"/>
    <limit effort="2000" lower="0" upper="0" velocity="1"/>
    <origin rpy="3.14159265359 0 0" xyz="0 0 -0.1600"/>
  </joint>
  <link name="j2s7s300_link_finger_1">
    <visual>
      <geometry>
        <mesh filename="package://drake/manipulation/models/jaco_description/meshes/finger_proximal.obj"/>
      </geometry>
      <material name="carbon_fiber">
        <color rgba="0.792156862745098 0.819607843137255 0.933333333333333 1"/>
      </material>
    </visual>
    <collision>
      <origin rpy="0 0 0" xyz="0.01 -0.01 0.0"/>
      <geometry>
        <sphere radius="0.014"/>
      </geometry>
    </collision>
    <collision>
      <origin rpy="0 0 0" xyz="0.02 -0.01 0.0"/>
      <geometry>
        <sphere radius="0.014"/>
      </geometry>
    </collision>
    <collision>
      <origin rpy="0 0 0" xyz="0.03 -0.01 0.0"/>
      <geometry>
        <sphere radius="0.014"/>
      </geometry>
    </collision>
    <collision>
      <origin rpy="0 0 0" xyz="0.04 -0.007 0.0"/>
      <geometry>
        <sphere radius="0.013"/>
      </geometry>
    </collision>
    <inertial>
      <mass value="0.01"/>
      <origin xyz="0.022 0 0"/>
      <inertia ixx="7.8999684e-07" ixy="0" ixz="0" iyy="7.8999684e-07" iyz="0" izz="8e-08"/>
    </inertial>
  </link>
  <joint name="j2s7s300_joint_finger_1" type="revolute">
    <parent link="hand_base"/>
    <child link="j2s7s300_link_finger_1"/>
    <axis xyz="0 0 1"/>
    <origin rpy="-1.570796327 .649262481663582 1.35961148639407" xyz="0.00279 0.03126 -0.11467"/>
    <limit effort="2000" lower="0" upper="2" velocity="1"/>
  </joint>
  <transmission name="j2s7s300_joint_finger_1_trans">
    <type>transmission_interface/SimpleTransmission</type>
    <joint name="j2s7s300_joint_finger_1">
      <hardwareInterface>EffortJointInterface</hardwareInterface>
    </joint>
    <actuator name="j2s7s300_joint_finger_1_actuator">
      <hardwareInterface>EffortJointInterface</hardwareInterface>
      <mechanicalReduction>1</mechanicalReduction>
    </actuator>
  </transmission>
  <link name="j2s7s300_link_finger_tip_1">
    <visual>
      <geometry>
        <mesh filename="package://drake/manipulation/models/jaco_description/meshes/finger_distal.obj"/>
      </geometry>
      <material name="carbon_fiber">
        <color rgba="0.792156862745098 0.819607843137255 0.933333333333333 1"/>
      </material>
    </visual>
    <collision>
      <origin rpy="0 0 0" xyz="0.01 -0.005 0.005"/>
      <geometry>
        <sphere radius="0.01"/>
      </geometry>
    </collision>
    <collision>
      <origin rpy="0 0 0" xyz="0.01 -0.005 -0.005"/>
      <geometry>
        <sphere radius="0.01"/>
      </geometry>
    </collision>
    <collision>
      <origin rpy="0 0 0" xyz="0.02 -0.005 0.005"/>
      <geometry>
        <sphere radius="0.01"/>
      </geometry>
    </collision>
    <collision>
      <origin rpy="0 0 0" xyz="0.02 -0.005 -0.005"/>
      <geometry>
        <sphere radius="0.01"/>
      </geometry>
    </collision>
    <collision>
      <origin rpy="0 0 0" xyz="0.035 -0.005 -0.00"/>
      <geometry>
        <sphere radius="0.01"/>
      </geometry>
    </collision>
    <inertial>
      <mass value="0.01"/>
      <origin xyz="0.022 0 0"/>
      <inertia ixx="7.8999684e-07" ixy="0" ixz="0" iyy="7.8999684e-07" iyz="0" izz="8e-08"/>
    </inertial>
  </link>
  <joint name="j2s7s300_joint_finger_tip_1" type="fixed">
    <parent link="j2s7s300_link_finger_1"/>
    <child link="j2s7s300_link_finger_tip_1"/>
    <axis xyz="0 0 1"/>
    <origin rpy="0 0 0" xyz="0.044 -0.003 0"/>
    <limit effort="2000" lower="0" upper="2" velocity="1"/>
  </joint>
  <link name="j2s7s300_link_finger_2">
    <visual>
      <geometry>
        <mesh filename="package://drake/manipulation/models/jaco_description/meshes/finger_proximal.obj"/>
      </geometry>
      <material name="carbon_fiber">
        <color rgba="0.792156862745098 0.819607843137255 0.933333333333333 1"/>
      </material>
    </visual>
    <collision>
      <origin rpy="0 0 0" xyz="0.01 -0.01 0.0"/>
      <geometry>
        <sphere radius="0.014"/>
      </geometry>
    </collision>
    <collision>
      <origin rpy="0 0 0" xyz="0.02 -0.01 0.0"/>
      <geometry>
        <sphere radius="0.014"/>
      </geometry>
    </collision>
    <collision>
      <origin rpy="0 0 0" xyz="0.03 -0.01 0.0"/>
      <geometry>
        <sphere radius="0.014"/>
      </geometry>
    </collision>
    <collision>
      <origin rpy="0 0 0" xyz="0.04 -0.007 0.0"/>
      <geometry>
        <sphere radius="0.013"/>
      </geometry>
    </collision>
    <inertial>
      <mass value="0.01"/>
      <origin xyz="0.022 0 0"/>
      <inertia ixx="7.8999684e-07" ixy="0" ixz="0" iyy="7.8999684e-07" iyz="0" izz="8e-08"/>
    </inertial>
  </link>
  <joint name="j2s7s300_joint_finger_2" type="revolute">
    <parent link="hand_base"/>
    <child link="j2s7s300_link_finger_2"/>
    <axis xyz="0 0 1"/>
    <origin rpy="-1.570796327 .649262481663582 -1.38614049188413" xyz="0.02226 -0.02707 -0.11482"/>
    <limit effort="2000" lower="0" upper="2" velocity="1"/>
  </joint>
  <transmission name="j2s7s300_joint_finger_2_trans">
    <type>transmission_interface/SimpleTransmission</type>
    <joint name="j2s7s300_joint_finger_2">
      <hardwareInterface>EffortJointInterface</hardwareInterface>
    </joint>
    <actuator name="j2s7s300_joint_finger_2_actuator">
      <hardwareInterface>EffortJointInterface</hardwareInterface>
      <mechanicalReduction>1</mechanicalReduction>
    </actuator>
  </transmission>
  <link name="j2s7s300_link_finger_tip_2">
    <visual>
      <geometry>
        <mesh filename="package://drake/manipulation/models/jaco_description/meshes/finger_distal.obj"/>
      </geometry>
      <material name="carbon_fiber">
        <color rgba="0.792156862745098 0.819607843137255 0.933333333333333 1"/>
      </material>
    </visual>
    <collision>
      <origin rpy="0 0 0" xyz="0.01 -0.005 0.005"/>
      <geometry>
        <sphere radius="0.01"/>
      </geometry>
    </collision>
    <collision>
      <origin rpy="0 0 0" xyz="0.01 -0.005 -0.005"/>
      <geometry>
        <sphere radius="0.01"/>
      </geometry>
    </collision>
    <collision>
      <origin rpy="0 0 0" xyz="0.02 -0.005 0.005"/>
      <geometry>
        <sphere radius="0.01"/>
      </geometry>
    </collision>
    <collision>
      <origin rpy="0 0 0" xyz="0.02 -0.005 -0.005"/>
      <geometry>
        <sphere radius="0.01"/>
      </geometry>
    </collision>
    <collision>
      <origin rpy="0 0 0" xyz="0.035 -0.005 -0.00"/>
      <geometry>
        <sphere radius="0.01"/>
      </geometry>
    </collision>
    <inertial>
      <mass value="0.01"/>
      <origin xyz="0.022 0 0"/>
      <inertia ixx="7.8999684e-07" ixy="0" ixz="0" iyy="7.8999684e-07" iyz="0" izz="8e-08"/>
    </inertial>
  </link>
  <joint name="j2s7s300_joint_finger_tip_2" type="fixed">
    <parent link="j2s7s300_link_finger_2"/>
    <child link="j2s7s300_link_finger_tip_2"/>
    <axis xyz="0 0 1"/>
    <origin rpy="0 0 0" xyz="0.044 -0.003 0"/>
    <limit effort="2000" lower="0" upper="2" velocity="1"/>
  </joint>
  <link name="j2s7s300_link_finger_3">
    <visual>
      <geometry>
        <mesh filename="package://drake/manipulation/models/jaco_description/meshes/finger_proximal.obj"/>
      </geometry>
      <material name="carbon_fiber">
        <color rgba="0.792156862745098 0.819607843137255 0.933333333333333 1"/>
      </material>
    </visual>
    <collision>
      <origin rpy="0 0 0" xyz="0.01 -0.01 0.0"/>
      <geometry>
        <sphere radius="0.014"/>
      </geometry>
    </collision>
    <collision>
      <origin rpy="0 0 0" xyz="0.02 -0.01 0.0"/>
      <geometry>
        <sphere radius="0.014"/>
      </geometry>
    </collision>
    <collision>
      <origin rpy="0 0 0" xyz="0.03 -0.01 0.0"/>
      <geometry>
        <sphere radius="0.014"/>
      </geometry>
    </collision>
    <collision>
      <origin rpy="0 0 0" xyz="0.04 -0.007 0.0"/>
      <geometry>
        <sphere radius="0.013"/>
      </geometry>
    </collision>
    <inertial>
      <mass value="0.01"/>
      <origin xyz="0.022 0 0"/>
      <inertia ixx="7.8999684e-07" ixy="0" ixz="0" iyy="7.8999684e-07" iyz="0" izz="8e-08"/>
    </inertial>
  </link>
  <joint name="j2s7s300_joint_finger_3" type="revolute">
    <parent link="hand_base"/>
    <child link="j2s7s300_link_finger_3"/>
    <axis xyz="0 0 1"/>
    <origin rpy="-1.570796327 .649262481663582 -1.75545216211587" xyz="-0.02226 -0.02707 -0.11482"/>
    <limit effort="2000" lower="0" upper="2" velocity="1"/>
  </joint>
  <transmission name="j2s7s300_joint_finger_3_trans">
    <type>transmission_interface/SimpleTransmission</type>
    <joint name="j2s7s300_joint_finger_3">
      <hardwareInterface>EffortJointInterface</hardwareInterface>
    </joint>
    <actuator name="j2s7s300_joint_finger_3_actuator">
      <hardwareInterface>EffortJointInterface</hardwareInterface>
      <mechanicalReduction>1</mechanicalReduction>
    </actuator>
  </transmission>
  <link name="j2s7s300_link_finger_tip_3">
    <visual>
      <geometry>
        <mesh filename="package://drake/manipulation/models/jaco_description/meshes/finger_distal.obj"/>
      </geometry>
      <material name="carbon_fiber">
        <color rgba="0.792156862745098 0.819607843137255 0.933333333333333 1"/>
      </material>
    </visual>
    <collision>
      <origin rpy="0 0 0" xyz="0.01 -0.005 0.005"/>
      <geometry>
        <sphere radius="0.01"/>
      </geometry>
    </collision>
    <collision>
      <origin rpy="0 0 0" xyz="0.01 -0.005 -0.005"/>
      <geometry>
        <sphere radius="0.01"/>
      </geometry>
    </collision>
    <collision>
      <origin rpy="0 0 0" xyz="0.02 -0.005 0.005"/>
      <geometry>
        <sphere radius="0.01"/>
      </geometry>
    </collision>
    <collision>
      <origin rpy="0 0 0" xyz="0.02 -0.005 -0.005"/>
      <geometry>
        <sphere radius="0.01"/>
      </geometry>
    </collision>
    <collision>
      <origin rpy="0 0 0" xyz="0.035 -0.005 -0.00"/>
      <geometry>
        <sphere radius="0.01"/>
      </geometry>
    </collision>
    <inertial>
      <mass value="0.01"/>
      <origin xyz="0.022 0 0"/>
      <inertia ixx="7.8999684e-07" ixy="0" ixz="0" iyy="7.8999684e-07" iyz="0" izz="8e-08"/>
    </inertial>
  </link>
  <joint name="j2s7s300_joint_finger_tip_3" type="fixed">
    <parent link="j2s7s300_link_finger_3"/>
    <child link="j2s7s300_link_finger_tip_3"/>
    <axis xyz="0 0 1"/>
    <origin rpy="0 0 0" xyz="0.044 -0.003 0"/>
    <limit effort="2000" lower="0" upper="2" velocity="1"/>
  </joint>
</robot>
