<?xml version="1.0"?>
<!--
SDF automatically generated with: gz sdf -p ../urdf/iiwa14_polytope_collision.urdf > /iiwa14_polytope_collision.sdf

Later edited by hand to rename the base link and remove damping from the joints.
-->
<sdf xmlns:drake="http://drake.mit.edu" version="1.7">
  <model name="iiwa14">
    <link name="iiwa_link_0">
      <inertial>
        <pose>-0.1 0 0.07 0 0 0</pose>
        <mass>5</mass>
        <inertia>
          <ixx>0.05</ixx>
          <ixy>0</ixy>
          <ixz>0</ixz>
          <iyy>0.06</iyy>
          <iyz>0</iyz>
          <izz>0.03</izz>
        </inertia>
      </inertial>
      <visual name="iiwa_link_0_fixed_joint_lump__iiwa_link_0_visual">
        <geometry>
          <mesh>
            <scale>1 1 1</scale>
            <uri>package://drake_models/iiwa_description/meshes/iiwa14/visual/link_0.gltf</uri>
          </mesh>
        </geometry>
      </visual>
    </link>
    <link name="iiwa_link_1">
      <pose>0 0 0.1575 0 0 0</pose>
      <inertial>
        <pose>0 -0.03 0.12 0 0 0</pose>
        <mass>5.76</mass>
        <inertia>
          <ixx>0.033</ixx>
          <ixy>0</ixy>
          <ixz>0</ixz>
          <iyy>0.0333</iyy>
          <iyz>0</iyz>
          <izz>0.0123</izz>
        </inertia>
      </inertial>
      <visual name="iiwa_link_1_visual">
        <geometry>
          <mesh>
            <scale>1 1 1</scale>
            <uri>package://drake_models/iiwa_description/meshes/iiwa14/visual/link_1.gltf</uri>
          </mesh>
        </geometry>
      </visual>
    </link>
    <joint name="iiwa_joint_1" type="revolute">
      <child>iiwa_link_1</child>
      <parent>iiwa_link_0</parent>
      <axis>
        <xyz expressed_in="__model__">0 0 1</xyz>
        <limit>
          <lower>-2.96705972839</lower>
          <upper>2.96705972839</upper>
          <effort>320</effort>
          <velocity>1.4835298641951802</velocity>
          <drake:acceleration>8.57</drake:acceleration>
        </limit>
        <dynamics>
          <damping>0</damping>
          <friction>0</friction>
          <spring_reference>0</spring_reference>
          <spring_stiffness>0</spring_stiffness>
        </dynamics>
      </axis>
      <drake:gear_ratio>160.0</drake:gear_ratio>
      <drake:rotor_inertia>0.0001321</drake:rotor_inertia>
    </joint>
    <link name="iiwa_link_2">
      <pose>0 0 0.36 1.5708 0 -3.14159</pose>
      <inertial>
        <pose>0.0003 0.059 0.042 0 0 0</pose>
        <mass>6.35</mass>
        <inertia>
          <ixx>0.0305</ixx>
          <ixy>0</ixy>
          <ixz>0</ixz>
          <iyy>0.011</iyy>
          <iyz>0</iyz>
          <izz>0.0304</izz>
        </inertia>
      </inertial>
      <visual name="iiwa_link_2_visual_grey">
        <geometry>
          <mesh>
            <scale>1 1 1</scale>
            <uri>package://drake_models/iiwa_description/meshes/iiwa14/visual/link_2_grey.gltf</uri>
          </mesh>
        </geometry>
      </visual>
      <visual name="iiwa_link_2_visual_orange">
        <geometry>
          <mesh>
            <scale>1 1 1</scale>
            <uri>package://drake_models/iiwa_description/meshes/iiwa14/visual/link_2_orange.gltf</uri>
          </mesh>
        </geometry>
      </visual>
    </link>
    <joint name="iiwa_joint_2" type="revolute">
      <child>iiwa_link_2</child>
      <parent>iiwa_link_1</parent>
      <axis>
        <xyz expressed_in="__model__">-0 1 0</xyz>
        <limit>
          <lower>-2.09439510239</lower>
          <upper>2.09439510239</upper>
          <effort>320</effort>
          <velocity>1.4835298641951802</velocity>
          <drake:acceleration>8.57</drake:acceleration>
        </limit>
        <dynamics>
          <damping>0</damping>
          <friction>0</friction>
          <spring_reference>0</spring_reference>
          <spring_stiffness>0</spring_stiffness>
        </dynamics>
      </axis>
      <drake:gear_ratio>160.0</drake:gear_ratio>
      <drake:rotor_inertia>0.0001321</drake:rotor_inertia>
    </joint>
    <link name="iiwa_link_3">
      <pose>0 0 0.5645 0 0 0</pose>
      <inertial>
        <pose>0 0.03 0.13 0 0 0</pose>
        <mass>3.5</mass>
        <inertia>
          <ixx>0.025</ixx>
          <ixy>0</ixy>
          <ixz>0</ixz>
          <iyy>0.0238</iyy>
          <iyz>0</iyz>
          <izz>0.0076</izz>
        </inertia>
      </inertial>
      <visual name="iiwa_link_3_visual">
        <geometry>
          <mesh>
            <scale>1 1 1</scale>
            <uri>package://drake_models/iiwa_description/meshes/iiwa14/visual/link_3.gltf</uri>
          </mesh>
        </geometry>
      </visual>
      <visual name="iiwa_link_3_visual_band">
        <geometry>
          <mesh>
            <scale>1 1 1</scale>
            <uri>package://drake_models/iiwa_description/meshes/iiwa14/visual/band.gltf</uri>
          </mesh>
        </geometry>
      </visual>
      <visual name="iiwa_link_3_visual_kuka">
        <geometry>
          <mesh>
            <scale>1 1 1</scale>
            <uri>package://drake_models/iiwa_description/meshes/iiwa14/visual/kuka.gltf</uri>
          </mesh>
        </geometry>
      </visual>
    </link>
    <joint name="iiwa_joint_3" type="revolute">
      <child>iiwa_link_3</child>
      <parent>iiwa_link_2</parent>
      <axis>
        <xyz expressed_in="__model__">0 0 1</xyz>
        <limit>
          <lower>-2.96705972839</lower>
          <upper>2.96705972839</upper>
          <effort>176</effort>
          <velocity>1.7453292519943295</velocity>
          <drake:acceleration>8.74</drake:acceleration>
        </limit>
        <dynamics>
          <damping>0</damping>
          <friction>0</friction>
          <spring_reference>0</spring_reference>
          <spring_stiffness>0</spring_stiffness>
        </dynamics>
      </axis>
      <drake:gear_ratio>160.0</drake:gear_ratio>
      <drake:rotor_inertia>0.0001321</drake:rotor_inertia>
    </joint>
    <link name="iiwa_link_4">
      <pose>0 0 0.78 1.5708 0 0</pose>
      <inertial>
        <pose>0 0.067 0.034 0 0 0</pose>
        <mass>3.5</mass>
        <inertia>
          <ixx>0.017</ixx>
          <ixy>0</ixy>
          <ixz>0</ixz>
          <iyy>0.006</iyy>
          <iyz>0</iyz>
          <izz>0.0164</izz>
        </inertia>
      </inertial>
      <visual name="iiwa_link_4_visual_grey">
        <geometry>
          <mesh>
            <scale>1 1 1</scale>
            <uri>package://drake_models/iiwa_description/meshes/iiwa14/visual/link_4_grey.gltf</uri>
          </mesh>
        </geometry>
      </visual>
      <visual name="iiwa_link_4_visual_orange">
        <geometry>
          <mesh>
            <scale>1 1 1</scale>
            <uri>package://drake_models/iiwa_description/meshes/iiwa14/visual/link_4_orange.gltf</uri>
          </mesh>
        </geometry>
      </visual>
    </link>
    <joint name="iiwa_joint_4" type="revolute">
      <child>iiwa_link_4</child>
      <parent>iiwa_link_3</parent>
      <axis>
        <xyz expressed_in="__model__">0 -1 0</xyz>
        <limit>
          <lower>-2.09439510239</lower>
          <upper>2.09439510239</upper>
          <effort>176</effort>
          <velocity>1.3089969389957472</velocity>
          <drake:acceleration>11.36</drake:acceleration>
        </limit>
        <dynamics>
          <damping>0</damping>
          <friction>0</friction>
          <spring_reference>0</spring_reference>
          <spring_stiffness>0</spring_stiffness>
        </dynamics>
      </axis>
      <drake:gear_ratio>160.0</drake:gear_ratio>
      <drake:rotor_inertia>0.0001321</drake:rotor_inertia>
    </joint>
    <link name="iiwa_link_5">
      <pose>0 0 0.9645 0 0 -3.14159</pose>
      <inertial>
        <pose>0.0001 0.021 0.076 0 0 0</pose>
        <mass>3.5</mass>
        <inertia>
          <ixx>0.01</ixx>
          <ixy>0</ixy>
          <ixz>0</ixz>
          <iyy>0.0087</iyy>
          <iyz>0</iyz>
          <izz>0.00449</izz>
        </inertia>
      </inertial>
      <visual name="iiwa_link_5_visual">
        <geometry>
          <mesh>
            <scale>1 1 1</scale>
            <uri>package://drake_models/iiwa_description/meshes/iiwa14/visual/link_5.gltf</uri>
          </mesh>
        </geometry>
      </visual>
      <visual name="iiwa_link_5_visual_band">
        <geometry>
          <mesh>
            <scale>1 1 1</scale>
            <uri>package://drake_models/iiwa_description/meshes/iiwa14/visual/band.gltf</uri>
          </mesh>
        </geometry>
      </visual>
      <visual name="iiwa_link_5_visual_kuka">
        <geometry>
          <mesh>
            <scale>1 1 1</scale>
            <uri>package://drake_models/iiwa_description/meshes/iiwa14/visual/kuka.gltf</uri>
          </mesh>
        </geometry>
      </visual>
    </link>
    <joint name="iiwa_joint_5" type="revolute">
      <child>iiwa_link_5</child>
      <parent>iiwa_link_4</parent>
      <axis>
        <xyz expressed_in="__model__">0 0 1</xyz>
        <limit>
          <lower>-2.96705972839</lower>
          <upper>2.96705972839</upper>
          <effort>110</effort>
          <velocity>2.2689280275926285</velocity>
          <drake:acceleration>12.23</drake:acceleration>
        </limit>
        <dynamics>
          <damping>0</damping>
          <friction>0</friction>
          <spring_reference>0</spring_reference>
          <spring_stiffness>0</spring_stiffness>
        </dynamics>
      </axis>
      <drake:gear_ratio>100.0</drake:gear_ratio>
      <drake:rotor_inertia>0.0001321</drake:rotor_inertia>
    </joint>
    <link name="iiwa_link_6">
      <pose>0 0 1.18 1.5708 0 -3.14159</pose>
      <inertial>
        <pose>0 0.0006 0.0004 0 0 0</pose>
        <mass>1.8</mass>
        <inertia>
          <ixx>0.0049</ixx>
          <ixy>0</ixy>
          <ixz>0</ixz>
          <iyy>0.0047</iyy>
          <iyz>0</iyz>
          <izz>0.0036</izz>
        </inertia>
      </inertial>
      <visual name="iiwa_link_6_visual_grey">
        <geometry>
          <mesh>
            <scale>1 1 1</scale>
            <uri>package://drake_models/iiwa_description/meshes/iiwa14/visual/link_6_grey.gltf</uri>
          </mesh>
        </geometry>
      </visual>
      <visual name="iiwa_link_6_visual_orange">
        <geometry>
          <mesh>
            <scale>1 1 1</scale>
            <uri>package://drake_models/iiwa_description/meshes/iiwa14/visual/link_6_orange.gltf</uri>
          </mesh>
        </geometry>
      </visual>
    </link>
    <joint name="iiwa_joint_6" type="revolute">
      <child>iiwa_link_6</child>
      <parent>iiwa_link_5</parent>
      <axis>
        <xyz expressed_in="__model__">-0 1 -0</xyz>
        <limit>
          <lower>-2.09439510239</lower>
          <upper>2.09439510239</upper>
          <effort>40</effort>
          <velocity>2.356194490192345"</velocity>
          <drake:acceleration>15.72</drake:acceleration>
        </limit>
        <dynamics>
          <damping>0</damping>
          <friction>0</friction>
          <spring_reference>0</spring_reference>
          <spring_stiffness>0</spring_stiffness>
        </dynamics>
      </axis>
      <drake:gear_ratio>160.0</drake:gear_ratio>
      <drake:rotor_inertia>0.0000454</drake:rotor_inertia>
    </joint>
    <link name="iiwa_link_7">
      <pose>0 0 1.261 0 0 0</pose>
      <inertial>
        <pose>0 0 0.02 0 0 0</pose>
        <mass>1.2</mass>
        <inertia>
          <ixx>0.001</ixx>
          <ixy>0</ixy>
          <ixz>0</ixz>
          <iyy>0.001</iyy>
          <iyz>0</iyz>
          <izz>0.001</izz>
        </inertia>
      </inertial>
      <collision name="iiwa_link_7_collision">
        <geometry>
          <mesh>
            <scale>1 1 1</scale>
            <uri>package://drake_models/iiwa_description/meshes/iiwa14/collision/link_7_polytope.obj</uri>
          </mesh>
        </geometry>
        <surface>
          <contact>
            <ode/>
          </contact>
          <friction>
            <ode>
              <mu>0.2</mu>
              <mu2>0.2</mu2>
            </ode>
          </friction>
        </surface>
      </collision>
      <visual name="iiwa_link_7_visual">
        <geometry>
          <mesh>
            <scale>1 1 1</scale>
            <uri>package://drake_models/iiwa_description/meshes/iiwa14/visual/link_7.gltf</uri>
          </mesh>
        </geometry>
      </visual>
    </link>
    <joint name="iiwa_joint_7" type="revolute">
      <child>iiwa_link_7</child>
      <parent>iiwa_link_6</parent>
      <axis>
        <xyz expressed_in="__model__">0 0 1</xyz>
        <limit>
          <lower>-3.05432619099</lower>
          <upper>3.05432619099</upper>
          <effort>40</effort>
          <velocity>2.356194490192345"</velocity>
          <drake:acceleration>15.72</drake:acceleration>
        </limit>
        <dynamics>
          <damping>0</damping>
          <friction>0</friction>
          <spring_reference>0</spring_reference>
          <spring_stiffness>0</spring_stiffness>
        </dynamics>
      </axis>
      <drake:gear_ratio>160.0</drake:gear_ratio>
      <drake:rotor_inertia>0.0000454</drake:rotor_inertia>
    </joint>
    <static>0</static>
  </model>
</sdf>
