<?xml version='1.0'?>
<sdf version='1.6'>
  <!-- Note: This is the accompaning SDF file for the example demo in
       simple_gripper.cc and therefore these two files must be kept in sync.

         This file defines the model for a simple gripper having two fingers.
       The right finger is fixed to the body of the gripper. The left finger
       is attached to the main body by a prismatic joint that allows it to
       perform a grip.
         The frame of the gripper, G, has its x-axis pointing to the right
       of the gripper, its y-axis pointing "forward" (towards the fingers
       side) and, the z-axis pointing upwards. This file only defines visual
       geometry but not contact geometry, allowing the demo in
       simple_gripper.cc to add contact geometry programmatically.
  -->
  <model name='box2d'>
    <pose>0.0 0 0.0 0 0 0.</pose>
    <joint name='vertical_dof' type='prismatic'>
      <parent>world</parent>
      <child>x_translate_link</child>
      <pose frame=''>0 0 0 0 0 0</pose>
      <axis>
        <xyz>0 0 1</xyz>
        <use_parent_model_frame>0</use_parent_model_frame>
        <!-- Drake attaches an actuator to all joints with a non-zero effort
             limit. We do want an actuator for this joint. (gravity) -->
        <limit>
          <effort>500</effort>
        </limit>
      </axis>
    </joint>
    <link name='x_translate_link'>
      <pose frame=''>0 0 0 0 -0 0</pose>
      <inertial>
        <mass>0.000001</mass>
        <inertia>
          <ixx>0.000001</ixx>
          <ixy>0</ixy>
          <ixz>0</ixz>
          <iyy>0.000001</iyy>
          <iyz>0</iyz>
          <izz>0.000001</izz>
        </inertia>
        <pose frame=''>0 0 0 0 -0 0</pose>
      </inertial>
    </link>
    <joint name='x_translate_dof' type='prismatic'>
      <parent>x_translate_link</parent>
      <child>moving_box</child>
      <pose frame=''>0 0 0 0 0 0</pose>
      <axis>
        <xyz>1 0 0</xyz>
        <use_parent_model_frame>0</use_parent_model_frame>
        <!-- Drake attaches an actuator to all joints with a non-zero effort
             limit. We do want an actuator for this joint. -->
        <limit>
          <effort>500</effort>
        </limit>
      </axis>
    </joint>
    <link name='moving_box'>
      <pose frame=''>0.000 0.000 0 0 -0 0</pose>
      <inertial>
        <mass>0.33</mass>
        <inertia>
          <ixx>0.000141377</ixx>
          <ixy>0</ixy>
          <ixz>0</ixz>
          <iyy>0.000466688</iyy>
          <iyz>0</iyz>
          <izz>0.000466688</izz>
        </inertia>
        <pose frame=''>0 0 0 0 -0 0</pose>
      </inertial>
      <visual name='moving_box_visual'>
        <pose frame=''>0 0 0 0 -0 0</pose>
        <geometry>
          <box>
            <size>0.12 0.0507 0.0507</size>
          </box>
        </geometry>
        <material name="purple">
          <ambient> 0.6 0.3 0.6 1</ambient>
          <diffuse> 0.6 0.3 0.6 1</diffuse>
        </material>
      </visual>
      <collision name='moving_box_collision'>
        <pose frame=''>0 0 0 0 -0 0</pose>
        <geometry>
          <box>
            <size>0.12 0.0507 0.0507</size>
          </box>
        </geometry>

        <surface>
          <friction>
            <ode>
              <mu>1</mu>
              <mu2>1</mu2>
            </ode>
          </friction>
        </surface>
      </collision>
    </link>
    <joint name='weld_base' type='fixed'>
      <parent>world</parent>
      <child>base_box</child>
      <pose>0 0 0 0 0 0</pose>
    </joint>
    <link name='base_box'>
      <pose frame=''>0.000 0.0 -0.070415406 0 -0 0</pose>
      <!-- right height for penetration allowance 10 -->
      <inertial>
        <mass>668.75</mass>
        <inertia>
          <ixx>348.864583333</ixx>
          <ixy>0</ixy>
          <ixz>0</ixz>
          <iyy>348.864583333</iyy>
          <iyz>0</iyz>
          <izz>696.614583333</izz>
        </inertia>
        <pose frame=''>0 0 0 0 -0 0</pose>
      </inertial>
      <visual name='base_box_visual'>
        <pose frame=''>0 0 0 0 -0 0</pose>
        <geometry>
          <box>
            <size>2.5 2.5 0.1</size>
          </box>
        </geometry>
        <material name="blue">
          <ambient> 0.2 0.2 0.8 1</ambient>
          <diffuse> 0.2 0.2 0.8 1</diffuse>
        </material>
      </visual>
      <collision name='base_box_collision'>
        <pose frame=''>0 0 0 0 -0 0</pose>
        <geometry>
          <box>
            <size>2.5 2.5 0.1</size>
          </box>
        </geometry>

        <surface>
          <friction>
            <ode>
              <mu>1</mu>
              <mu2>1</mu2>
            </ode>
          </friction>
        </surface>
      </collision>
    </link>
  </model>
  
</sdf>
