<?xml version="1.0"?>

<robot xmlns="http://drake.mit.edu"
 xmlns:xsi="http://www.w3.org/2001/XMLSchema-instance"
 xsi:schemaLocation="http://drake.mit.edu ../../doc/drakeURDF.xsd" name="UnderwaterAcrobot">

  <link name="base_link">
    <visual>
      <geometry>
         <box size=".5 1 .5" />
      </geometry>
      <material name="green">
	<color rgba="0 1 0 1" />
      </material>
    </visual>
  </link>

  <link name="upper_link">
    <inertial>
      <origin xyz="0 0 -1" rpy="0 0 0" />
      <mass value="800" />
      <inertia ixx="1" ixy="0" ixz="0" iyy="250" iyz="0" izz="1" />
    </inertial>
    <visual>
      <origin xyz="0 0 -1" rpy="0 0 0" />
      <geometry>
         <box size="1 1 2" />
      </geometry>
      <material name="red">
	<color rgba="1 0 0 1" />
      </material>
    </visual>
  </link>

  <link name="lower_link">
    <inertial>
      <origin xyz="0 0 -1" rpy="0 0 0" />
      <mass value="800" />
      <inertia ixx="1" ixy="0" ixz="0" iyy="250" iyz="0" izz="1" />
    </inertial>
    <visual>
      <origin xyz="0 0 -1" rpy="0 0 0" />
      <geometry>
         <box size="1 1 2" />
      </geometry>
      <material name="blue">
	<color rgba="0 0 1 1" />
      </material>
    </visual>
  </link>
  
  <joint name="shoulder" type="continuous">
    <parent link="base_link" />
    <child link="upper_link" />
    <origin xyz="0 0 0" />
    <axis xyz="0 1 0" />
    <dynamics damping="0" />
  </joint>

  <joint name="elbow" type="continuous">
    <parent link="upper_link" />
    <child link="lower_link" />
    <origin xyz="0 0 -2" />
    <axis xyz="0 1 0" />
    <dynamics damping="0" />
  </joint>

  <transmission type="SimpleTransmission" name="elbow_trans">
    <actuator name="elbow_torque" />
    <joint name="elbow" />
    <mechanicalReduction>1</mechanicalReduction>
  </transmission>
  
<force_element name="upper_link_buoyancy">
<buoyancy rho="1000" volume="1.6">
      <parent link="upper_link"/>
      <origin xyz="0 0 -1" rpy="0 0 0" /> 
    </buoyancy>
</force_element>

<force_element name="lower_link_buoyancy">
<buoyancy rho="1000" volume="1.6">
      <parent link="lower_link"/>
      <origin xyz="0 0 -1" rpy="0 0 0" />
    </buoyancy>
</force_element>

<force_element name="upper_link_addedmass">
<added_mass m11="3000" m33="800" m55 = "200">
      <parent link="upper_link"/>
      <origin xyz="0 0 -1" rpy="0 0 0" />
    </added_mass>
</force_element>

<force_element name="lower_link_addedmass">
<added_mass m11="3000" m33="800" m55 = "200">
      <parent link="lower_link"/>
      <origin xyz="0 0 -1" rpy="0 0 0" />
    </added_mass>
</force_element>

  <frame name="hand" link="lower_link" xyz="0 0 -2.1" rpy="0 0 0" />
</robot>
