<?xml version="1.0" ?>
<!-- =================================================================================== -->
<!-- |    This document was autogenerated by xacro from atlas_full_contact_no_hands.urdf.xacro | -->
<!-- |    EDITING THIS FILE BY HAND IS NOT RECOMMENDED                                 | -->
<!-- =================================================================================== -->
<robot name="atlas" xmlns:xacro="http://www.ros.org/wiki/xacro">
  <link name="l_clav">
    <inertial>
      <mass value="3.45"/>
      <origin rpy="0 -0 0" xyz="0 0.048 0.084"/>
      <inertia ixx="0.011" ixy="0" ixz="0" iyy="0.009" iyz="-0.004" izz="0.004"/>
    </inertial>
    <visual>
      <origin rpy="0 -0 0" xyz="0 0 0"/>
      <geometry>
        <mesh filename="meshes/l_clav.wrl" scale="1 1 1"/>
      </geometry>
    </visual>
    <collision>
      <origin rpy="0 -0 0" xyz="0 0 0"/>
      <geometry>
        <mesh filename="meshes/l_clav_chull.wrl" scale="1 1 1"/>
      </geometry>
    </collision>
  </link>
  <link name="l_farm">
    <inertial>
      <mass value="3.388"/>
      <origin rpy="0 -0 0" xyz="0 -0.065 0"/>
      <inertia ixx="0.00656" ixy="0" ixz="0" iyy="0.00358" iyz="0" izz="0.00656"/>
    </inertial>
    <visual>
      <origin rpy="0 -0 0" xyz="0 0 0"/>
      <geometry>
        <mesh filename="meshes/l_farm.wrl" scale="1 1 1"/>
      </geometry>
    </visual>
    <collision>
      <origin rpy="0 -0 0" xyz="0 0 0"/>
      <geometry>
        <mesh filename="meshes/l_farm_chull.wrl" scale="1 1 1"/>
      </geometry>
    </collision>
  </link>
  <link name="l_foot">
    <inertial>
      <mass value="2.05"/>
      <origin rpy="0 -0 0" xyz="0.027 0 -0.067"/>
      <inertia ixx="0.002" ixy="0" ixz="0" iyy="0.007" iyz="0" izz="0.008"/>
    </inertial>
    <visual>
      <origin rpy="0 -0 0" xyz="0 0 0"/>
      <geometry>
        <mesh filename="meshes/l_foot.wrl" scale="1 1 1"/>
      </geometry>
    </visual>
    <collision>
      <origin rpy="0 -0 0" xyz="0 0 0"/>
      <geometry>
        <mesh filename="meshes/l_foot_chull.wrl" scale="1 1 1"/>
      </geometry>
    </collision>


   <collision group="heel">
      <origin rpy="0 0 0" xyz="-0.082 0.0624435 -0.081119"/>
      <geometry>
        <sphere radius="0"/>
      </geometry>
    </collision>
    <visual>
      <origin rpy="0 0 0" xyz="-0.082 0.0624435 -0.081119"/>
      <geometry>
        <sphere radius="0.01"/>
      </geometry>
    </visual>
    <collision group="heel">
      <origin rpy="0 0 0" xyz="-0.082 -0.0624435 -0.081119"/>
      <geometry>
        <sphere radius="0"/>
      </geometry>
    </collision>
    <visual>
      <origin rpy="0 0 0" xyz="-0.082 -0.0624435 -0.081119"/>
      <geometry>
        <sphere radius="0.01"/>
      </geometry>
    </visual>
    <collision group="toe">
      <origin rpy="0 0 0" xyz="0.178 0.0624435 -0.081119"/>
      <geometry>
        <sphere radius="0"/>
      </geometry>
    </collision>
    <visual>
      <origin rpy="0 0 0" xyz="0.178 0.0624435 -0.081119"/>
      <geometry>
        <sphere radius="0.01"/>
      </geometry>
    </visual>
    <collision group="toe">
      <origin rpy="0 0 0" xyz="0.178 -0.0624435 -0.081119"/>
      <geometry>
        <sphere radius="0"/>
      </geometry>
    </collision>
    <visual>
      <origin rpy="0 0 0" xyz="0.178 -0.0624435 -0.081119"/>
      <geometry>
        <sphere radius="0.01"/>
      </geometry>
    </visual>
    <!--<visual>-->
    <!--<origin xyz="0.048 0 -0.056119" rpy="0 0 0"/>-->
    <!--<geometry>-->
    <!--<box size="0.26 0.124887 0.05"/>-->
    <!--</geometry>-->
    <!--</visual>-->
    <!--<collision>-->
    <!--<origin xyz="0.048 0 -0.056119" rpy="0 0 0"/>-->
    <!--<geometry>-->
    <!--<box size="0.26 0.124887 0.05"/>-->
    <!--</geometry>-->
    <!--</collision>-->
    <!--<xacro:collision_point group="heel" xyz="-0.082 0.0624435 -0.081119" visualize="1"/>-->
    <!--<xacro:collision_point group="heel" xyz="-0.082 -0.0624435 -0.081119" visualize="1"/>-->
    <!--<xacro:collision_point group="toe" xyz="0.178 0.0624435 -0.081119" visualize="1"/>-->
    <!--<xacro:collision_point group="toe" xyz="0.178 -0.0624435 -0.081119" visualize="1"/>-->
    <!--<xacro:collision_point group="heel_mid" xyz="-0.082 0 -0.081119" visualize="1"/>-->
    <!--<xacro:collision_point group="toe_mid" xyz="0.178 0 -0.081119" visualize="1"/>-->
    <!--    <xacro:collision_point group="inner" xyz="-0.08 0.055 -0.081119" visualize="1"/>-->
    <!--    <xacro:collision_point group="inner" xyz="-0.08 -0.055 -0.081119" visualize="1"/>-->
    <!--    <xacro:collision_point group="inner" xyz="0.06 0.055 -0.081119" visualize="1"/>-->
    <!--    <xacro:collision_point group="inner" xyz="0.06 -0.055 -0.081119" visualize="1"/>-->
  </link>
  <frame link="l_foot" name="l_foot_sole" rpy="0 0 0" xyz="0.0480 0 -0.081119"/>
  <link name="l_hand">
    <inertial>
      <mass value="2.509"/>
      <origin rpy="0 -0 0" xyz="0 0 0"/>
      <inertia ixx="0.00265" ixy="0" ixz="0" iyy="0.00446" iyz="0" izz="0.00446"/>
    </inertial>
    <visual>
      <origin rpy="0 -0 0" xyz="0 0 0"/>
      <geometry>
        <mesh filename="meshes/l_hand.wrl" scale="1 1 1"/>
      </geometry>
    </visual>
    <collision>
      <origin rpy="0 -0 0" xyz="0 0 0"/>
      <geometry>
        <mesh filename="meshes/l_hand_chull.wrl" scale="1 1 1"/>
      </geometry>
    </collision>
    <visual group="l_hand_extra">
      <origin rpy="-1.57079 -1.57079 0" xyz="0 0.29016 0.0112"/>
      <geometry>
        <mesh filename="meshes/GRIPPER_OPEN_chull.wrl" scale="1 1 1"/>
      </geometry>
    </visual>
    <collision group="l_hand_extra">
      <origin rpy="-1.57079 -1.57079 0" xyz="0 0.29016 0.0112"/>
      <geometry>
        <mesh filename="meshes/GRIPPER_OPEN_chull.wrl" scale="1 1 1"/>
      </geometry>
    </collision>
  </link>
  <link name="l_larm">
    <inertial>
      <mass value="2.509"/>
      <origin rpy="0 -0 0" xyz="0 0 0"/>
      <inertia ixx="0.00265" ixy="0" ixz="0" iyy="0.00446" iyz="0" izz="0.00446"/>
    </inertial>
    <visual>
      <origin rpy="0 -0 0" xyz="0 0 0"/>
      <geometry>
        <mesh filename="meshes/l_elbow_rx.wrl" scale="1 1 1"/>
      </geometry>
    </visual>
    <collision>
      <origin rpy="0 -0 0" xyz="0 0 0"/>
      <geometry>
        <mesh filename="meshes/l_elbow_rx_chull.wrl" scale="1 1 1"/>
      </geometry>
    </collision>
  </link>
  <link name="l_lglut">
    <inertial>
      <mass value="0.866"/>
      <origin rpy="0 -0 0" xyz="0.0133341 0.0170484 -0.0312052"/>
      <inertia ixx="0.000691326" ixy="-2.24344e-05" ixz="2.50508e-06" iyy="0.00126856" iyz="0.000137862" izz="0.00106487"/>
    </inertial>
    <visual>
      <origin rpy="0 -0 0" xyz="0 0 0"/>
      <geometry>
        <mesh filename="meshes/l_lglut.wrl" scale="1 1 1"/>
      </geometry>
    </visual>
  </link>
  <link name="l_lleg">
    <inertial>
      <mass value="5.479"/>
      <origin rpy="0 -0 0" xyz="0.001 0 -0.187"/>
      <inertia ixx="0.077" ixy="0" ixz="-0.003" iyy="0.076" iyz="0" izz="0.01"/>
    </inertial>
    <visual>
      <origin rpy="0 -0 0" xyz="0 0 0"/>
      <geometry>
        <mesh filename="meshes/l_lleg.wrl" scale="1 1 1"/>
      </geometry>
    </visual>
    <collision>
      <origin rpy="0 -0 0" xyz="0 0 0"/>
      <geometry>
        <mesh filename="meshes/l_lleg_chull.wrl" scale="1 1 1"/>
      </geometry>
    </collision>
  </link>
  <link name="l_scap">
    <inertial>
      <mass value="3.012"/>
      <origin rpy="0 -0 0" xyz="0 0 0"/>
      <inertia ixx="0.00319" ixy="0" ixz="0" iyy="0.00583" iyz="0" izz="0.00583"/>
    </inertial>
    <visual>
      <origin rpy="0 -0 0" xyz="0 0 0"/>
      <geometry>
        <mesh filename="meshes/l_sh_rx.wrl" scale="1 1 1"/>
      </geometry>
    </visual>
    <collision>
      <origin rpy="0 -0 0" xyz="0 0 0"/>
      <geometry>
        <mesh filename="meshes/l_sh_rx_chull.wrl" scale="1 1 1"/>
      </geometry>
    </collision>
  </link>
  <link name="l_talus">
    <inertial>
      <mass value="0.125"/>
      <origin rpy="0 -0 0" xyz="0 0 0"/>
      <inertia ixx="1.01674e-05" ixy="0" ixz="0" iyy="8.42775e-06" iyz="0" izz="1.30101e-05"/>
    </inertial>
    <visual>
      <origin rpy="0 -0 0" xyz="0 0 0"/>
      <geometry>
        <mesh filename="meshes/l_talus.wrl" scale="1 1 1"/>
      </geometry>
    </visual>
  </link>
  <link name="l_uarm">
    <inertial>
      <mass value="3.388"/>
      <origin rpy="0 -0 0" xyz="0 -0.065 0"/>
      <inertia ixx="0.00656" ixy="0" ixz="0" iyy="0.00358" iyz="0" izz="0.00656"/>
    </inertial>
    <visual>
      <origin rpy="0 -0 0" xyz="0 0 0"/>
      <geometry>
        <mesh filename="meshes/l_elbow_ry.wrl" scale="1 1 1"/>
      </geometry>
    </visual>
    <collision>
      <origin rpy="0 -0 0" xyz="0 0 0"/>
      <geometry>
        <mesh filename="meshes/l_elbow_ry_chull.wrl" scale="1 1 1"/>
      </geometry>
    </collision>
  </link>
  <link name="l_uglut">
    <inertial>
      <mass value="0.648"/>
      <origin rpy="0 -0 0" xyz="0.00529262 -0.00344732 0.00313046"/>
      <inertia ixx="0.00074276" ixy="-3.79607e-08" ixz="-2.79549e-05" iyy="0.000688179" iyz="-3.2735e-08" izz="0.00041242"/>
    </inertial>
    <visual>
      <origin rpy="0 -0 0" xyz="0 0 0"/>
      <geometry>
        <mesh filename="meshes/l_uglut.wrl" scale="1 1 1"/>
      </geometry>
    </visual>
  </link>
  <link name="l_uleg">
    <inertial>
      <mass value="9.209"/>
      <origin rpy="0 -0 0" xyz="0 0 -0.21"/>
      <inertia ixx="0.09" ixy="0" ixz="0" iyy="0.09" iyz="0" izz="0.02"/>
    </inertial>
    <visual>
      <origin rpy="0 -0 0" xyz="0 0 0"/>
      <geometry>
        <mesh filename="meshes/l_uleg.wrl" scale="1 1 1"/>
      </geometry>
    </visual>
    <collision>
      <origin rpy="0 -0 0" xyz="0 0 0"/>
      <geometry>
        <mesh filename="meshes/l_uleg_chull.wrl" scale="1 1 1"/>
      </geometry>
    </collision>
  </link>
  <link name="ltorso">
    <inertial>
      <mass value="2.409"/>
      <origin rpy="0 -0 0" xyz="-0.0112984 -3.15366e-06 0.0746835"/>
      <inertia ixx="0.0039092" ixy="-5.04491e-08" ixz="-0.000342157" iyy="0.00341694" iyz="4.87119e-07" izz="0.00174492"/>
    </inertial>
    <visual>
      <origin rpy="0 -0 0" xyz="0 0 0"/>
      <geometry>
        <mesh filename="meshes/ltorso.wrl" scale="1 1 1"/>
      </geometry>
    </visual>
  </link>
  <link name="mtorso">
    <inertial>
      <mass value="0.69"/>
      <origin rpy="0 -0 0" xyz="-0.00816266 -0.0131245 0.0305974"/>
      <inertia ixx="0.000454181" ixy="-6.10764e-05" ixz="3.94009e-05" iyy="0.000483282" iyz="5.27463e-05" izz="0.000444215"/>
    </inertial>
    <visual>
      <origin rpy="0 -0 0" xyz="0 0 0"/>
      <geometry>
        <mesh filename="meshes/mtorso.wrl" scale="1 1 1"/>
      </geometry>
    </visual>
  </link>
  <link name="pelvis">
    <inertial>
      <mass value="17.882"/>
      <origin rpy="0 -0 0" xyz="0.0111 0 0.0271"/>
      <inertia ixx="0.1244" ixy="0.0008" ixz="-0.0007" iyy="0.0958" iyz="-0.0005" izz="0.1167"/>
    </inertial>
    <visual>
      <origin rpy="0 -0 0" xyz="0 0 0"/>
      <geometry>
        <mesh filename="meshes/pelvis.wrl" scale="1 1 1"/>
      </geometry>
    </visual>
    <collision>
      <origin rpy="0 -0 0" xyz="0 0 0"/>
      <geometry>
        <mesh filename="meshes/pelvis_chull.wrl" scale="1 1 1"/>
      </geometry>
    </collision>
  </link>
  <link name="r_clav">
    <inertial>
      <mass value="3.45"/>
      <origin rpy="0 -0 0" xyz="0 -0.048 0.084"/>
      <inertia ixx="0.011" ixy="0" ixz="0" iyy="0.009" iyz="0.004" izz="0.004"/>
    </inertial>
    <visual>
      <origin rpy="0 -0 0" xyz="0 0 0"/>
      <geometry>
        <mesh filename="meshes/r_clav.wrl" scale="1 1 1"/>
      </geometry>
    </visual>
    <collision>
      <origin rpy="0 -0 0" xyz="0 0 0"/>
      <geometry>
        <mesh filename="meshes/r_clav_chull.wrl" scale="1 1 1"/>
      </geometry>
    </collision>
  </link>
  <link name="r_farm">
    <inertial>
      <mass value="3.388"/>
      <origin rpy="0 -0 0" xyz="0 0.065 0"/>
      <inertia ixx="0.00656" ixy="0" ixz="0" iyy="0.00358" iyz="0" izz="0.00656"/>
    </inertial>
    <visual>
      <origin rpy="0 -0 0" xyz="0 0 0"/>
      <geometry>
        <mesh filename="meshes/r_farm.wrl" scale="1 1 1"/>
      </geometry>
    </visual>
    <collision>
      <origin rpy="0 -0 0" xyz="0 0 0"/>
      <geometry>
        <mesh filename="meshes/r_farm_chull.wrl" scale="1 1 1"/>
      </geometry>
    </collision>
  </link>
  <link name="r_foot">
    <inertial>
      <mass value="2.05"/>
      <origin rpy="0 -0 0" xyz="0.027 0 -0.067"/>
      <inertia ixx="0.002" ixy="0" ixz="0" iyy="0.007" iyz="0" izz="0.008"/>
    </inertial>
    <visual>
      <geometry>
        <mesh filename="meshes/r_foot.wrl" scale="1 1 1"/>
      </geometry>
    </visual>
    <collision>
      <origin rpy="0 -0 0" xyz="0 0 0"/>
      <geometry>
        <mesh filename="meshes/r_foot_chull.wrl" scale="1 1 1"/>
      </geometry>
    </collision>

   <collision group="heel">
      <origin rpy="0 0 0" xyz="-0.082 0.0624435 -0.081119"/>
      <geometry>
        <sphere radius="0"/>
      </geometry>
    </collision>
    <visual>
      <origin rpy="0 0 0" xyz="-0.082 0.0624435 -0.081119"/>
      <geometry>
        <sphere radius="0.01"/>
      </geometry>
    </visual>
    <collision group="heel">
      <origin rpy="0 0 0" xyz="-0.082 -0.0624435 -0.081119"/>
      <geometry>
        <sphere radius="0"/>
      </geometry>
    </collision>
    <visual>
      <origin rpy="0 0 0" xyz="-0.082 -0.0624435 -0.081119"/>
      <geometry>
        <sphere radius="0.01"/>
      </geometry>
    </visual>
    <collision group="toe">
      <origin rpy="0 0 0" xyz="0.178 0.0624435 -0.081119"/>
      <geometry>
        <sphere radius="0"/>
      </geometry>
    </collision>
    <visual>
      <origin rpy="0 0 0" xyz="0.178 0.0624435 -0.081119"/>
      <geometry>
        <sphere radius="0.01"/>
      </geometry>
    </visual>
    <collision group="toe">
      <origin rpy="0 0 0" xyz="0.178 -0.0624435 -0.081119"/>
      <geometry>
        <sphere radius="0"/>
      </geometry>
    </collision>
    <visual>
      <origin rpy="0 0 0" xyz="0.178 -0.0624435 -0.081119"/>
      <geometry>
        <sphere radius="0.01"/>
      </geometry>
    </visual>


    <!--<visual>-->
    <!--<origin xyz="0.048 0 -0.056119" rpy="0 0 0"/>-->
    <!--<geometry>-->
    <!--<box size="0.26 0.124887 0.05"/>-->
    <!--</geometry>-->
    <!--</visual>-->
    <!--<collision>-->
    <!--<origin xyz="0.048 0 -0.056119" rpy="0 0 0"/>-->
    <!--<geometry>-->
    <!--<box size="0.26 0.124887 0.05"/>-->
    <!--</geometry>-->
    <!--</collision>-->
    <!--<xacro:collision_point group="heel" xyz="-0.082 0.0624435 -0.081119" visualize="1"/>-->
    <!--<xacro:collision_point group="heel" xyz="-0.082 -0.0624435 -0.081119" visualize="1"/>-->
    <!--<xacro:collision_point group="toe" xyz="0.178 0.0624435 -0.081119" visualize="1"/>-->
    <!--<xacro:collision_point group="toe" xyz="0.178 -0.0624435 -0.081119" visualize="1"/>-->
    <!--<xacro:collision_point group="heel_mid" xyz="-0.082 0 -0.081119" visualize="1"/>-->
    <!--<xacro:collision_point group="toe_mid" xyz="0.178 0 -0.081119" visualize="1"/>-->
    <!--    <xacro:collision_point group="inner" xyz="-0.08 0.055 -0.081119" visualize="1"/>-->
    <!--    <xacro:collision_point group="inner" xyz="-0.08 -0.055 -0.081119" visualize="1"/>-->
    <!--    <xacro:collision_point group="inner" xyz="0.06 0.055 -0.081119" visualize="1"/>-->
    <!--    <xacro:collision_point group="inner" xyz="0.06 -0.055 -0.081119" visualize="1"/>-->
  </link>
  <frame link="r_foot" name="r_foot_sole" rpy="0 0 0" xyz="0.0480 0 -0.081119"/>
  <link name="r_hand">
    <inertial>
      <mass value="2.509"/>
      <origin rpy="0 -0 0" xyz="0 0 0"/>
      <inertia ixx="0.00265" ixy="0" ixz="0" iyy="0.00446" iyz="0" izz="0.00446"/>
    </inertial>
    <visual>
      <origin rpy="0 3.14159 0" xyz="0 0 0"/>
      <geometry>
        <mesh filename="meshes/r_hand.wrl" scale="1 1 1"/>
      </geometry>
    </visual>
    <collision>
      <origin rpy="0 -0 0" xyz="0 0 0"/>
      <geometry>
        <mesh filename="meshes/r_hand_chull.wrl" scale="1 1 1"/>
      </geometry>
    </collision>

    <visual group="r_hand_extra">
      <origin rpy="-1.57079 -1.57079 3.142" xyz="0 -0.29016 0.0112"/>
      <geometry>
        <mesh filename="meshes/GRIPPER_OPEN_chull.wrl" scale="1 1 1"/>
      </geometry>
    </visual>
    <collision group="r_hand_extra">
      <origin rpy="-1.57079 -1.57079 3.142" xyz="0 -0.29016 0.0112"/>
      <geometry>
        <mesh filename="meshes/GRIPPER_OPEN_chull.wrl" scale="1 1 1"/>
      </geometry>
    </collision>

  </link>
  <link name="r_larm">
    <inertial>
      <mass value="2.509"/>
      <origin rpy="0 -0 0" xyz="0 0 0"/>
      <inertia ixx="0.00265" ixy="0" ixz="0" iyy="0.00446" iyz="0" izz="0.00446"/>
    </inertial>
    <visual>
      <origin rpy="0 -0 0" xyz="0 0 0"/>
      <geometry>
        <mesh filename="meshes/r_elbow_rx.wrl" scale="1 1 1"/>
      </geometry>
    </visual>
    <collision>
      <origin rpy="0 -0 0" xyz="0 0 0"/>
      <geometry>
        <mesh filename="meshes/r_elbow_rx_chull.wrl" scale="1 1 1"/>
      </geometry>
    </collision>
  </link>
  <link name="r_lglut">
    <inertial>
      <mass value="0.866"/>
      <origin rpy="0 -0 0" xyz="0.0133341 -0.0170484 -0.0312052"/>
      <inertia ixx="0.000691326" ixy="2.24344e-05" ixz="2.50508e-06" iyy="0.00126856" iyz="-0.000137862" izz="0.00106487"/>
    </inertial>
    <visual>
      <origin rpy="0 -0 0" xyz="0 0 0"/>
      <geometry>
        <mesh filename="meshes/r_lglut.wrl" scale="1 1 1"/>
      </geometry>
    </visual>
  </link>
  <link name="r_lleg">
    <inertial>
      <mass value="5.479"/>
      <origin rpy="0 -0 0" xyz="0.001 0 -0.187"/>
      <inertia ixx="0.077" ixy="-0" ixz="-0.003" iyy="0.076" iyz="-0" izz="0.01"/>
    </inertial>
    <visual>
      <origin rpy="0 -0 0" xyz="0 0 0"/>
      <geometry>
        <mesh filename="meshes/r_lleg.wrl" scale="1 1 1"/>
      </geometry>
    </visual>
    <collision>
      <origin rpy="0 -0 0" xyz="0 0 0"/>
      <geometry>
        <mesh filename="meshes/r_lleg_chull.wrl" scale="1 1 1"/>
      </geometry>
    </collision>
  </link>
  <link name="r_scap">
    <inertial>
      <mass value="3.012"/>
      <origin rpy="0 -0 0" xyz="0 0 0"/>
      <inertia ixx="0.00319" ixy="0" ixz="0" iyy="0.00583" iyz="0" izz="0.00583"/>
    </inertial>
    <visual>
      <origin rpy="0 -0 0" xyz="0 0 0"/>
      <geometry>
        <mesh filename="meshes/r_sh_rx.wrl" scale="1 1 1"/>
      </geometry>
    </visual>
    <collision>
      <origin rpy="0 -0 0" xyz="0 0 0"/>
      <geometry>
        <mesh filename="meshes/r_sh_rx_chull.wrl" scale="1 1 1"/>
      </geometry>
    </collision>
  </link>
  <link name="r_talus">
    <inertial>
      <mass value="0.125"/>
      <origin rpy="0 -0 0" xyz="0 0 0"/>
      <inertia ixx="1.01674e-05" ixy="0" ixz="0" iyy="8.42775e-06" iyz="0" izz="1.30101e-05"/>
    </inertial>
    <visual>
      <origin rpy="0 -0 0" xyz="0 0 0"/>
      <geometry>
        <mesh filename="meshes/r_talus.wrl" scale="1 1 1"/>
      </geometry>
    </visual>
  </link>
  <link name="r_uarm">
    <inertial>
      <mass value="3.388"/>
      <origin rpy="0 -0 0" xyz="0 0.065 0"/>
      <inertia ixx="0.00656" ixy="0" ixz="0" iyy="0.00358" iyz="0" izz="0.00656"/>
    </inertial>
    <visual>
      <origin rpy="0 -0 0" xyz="0 0 0"/>
      <geometry>
        <mesh filename="meshes/r_elbow_ry.wrl" scale="1 1 1"/>
      </geometry>
    </visual>
    <collision>
      <origin rpy="0 -0 0" xyz="0 0 0"/>
      <geometry>
        <mesh filename="meshes/r_elbow_ry_chull.wrl" scale="1 1 1"/>
      </geometry>
    </collision>
  </link>
  <link name="r_uglut">
    <inertial>
      <mass value="0.648"/>
      <origin rpy="0 -0 0" xyz="0.00529262 0.00344732 0.00313046"/>
      <inertia ixx="0.00074276" ixy="3.79607e-08" ixz="-2.79549e-05" iyy="0.000688179" iyz="3.2735e-08" izz="0.00041242"/>
    </inertial>
    <visual>
      <origin rpy="0 -0 0" xyz="0 0 0"/>
      <geometry>
        <mesh filename="meshes/r_uglut.wrl" scale="1 1 1"/>
      </geometry>
    </visual>
  </link>
  <link name="r_uleg">
    <inertial>
      <mass value="9.209"/>
      <origin rpy="0 -0 0" xyz="0 0 -0.21"/>
      <inertia ixx="0.09" ixy="0" ixz="0" iyy="0.09" iyz="0" izz="0.02"/>
    </inertial>
    <visual>
      <origin rpy="0 -0 0" xyz="0 0 0"/>
      <geometry>
        <mesh filename="meshes/r_uleg.wrl" scale="1 1 1"/>
      </geometry>
    </visual>
    <collision>
      <origin rpy="0 -0 0" xyz="0 0 0"/>
      <geometry>
        <mesh filename="meshes/r_uleg_chull.wrl" scale="1 1 1"/>
      </geometry>
    </collision>
  </link>
  <link name="utorso">
    <inertial>
      <mass value="52"/>
      <origin rpy="0 -0 0" xyz="-0.0923 0 0.3"/>
      <inertia ixx="1.466" ixy="0.00362" ixz="0.336" iyy="1.51" iyz="0.001" izz="1.3"/>
    </inertial>
    <visual>
      <origin rpy="0 -0 0" xyz="0 0 0"/>
      <geometry>
        <mesh filename="meshes/utorso.wrl" scale="1 1 1"/>
      </geometry>
    </visual>
    <collision>
      <origin rpy="0 -0 0" xyz="0 0 0"/>
      <geometry>
        <mesh filename="meshes/utorso_chull.wrl" scale="1 1 1"/>
      </geometry>
    </collision>
    <visual>
      <origin rpy="0 -0 0" xyz="0 0 0"/>
      <geometry>
        <mesh filename="meshes/utorso_pack.wrl" scale="1 1 1"/>
      </geometry>
    </visual>
    <collision>
      <origin rpy="0 -0 0" xyz="0 0 0"/>
      <geometry>
        <mesh filename="meshes/utorso_pack_chull.wrl" scale="1 1 1"/>
      </geometry>
    </collision>
  </link>
  <collision_filter_group name="core">
    <member link="utorso"/>
    <member link="pelvis"/>
    <ignored_collision_filter_group collision_filter_group="core"/>
  </collision_filter_group>
  <collision_filter_group name="ignore_core">
    <member link="r_scap"/>
    <member link="l_scap"/>
    <member link="r_clav"/>
    <member link="l_clav"/>
    <ignored_collision_filter_group collision_filter_group="core"/>
  </collision_filter_group>
  <collision_filter_group name="r_uleg">
    <member link="r_uglut"/>
    <member link="r_lglut"/>
    <member link="r_uleg"/>
    <ignored_collision_filter_group collision_filter_group="core"/>
    <ignored_collision_filter_group collision_filter_group="r_uleg"/>
    <ignored_collision_filter_group collision_filter_group="l_uleg"/>
  </collision_filter_group>
  <collision_filter_group name="l_uleg">
    <member link="l_uglut"/>
    <member link="l_lglut"/>
    <member link="l_uleg"/>
    <ignored_collision_filter_group collision_filter_group="core"/>
    <ignored_collision_filter_group collision_filter_group="r_uleg"/>
    <ignored_collision_filter_group collision_filter_group="l_uleg"/>
  </collision_filter_group>
  <collision_filter_group name="r_leg">
    <member link="r_lleg"/>
    <member link="r_talus"/>
    <member link="r_foot"/>
    <ignored_collision_filter_group collision_filter_group="r_leg"/>
    <ignored_collision_filter_group collision_filter_group="r_uleg"/>
  </collision_filter_group>
  <collision_filter_group name="l_leg">
    <member link="l_lleg"/>
    <member link="l_talus"/>
    <member link="l_foot"/>
    <ignored_collision_filter_group collision_filter_group="l_leg"/>
    <ignored_collision_filter_group collision_filter_group="l_uleg"/>
  </collision_filter_group>
  <collision_filter_group name="r_arm">
    <member link="r_clav"/>
    <member link="r_scap"/>
    <member link="r_uarm"/>
    <member link="r_larm"/>
    <member link="r_farm"/>
    <member link="r_hand"/>
    <ignored_collision_filter_group collision_filter_group="r_arm"/>
  </collision_filter_group>
  <collision_filter_group name="l_arm">
    <member link="l_clav"/>
    <member link="l_scap"/>
    <member link="l_uarm"/>
    <member link="l_larm"/>
    <member link="l_farm"/>
    <member link="l_hand"/>
    <ignored_collision_filter_group collision_filter_group="l_arm"/>
  </collision_filter_group>
  <joint name="back_bkx" type="revolute">
    <origin rpy="0 -0 0" xyz="0 0 0.05"/>
    <axis xyz="1 0 0"/>
    <parent link="mtorso"/>
    <child link="utorso"/>
    <dynamics damping="0.1" friction="0"/>
    <limit effort="200" lower="-0.698132" upper="0.698132" velocity="12"/>
    <safety_controller k_position="100" k_velocity="100" soft_lower_limit="-10.6981" soft_upper_limit="10.6981"/>
  </joint>
  <joint name="back_bky" type="revolute">
    <origin rpy="0 -0 0" xyz="0 0 0.16197"/>
    <axis xyz="0 1 0"/>
    <parent link="ltorso"/>
    <child link="mtorso"/>
    <dynamics damping="0.1" friction="0"/>
    <limit effort="206.843" lower="-0.262" upper="0.524" velocity="12"/>
    <safety_controller k_position="100" k_velocity="100" soft_lower_limit="-10.6107" soft_upper_limit="10.4384"/>
  </joint>
  <joint name="back_bkz" type="revolute">
    <origin rpy="0 -0 0" xyz="-0.0125 0 0"/>
    <axis xyz="0 0 1"/>
    <parent link="pelvis"/>
    <child link="ltorso"/>
    <dynamics damping="0.1" friction="0"/>
    <limit effort="114" lower="-0.663225" upper="0.663225" velocity="12"/>
    <safety_controller k_position="100" k_velocity="100" soft_lower_limit="-10.6632" soft_upper_limit="10.6632"/>
  </joint>
  <joint name="l_arm_elx" type="revolute">
    <origin rpy="0 -0 0" xyz="0 0.119 0.00921"/>
    <axis xyz="1 0 0"/>
    <parent link="l_uarm"/>
    <child link="l_larm"/>
    <dynamics damping="0.1" friction="0"/>
    <limit effort="55" lower="0" upper="2.35619" velocity="12"/>
    <safety_controller k_position="100" k_velocity="100" soft_lower_limit="-10" soft_upper_limit="12.3562"/>
  </joint>
  <joint name="l_arm_ely" type="revolute">
    <origin rpy="0 -0 0" xyz="0 0.187 0.016"/>
    <axis xyz="0 1 0"/>
    <parent link="l_scap"/>
    <child link="l_uarm"/>
    <dynamics damping="0.1" friction="0"/>
    <limit effort="55" lower="0" upper="3.14159" velocity="12"/>
    <safety_controller k_position="100" k_velocity="100" soft_lower_limit="-10" soft_upper_limit="13.1416"/>
  </joint>
  <joint name="l_arm_shx" type="revolute">
    <origin rpy="0 -0 0" xyz="0 0.14035 0.19609"/>
    <axis xyz="1 0 0"/>
    <parent link="l_clav"/>
    <child link="l_scap"/>
    <dynamics damping="0.1" friction="0"/>
    <limit effort="107" lower="-1.5708" upper="1.5708" velocity="12"/>
    <safety_controller k_position="100" k_velocity="100" soft_lower_limit="-11.5708" soft_upper_limit="11.5708"/>
  </joint>
  <joint name="l_arm_usy" type="revolute">
    <origin rpy="0 -0 0" xyz="0.06441 0.13866 0.10718"/>
    <axis xyz="0 0.5 0.866025"/>
    <parent link="utorso"/>
    <child link="l_clav"/>
    <dynamics damping="0.1" friction="0"/>
    <limit effort="75" lower="-1.5708" upper="0.785398" velocity="12"/>
    <safety_controller k_position="100" k_velocity="100" soft_lower_limit="-11.5708" soft_upper_limit="10.7854"/>
  </joint>
  <joint name="l_arm_mwx" type="revolute">
    <origin rpy="0 -0 0" xyz="0 0.119 0.00921"/>
    <axis xyz="1 0 0"/>
    <parent link="l_farm"/>
    <child link="l_hand"/>
    <dynamics damping="0.1" friction="0"/>
    <limit effort="55" lower="-1.1781" upper="1.1781" velocity="12"/>
    <safety_controller k_position="100" k_velocity="100" soft_lower_limit="-11.1781" soft_upper_limit="11.1781"/>
  </joint>









  <joint name="l_arm_uwy" type="revolute">
    <origin rpy="0 -0 0" xyz="0 0.187 -0.00921"/>
    <axis xyz="0 1 0"/>
    <parent link="l_larm"/>
    <child link="l_farm"/>
    <dynamics damping="0.1" friction="0"/>
    <limit effort="55" lower="0" upper="3.14159" velocity="12"/>
    <safety_controller k_position="100" k_velocity="100" soft_lower_limit="-10" soft_upper_limit="13.1416"/>
  </joint>
  <joint name="l_leg_akx" type="revolute">
    <origin rpy="0 -0 0" xyz="0 0 0"/>
    <axis xyz="1 0 0"/>
    <parent link="l_talus"/>
    <child link="l_foot"/>
    <dynamics damping="1.0" friction="0"/>
    <limit effort="130" lower="-0.8" upper="0.8" velocity="12"/>
    <safety_controller k_position="100" k_velocity="100" soft_lower_limit="-10.8" soft_upper_limit="10.8"/>
  </joint>
  <joint name="l_leg_aky" type="revolute">
    <origin rpy="0 -0 0" xyz="0 0 -0.422"/>
    <axis xyz="0 1 0"/>
    <parent link="l_lleg"/>
    <child link="l_talus"/>
    <dynamics damping="1.0" friction="0"/>
    <limit effort="350" lower="-1" upper="0.7" velocity="12"/>
    <safety_controller k_position="100" k_velocity="100" soft_lower_limit="-11" soft_upper_limit="10.7"/>
  </joint>
  <joint name="l_leg_hpx" type="revolute">
    <origin rpy="0 -0 0" xyz="0 0 0"/>
    <axis xyz="1 0 0"/>
    <parent link="l_uglut"/>
    <child link="l_lglut"/>
    <dynamics damping="0.1" friction="0"/>
    <limit effort="250" effort_max="250" effort_min="-343" lower="-0.523599" upper="0.523599" velocity="12"/>
    <safety_controller k_position="100" k_velocity="100" soft_lower_limit="-10.5236" soft_upper_limit="10.5236"/>
  </joint>
  <joint name="l_leg_hpy" type="revolute">
    <origin rpy="0 -0 0" xyz="0.05 0 -0.05"/>
    <axis xyz="0 1 0"/>
    <parent link="l_lglut"/>
    <child link="l_uleg"/>
    <dynamics damping="0.1" friction="0"/>
    <limit effort="260" effort_max="353" effort_min="-260" lower="-1.72072" upper="0.524821" velocity="12"/>
    <safety_controller k_position="100" k_velocity="100" soft_lower_limit="-11.7207" soft_upper_limit="10.5248"/>
  </joint>
  <joint name="l_leg_hpz" type="revolute">
    <origin rpy="0 -0 0" xyz="0 0.089 0"/>
    <axis xyz="0 0 1"/>
    <parent link="pelvis"/>
    <child link="l_uglut"/>
    <dynamics damping="0.1" friction="0"/>
    <limit effort="68" effort_max="68" effort_min="-105" lower="-0.174533" upper="1.22173" velocity="12"/>
    <safety_controller k_position="100" k_velocity="100" soft_lower_limit="-10.1745" soft_upper_limit="11.2217"/>
  </joint>
  <joint name="l_leg_kny" type="revolute">
    <origin rpy="0 -0 0" xyz="-0.05 0 -0.374"/>
    <axis xyz="0 1 0"/>
    <parent link="l_uleg"/>
    <child link="l_lleg"/>
    <dynamics damping="0.1" friction="0"/>
    <limit effort="220" effort_max="220" effort_min="-300" lower="0" upper="2.38569" velocity="12"/>
    <safety_controller k_position="100" k_velocity="100" soft_lower_limit="-10" soft_upper_limit="12.3857"/>
  </joint>
  <joint name="neck_ay" type="revolute">
    <origin rpy="0 -0 0" xyz="0.21672 0 0.53796"/>
    <axis xyz="0 1 0"/>
    <parent link="utorso"/>
    <child link="head"/>
    <dynamics damping="0.1" friction="0"/>
    <limit effort="5" lower="-0.602139" upper="1.14494" velocity="12"/>
    <safety_controller k_position="100" k_velocity="100" soft_lower_limit="-10.6021" soft_upper_limit="11.1449"/>
  </joint>
  <joint name="r_arm_elx" type="revolute">
    <origin rpy="0 -0 0" xyz="0 -0.119 0.00921"/>
    <axis xyz="1 0 0"/>
    <parent link="r_uarm"/>
    <child link="r_larm"/>
    <dynamics damping="0.1" friction="0"/>
    <limit effort="55" lower="-2.35619" upper="0" velocity="12"/>
    <safety_controller k_position="100" k_velocity="100" soft_lower_limit="-12.3562" soft_upper_limit="10"/>
  </joint>
  <joint name="r_arm_ely" type="revolute">
    <origin rpy="0 -0 0" xyz="0 -0.187 0.016"/>
    <axis xyz="0 1 0"/>
    <parent link="r_scap"/>
    <child link="r_uarm"/>
    <dynamics damping="0.1" friction="0"/>
    <limit effort="55" lower="0" upper="3.14159" velocity="12"/>
    <safety_controller k_position="100" k_velocity="100" soft_lower_limit="-10" soft_upper_limit="13.1416"/>
  </joint>
  <joint name="r_arm_shx" type="revolute">
    <origin rpy="0 -0 0" xyz="0 -0.14035 0.19609"/>
    <axis xyz="1 0 0"/>
    <parent link="r_clav"/>
    <child link="r_scap"/>
    <dynamics damping="0.1" friction="0"/>
    <limit effort="107" lower="-1.5708" upper="1.5708" velocity="12"/>
    <safety_controller k_position="100" k_velocity="100" soft_lower_limit="-11.5708" soft_upper_limit="11.5708"/>
  </joint>
  <joint name="r_arm_usy" type="revolute">
    <origin rpy="0 -0 0" xyz="0.06441 -0.13866 0.10718"/>
    <axis xyz="0 0.5 -0.866025"/>
    <parent link="utorso"/>
    <child link="r_clav"/>
    <dynamics damping="0.1" friction="0"/>
    <limit effort="75" lower="-1.5708" upper="0.785398" velocity="12"/>
    <safety_controller k_position="100" k_velocity="100" soft_lower_limit="-11.5708" soft_upper_limit="10.7854"/>
  </joint>
  <joint name="r_arm_mwx" type="revolute">
    <origin rpy="0 -0 0" xyz="0 -0.119 0.00921"/>
    <axis xyz="1 0 0"/>
    <parent link="r_farm"/>
    <child link="r_hand"/>
    <dynamics damping="0.1" friction="0"/>
    <limit effort="55" lower="-1.1781" upper="1.1781" velocity="12"/>
    <safety_controller k_position="100" k_velocity="100" soft_lower_limit="-11.1781" soft_upper_limit="11.1781"/>
  </joint>
  <joint name="r_arm_uwy" type="revolute">
    <origin rpy="0 -0 0" xyz="0 -0.187 -0.00921"/>
    <axis xyz="0 1 0"/>
    <parent link="r_larm"/>
    <child link="r_farm"/>
    <dynamics damping="0.1" friction="0"/>
    <limit effort="55" lower="0" upper="3.14159" velocity="12"/>
    <safety_controller k_position="100" k_velocity="100" soft_lower_limit="-10" soft_upper_limit="13.1416"/>
  </joint>
  <joint name="r_leg_akx" type="revolute">
    <origin rpy="0 -0 0" xyz="0 0 0"/>
    <axis xyz="1 0 0"/>
    <parent link="r_talus"/>
    <child link="r_foot"/>
    <dynamics damping="1.0" friction="0"/>
    <limit effort="130" lower="-0.8" upper="0.8" velocity="12"/>
    <safety_controller k_position="100" k_velocity="100" soft_lower_limit="-10.8" soft_upper_limit="10.8"/>
  </joint>
  <joint name="r_leg_aky" type="revolute">
    <origin rpy="0 -0 0" xyz="0 0 -0.422"/>
    <axis xyz="0 1 0"/>
    <parent link="r_lleg"/>
    <child link="r_talus"/>
    <dynamics damping="1.0" friction="0"/>
    <limit effort="350" lower="-1" upper="0.7" velocity="12"/>
    <safety_controller k_position="100" k_velocity="100" soft_lower_limit="-11" soft_upper_limit="10.7"/>
  </joint>
  <joint name="r_leg_hpx" type="revolute">
    <origin rpy="0 -0 0" xyz="0 0 0"/>
    <axis xyz="1 0 0"/>
    <parent link="r_uglut"/>
    <child link="r_lglut"/>
    <dynamics damping="0.1" friction="0"/>
    <limit effort="250" effort_max="343" effort_min="-250" lower="-0.523599" upper="0.523599" velocity="12"/>
    <safety_controller k_position="100" k_velocity="100" soft_lower_limit="-10.5236" soft_upper_limit="10.5236"/>
  </joint>
  <joint name="r_leg_hpy" type="revolute">
    <origin rpy="0 -0 0" xyz="0.05 0 -0.05"/>
    <axis xyz="0 1 0"/>
    <parent link="r_lglut"/>
    <child link="r_uleg"/>
    <dynamics damping="0.1" friction="0"/>
    <limit effort="260" effort_max="353" effort_min="-260" lower="-1.72072" upper="0.524821" velocity="12"/>
    <safety_controller k_position="100" k_velocity="100" soft_lower_limit="-11.7207" soft_upper_limit="10.5248"/>
  </joint>
  <joint name="r_leg_hpz" type="revolute">
    <origin rpy="0 -0 0" xyz="0 -0.089 0"/>
    <axis xyz="0 0 1"/>
    <parent link="pelvis"/>
    <child link="r_uglut"/>
    <dynamics damping="0.1" friction="0"/>
    <limit effort="68" effort_max="105" effort_min="-68" lower="-1.22173" upper="0.174533" velocity="12"/>
    <safety_controller k_position="100" k_velocity="100" soft_lower_limit="-11.2217" soft_upper_limit="10.1745"/>
  </joint>
  <joint name="r_leg_kny" type="revolute">
    <origin rpy="0 -0 0" xyz="-0.05 0 -0.374"/>
    <axis xyz="0 1 0"/>
    <parent link="r_uleg"/>
    <child link="r_lleg"/>
    <dynamics damping="0.1" friction="0"/>
    <limit effort="220" effort_max="220" effort_min="-300" lower="0" upper="2.38569" velocity="12"/>
    <safety_controller k_position="100" k_velocity="100" soft_lower_limit="-10" soft_upper_limit="12.3857"/>
  </joint>
  <transmission name="back_bkz_trans" type="pr2_mechanism_model/SimpleTransmission">
    <joint name="back_bkz"/>
    <actuator name="back_bkz_motor"/>
    <mechanicalReduction>1</mechanicalReduction>
  </transmission>
  <transmission name="back_bky_trans" type="pr2_mechanism_model/SimpleTransmission">
    <actuator name="back_bky_motor"/>
    <joint name="back_bky"/>
    <mechanicalReduction>1</mechanicalReduction>
  </transmission>
  <transmission name="back_bkx_trans" type="pr2_mechanism_model/SimpleTransmission">
    <actuator name="back_bkx_motor"/>
    <joint name="back_bkx"/>
    <mechanicalReduction>1</mechanicalReduction>
  </transmission>
  <transmission name="l_arm_elx_trans" type="pr2_mechanism_model/SimpleTransmission">
    <actuator name="l_arm_elx_motor"/>
    <joint name="l_arm_elx"/>
    <mechanicalReduction>1</mechanicalReduction>
  </transmission>
  <transmission name="l_arm_ely_trans" type="pr2_mechanism_model/SimpleTransmission">
    <actuator name="l_arm_ely_motor"/>
    <joint name="l_arm_ely"/>
    <mechanicalReduction>1</mechanicalReduction>
  </transmission>
  <transmission name="l_arm_mwx_trans" type="pr2_mechanism_model/SimpleTransmission">
    <actuator name="l_arm_mwx_motor"/>
    <joint name="l_arm_mwx"/>
    <mechanicalReduction>1</mechanicalReduction>
  </transmission>
  <transmission name="l_arm_shx_trans" type="pr2_mechanism_model/SimpleTransmission">
    <actuator name="l_arm_shx_motor"/>
    <joint name="l_arm_shx"/>
    <mechanicalReduction>1</mechanicalReduction>
  </transmission>
  <transmission name="l_arm_usy_trans" type="pr2_mechanism_model/SimpleTransmission">
    <actuator name="l_arm_usy_motor"/>
    <joint name="l_arm_usy"/>
    <mechanicalReduction>1</mechanicalReduction>
  </transmission>
  <transmission name="l_arm_uwy_trans" type="pr2_mechanism_model/SimpleTransmission">
    <actuator name="l_arm_uwy_motor"/>
    <joint name="l_arm_uwy"/>
    <mechanicalReduction>1</mechanicalReduction>
  </transmission>
  <transmission name="l_leg_kny_trans" type="pr2_mechanism_model/SimpleTransmission">
    <actuator name="l_leg_kny_motor"/>
    <joint name="l_leg_kny"/>
    <mechanicalReduction>1</mechanicalReduction>
  </transmission>
  <transmission name="l_leg_akx_trans" type="pr2_mechanism_model/SimpleTransmission">
    <actuator name="l_leg_akx_motor"/>
    <joint name="l_leg_akx"/>
    <mechanicalReduction>1</mechanicalReduction>
  </transmission>
  <transmission name="l_leg_hpy_trans" type="pr2_mechanism_model/SimpleTransmission">
    <actuator name="l_leg_hpy_motor"/>
    <joint name="l_leg_hpy"/>
    <mechanicalReduction>1</mechanicalReduction>
  </transmission>
  <transmission name="l_leg_hpx_trans" type="pr2_mechanism_model/SimpleTransmission">
    <actuator name="l_leg_hpx_motor"/>
    <joint name="l_leg_hpx"/>
    <mechanicalReduction>1</mechanicalReduction>
  </transmission>
  <transmission name="l_leg_aky_trans" type="pr2_mechanism_model/SimpleTransmission">
    <actuator name="l_leg_aky_motor"/>
    <joint name="l_leg_aky"/>
    <mechanicalReduction>1</mechanicalReduction>
  </transmission>
  <transmission name="l_leg_hpz_trans" type="pr2_mechanism_model/SimpleTransmission">
    <actuator name="l_leg_hpz_motor"/>
    <joint name="l_leg_hpz"/>
    <mechanicalReduction>1</mechanicalReduction>
  </transmission>
  <transmission name="neck_ay_trans" type="pr2_mechanism_model/SimpleTransmission">
    <actuator name="neck_ay_motor"/>
    <joint name="neck_ay"/>
    <mechanicalReduction>1</mechanicalReduction>
  </transmission>
  <transmission name="r_arm_elx_trans" type="pr2_mechanism_model/SimpleTransmission">
    <actuator name="r_arm_elx_motor"/>
    <joint name="r_arm_elx"/>
    <mechanicalReduction>1</mechanicalReduction>
  </transmission>
  <transmission name="r_arm_ely_trans" type="pr2_mechanism_model/SimpleTransmission">
    <actuator name="r_arm_ely_motor"/>
    <joint name="r_arm_ely"/>
    <mechanicalReduction>1</mechanicalReduction>
  </transmission>
  <transmission name="r_arm_mwx_trans" type="pr2_mechanism_model/SimpleTransmission">
    <actuator name="r_arm_mwx_motor"/>
    <joint name="r_arm_mwx"/>
    <mechanicalReduction>1</mechanicalReduction>
  </transmission>
  <transmission name="r_arm_shx_trans" type="pr2_mechanism_model/SimpleTransmission">
    <actuator name="r_arm_shx_motor"/>
    <joint name="r_arm_shx"/>
    <mechanicalReduction>1</mechanicalReduction>
  </transmission>
  <transmission name="r_arm_usy_trans" type="pr2_mechanism_model/SimpleTransmission">
    <actuator name="r_arm_usy_motor"/>
    <joint name="r_arm_usy"/>
    <mechanicalReduction>1</mechanicalReduction>
  </transmission>
  <transmission name="r_arm_uwy_trans" type="pr2_mechanism_model/SimpleTransmission">
    <actuator name="r_arm_uwy_motor"/>
    <joint name="r_arm_uwy"/>
    <mechanicalReduction>1</mechanicalReduction>
  </transmission>
  <transmission name="r_leg_kny_trans" type="pr2_mechanism_model/SimpleTransmission">
    <actuator name="r_leg_kny_motor"/>
    <joint name="r_leg_kny"/>
    <mechanicalReduction>1</mechanicalReduction>
  </transmission>
  <transmission name="r_leg_akx_trans" type="pr2_mechanism_model/SimpleTransmission">
    <actuator name="r_leg_akx_motor"/>
    <joint name="r_leg_akx"/>
    <mechanicalReduction>1</mechanicalReduction>
  </transmission>
  <transmission name="r_leg_hpy_trans" type="pr2_mechanism_model/SimpleTransmission">
    <actuator name="r_leg_hpy_motor"/>
    <joint name="r_leg_hpy"/>
    <mechanicalReduction>1</mechanicalReduction>
  </transmission>
  <transmission name="r_leg_hpx_trans" type="pr2_mechanism_model/SimpleTransmission">
    <actuator name="r_leg_hpx_motor"/>
    <joint name="r_leg_hpx"/>
    <mechanicalReduction>1</mechanicalReduction>
  </transmission>
  <transmission name="r_leg_aky_trans" type="pr2_mechanism_model/SimpleTransmission">
    <actuator name="r_leg_aky_motor"/>
    <joint name="r_leg_aky"/>
    <mechanicalReduction>1</mechanicalReduction>
  </transmission>
  <transmission name="r_leg_hpz_trans" type="pr2_mechanism_model/SimpleTransmission">
    <actuator name="r_leg_hpz_motor"/>
    <joint name="r_leg_hpz"/>
    <mechanicalReduction>1</mechanicalReduction>
  </transmission>
  <link name="head">
    <inertial>
      <origin rpy="0 0 0" xyz="-0.075493 3.3383E-05 0.02774"/>
      <!-- includes mass of hokuyo link and imu -->
      <mass value="1.477574"/>
      <inertia ixx="0.0036053766" ixy="-1.5797E-06" ixz="-0.00089293" iyy="0.002080106" iyz="-6.8415E-07" izz="0.001782985"/>
    </inertial>
    <visual>
      <origin rpy="0 0 0" xyz="0 0 0"/>
      <geometry>
        <mesh filename="meshes/head.wrl"/>
      </geometry>
      <material name="">
        <color rgba="0.9098 0.44314 0.031373 1"/>
      </material>
    </visual>
  </link>
</robot>
