<?xml version='1.0' ?>

<sdf version='1.6'>
  <model name='prius_1'>
    <pose>0 0 0 0 0 0</pose>
    <link name='chassis_floor'>
      <pose>0 0 0.385184 0 0 0</pose>
      <inertial>
       <pose>0 0 0 0 0 0</pose>
        <mass>57.833</mass>
        <inertia>
          <ixx>2.71553</ixx>
          <ixy>0</ixy>
          <ixz>0</ixz>
          <iyy>68.9</iyy>
          <iyz>0</iyz>
          <izz>71.6063</izz>
        </inertia>
      </inertial>
      <visual name='main'>
        <pose>0 0 0 0 0 0</pose>
        <geometry>
          <box>
            <size>2.8808 0.75 0.030921</size>
          </box>
        </geometry>
        <material>
          <diffuse>1 1 1 1</diffuse>
        </material>
      </visual>
    </link>

    <link name='front_axle'>
      <pose>1.40948 0 0.3302 0 0 0</pose>
      <visual name='visual'>
        <pose>0 0 0 0 0 0</pose>
        <geometry>
          <box>
            <size>0.061842 1.05132 0.030921</size>
          </box>
        </geometry>
        <material>
          <diffuse>0 0 1 1</diffuse>
        </material>
      </visual>
    </link>
    
    <link name='left_tie_rod_arm'>
      <pose>1.23701032 .40850253 0.299279 0 0 0</pose>
      <visual name='v2'>
        <pose>.06385963 0.03192981 0 0 0 0.463648</pose>
        <geometry>
          <box>
            <size>0.204637 0.061842 0.030921</size>
          </box>
        </geometry>
        <material>
          <diffuse>0 0.5 0 1</diffuse>
        </material>
      </visual>
      <visual name='v1'>
        <pose>.17246863 0.10851978 0 0 -0 0</pose>
        <geometry>
          <box>
            <size>0.061842 0.140955 0.030921</size>
          </box>
        </geometry>
        <material>
          <diffuse>0 0.5 0 1</diffuse>
        </material>
      </visual>
    </link>

    <link name='left_hub'>
      <pose>1.40948 0.618421 0.323342 1.5708 0 0</pose>
      <visual name='visual'>
        <pose>0 0 0 0 0 0</pose>
        <geometry>
          <cylinder>
            <length>0.0618421</length>
            <radius>0.0154605</radius>
          </cylinder>
        </geometry>
        <material>
          <diffuse>0 0 1 1</diffuse>
        </material>
      </visual>
    </link>

    <link name='tie_rod'> 
      <pose>1.23701 0 0.3302 0 0 0</pose>
      <visual name='visual'>
        <pose>0 0 0 0 0 0</pose>
        <geometry>
          <box>
            <size>0.061842 0.878847 0.030921</size>
          </box>
        </geometry>
        <material>
          <diffuse>0 0 1 1</diffuse>
      </material>
      </visual>
    </link>

    <link name='left_wheel'>
      <pose>1.40948 0.801993 0.323342 1.5708 0 0</pose>
      <inertial>
        <mass>14.28</mass>
        <inertia>
          <ixx>0.499912</ixx>
          <ixy>0</ixy>
          <ixz>0</ixz>
          <iyy>0.778439</iyy>
          <iyz>0</iyz>
          <izz>0.499912</izz>
        </inertia>
      </inertial>
      <visual name='m2'>
        <pose>0 0 -.1075 0 1.57079 3.14159</pose>
        <material>
          <diffuse>0.9 0.9 0.9 1</diffuse>
        </material>
        <geometry>
          <box>
            <size>0.0025 0.0025 0.25</size>
          </box>
        </geometry>
      </visual>
      <visual name='wheel'>
        <pose>0 0 0 0 0 0</pose>
        <geometry>
          <cylinder>
            <length>0.215</length>
            <radius>0.323342</radius>
          </cylinder>
        </geometry>
        <material>
          <diffuse>0.2 0.2 0.2 1</diffuse>
        </material>
      </visual>
      <visual name='m1'>
        <pose>0 0 -.1075 0 1.5708 1.5708</pose>
        <material>
          <diffuse>0.9 0.9 0.9 1</diffuse>
        </material>
        <geometry>
          <box>
            <size>0.0025 0.0025 0.25</size>
          </box>
        </geometry>
      </visual>
      <collision name='wheel'>
        <laser_retro>0</laser_retro>
        <max_contacts>10</max_contacts>
        <pose>0 0 0 0 0 0</pose>
        <geometry>
          <cylinder>
            <radius>0.323342</radius>
            <length>0.215</length>
          </cylinder>
        </geometry>
      </collision>
    </link>

    <link name='right_tie_rod_arm'>
      <pose>1.23701032 -.40850253 0.299279 0 0 0</pose>
      <visual name='v1'>
        <pose>.17246863 -0.10851978 0 0 -0 0</pose>
        <geometry>
          <box>
            <size>0.061842 0.140955 0.030921</size>
          </box>
        </geometry>
        <material>
          <diffuse>0 0.5 0 1</diffuse>
        </material>
      </visual>
      <visual name='v2'>
        <pose>.06385963 -0.03192981 0 0 0 -0.463648</pose>
        <geometry>
          <box>
            <size>0.204637 0.061842 0.030921</size>
          </box>
        </geometry>
        <material>
          <diffuse>0 0.5 0 1</diffuse>
        </material>
      </visual>
    </link>

    <link name='right_hub'>
      <pose>1.40948 -0.618421 0.323342 1.5708 0 0</pose>
      <visual name='visual'>
        <pose>0 0 0 0 0 0</pose>
        <geometry>
          <cylinder>
            <length>0.0618421</length>
            <radius>0.0154605</radius>
          </cylinder>
        </geometry>
        <material>
          <diffuse>0 0 1 1</diffuse>
        </material>
      </visual>
    </link>

    <link name='right_wheel'>
      <pose>1.40948 -0.801993 0.323342 1.5708 0 0</pose>
      <inertial>
        <mass>14.28</mass>
        <inertia>
          <ixx>0.499912</ixx>
          <ixy>0</ixy>
          <ixz>0</ixz>
          <iyy>0.778439</iyy>
          <iyz>0</iyz>
          <izz>0.499912</izz>
        </inertia>
      </inertial>
      <visual name='m2'>
        <pose>0 0 .1075 0 1.57079 3.14159</pose>
        <material>
          <diffuse>0.9 0.9 0.9 1</diffuse>
        </material>
        <geometry>
          <box>
            <size>0.0025 0.0025 0.25</size>
          </box>
        </geometry>
      </visual>
      <visual name='wheel'>
        <pose>0 0 0 0 0 0</pose>
        <geometry>
          <cylinder>
            <length>0.215</length>
            <radius>0.323342</radius>
          </cylinder>
        </geometry>
        <material>
          <diffuse>0.2 0.2 0.2 1</diffuse>
        </material>
      </visual>
      <visual name='m1'>
        <pose>0 0 .1075 0 1.5708 1.5708</pose>
        <material>
          <diffuse>0.9 0.9 0.9 1</diffuse>
        </material>
        <geometry>
          <box>
            <size>0.0025 0.0025 0.25</size>
          </box>
        </geometry>
      </visual>
      <collision name='wheel'>
        <laser_retro>0</laser_retro>
        <max_contacts>10</max_contacts>
        <pose>0 0 0 0 0 0</pose>
        <geometry>
          <cylinder>
            <radius>0.323342</radius>
            <length>0.215</length>
          </cylinder>
        </geometry>
      </collision>
    </link>
    
    <joint name='chassis_floor_axle' type='fixed'>
      <parent>chassis_floor</parent>
      <child>front_axle</child>
      <pose>0 0 0 0 0 0</pose>
    </joint>

    <joint name='steering' type='revolute'>
      <parent>front_axle</parent>
      <child>left_tie_rod_arm</child>
      <pose>.17246863 .08623431 0 0 0 0</pose>
      <axis>
        <xyz>0 0 1</xyz>
        <limit>
          <lower>-0.401426</lower>
          <upper>0.5</upper>
        </limit>
      </axis>
    </joint>

    <joint name='left_hub' type='fixed'>
      <parent>left_tie_rod_arm</parent>
      <child>left_hub</child>
      <pose>0 0 0 0 0 0</pose> 
    </joint>
    
    <joint name='left_pin' type='revolute'>
      <parent>left_tie_rod_arm</parent>
      <child>tie_rod</child>
      <pose>0 0.408503 0 0 0 0</pose>
      <axis>
        <xyz>0 0 1</xyz>
        <limit>
          <lower>-3.14</lower>
          <upper>3.14</upper>
          <effort>0</effort>
        </limit>
      </axis>
    </joint>
    
    <joint name='left_wheel_joint' type='revolute'>
      <parent>left_hub</parent>
      <child>left_wheel</child>
      <pose>0 0 0 0 0 0</pose>
      <axis>
        <!-- <xyz>0 0 -1</xyz> -->
        <xyz>0 1 0</xyz>
        <use_parent_model_frame>1</use_parent_model_frame>
      </axis>
    </joint>
    
    <joint name='axle_tie_rod_arm' type='revolute'>
      <parent>front_axle</parent>
      <child>right_tie_rod_arm</child>
      <pose>.17246863 -.08623431 0 0 0 0</pose>
      <axis>
        <xyz>0 0 1</xyz>
        <limit>
          <lower>-0.401426</lower>
          <upper>0.5</upper>
          <effort>0</effort>
        </limit>
      </axis>
    </joint>

    <joint name='right_hub' type='fixed'>
      <parent>right_tie_rod_arm</parent>
      <child>right_hub</child>
      <pose>0 0 0 0 0 0</pose>
    </joint>
    
   <!--  <joint name='right_pin' type='revolute'>
      <parent>right_tie_rod_arm</parent>
      <child>tie_rod</child> -->
      <!-- the tie_rod's reference frame was modified internally by Drake to be at the left_pin -->
      <!-- <pose>0 -0.408503 0 0 0 0</pose> -->
      <!-- <pose>0 -0.817006 0 0 0 0</pose>
      <axis>
        <xyz>0 0 1</xyz>
        <limit>
          <lower>-3.1416</lower>
          <upper>3.1416</upper>
        </limit>
      </axis>
    </joint> -->

    <joint name='right_wheel_joint' type='revolute'>
      <parent>right_hub</parent>
      <child>right_wheel</child>
      <pose>0 0 0 0 0 0</pose>
      <axis>
        <xyz>0 1 0</xyz>
        <use_parent_model_frame>1</use_parent_model_frame>
      </axis>
    </joint>

  </model>
</sdf>

 