<sdf version='1.6'>
  <model name='acrobot'>
    <!-- This sdf file produces a model with the default parameters documented
         in AcrobotParameters in make_acrobot_plant.h.
         They MUST be kept in sync. -->
    <link name='Link1'>
      <pose>0 0 -0.5 0 0 0</pose>
      <inertial>
        <mass>1.0</mass>
        <!-- This inertia is based on a solid cylinder with
             radius=0.001 meters and height=1.0 meters. -->
	    <!-- For this model we could make izz = 0 however, sdformat will throw
	         an exception. -->
        <inertia>
          <ixx>0.083</ixx><iyy>0.083</iyy><izz>5e-7</izz>
          <ixy>0</ixy><ixz>0</ixz><iyz>0</iyz>
        </inertia>
      </inertial>
    </link>
    <link name='Link2'>
      <pose>0 0 -2.0 0 0 0</pose>
      <inertial>
        <mass>1.0</mass>
        <!-- This inertia is based on a solid cylinder with
             radius=1.0 meters and height=2.0 meters. -->
        <!-- For this model we could make izz = 0 however, sdformat will throw
             an exception. -->
        <inertia>
          <ixx>0.33</ixx><iyy>0.33</iyy><izz>5e-7</izz>
          <ixy>0</ixy><ixz>0</ixz><iyz>0</iyz>
        </inertia>
      </inertial>
    </link>
    <joint name='ShoulderJoint' type='revolute'>
      <parent>world</parent>
      <child>Link1</child>
      <axis>
        <xyz>0.0 1.0 0.0</xyz>
      </axis>
    </joint>
    <joint name='ElbowJoint' type='revolute'>
      <pose>0 0 -1.0 0 0 0</pose>
      <parent>Link1</parent>
      <child>Link2</child>
      <axis>
        <xyz>0.0 1.0 0.0</xyz>
      </axis>
    </joint>
  </model>
</sdf>
