<?xml version="1.0" ?>
<!-- =================================================================================== -->
<!-- |    This document was autogenerated by xacro from KneedCompassGait.xacro         | -->
<!-- |    EDITING THIS FILE BY HAND IS NOT RECOMMENDED                                 | -->
<!-- =================================================================================== -->
<robot xmlns="http://drake.mit.edu"
 xmlns:xsi="http://www.w3.org/2001/XMLSchema-instance"
 xsi:schemaLocation="http://drake.mit.edu ../../doc/drakeURDF.xsd"
 xmlns:xacro="http://ros.org/wiki/xacro" name="KneedCompassGait">
  <link name="hip">
    <inertial>
      <mass value="10"/>
      <inertia ixx="0" ixy="0" ixz="0" iyy="0" iyz="0" izz="0"/>
    </inertial>
    <visual>
      <geometry>
        <sphere radius="0.05"/>
      </geometry>
      <material name="green">
        <color rgba="0 1 0 1"/>
      </material>
    </visual>
  </link>
  <link name="left_upper_leg">
    <visual>
      <origin xyz="0 0 -0.25"/>
      <geometry>
        <cylinder length="0.5" radius="0.0075"/>
      </geometry>
      <material name="red">
        <color rgba="1 0 0 1"/>
      </material>
    </visual>
  </link>
  <link name="left_upper_leg_mass">
    <visual>
      <origin xyz="0 0 -0.25"/>
      <geometry>
        <sphere radius="0.025"/>
      </geometry>
      <material name="red">
        <color rgba="1 0 0 1"/>
      </material>
    </visual>
    <inertial>
      <origin xyz="0 0 -0.25"/>
      <mass value="2.5"/>
      <inertia ixx="0" ixy="0" ixz="0" iyy="0" iyz="0" izz="0"/>
    </inertial>
  </link>
  <joint name="left_upper_leg_mass_weld" type="fixed">
    <parent link="left_upper_leg"/>
    <child link="left_upper_leg_mass"/>
  </joint>
  <link name="left_lower_leg">
    <visual>
      <origin xyz="0 0 -0.25"/>
      <geometry>
        <cylinder length="0.5" radius="0.0075"/>
      </geometry>
      <material name="red">
        <color rgba="1 0 0 1"/>
      </material>
    </visual>
    <collision>
      <origin xyz="0 0 -0.5"/>
      <geometry>
        <sphere radius="0"/>
      </geometry>
    </collision>
  </link>
  <link name="left_lower_leg_mass">
    <visual>
      <origin xyz="0 0 -0.25"/>
      <geometry>
        <sphere radius="0.025"/>
      </geometry>
      <material name="red">
        <color rgba="1 0 0 1"/>
      </material>
    </visual>
    <inertial>
      <origin xyz="0 0 -0.25"/>
      <mass value="2.5"/>
      <inertia ixx="0" ixy="0" ixz="0" iyy="0" iyz="0" izz="0"/>
    </inertial>
  </link>
  <joint name="left_lower_leg_mass_weld" type="fixed">
    <parent link="left_lower_leg"/>
    <child link="left_lower_leg_mass"/>
  </joint>
  <link name="right_upper_leg">
    <visual>
      <origin xyz="0 0 -0.25"/>
      <geometry>
        <cylinder length="0.5" radius="0.0075"/>
      </geometry>
      <material name="blue">
        <color rgba="0 0 1 1"/>
      </material>
    </visual>
  </link>
  <link name="right_upper_leg_mass">
    <visual>
      <origin xyz="0 0 -0.25"/>
      <geometry>
        <sphere radius="0.025"/>
      </geometry>
      <material name="blue">
        <color rgba="0 0 1 1"/>
      </material>
    </visual>
    <inertial>
      <origin xyz="0 0 -0.25"/>
      <mass value="2.5"/>
      <inertia ixx="0" ixy="0" ixz="0" iyy="0" iyz="0" izz="0"/>
    </inertial>
  </link>
  <joint name="right_upper_leg_mass_weld" type="fixed">
    <parent link="right_upper_leg"/>
    <child link="right_upper_leg_mass"/>
  </joint>
  <link name="right_lower_leg">
    <visual>
      <origin xyz="0 0 -0.25"/>
      <geometry>
        <cylinder length="0.5" radius="0.0075"/>
      </geometry>
      <material name="blue">
        <color rgba="0 0 1 1"/>
      </material>
    </visual>
    <collision>
      <origin xyz="0 0 -0.5"/>
      <geometry>
        <sphere radius="0"/>
      </geometry>
    </collision>
  </link>
  <link name="right_lower_leg_mass">
    <visual>
      <origin xyz="0 0 -0.25"/>
      <geometry>
        <sphere radius="0.025"/>
      </geometry>
      <material name="blue">
        <color rgba="0 0 1 1"/>
      </material>
    </visual>
    <inertial>
      <origin xyz="0 0 -0.25"/>
      <mass value="2.5"/>
      <inertia ixx="0" ixy="0" ixz="0" iyy="0" iyz="0" izz="0"/>
    </inertial>
  </link>
  <joint name="right_lower_leg_mass_weld" type="fixed">
    <parent link="right_lower_leg"/>
    <child link="right_lower_leg_mass"/>
  </joint>
  <joint name="left_leg_weld" type="fixed">
    <parent link="hip"/>
    <child link="left_upper_leg"/>
  </joint>
  <joint name="hip_pin" type="continuous">
    <parent link="hip"/>
    <child link="right_upper_leg"/>
    <axis xyz="0 1 0"/>
  </joint>
  <joint name="left_knee_pin" type="continuous">
    <parent link="left_upper_leg"/>
    <child link="left_lower_leg"/>
    <axis xyz="0 1 0"/>
    <origin xyz="0 0 -0.5"/>
    <limit effort="100" lower="0"/>
  </joint>
  <joint name="right_knee_pin" type="revolute">
    <parent link="right_upper_leg"/>
    <child link="right_lower_leg"/>
    <axis xyz="0 1 0"/>
    <origin xyz="0 0 -0.5"/>
    <limit effort="100" lower="0"/>
  </joint>
  <transmission name="hip_trans" type="SimpleTransmission">
    <actuator name="hip_torque"/>
    <joint name="hip_pin"/>
    <mechanicalReduction>1</mechanicalReduction>
  </transmission>
  <transmission name="left_knee_trans" type="SimpleTransmission">
    <actuator name="left_knee_torque"/>
    <joint name="left_knee_pin"/>
    <mechanicalReduction>1</mechanicalReduction>
  </transmission>
  <transmission name="right_knee_trans" type="SimpleTransmission">
    <actuator name="right_knee_torque"/>
    <joint name="right_knee_pin"/>
    <mechanicalReduction>1</mechanicalReduction>
  </transmission>
  <collision_filter_group name="robot_links">
    <member link="left_lower_leg_mass"/>
    <member link="right_lower_leg_mass"/>
    <member link="left_lower_leg"/>
    <member link="right_lower_leg"/>
    <member link="right_upper_leg"/>
    <member link="left_upper_leg"/>
    <member link="hip"/>
    <ignored_collision_filter_group collision_filter_group="robot_links"/>
  </collision_filter_group>
</robot>


