<sdf version='1.7'>
  <model name='four_bar'>
    <!--
    This sdf file produces a model of a four bar linkage.

    Links A, B, C, and (the implicit) World link complete the closed kinematic
    chain.

    Each link A, B, C have length 4m and mass 20kg and are approximated by
    boxes with dimensions (4m, 0.1m, 0.1m).

    For each link we define a frame: A, B, C, and W.

              Wz
              ^
              |
   Wx  <- - - ·

   Frame W is the implicit world link with Wo its origin, Wz pointing up, Wx
   pointing left, and Wy pointing out of the page. Gravity points in the -Wz
   direction.

   Frame A is coincident with frame W. In other words X_WA is the identity.
   The origin of the A frame measured in the world, p_WA, is (0, 0, 0).
   Frame A's orientation measured in the world, R_WA, is the identity.
   The Ax axis points along the link.

   Frame B is defined relative to A.
   The origin of the B frame measured in A, p_AB, is (-4, 0, 0)
   Frame B's orientation measured in A, R_AB, is the identity.
   The Bx axis points along the link.

   Frame C is defined relative to W.
   The origin of the C frame measured in the world, p_WC, is (-2, 0, 0).
   Frame C's orientation measured in the world, R_WC, is the identity.
   The Cx axis points along the link.

   For each link, we also define create a revolute joint, located at the
   origin of that link's frame, aligned with the y-axis of that link's frame,
   connecting it to it's "parent".
   q_WA is the y-axis revolute joint between the parent world and the child A.
   q_AB is the y-axis revolute joint between the parent A and the child B.
   q_WC is the y-axis revolute joint between the parent world and the child B.

   There is no joint connecting link B to link C. We will approximate a
   revolute joint between them with a LinearBushingRollPitchYaw ForceElement in
   the code. For this we define two frames:
   BC_bushing is a frame attached to link B.
   CB_bushing is a frame attached to link C.
   See their definition below for the details of how they are defined.

   In the default configuration (i.e. q_WA = q_AB = q_WC = 0) all of the links
   lie flat along the Wx axis. Note this is not a valid configuration that
   satisfies loop closure. However, they are defined in such a way to make
   this SDF readable and so at least q_WA and q_WC are measured relative to a
   fixed axis of the world frame. Please see the README for a detailed
   diagram with configuration angles that satisfy the loop closure equation.
    -->
    <link name='A'>
      <!-- The frame A measured in the world frame, X_WA is the identity. -->
      <pose>0 0 0 0 0 0</pose>
      <inertial>
        <!-- A_cm is located at the midpoint of the bar -->
        <pose>2 0 0 0 0 0</pose>
        <mass>20</mass>
        <inertia>
          <!-- Inertia tensor for a solid cuboid of dimensions
          (l, w, h) = (4.2, 0.1, 0.1) and mass 20kg-->
          <ixx>0.0333333334</ixx><iyy>29.4166667</iyy><izz>29.4166667</izz>
          <ixy>0</ixy><ixz>0</ixz><iyz>0</iyz>
        </inertia>
      </inertial>
      <!-- A skinny red box along the Ax axis -->
      <visual name='A_visual'>
        <pose>2 0 0 0 0 0</pose>
        <geometry>
          <box>
            <size>4.2 0.1 0.1</size>
          </box>
        </geometry>
        <material>
          <diffuse>1 0 0 1</diffuse>
        </material>
      </visual>
      <!-- A visual representing the revolute joint between the world and
       link A. -->
      <visual name='A_pivot_visual'>
        <pose>0 0 0 1.57 0 0</pose>
        <geometry>
          <cylinder>
            <radius>0.01</radius>
            <length>0.15</length>
          </cylinder>
        </geometry>
        <material>
          <diffuse>0 1 0 1</diffuse>
        </material>
      </visual>
    </link>

    <link name='B'>
      <!-- The frame B measured in A, X_AB, is a translation along the Ax
      axis, and a small translation along the Ay (revolute) axis for visual
      purposes -->
      <pose relative_to="A">4 0.1 0 0 0 0</pose>
      <inertial>
        <!-- B_cm is located at the midpoint of the bar -->
        <pose>2 0 0 0 0 0</pose>
        <mass>20</mass>
        <inertia>
          <!-- Inertia tensor for a solid cuboid of dimensions
          (l, w, h) = (4.2, 0.1, 0.1) and mass 20kg-->
          <ixx>0.0333333334</ixx><iyy>29.4166667</iyy><izz>29.4166667</izz>
          <ixy>0</ixy><ixz>0</ixz><iyz>0</iyz>
        </inertia>
      </inertial>
      <!-- A skinny blue box along the Bx axis -->
      <visual name='B_visual'>
        <pose>2 0 0 0 0 0</pose>
        <geometry>
          <box><size>4.1 0.1 0.1</size></box>
        </geometry>
        <material>
          <diffuse>0 0 1 1</diffuse>
        </material>
      </visual>
      <!-- A visual representing the revolute joint between
      link A and link B.  -->
      <visual name='B_pivot_visual'>
        <pose>0 -0.05 0 1.57 0 0</pose>
        <geometry>
          <cylinder>
            <radius>0.01</radius>
            <length>0.25</length>
          </cylinder>
        </geometry>
        <material>
          <diffuse>0 1 0 1</diffuse>
        </material>
      </visual>
    </link>

    <link name='C'>
      <!-- The frame C measured in W, X_WC, is a translation along the Wx
      axis, and a small translation along the Wy (revolute) axis for visual
      purposes -->
      <pose>-2 0.2 0 0 0 0</pose>
      <inertial>
        <!-- C_cm is located at the midpoint of the bar -->
        <pose>2 0 0 0 0 0</pose>
        <mass>20</mass>
        <inertia>
          <!-- Inertia tensor for a solid cuboid of dimensions
          (l, w, h) = (4.2, 0.1, 0.1) and mass 20kg-->
          <ixx>0.0333333334</ixx><iyy>29.4166667</iyy><izz>29.4166667</izz>
          <ixy>0</ixy><ixz>0</ixz><iyz>0</iyz>
        </inertia>
      </inertial>
      <!-- A skinny yellow box along the Bx axis -->
      <visual name='C_visual'>
        <pose>2 0 0 0 0 0</pose>
        <geometry>
          <box><size>4.1 0.1 0.1</size></box>
        </geometry>
        <material>
          <diffuse>1 1 0 1</diffuse>
        </material>
      </visual>
      <!-- A visual representing the revolute joint between the world
      and link C.  -->
      <visual name='C_pivot_visual'>
        <pose>0 0 0 1.57 0 0</pose>
        <geometry>
          <cylinder>
            <radius>0.01</radius>
            <length>0.15</length>
          </cylinder>
        </geometry>
        <material>
          <diffuse>0 1 0 1</diffuse>
        </material>
      </visual>
    </link>

    <joint name='q_WA' type='revolute'>
      <child>A</child>
      <parent>world</parent>
      <axis>
        <!-- atan2(sqrt(15.0), 1.0) see the README for more details.-->
        <initial_position>1.318116071652818</initial_position>
        <xyz>0 1 0</xyz>
        <limit>
          <!-- No limit provided. sdformat defaults to -1, which we parse as
               an actuated joint. -->
        </limit>
        <dynamics>
          <damping>0.1</damping>
        </dynamics>
        <use_parent_model_frame>1</use_parent_model_frame>
      </axis>
    </joint>

    <joint name='q_AB' type='revolute'>
      <child>B</child>
      <parent>A</parent>
      <axis>
        <!-- M_PI - atan2(sqrt(15.0), 1.0) see the README for more details. -->
        <initial_position>1.8234765819369751</initial_position>
        <xyz>0 1 0</xyz>
        <limit>
          <!-- An effort of 0 is parsed as an unactuated joint. -->
          <effort>0</effort>
        </limit>
        <dynamics>
          <damping>0.1</damping>
        </dynamics>
        <use_parent_model_frame>1</use_parent_model_frame>
      </axis>
    </joint>

    <joint name='q_WC' type='revolute'>
      <child>C</child>
      <parent>world</parent>
      <axis>
        <!-- M_PI - atan2(sqrt(15.0), 1.0) see the README for more details. -->
        <initial_position>1.8234765819369751</initial_position>
        <xyz>0 1 0</xyz>
        <limit>
          <!-- An effort of 0 is parsed as an unactuated joint. -->
          <effort>0</effort>
        </limit>
        <dynamics>
          <damping>0.1</damping>
        </dynamics>
        <use_parent_model_frame>1</use_parent_model_frame>
      </axis>
    </joint>

    <!-- A frame at the end of the B link, down the Bx axis. The frame is
    rotated so that the z of BC_Bushing is aligned with the By axis. This is
    done so the LinearBushingRollPitchYaw ForceElement freely rotates around
    its z axis (Yaw) to avoid gimbal lock on the y axis (Pitch) -->
    <frame name="BC_Bushing" attached_to="B">
      <pose relative_to="B">4 0 0 -1.57 0 0</pose>
    </frame>

    <!-- A frame at the end of the C link, down the Cx axis. The frame is
    rotated so that the z of CB_Bushing is aligned with the Cy axis. This is
    done so the LinearBushingRollPitchYaw ForceElement freely rotates around
    its z axis (Yaw) to avoid gimbal lock on the y axis (Pitch) -->
    <frame name="CB_Bushing" attached_to="C">
      <pose relative_to="C">4 0 0 -1.57 0 0</pose>
    </frame>

  </model>
</sdf>
