<?xml version="1.0"?>
<sdf version="1.6">
  <model name="FourBar">
    <link name="base_link">
      <inertial>
        <mass>1</mass>
        <inertia>
          <ixx>1</ixx>
          <ixy>0</ixy>
          <ixz>0</ixz>
          <iyy>1</iyy>
          <iyz>0</iyz>
          <izz>1</izz>
        </inertia>
      </inertial>
      <visual name="base">
        <pose>0 0 0 0 0 0</pose>
        <geometry>
          <cylinder>
            <length>4</length>
            <radius>0.2</radius>
          </cylinder>
        </geometry>
        <material>
          <diffuse>.6353 .6353 .6353 1</diffuse>
        </material>
      </visual>
    </link>
    <link name="link_1">
      <inertial>
        <mass>1</mass>
        <inertia>
          <ixx>1</ixx>
          <ixy>0</ixy>
          <ixz>0</ixz>
          <iyy>1</iyy>
          <iyz>0</iyz>
          <izz>1</izz>
        </inertia>
      </inertial>
      <visual name="link1">
        <pose>0 0 .9 0 0 0</pose>
        <geometry>
          <cylinder>
            <length>1.8</length>
            <radius>0.2</radius>
          </cylinder>
        </geometry>
        <material>
          <diffuse>.6353 .6353 .6353 1</diffuse>
        </material>
      </visual>
    </link>
    <link name="link_2">
      <inertial>
        <mass>1</mass>
        <inertia>
          <ixx>1</ixx>
          <ixy>0</ixy>
          <ixz>0</ixz>
          <iyy>1</iyy>
          <iyz>0</iyz>
          <izz>1</izz>
        </inertia>
      </inertial>
      <visual name="link2">
        <pose>0 0 1.8 0 0 0</pose>
        <geometry>
          <cylinder>
            <length>3.6</length>
            <radius>0.2</radius>
          </cylinder>
        </geometry>
        <material>
          <diffuse>.6353 .6353 .6353 1</diffuse>
        </material>
      </visual>
    </link>
    <link name="link_3">
      <inertial>
        <mass>1</mass>
        <inertia>
          <ixx>1</ixx>
          <ixy>0</ixy>
          <ixz>0</ixz>
          <iyy>1</iyy>
          <iyz>0</iyz>
          <izz>1</izz>
        </inertia>
      </inertial>
      <visual name="link3">
        <pose>0 0 1.3 0 0 0</pose>
        <geometry>
          <cylinder>
            <length>2.6</length>
            <radius>0.2</radius>
          </cylinder>
        </geometry>
        <material>
          <diffuse>.6353 .6353 .6353 1</diffuse>
        </material>
      </visual>
    </link>
    <joint name="joint_0" type="revolute">
      <parent>base_link</parent>
      <child>link_1</child>
      <pose>0 0 2 0 0 0</pose>
      <axis>
        <xyz>0 1 0</xyz>
        <limit>
          <effort>100</effort>
        </limit>
      </axis>
    </joint>
    <joint name="joint_1" type="revolute">
      <parent>link_1</parent>
      <child>link_2</child>
      <pose>0 0 1.8 0 0 0</pose>
      <axis>
        <xyz>0 1 0</xyz>
        <limit>
          <effort>0</effort>
        </limit>
        <dynamics>
          <damping>0</damping>
          <friction>0</friction>
        </dynamics>
      </axis>
    </joint>
    <joint name="joint_2" type="revolute">
      <parent>link_2</parent>
      <child>link_3</child>
      <pose>0 0 3.6 0 0 0</pose>
      <axis>
        <xyz>0 1 0</xyz>
        <limit>
          <effort>0</effort>
        </limit>
      </axis>
    </joint>
    <joint name="joint_3" type="revolute">
      <parent>base_link</parent>
      <child>link_3</child>
      <pose>0 0 0 0 0 0</pose>
      <axis>
        <xyz>0 1 0</xyz>
        <limit>
          <effort>0</effort>
        </limit>
      </axis>
    </joint>
  </model>
</sdf>
