<?xml version="1.0" ?>
<!-- =================================================================================== -->
<!-- |    This document was autogenerated by xacro from atlas_robot_minimal_contact.urdf.xacro | -->
<!-- |    EDITING THIS FILE BY HAND IS NOT RECOMMENDED                                 | -->
<!-- =================================================================================== -->
<robot name="atlas" xmlns:controller="http://playerstage.sourceforge.net/gazebo/xmlschema/#controller" xmlns:interface="http://playerstage.sourceforge.net/gazebo/xmlschema/#interface" xmlns:sensor="http://playerstage.sourceforge.net/gazebo/xmlschema/#sensor" xmlns:xacro="http://ros.org/wiki/xacro">
  <!--
  ROS urdf definition of Atlas humanoid robot from Boston Dynamics. Represents the kinematic structure of the robot which is based on the 50th percentile male anthropometry,. 

This file has been based upon a similar urdf file for the Nao humanoid robot (by Aldebaran Robotics) provided in the Nao-Stack of University of Freiburg (Authors: Armin Hornung, Stefan Osswald) which is available at: is available at: http://code.google.com/p/alufr-ros-pkg/.

  Joint names and properties are according to the Boston Dynamics Slide during DRC proposers day talk.
  -->
  <material name="LightGrey">
    <color rgba="0.8 0.8 0.8 1.0"/>
  </material>
  <material name="Grey">
    <color rgba="0.6 0.6 0.6 1.0"/>
  </material>
  <material name="DarkGrey">
    <color rgba="0.3 0.3 0.3 1.0"/>
  </material>
  <material name="Black">
    <color rgba="0.1 0.1 0.1 1.0"/>
  </material>
  <link name="base_link">
    <inertial>
      <origin rpy="0 0 0" xyz="0 0 0"/>
      <mass value="0.01"/>
      <inertia ixx="0.0001" ixy="0.0" ixz="0.0" iyy="0.0001" iyz="0.0" izz="0.0001"/>
    </inertial>
  </link>
  <link name="Back">
    <inertial>
      <mass value="0.98"/>
      <inertia ixx="0.0142307887763" ixy="0.0" ixz="0.0" iyy="0.0142307887763" iyz="0.0" izz="0.0232537942048"/>
    </inertial>
  </link>
  <link name="Pelvis-link1">
    <inertial>
      <mass value="2.85"/>
      <inertia ixx="0.0167937478046" ixy="0.0" ixz="0.0" iyy="0.0130953182366" iyz="0.0" izz="0.0188435137939"/>
    </inertial>
    <visual>
      <origin rpy="0 0 0" xyz="0 0 -0.076245974"/>
      <geometry>
        <cylinder length="0.112491948" radius="0.025"/>
      </geometry>
      <material name="LightGrey"/>
    </visual>
  </link>
  <link name="Pelvis-link2">
    <inertial>
      <mass value="2.85"/>
      <inertia ixx="0.0167937478046" ixy="0.0" ixz="0.0" iyy="0.0188435137939" iyz="0.0" izz="0.0130953182366"/>
    </inertial>
    <visual>
      <origin rpy="1.57079632679 0 0" xyz="0 0 0"/>
      <geometry>
        <cylinder length="0.17784564" radius="0.025"/>
      </geometry>
      <material name="LightGrey"/>
    </visual>
  </link>
  <link name="BackYaw_link">
    <inertial>
      <mass value="0.98"/>
      <inertia ixx="0.0168406694011" ixy="0.0" ixz="0.0" iyy="0.0168406694011" iyz="0.0" izz="0.0284735554544"/>
    </inertial>
  </link>
  <link name="BackPitch_link">
    <inertial>
      <mass value="0.98"/>
      <inertia ixx="0.0391167022824" ixy="0.0" ixz="0.0" iyy="0.0213060832327" iyz="0.0" izz="0.0230184023975"/>
    </inertial>
  </link>
  <link name="BackRoll_link">
    <inertial>
      <mass value="0.98"/>
      <inertia ixx="0.0391167022824" ixy="0.0" ixz="0.0" iyy="0.0213060832327" iyz="0.0" izz="0.0230184023975"/>
    </inertial>
  </link>
  <link name="Torso">
    <!-- assuming the rotational inertia of the torso is of a cuboid -->
    <inertial>
      <mass value="15.347"/>
      <inertia ixx="0.612575540743" ixy="0.0" ixz="0.0" iyy="0.333657611605" iyz="0.0" izz="0.360472879178"/>
    </inertial>
    <visual>
      <origin rpy="0 0 0" xyz="0.0 0.0 0.23927308"/>
      <geometry>
        <cylinder length="0.47854616" radius="0.025"/>
      </geometry>
      <material name="LightGrey"/>
    </visual>
  </link>
  <link name="NeckYaw_link">
    <inertial>
      <mass value="0.9"/>
      <inertia ixx="0.00530271247008" ixy="0.0" ixz="0.0" iyy="0.00530271247008" iyz="0.0" izz="0.00201768391825"/>
    </inertial>
  </link>
  <link name="NeckPitch_link">
    <inertial>
      <mass value="0.9"/>
      <inertia ixx="0.00530271247008" ixy="0.0" ixz="0.0" iyy="0.00530271247008" iyz="0.0" izz="0.00201768391825"/>
    </inertial>
    <visual>
      <origin rpy="1.57079632679 0 0" xyz="0 0 0.13749274"/>
      <geometry>
        <cylinder length="0.22141688" radius="0.06696075"/>
        <!--  <sphere radius="${(l_head/2)*height}"/>-->
      </geometry>
      <material name="LightGrey"/>
    </visual>
  </link>
  <link name="LShoulderYaw_link">
    <inertial>
      <mass value="2.18522222222"/>
      <inertia ixx="0.0231667622255" ixy="0.0" ixz="0.0" iyy="0.0231667622255" iyz="0.0" izz="0.00217732727683"/>
    </inertial>
  </link>
  <link name="LShoulderPitch_link">
    <inertial>
      <mass value="2.18522222222"/>
      <inertia ixx="0.0231667622255" ixy="0.0" ixz="0.0" iyy="0.0231667622255" iyz="0.0" izz="0.00217732727683"/>
    </inertial>
  </link>
  <link name="LShoulderRoll_link">
    <inertial>
      <mass value="2.18522222222"/>
      <inertia ixx="0.0231667622255" ixy="0.0" ixz="0.0" iyy="0.0231667622255" iyz="0.0" izz="0.00217732727683"/>
    </inertial>
    <visual>
      <origin rpy="0 0 0" xyz="0 0 -0.17409795"/>
      <geometry>
        <cylinder length="0.3081959" radius="0.025"/>
      </geometry>
      <material name="LightGrey"/>
    </visual>
  </link>
  <link name="LElbowPitch_link">
    <inertial>
      <mass value="3.27783333333"/>
      <inertia ixx="0.0268028987778" ixy="0.0" ixz="0.0" iyy="0.0268028987778" iyz="0.0" izz="0.00326599091525"/>
    </inertial>
    <visual>
      <origin rpy="0 0 0" xyz="0 0 -0.1517777"/>
      <geometry>
        <cylinder length="0.2635554" radius="0.025"/>
      </geometry>
      <material name="LightGrey"/>
    </visual>
  </link>
  <link name="LWristYaw_link">
    <inertial>
      <mass value="1.0"/>
      <inertia ixx="0.0048720194876" ixy="0.0" ixz="0.0" iyy="0.0048720194876" iyz="0.0" izz="0.00199277424025"/>
    </inertial>
  </link>
  <link name="LWristRoll_link">
    <inertial>
      <mass value="1.0"/>
      <inertia ixx="0.0048720194876" ixy="0.0" ixz="0.0" iyy="0.0048720194876" iyz="0.0" izz="0.00199277424025"/>
    </inertial>
    <visual>
      <origin rpy="0 0 0" xyz="0 0 -0.076245974"/>
      <geometry>
        <cylinder length="0.112491948" radius="0.025"/>
      </geometry>
      <material name="LightGrey"/>
    </visual>
  </link>
  <link name="RShoulderYaw_link">
    <inertial>
      <mass value="2.18522222222"/>
      <inertia ixx="0.0231667622255" ixy="0.0" ixz="0.0" iyy="0.0231667622255" iyz="0.0" izz="0.00217732727683"/>
    </inertial>
  </link>
  <link name="RShoulderPitch_link">
    <inertial>
      <mass value="2.18522222222"/>
      <inertia ixx="0.0231667622255" ixy="0.0" ixz="0.0" iyy="0.0231667622255" iyz="0.0" izz="0.00217732727683"/>
    </inertial>
  </link>
  <link name="RShoulderRoll_link">
    <inertial>
      <mass value="2.18522222222"/>
      <inertia ixx="0.0231667622255" ixy="0.0" ixz="0.0" iyy="0.0231667622255" iyz="0.0" izz="0.00217732727683"/>
    </inertial>
    <visual>
      <origin rpy="0 0 0" xyz="0 0 -0.17409795"/>
      <geometry>
        <cylinder length="0.3081959" radius="0.025"/>
      </geometry>
      <material name="LightGrey"/>
    </visual>
  </link>
  <link name="RElbowPitch_link">
    <inertial>
      <mass value="3.27783333333"/>
      <inertia ixx="0.0268028987778" ixy="0.0" ixz="0.0" iyy="0.0268028987778" iyz="0.0" izz="0.00326599091525"/>
    </inertial>
    <visual>
      <origin rpy="0 0 0" xyz="0 0 -0.1517777"/>
      <geometry>
        <cylinder length="0.2635554" radius="0.025"/>
      </geometry>
      <material name="LightGrey"/>
    </visual>
  </link>
  <link name="RWristYaw_link">
    <inertial>
      <mass value="1.0"/>
      <inertia ixx="0.0048720194876" ixy="0.0" ixz="0.0" iyy="0.0048720194876" iyz="0.0" izz="0.00199277424025"/>
    </inertial>
  </link>
  <link name="RWristRoll_link">
    <inertial>
      <mass value="1.0"/>
      <inertia ixx="0.0048720194876" ixy="0.0" ixz="0.0" iyy="0.0048720194876" iyz="0.0" izz="0.00199277424025"/>
    </inertial>
    <visual>
      <origin rpy="0 0 0" xyz="0 0 -0.076245974"/>
      <geometry>
        <cylinder length="0.112491948" radius="0.025"/>
      </geometry>
      <material name="LightGrey"/>
    </visual>
  </link>
  <link name="LHipYaw_link">
    <inertial>
      <mass value="3.38522222222"/>
      <inertia ixx="0.0670316913245" ixy="0.0" ixz="0.0" iyy="0.0670316913245" iyz="0.0" izz="0.00485710822221"/>
    </inertial>
  </link>
  <link name="LHipPitch_link">
    <inertial>
      <mass value="3.38522222222"/>
      <inertia ixx="0.0670316913245" ixy="0.0" ixz="0.0" iyy="0.0670316913245" iyz="0.0" izz="0.00485710822221"/>
    </inertial>
  </link>
  <link name="LHipRoll_link">
    <inertial>
      <mass value="3.38522222222"/>
      <inertia ixx="0.0670316913245" ixy="0.0" ixz="0.0" iyy="0.0670316913245" iyz="0.0" izz="0.00485710822221"/>
    </inertial>
    <visual>
      <origin rpy="0 0 0" xyz="0.0 0.0 -0.23927308"/>
      <geometry>
        <cylinder length="0.43854616" radius="0.025"/>
      </geometry>
      <material name="LightGrey"/>
    </visual>
  </link>
  <link name="LKneePitch_link">
    <inertial>
      <mass value="5.07783333333"/>
      <inertia ixx="0.0839686075882" ixy="0.0" ixz="0.0" iyy="0.0839686075882" iyz="0.0" izz="0.00728566233332"/>
    </inertial>
    <visual>
      <origin rpy="0 0 0" xyz="0 0 -0.21784564"/>
      <geometry>
        <cylinder length="0.39569128" radius="0.025"/>
      </geometry>
      <material name="LightGrey"/>
    </visual>
  </link>
  <link name="LAnklePitch_link">
    <inertial>
      <mass value="1.0"/>
      <inertia ixx="0.000313145101483" ixy="0.0" ixz="0.0" iyy="0.000313145101483" iyz="0.0" izz="0.0003125"/>
    </inertial>
    <visual>
      <origin rpy="0 0 0" xyz="0 0 -0.021695283"/>
      <geometry>
        <cylinder length="0.043390566" radius="0.025"/>
      </geometry>
      <material name="LightGrey"/>
    </visual>
  </link>
  <link name="LAnkle">
    <inertial>
      <mass value="1.0"/>
      <inertia ixx="0.000313145101483" ixy="0.0" ixz="0.0" iyy="0.000313145101483" iyz="0.0" izz="0.0003125"/>
    </inertial>
  </link>
  <link name="LFoot">
    <inertial>
      <mass value="2.0"/>
      <inertia ixx="0.0006375" ixy="0.0" ixz="0.0" iyy="0.00509955043915" iyz="0.0" izz="0.00566205043915"/>
    </inertial>
    <visual>
      <origin rpy="0 0 0" xyz="0.087138256 0 0.0075"/>
      <geometry>
        <box size="0.224276512 0.06 0.015"/>
      </geometry>
      <material name="LightGrey"/>
    </visual>
    <collision>
      <origin rpy="0 0 0" xyz="-0.025 0.03 0"/>
      <geometry>
        <sphere radius="0"/>
      </geometry>
    </collision>
    <collision>
      <origin rpy="0 0 0" xyz="-0.025 -0.03 0"/>
      <geometry>
        <sphere radius="0"/>
      </geometry>
    </collision>
    <collision>
      <origin rpy="0 0 0" xyz="0.199276512 -0.03 0"/>
      <geometry>
        <sphere radius="0"/>
      </geometry>
    </collision>
    <collision>
      <origin rpy="0 0 0" xyz="0.199276512 0.03 0"/>
      <geometry>
        <sphere radius="0"/>
      </geometry>
    </collision>
  </link>
  <link name="RHipYaw_link">
    <inertial>
      <mass value="3.38522222222"/>
      <inertia ixx="0.0670316913245" ixy="0.0" ixz="0.0" iyy="0.0670316913245" iyz="0.0" izz="0.00485710822221"/>
    </inertial>
  </link>
  <link name="RHipPitch_link">
    <inertial>
      <mass value="3.38522222222"/>
      <inertia ixx="0.0670316913245" ixy="0.0" ixz="0.0" iyy="0.0670316913245" iyz="0.0" izz="0.00485710822221"/>
    </inertial>
  </link>
  <link name="RHipRoll_link">
    <inertial>
      <mass value="3.38522222222"/>
      <inertia ixx="0.0670316913245" ixy="0.0" ixz="0.0" iyy="0.0670316913245" iyz="0.0" izz="0.00485710822221"/>
    </inertial>
    <visual>
      <origin rpy="0 0 0" xyz="0.0 0.0 -0.23927308"/>
      <geometry>
        <cylinder length="0.43854616" radius="0.025"/>
      </geometry>
      <material name="LightGrey"/>
    </visual>
  </link>
  <link name="RKneePitch_link">
    <inertial>
      <mass value="5.07783333333"/>
      <inertia ixx="0.0839686075882" ixy="0.0" ixz="0.0" iyy="0.0839686075882" iyz="0.0" izz="0.00728566233332"/>
    </inertial>
    <visual>
      <origin rpy="0 0 0" xyz="0 0 -0.21784564"/>
      <geometry>
        <cylinder length="0.39569128" radius="0.025"/>
      </geometry>
      <material name="LightGrey"/>
    </visual>
  </link>
  <link name="RAnklePitch_link">
    <inertial>
      <mass value="1.0"/>
      <inertia ixx="0.000313145101483" ixy="0.0" ixz="0.0" iyy="0.000313145101483" iyz="0.0" izz="0.0003125"/>
    </inertial>
    <visual>
      <origin rpy="0 0 0" xyz="0 0 -0.021695283"/>
      <geometry>
        <cylinder length="0.043390566" radius="0.025"/>
      </geometry>
      <material name="LightGrey"/>
    </visual>
  </link>
  <link name="RAnkle">
    <inertial>
      <mass value="1.0"/>
      <inertia ixx="0.000313145101483" ixy="0.0" ixz="0.0" iyy="0.000313145101483" iyz="0.0" izz="0.0003125"/>
    </inertial>
  </link>
  <link name="RFoot">
    <inertial>
      <mass value="2.0"/>
      <inertia ixx="0.0006375" ixy="0.0" ixz="0.0" iyy="0.00509955043915" iyz="0.0" izz="0.00566205043915"/>
    </inertial>
    <visual>
      <origin rpy="0 0 0" xyz="0.087138256 0 0.0075"/>
      <geometry>
        <box size="0.224276512 0.06 0.015"/>
      </geometry>
      <material name="LightGrey"/>
    </visual>
    <collision>
      <origin rpy="0 0 0" xyz="-0.025 0.03 0"/>
      <geometry>
        <sphere radius="0"/>
      </geometry>
    </collision>
    <collision>
      <origin rpy="0 0 0" xyz="-0.025 -0.03 0"/>
      <geometry>
        <sphere radius="0"/>
      </geometry>
    </collision>
    <collision>
      <origin rpy="0 0 0" xyz="0.199276512 -0.03 0"/>
      <geometry>
        <sphere radius="0"/>
      </geometry>
    </collision>
    <collision>
      <origin rpy="0 0 0" xyz="0.199276512 0.03 0"/>
      <geometry>
        <sphere radius="0"/>
      </geometry>
    </collision>
  </link>
  <joint name="base_joint" type="fixed">
    <child link="Back"/>
    <parent link="base_link"/>
    <origin rpy="0 0 0" xyz="0 0 0"/>
  </joint>
  <joint name="BackYaw" type="revolute">
    <parent link="Back"/>
    <child link="BackYaw_link"/>
    <origin rpy="0 0 0" xyz="0 0 0.0"/>
    <axis xyz="0 0 1"/>
    <limit effort="110" lower="-0.78539816295" upper="0.78539816295" velocity="3"/>
    <dynamics damping="1" friction="10"/>
  </joint>
  <transmission name="BackYaw_trans" type="SimpleTransmission">
    <actuator name="BackYawTorque"/>
    <joint name="BackYaw"/>
    <mechanicalReduction>1</mechanicalReduction>
  </transmission>
  <joint name="BackPitch" type="revolute">
    <parent link="BackYaw_link"/>
    <child link="BackPitch_link"/>
    <origin rpy="0 0 0" xyz="0 0 0"/>
    <axis xyz="0 1 0"/>
    <limit effort="180" lower="-0.61086523785" upper="0.43633231275" velocity="3"/>
    <dynamics damping="1" friction="10"/>
  </joint>
  <transmission name="BackPitch_trans" type="SimpleTransmission">
    <actuator name="BackPitchTorque"/>
    <joint name="BackPitch"/>
    <mechanicalReduction>1</mechanicalReduction>
  </transmission>
  <joint name="BackRoll" type="revolute">
    <parent link="BackPitch_link"/>
    <child link="BackRoll_link"/>
    <origin rpy="0 0 0" xyz="0 0 0"/>
    <axis xyz="1 0 0"/>
    <limit effort="100" lower="-0.6981317004" upper="0.6981317004" velocity="3"/>
    <dynamics damping="1" friction="10"/>
  </joint>
  <transmission name="BackRoll_trans" type="SimpleTransmission">
    <actuator name="BackRollTorque"/>
    <joint name="BackRoll"/>
    <mechanicalReduction>1</mechanicalReduction>
  </transmission>
  <joint name="BackRoll_Torso_joint" type="fixed">
    <child link="Torso"/>
    <parent link="BackRoll_link"/>
    <origin rpy="0 0 0" xyz="0 0 0"/>
  </joint>
  <joint name="NeckYaw" type="revolute">
    <parent link="Torso"/>
    <child link="NeckYaw_link"/>
    <origin rpy="0 0 0" xyz="0 0 0.47854616"/>
    <axis xyz="0 0 1"/>
    <limit effort="54" lower="-1.5707963259" upper="1.5707963259" velocity="3"/>
    <dynamics damping="1" friction="10"/>
  </joint>
  <transmission name="NeckYaw_trans" type="SimpleTransmission">
    <actuator name="NeckYawTorque"/>
    <joint name="NeckYaw"/>
    <mechanicalReduction>1</mechanicalReduction>
  </transmission>
  <joint name="NeckPitch" type="revolute">
    <parent link="NeckYaw_link"/>
    <child link="NeckPitch_link"/>
    <origin rpy="0 0 0" xyz="0 0 0"/>
    <axis xyz="0 1 0"/>
    <limit effort="25" lower="-0.78539816295" upper="0.78539816295" velocity="3"/>
    <dynamics damping="1" friction="10"/>
  </joint>
  <transmission name="NeckPitch_trans" type="SimpleTransmission">
    <actuator name="NeckPitchTorque"/>
    <joint name="NeckPitch"/>
    <mechanicalReduction>1</mechanicalReduction>
  </transmission>
  <joint name="LShoulderRoll" type="revolute">
    <parent link="LShoulderPitch_link"/>
    <child link="LShoulderRoll_link"/>
    <origin rpy="0 0 0" xyz="0 0 0"/>
    <axis xyz="1 0 0"/>
    <limit effort="110" lower="0.0" upper="2.00712863865" velocity="3"/>
    <dynamics damping="1" friction="10"/>
  </joint>
  <transmission name="LShoulderRoll_trans" type="SimpleTransmission">
    <actuator name="LShoulderRollTorque"/>
    <joint name="LShoulderRoll"/>
    <mechanicalReduction>1</mechanicalReduction>
  </transmission>
  <joint name="RShoulderRoll" type="revolute">
    <parent link="RShoulderPitch_link"/>
    <child link="RShoulderRoll_link"/>
    <origin rpy="0 0 0" xyz="0 0 0"/>
    <axis xyz="1 0 0"/>
    <limit effort="110" lower="-2.00712863865" upper="-0.0" velocity="3"/>
    <dynamics damping="1" friction="10"/>
  </joint>
  <transmission name="RShoulderRoll_trans" type="SimpleTransmission">
    <actuator name="RShoulderRollTorque"/>
    <joint name="RShoulderRoll"/>
    <mechanicalReduction>1</mechanicalReduction>
  </transmission>
  <joint name="LShoulderYaw" type="revolute">
    <parent link="BackRoll_link"/>
    <child link="LShoulderYaw_link"/>
    <origin rpy="0 0 0" xyz="0 0.2410587 0.41426384"/>
    <axis xyz="0 0 1"/>
    <limit effort="80" lower="-0.6981317004" upper="1.745329251" velocity="3"/>
    <dynamics damping="1" friction="10"/>
  </joint>
  <transmission name="LShoulderYaw_trans" type="SimpleTransmission">
    <actuator name="LShoulderYawTorque"/>
    <joint name="LShoulderYaw"/>
    <mechanicalReduction>1</mechanicalReduction>
  </transmission>
  <joint name="LShoulderPitch" type="revolute">
    <parent link="LShoulderYaw_link"/>
    <child link="LShoulderPitch_link"/>
    <origin rpy="0 0 0" xyz="0 0 0"/>
    <axis xyz="0 1 0"/>
    <limit effort="110" lower="-1.5707963259" upper="0.8726646255" velocity="3"/>
    <dynamics damping="1" friction="10"/>
  </joint>
  <transmission name="LShoulderPitch_trans" type="SimpleTransmission">
    <actuator name="LShoulderPitchTorque"/>
    <joint name="LShoulderPitch"/>
    <mechanicalReduction>1</mechanicalReduction>
  </transmission>
  <joint name="LElbowPitch" type="revolute">
    <parent link="LShoulderRoll_link"/>
    <child link="LElbowPitch_link"/>
    <origin rpy="0 0 0" xyz="0 0 -0.3481959"/>
    <axis xyz="0 1 0"/>
    <limit effort="100" lower="-2.35619448885" upper="0.0" velocity="3"/>
    <dynamics damping="1" friction="10"/>
  </joint>
  <transmission name="LElbowPitch_trans" type="SimpleTransmission">
    <actuator name="LElbowPitchTorque"/>
    <joint name="LElbowPitch"/>
    <mechanicalReduction>1</mechanicalReduction>
  </transmission>
  <joint name="LWristYaw" type="revolute">
    <parent link="LElbowPitch_link"/>
    <child link="LWristYaw_link"/>
    <origin rpy="0 0 0" xyz="0 0 -0.3035554"/>
    <axis xyz="0 0 1"/>
    <limit effort="15" lower="-1.48352986335" upper="1.48352986335" velocity="3"/>
    <dynamics damping="1" friction="10"/>
  </joint>
  <transmission name="LWristYaw_trans" type="SimpleTransmission">
    <actuator name="LWristYawTorque"/>
    <joint name="LWristYaw"/>
    <mechanicalReduction>1</mechanicalReduction>
  </transmission>
  <joint name="RShoulderYaw" type="revolute">
    <parent link="BackRoll_link"/>
    <child link="RShoulderYaw_link"/>
    <origin rpy="0 0 0" xyz="0 -0.2410587 0.41426384"/>
    <axis xyz="0 0 1"/>
    <limit effort="80" lower="-0.6981317004" upper="1.745329251" velocity="3"/>
    <dynamics damping="1" friction="10"/>
  </joint>
  <transmission name="RShoulderYaw_trans" type="SimpleTransmission">
    <actuator name="RShoulderYawTorque"/>
    <joint name="RShoulderYaw"/>
    <mechanicalReduction>1</mechanicalReduction>
  </transmission>
  <joint name="RShoulderPitch" type="revolute">
    <parent link="RShoulderYaw_link"/>
    <child link="RShoulderPitch_link"/>
    <origin rpy="0 0 0" xyz="0 0 0"/>
    <axis xyz="0 1 0"/>
    <limit effort="110" lower="-1.5707963259" upper="0.8726646255" velocity="3"/>
    <dynamics damping="1" friction="10"/>
  </joint>
  <transmission name="RShoulderPitch_trans" type="SimpleTransmission">
    <actuator name="RShoulderPitchTorque"/>
    <joint name="RShoulderPitch"/>
    <mechanicalReduction>1</mechanicalReduction>
  </transmission>
  <joint name="RElbowPitch" type="revolute">
    <parent link="RShoulderRoll_link"/>
    <child link="RElbowPitch_link"/>
    <origin rpy="0 0 0" xyz="0 0 -0.3481959"/>
    <axis xyz="0 1 0"/>
    <limit effort="100" lower="-2.35619448885" upper="0.0" velocity="3"/>
    <dynamics damping="1" friction="10"/>
  </joint>
  <transmission name="RElbowPitch_trans" type="SimpleTransmission">
    <actuator name="RElbowPitchTorque"/>
    <joint name="RElbowPitch"/>
    <mechanicalReduction>1</mechanicalReduction>
  </transmission>
  <joint name="RWristYaw" type="revolute">
    <parent link="RElbowPitch_link"/>
    <child link="RWristYaw_link"/>
    <origin rpy="0 0 0" xyz="0 0 -0.3035554"/>
    <axis xyz="0 0 1"/>
    <limit effort="15" lower="-1.48352986335" upper="1.48352986335" velocity="3"/>
    <dynamics damping="1" friction="10"/>
  </joint>
  <transmission name="RWristYaw_trans" type="SimpleTransmission">
    <actuator name="RWristYawTorque"/>
    <joint name="RWristYaw"/>
    <mechanicalReduction>1</mechanicalReduction>
  </transmission>
  <joint name="LWristRoll" type="revolute">
    <parent link="LWristYaw_link"/>
    <child link="LWristRoll_link"/>
    <origin rpy="0 0 0" xyz="0 0 0"/>
    <axis xyz="1 0 0"/>
    <limit effort="30" lower="-0.5235987753" upper="1.0471975506" velocity="3"/>
    <dynamics damping="1" friction="10"/>
  </joint>
  <transmission name="LWristRoll_trans" type="SimpleTransmission">
    <actuator name="LWristRollTorque"/>
    <joint name="LWristRoll"/>
    <mechanicalReduction>1</mechanicalReduction>
  </transmission>
  <joint name="RWristRoll" type="revolute">
    <parent link="RWristYaw_link"/>
    <child link="RWristRoll_link"/>
    <origin rpy="0 0 0" xyz="0 0 0"/>
    <axis xyz="1 0 0"/>
    <limit effort="30" lower="-1.0471975506" upper="0.5235987753" velocity="3"/>
    <dynamics damping="1" friction="10"/>
  </joint>
  <transmission name="RWristRoll_trans" type="SimpleTransmission">
    <actuator name="RWristRollTorque"/>
    <joint name="RWristRoll"/>
    <mechanicalReduction>1</mechanicalReduction>
  </transmission>
  <joint name="Back_Pelvis_Joint" type="fixed">
    <parent link="Back"/>
    <child link="Pelvis-link1"/>
    <origin rpy="0 0 0" xyz="0 0 0"/>
  </joint>
  <joint name="Mid_Pelvis_Joint" type="fixed">
    <parent link="Pelvis-link1"/>
    <child link="Pelvis-link2"/>
    <origin rpy="0 0 0" xyz="0 0 -0.152491948"/>
  </joint>
  <joint name="LHipYaw" type="revolute">
    <parent link="Pelvis-link2"/>
    <child link="LHipYaw_link"/>
    <origin rpy="0 0 0" xyz="0 0.10892282 0"/>
    <axis xyz="0 0 1"/>
    <limit effort="110" lower="-0.1745329251" upper="1.2217304757" velocity="3"/>
    <dynamics damping="1" friction="10"/>
  </joint>
  <transmission name="LHipYaw_trans" type="SimpleTransmission">
    <actuator name="LHipYawTorque"/>
    <joint name="LHipYaw"/>
    <mechanicalReduction>1</mechanicalReduction>
  </transmission>
  <joint name="RHipYaw" type="revolute">
    <parent link="Pelvis-link2"/>
    <child link="RHipYaw_link"/>
    <origin rpy="0 0 0" xyz="0 -0.10892282 0"/>
    <axis xyz="0 0 1"/>
    <limit effort="110" lower="-1.2217304757" upper="0.1745329251" velocity="3"/>
    <dynamics damping="1" friction="10"/>
  </joint>
  <transmission name="RHipYaw_trans" type="SimpleTransmission">
    <actuator name="RHipYawTorque"/>
    <joint name="RHipYaw"/>
    <mechanicalReduction>1</mechanicalReduction>
  </transmission>
  <joint name="LHipPitch" type="revolute">
    <parent link="LHipYaw_link"/>
    <child link="LHipPitch_link"/>
    <origin rpy="0 0 0" xyz="0 0 0"/>
    <axis xyz="0 1 0"/>
    <limit effort="260" lower="-1.745329251" upper="0.3490658502" velocity="3"/>
    <dynamics damping="1" friction="10"/>
  </joint>
  <transmission name="LHipPitch_trans" type="SimpleTransmission">
    <actuator name="LHipPitchTorque"/>
    <joint name="LHipPitch"/>
    <mechanicalReduction>1</mechanicalReduction>
  </transmission>
  <joint name="LHipRoll" type="revolute">
    <parent link="LHipPitch_link"/>
    <child link="LHipRoll_link"/>
    <origin rpy="0 0 0" xyz="0 0 0"/>
    <axis xyz="1 0 0"/>
    <limit effort="180" lower="-0.3490658502" upper="0.3490658502" velocity="3"/>
    <dynamics damping="1" friction="10"/>
  </joint>
  <transmission name="LHipRoll_trans" type="SimpleTransmission">
    <actuator name="LHipRollTorque"/>
    <joint name="LHipRoll"/>
    <mechanicalReduction>1</mechanicalReduction>
  </transmission>
  <joint name="LKneePitch" type="revolute">
    <parent link="LHipRoll_link"/>
    <child link="LKneePitch_link"/>
    <origin rpy="0 0 0" xyz="0 0 -0.47854616"/>
    <axis xyz="0 1 0"/>
    <limit effort="220" lower="0.0" upper="2.35619448885" velocity="3"/>
    <dynamics damping="1" friction="10"/>
  </joint>
  <transmission name="LKneePitch_trans" type="SimpleTransmission">
    <actuator name="LKneePitchTorque"/>
    <joint name="LKneePitch"/>
    <mechanicalReduction>1</mechanicalReduction>
  </transmission>
  <joint name="LAnklePitch" type="revolute">
    <parent link="LKneePitch_link"/>
    <child link="LAnklePitch_link"/>
    <origin rpy="0 0 0" xyz="0 0 -0.43569128"/>
    <axis xyz="0 1 0"/>
    <limit effort="220" lower="-0.6981317004" upper="0.6981317004" velocity="3"/>
    <dynamics damping="1" friction="10"/>
  </joint>
  <transmission name="LAnklePitch_trans" type="SimpleTransmission">
    <actuator name="LAnklePitchTorque"/>
    <joint name="LAnklePitch"/>
    <mechanicalReduction>1</mechanicalReduction>
  </transmission>
  <joint name="LAnkle_joint" type="fixed">
    <parent link="LAnklePitch_link"/>
    <child link="LAnkle"/>
    <origin xyz="0 0 0"/>
  </joint>
  <joint name="LFoot_joint" type="fixed">
    <parent link="LAnklePitch_link"/>
    <child link="LFoot"/>
    <origin xyz="0 0 -0.04519"/>
  </joint>
  <joint drakeIgnore="True" name="LFootToeIn_joint" type="fixed">
    <parent link="LAnklePitch_link"/>
    <child link="LFootToeIn_link"/>
    <origin xyz="0.199276512 -0.03 -0.04519"/>
  </joint>
  <joint drakeIgnore="True" name="LFootToeOut_joint" type="fixed">
    <parent link="LAnklePitch_link"/>
    <child link="LFootToeOut_link"/>
    <origin xyz="0.199276512 0.03 -0.04519"/>
  </joint>
  <joint drakeIgnore="True" name="LFootHeelIn_joint" type="fixed">
    <parent link="LAnklePitch_link"/>
    <child link="LFootHeelIn_link"/>
    <origin xyz="-0.025 -0.03 -0.04519"/>
  </joint>
  <joint drakeIgnore="True" name="LFootHeelOut_joint" type="fixed">
    <parent link="LAnklePitch_link"/>
    <child link="LFootHeelOut_link"/>
    <origin xyz="-0.025 0.03 -0.04519"/>
  </joint>
  <joint name="RHipPitch" type="revolute">
    <parent link="RHipYaw_link"/>
    <child link="RHipPitch_link"/>
    <origin rpy="0 0 0" xyz="0 0 0"/>
    <axis xyz="0 1 0"/>
    <limit effort="260" lower="-1.745329251" upper="0.3490658502" velocity="3"/>
    <dynamics damping="1" friction="10"/>
  </joint>
  <transmission name="RHipPitch_trans" type="SimpleTransmission">
    <actuator name="RHipPitchTorque"/>
    <joint name="RHipPitch"/>
    <mechanicalReduction>1</mechanicalReduction>
  </transmission>
  <joint name="RHipRoll" type="revolute">
    <parent link="RHipPitch_link"/>
    <child link="RHipRoll_link"/>
    <origin rpy="0 0 0" xyz="0 0 0"/>
    <axis xyz="1 0 0"/>
    <limit effort="180" lower="-0.3490658502" upper="0.3490658502" velocity="3"/>
    <dynamics damping="1" friction="10"/>
  </joint>
  <transmission name="RHipRoll_trans" type="SimpleTransmission">
    <actuator name="RHipRollTorque"/>
    <joint name="RHipRoll"/>
    <mechanicalReduction>1</mechanicalReduction>
  </transmission>
  <joint name="RKneePitch" type="revolute">
    <parent link="RHipRoll_link"/>
    <child link="RKneePitch_link"/>
    <origin rpy="0 0 0" xyz="0 0 -0.47854616"/>
    <axis xyz="0 1 0"/>
    <limit effort="220" lower="0.0" upper="2.35619448885" velocity="3"/>
    <dynamics damping="1" friction="10"/>
  </joint>
  <transmission name="RKneePitch_trans" type="SimpleTransmission">
    <actuator name="RKneePitchTorque"/>
    <joint name="RKneePitch"/>
    <mechanicalReduction>1</mechanicalReduction>
  </transmission>
  <joint name="RAnklePitch" type="revolute">
    <parent link="RKneePitch_link"/>
    <child link="RAnklePitch_link"/>
    <origin rpy="0 0 0" xyz="0 0 -0.43569128"/>
    <axis xyz="0 1 0"/>
    <limit effort="220" lower="-0.6981317004" upper="0.6981317004" velocity="3"/>
    <dynamics damping="1" friction="10"/>
  </joint>
  <transmission name="RAnklePitch_trans" type="SimpleTransmission">
    <actuator name="RAnklePitchTorque"/>
    <joint name="RAnklePitch"/>
    <mechanicalReduction>1</mechanicalReduction>
  </transmission>
  <joint name="RAnkle_joint" type="fixed">
    <parent link="RAnklePitch_link"/>
    <child link="RAnkle"/>
    <origin xyz="0 0 0"/>
  </joint>
  <joint name="RFoot_joint" type="fixed">
    <parent link="RAnklePitch_link"/>
    <child link="RFoot"/>
    <origin xyz="0 0 -0.04519"/>
  </joint>
  <joint drakeIgnore="True" name="RFootToeIn_joint" type="fixed">
    <parent link="RAnklePitch_link"/>
    <child link="RFootToeIn_link"/>
    <origin xyz="0.199276512 0.03 -0.04519"/>
  </joint>
  <joint drakeIgnore="True" name="RFootToeOut_joint" type="fixed">
    <parent link="RAnklePitch_link"/>
    <child link="RFootToeOut_link"/>
    <origin xyz="0.199276512 -0.03 -0.04519"/>
  </joint>
  <joint drakeIgnore="True" name="RFootHeelIn_joint" type="fixed">
    <parent link="RAnklePitch_link"/>
    <child link="RFootHeelIn_link"/>
    <origin xyz="-0.025 0.03 -0.04519"/>
  </joint>
  <joint drakeIgnore="True" name="RFootHeelOut_joint" type="fixed">
    <parent link="RAnklePitch_link"/>
    <child link="RFootHeelOut_link"/>
    <origin xyz="-0.025 -0.03 -0.04519"/>
  </joint>
  <gazebo>
    <!--<controller:gazebo_ros_p3d name="p3d_base_controller" plugin="libgazebo_ros_p3d.so">
                <alwaysOn>true</alwaysOn>
                <updateRate>100.0</updateRate>
                <bodyName>base_link</bodyName>
                <topicName>base_pose_ground_truth</topicName>
                <gaussianNoise>0.01</gaussianNoise>
                <frameName>map</frameName>
                <xyzOffsets>0 0 0</xyzOffsets> 
                <rpyOffsets>0 0 0</rpyOffsets>
                <interface:position name="p3d_base_position"/>
            </controller:gazebo_ros_p3d> -->
    <!-- this publishes empty joint_states due to no transmission, but
             triggering robot_state_publisher to publish tf between fixed joints in erratic,
             (e.g. base_laser_link for the base_scan frame) -->
    <!--   <controller:gazebo_ros_controller_manager name="gazebo_ros_controller_manager" plugin="libgazebo_ros_controller_manager.so">
                <alwaysOn>true</alwaysOn>
                <updateRate>100.0</updateRate>
                <interface:audio name="gazebo_ros_controller_manager_dummy_iface" />
            </controller:gazebo_ros_controller_manager>-->
    <controller:joint_actuation_plugin name="joint_torque_controller" plugin="libjoint_actuation_plugin.so">
      <alwaysOn>true</alwaysOn>
      <topicName>actuator_cmd</topicName>
    </controller:joint_actuation_plugin>
    <controller:gazebo_ros_pub_robot_state name="gazebo_ros_pub_robot_controller" plugin="libgazebo_ros_pub_robot_state.so">
      <alwaysOn>true</alwaysOn>
      <updateRate>100.0</updateRate>
      <topicName>true_robot_state</topicName>
    </controller:gazebo_ros_pub_robot_state>
  </gazebo>
</robot>

