<?xml version="1.0"?>
<robot xmlns="http://drake.mit.edu" xmlns:xsi="http://www.w3.org/2001/XMLSchema-instance"
 xsi:schemaLocation="http://drake.mit.edu ../../doc/drakeURDF.xsd" name="LegAssembly">
  <link name="crank_axle">
    <inertial>
      <origin xyz="0 0 0" rpy="1.5708 0 0"/>
      <mass value="1"/>
        <inertia ixx="1"  ixy="0"  ixz="0" iyy="1" iyz="0" izz="1" />
    </inertial>
    <visual>
      <origin xyz="0 0 0" rpy="1.5708 0 0"/>
      <geometry>
        <cylinder length="1" radius="0.02"/>
      </geometry>
      <material>
        <color rgba=".6353 .6353 .6353 1"/>
      </material>
    </visual>
  </link>

  <link name="bar_l">
    <inertial>
      <origin xyz="0 0 0.039" rpy="0 0 0"/>
      <mass value="1"/>
        <inertia ixx="1"  ixy="0"  ixz="0" iyy="1" iyz="0" izz="1" />
    </inertial>
    <visual>
      <origin xyz="0 0 0.039" rpy="0 0 0"/>
      <geometry>
        <cylinder length="0.078" radius="0.01"/>
      </geometry>
      <material>
        <color rgba=".6353 0 0 1"/>
      </material>
    </visual>
  </link>

  <joint name="joint_crank_axle_l" type="fixed">
    <axis xyz="0 1 0"/>
    <parent link="crank_axle"/>
    <child link="bar_l"/>
    <origin rpy="0 3.14159 0" xyz="0 0 0"/>
  </joint>

  <link name="bar_a">
    <inertial>
      <origin xyz="0 0 0.19" rpy="0 0 0"/>
      <mass value="1"/>
        <inertia ixx="1"  ixy="0"  ixz="0" iyy="1" iyz="0" izz="1" />
    </inertial>
    <visual>
      <origin xyz="0 0 0.19" rpy="0 0 0"/>
      <geometry>
        <cylinder length="0.38" radius="0.01"/>
      </geometry>
      <material>
        <color rgba="0 .6353 0 1"/>
      </material>
    </visual>
  </link>

  <joint name="joint_l_a" type="fixed">
    <axis xyz="0 1 0"/>
    <parent link="bar_l"/>
    <child link="bar_a"/>
    <origin rpy="0 1.5708 0" xyz="0 0 0.078"/>
  </joint>

  <loop_joint name="loop_a_c" type="continuous">
    <axis xyz="0 1 0"/>
    <link1 link="bar_a" rpy="0 0 0" xyz="0 0 0.38"/>
    <link2 link="bar_c" rpy="0 0 0" xyz="0 0 0.393"/>
  </loop_joint>

  <link name="bar_m">
    <inertial>
      <origin xyz="0 0 0.075" rpy="0 0 0"/>
      <mass value="1"/>
        <inertia ixx="1"  ixy="0"  ixz="0" iyy="1" iyz="0" izz="1" />
    </inertial>
    <visual>
      <origin xyz="0 0 0.075" rpy="0 0 0"/>
      <geometry>
        <cylinder length="0.15" radius="0.01"/>
      </geometry>
      <material>
        <color rgba=".6353 .6353 .6353 1"/>
      </material>
    </visual>
  </link>

  <joint name="joint_crank_axle_m" type="continuous">
    <axis xyz="0 1 0"/>
    <parent link="crank_axle"/>
    <child link="bar_m"/>
    <origin rpy="0 0 0" xyz="0 0 0"/>
  </joint>

  <link name="bar_j">
    <inertial>
      <origin xyz="0 0 0.25" rpy="0 0 0"/>
      <mass value="1"/>
        <inertia ixx="1"  ixy="0"  ixz="0" iyy="1" iyz="0" izz="1" />
    </inertial>
    <visual>
      <origin xyz="0 0 0.25" rpy="0 0 0"/>
      <geometry>
        <cylinder length="0.50" radius="0.01"/>
      </geometry>
      <material>
        <color rgba=".6353 .6353 .6353 1"/>
      </material>
    </visual>
  </link>

  <joint name="joint_m_j" type="continuous">
    <axis xyz="0 1 0"/>
    <parent link="bar_m"/>
    <child link="bar_j"/>
    <origin rpy="0 0 0" xyz="0 0 0.15"/>
  </joint>

  <link name="bar_k">
    <inertial>
      <origin xyz="0 0 0.3095" rpy="0 0 0"/>
      <mass value="1"/>
        <inertia ixx="1"  ixy="0"  ixz="0" iyy="1" iyz="0" izz="1" />
    </inertial>
    <visual>
      <origin xyz="0 0 0.3095" rpy="0 0 0"/>
      <geometry>
        <cylinder length="0.619" radius="0.01"/>
      </geometry>
      <material>
        <color rgba=".6353 .6353 .6353 1"/>
      </material>
    </visual>
  </link>

  <joint name="joint_m_k" type="continuous">
    <axis xyz="0 1 0"/>
    <parent link="bar_m"/>
    <child link="bar_k"/>
    <origin rpy="0 0 0" xyz="0 0 0.15"/>
  </joint>

  <link name="bar_b">
    <inertial>
      <origin xyz="0 0 0.2075" rpy="0 0 0"/>
      <mass value="1"/>
        <inertia ixx="1"  ixy="0"  ixz="0" iyy="1" iyz="0" izz="1" />
    </inertial>
    <visual>
      <origin xyz="0 0 0.2075" rpy="0 0 0"/>
      <geometry>
        <cylinder length="0.415" radius="0.01"/>
      </geometry>
      <material>
        <color rgba=".6353 .6353 .6353 1"/>
      </material>
    </visual>
  </link> 

  <joint name="joint_j_b" type="continuous">
    <axis xyz="0 1 0"/>
    <parent link="bar_j"/>
    <child link="bar_b"/>
    <origin rpy="0 0 0" xyz="0 0 0.5"/>
  </joint>

  <link name="bar_c">
    <inertial>
      <origin xyz="0 0 0.1965" rpy="0 0 0"/>
      <mass value="1"/>
        <inertia ixx="1"  ixy="0"  ixz="0" iyy="1" iyz="0" izz="1" />
    </inertial>
    <visual>
      <origin xyz="0 0 0.1965" rpy="0 0 0"/>
      <geometry>
        <cylinder length="0.393" radius="0.01"/>
      </geometry>
      <material>
        <color rgba=".6353 .6353 .6353 1"/>
      </material>
    </visual>
  </link> 

  <joint name="joint_k_c" type="continuous">
    <axis xyz="0 1 0"/>
    <parent link="bar_k"/>
    <child link="bar_c"/>
    <origin rpy="0 0 0" xyz="0 0 0.619"/>
  </joint>

  <loop_joint name="loop_b_c" type="continuous">
    <axis xyz="0 1 0"/>
    <link1 link="bar_b" rpy="0 0 0" xyz="0 0 0.415"/>
    <link2 link="bar_c" rpy="0 0 0" xyz="0 0 0.393"/>
  </loop_joint>

  <joint name="joint_j_b" type="continuous">
    <axis xyz="0 1 0"/>
    <parent link="bar_j"/>
    <child link="bar_b"/>
    <origin rpy="0 0 0" xyz="0 0 0.5"/>
  </joint>

  <link name="bar_e">
    <inertial>
      <origin xyz="0 0 0.279" rpy="0 0 0"/>
      <mass value="1"/>
        <inertia ixx="1"  ixy="0"  ixz="0" iyy="1" iyz="0" izz="1" />
    </inertial>
    <visual>
      <origin xyz="0 0 0.279" rpy="0 0 0"/>
      <geometry>
        <cylinder length="0.558" radius="0.01"/>
      </geometry>
      <material>
        <color rgba=".6353 .6353 .6353 1"/>
      </material>
    </visual>
  </link> 

  <joint name="joint_j_e" type="continuous">
    <axis xyz="0 1 0"/>
    <parent link="bar_j"/>
    <child link="bar_e"/>
    <origin rpy="0 0 0" xyz="0 0 0.5"/>
  </joint>

  <link name="bar_d">
    <inertial>
      <origin xyz="0 0 0.2005" rpy="0 0 0"/>
      <mass value="1"/>
        <inertia ixx="1"  ixy="0"  ixz="0" iyy="1" iyz="0" izz="1" />
    </inertial>
    <visual>
      <origin xyz="0 0 0.2005" rpy="0 0 0"/>
      <geometry>
        <cylinder length="0.401" radius="0.01"/>
      </geometry>
      <material>
        <color rgba=".6353 .6353 .6353 1"/>
      </material>
    </visual>
  </link> 

  <joint name="joint_e_d" type="continuous">
    <axis xyz="0 1 0"/>
    <parent link="bar_e"/>
    <child link="bar_d"/>
    <origin rpy="0 0 0" xyz="0 0 0.558"/>
  </joint>

  <loop_joint name="loop_d_b" type="continuous">
    <axis xyz="0 1 0"/>
    <link1 link="bar_d" rpy="0 0 0" xyz="0 0 0.401"/>
    <link2 link="bar_b" rpy="0 0 0" xyz="0 0 0.415"/>
  </loop_joint>

  <link name="bar_i">
    <inertial>
      <origin xyz="0 0 0.245" rpy="0 0 0"/>
      <mass value="1"/>
        <inertia ixx="1"  ixy="0"  ixz="0" iyy="1" iyz="0" izz="1" />
    </inertial>
    <visual>
      <origin xyz="0 0 0.245" rpy="0 0 0"/>
      <geometry>
        <cylinder length="0.49" radius="0.01"/>
      </geometry>
      <material>
        <color rgba=".6353 .6353 .6353 1"/>
      </material>
    </visual>
  </link> 

  <joint name="joint_k_i" type="continuous">
    <axis xyz="0 1 0"/>
    <parent link="bar_k"/>
    <child link="bar_i"/>
    <origin rpy="0 0 0" xyz="0 0 0.619"/>
  </joint>

  <link name="bar_h">
    <inertial>
      <origin xyz="0 0 0.3285" rpy="0 0 0"/>
      <mass value="1"/>
        <inertia ixx="1"  ixy="0"  ixz="0" iyy="1" iyz="0" izz="1" />
    </inertial>
    <visual>
      <origin xyz="0 0 0.3285" rpy="0 0 0"/>
      <geometry>
        <cylinder length="0.657" radius="0.01"/>
      </geometry>
      <material>
        <color rgba=".6353 .6353 .6353 1"/>
      </material>
    </visual>
  </link> 

  <joint name="joint_i_h" type="continuous">
    <axis xyz="0 1 0"/>
    <parent link="bar_i"/>
    <child link="bar_h"/>
    <origin rpy="0 -2.5573 0" xyz="0 0 0.49"/>
  </joint>

  <link name="bar_g">
    <inertial>
      <origin xyz="0 0 0.1835" rpy="0 0 0"/>
      <mass value="1"/>
        <inertia ixx="1"  ixy="0"  ixz="0" iyy="1" iyz="0" izz="1" />
    </inertial>
    <visual>
      <origin xyz="0 0 0.1835" rpy="0 0 0"/>
      <geometry>
        <cylinder length="0.367" radius="0.01"/>
      </geometry>
      <material>
        <color rgba=".6353 .6353 .6353 1"/>
      </material>
    </visual>
  </link> 

  <joint name="joint_k_g" type="continuous">
    <axis xyz="0 1 0"/>
    <parent link="bar_k"/>
    <child link="bar_g"/>
    <origin rpy="0 0 0" xyz="0 0 0.619"/>
  </joint>

  <loop_joint name="loop_h_g" type="continuous">
    <axis xyz="0 1 0"/>
    <link1 link="bar_h" rpy="0 0 0" xyz="0 0 0.657"/>
    <link2 link="bar_g" rpy="0 0 0" xyz="0 0 0.367"/>
  </loop_joint>

  <link name="bar_f">
    <inertial>
      <origin xyz="0 0 0.197" rpy="0 0 0"/>
      <mass value="1"/>
        <inertia ixx="1"  ixy="0"  ixz="0" iyy="1" iyz="0" izz="1" />
    </inertial>
    <visual>
      <origin xyz="0 0 0.197" rpy="0 0 0"/>
      <geometry>
        <cylinder length="0.394" radius="0.01"/>
      </geometry>
      <material>
        <color rgba=".6353 .6353 .6353 1"/>
      </material>
    </visual>
  </link> 

  <joint name="joint_e_f" type="continuous">
    <axis xyz="0 1 0"/>
    <parent link="bar_e"/>
    <child link="bar_f"/>
    <origin rpy="0 0 0" xyz="0 0 0.558"/>
  </joint>

  <loop_joint name="loop_h_f" type="continuous">
    <axis xyz="0 1 0"/>
    <link1 link="bar_h" rpy="0 0 0" xyz="0 0 0.657"/>
    <link2 link="bar_f" rpy="0 0 0" xyz="0 0 0.394"/>
  </loop_joint>


  <transmission type="SimpleTransmission" name="fake_actuator">
    <actuator name="fake_torque" />
    <joint name="joint_m_j" />
    <mechanicalReduction>1</mechanicalReduction>
  </transmission>
</robot>