<?xml version="1.0"?>

<robot xmlns="http://drake.mit.edu"
 xmlns:xsi="http://www.w3.org/2001/XMLSchema-instance"
 xsi:schemaLocation="http://drake.mit.edu ../../doc/drakeURDF.xsd"
 xmlns:xacro="http://ros.org/wiki/xacro" name="Strandbeest">
 <xacro:include filename="LegPair.xacro" />

 <link name="crank_axle">
    <inertial>
      <origin xyz="0 0 0" rpy="1.5708 0 0"/>
      <mass value="1"/>
        <inertia ixx="1"  ixy="0"  ixz="0" iyy="1" iyz="0" izz="1" />
    </inertial>
    <visual>
      <origin xyz="0 0 0" rpy="1.5708 0 0"/>
      <geometry>
        <cylinder length="1" radius="0.02"/>
      </geometry>
      <material>
        <color rgba=".6353 .6353 .6353 1"/>
      </material>
    </visual>
  </link>
  
  <xacro:strandbeest_leg_pair prefix="pair01">
  </xacro:strandbeest_leg_pair>

  <joint name="joint_crank_axle_l" type="fixed">
    <axis xyz="0 1 0"/>
    <parent link="crank_axle"/>
    <child link="pair01_bar_l"/>
    <origin rpy="0 3.14159 0" xyz="0 0 0"/>
  </joint>

  <joint name="joint_crank_axle_m" type="continuous">
    <axis xyz="0 1 0"/>
    <parent link="crank_axle"/>
    <child link="pair01_bar_m"/>
    <origin rpy="0 0 0" xyz="0 0 0"/>
  </joint>

</robot>