<?xml version="1.0" ?>
<!-- =================================================================================== -->
<!-- |    This document was autogenerated by xacro from r3.xacro                       | -->
<!-- |    EDITING THIS FILE BY HAND IS NOT RECOMMENDED                                 | -->
<!-- =================================================================================== -->
<!-- spring_flamingo revision 3 for questions/bugs/etc. email woursler@gmail.com-->
<robot name="spring_flamingo" xmlns:xacro="http://www.ros.org/wiki/xacro">
  <!-- body property xacros -->
  <!--measured relative to the center of the line connecting the hips-->
  <!-- upper leg property xacros -->
  <!-- lower leg property xacros -->
  <!-- foot property xacros -->
  <!-- Encapsulates the body code.-->
  <link name="base_link">
    <visual>
      <geometry>
        <cylinder length="0.24" radius="0.025"/>
      </geometry>
      <origin rpy="0 1.57075 0" xyz="0 0 0"/>
      <material name="grey">
        <color rgba=".8 .8 .8 1"/>
      </material>
    </visual>
    <inertial>
      <origin rpy="0 0 0" xyz="0 0 0.20"/>
      <mass value="1"/>
      <inertia ixx="100" ixy="0" ixz="0" iyy="100" iyz="0" izz="100"/>
    </inertial>
  </link>
  <link name="left_fan">
    <visual>
      <geometry>
        <cylinder length="0.12" radius="0.025"/>
      </geometry>
      <origin rpy="0 1.57075 0" xyz="0 0 0"/>
      <material name="grey">
        <color rgba=".8 .8 .8 1"/>
      </material>
    </visual>
  </link>
  <joint name="left_fan_fixed_joint" type="fixed">
    <parent link="base_link"/>
    <child link="left_fan"/>
    <origin rpy="0 0 0" xyz="0.12 0 0"/>
    <axis xyz="0 1 0"/>
  </joint>
  <link name="left_strut_1">
    <visual>
      <geometry>
        <box size="0.12 0.385 0.05"/>
      </geometry>
      <origin rpy="0 0 0" xyz="0 0.1925 0"/>
      <material name="grey">
        <color rgba=".8 .8 .8 1"/>
      </material>
    </visual>
  </link>
  <joint name="left_fixed_joint_1" type="fixed">
    <parent link="left_fan"/>
    <child link="left_strut_1"/>
    <origin rpy="0.610865238 0 0" xyz="0 0 0"/>
    <axis xyz="0 1 0"/>
  </joint>
  <link name="left_strut_2">
    <visual>
      <geometry>
        <box size="0.12 0.385 0.05"/>
      </geometry>
      <origin rpy="0 0 0" xyz="0 0.1925 0"/>
      <material name="grey">
        <color rgba=".8 .8 .8 1"/>
      </material>
    </visual>
  </link>
  <joint name="left_fixed_joint_2" type="fixed">
    <parent link="left_fan"/>
    <child link="left_strut_2"/>
    <origin rpy="0.73885605 0 0" xyz="0 0 0"/>
    <axis xyz="0 1 0"/>
  </joint>
  <link name="left_strut_3">
    <visual>
      <geometry>
        <box size="0.12 0.385 0.05"/>
      </geometry>
      <origin rpy="0 0 0" xyz="0 0.1925 0"/>
      <material name="grey">
        <color rgba=".8 .8 .8 1"/>
      </material>
    </visual>
  </link>
  <joint name="left_fixed_joint_3" type="fixed">
    <parent link="left_fan"/>
    <child link="left_strut_3"/>
    <origin rpy="0.866846862 0 0" xyz="0 0 0"/>
    <axis xyz="0 1 0"/>
  </joint>
  <link name="left_strut_4">
    <visual>
      <geometry>
        <box size="0.12 0.385 0.05"/>
      </geometry>
      <origin rpy="0 0 0" xyz="0 0.1925 0"/>
      <material name="grey">
        <color rgba=".8 .8 .8 1"/>
      </material>
    </visual>
  </link>
  <joint name="left_fixed_joint_4" type="fixed">
    <parent link="left_fan"/>
    <child link="left_strut_4"/>
    <origin rpy="0.994837674 0 0" xyz="0 0 0"/>
    <axis xyz="0 1 0"/>
  </joint>
  <link name="left_strut_5">
    <visual>
      <geometry>
        <box size="0.12 0.385 0.05"/>
      </geometry>
      <origin rpy="0 0 0" xyz="0 0.1925 0"/>
      <material name="grey">
        <color rgba=".8 .8 .8 1"/>
      </material>
    </visual>
  </link>
  <joint name="left_fixed_joint_5" type="fixed">
    <parent link="left_fan"/>
    <child link="left_strut_5"/>
    <origin rpy="1.122828486 0 0" xyz="0 0 0"/>
    <axis xyz="0 1 0"/>
  </joint>
  <link name="left_strut_6">
    <visual>
      <geometry>
        <box size="0.12 0.385 0.05"/>
      </geometry>
      <origin rpy="0 0 0" xyz="0 0.1925 0"/>
      <material name="grey">
        <color rgba=".8 .8 .8 1"/>
      </material>
    </visual>
  </link>
  <joint name="left_fixed_joint_6" type="fixed">
    <parent link="left_fan"/>
    <child link="left_strut_6"/>
    <origin rpy="1.250819298 0 0" xyz="0 0 0"/>
    <axis xyz="0 1 0"/>
  </joint>
  <link name="left_strut_7">
    <visual>
      <geometry>
        <box size="0.12 0.385 0.05"/>
      </geometry>
      <origin rpy="0 0 0" xyz="0 0.1925 0"/>
      <material name="grey">
        <color rgba=".8 .8 .8 1"/>
      </material>
    </visual>
  </link>
  <joint name="left_fixed_joint_7" type="fixed">
    <parent link="left_fan"/>
    <child link="left_strut_7"/>
    <origin rpy="1.37881011 0 0" xyz="0 0 0"/>
    <axis xyz="0 1 0"/>
  </joint>
  <link name="left_strut_8">
    <visual>
      <geometry>
        <box size="0.12 0.385 0.05"/>
      </geometry>
      <origin rpy="0 0 0" xyz="0 0.1925 0"/>
      <material name="grey">
        <color rgba=".8 .8 .8 1"/>
      </material>
    </visual>
  </link>
  <joint name="left_fixed_joint_8" type="fixed">
    <parent link="left_fan"/>
    <child link="left_strut_8"/>
    <origin rpy="1.506800922 0 0" xyz="0 0 0"/>
    <axis xyz="0 1 0"/>
  </joint>
  <link name="left_strut_9">
    <visual>
      <geometry>
        <box size="0.12 0.385 0.05"/>
      </geometry>
      <origin rpy="0 0 0" xyz="0 0.1925 0"/>
      <material name="grey">
        <color rgba=".8 .8 .8 1"/>
      </material>
    </visual>
  </link>
  <joint name="left_fixed_joint_9" type="fixed">
    <parent link="left_fan"/>
    <child link="left_strut_9"/>
    <origin rpy="1.634791734 0 0" xyz="0 0 0"/>
    <axis xyz="0 1 0"/>
  </joint>
  <link name="left_strut_10">
    <visual>
      <geometry>
        <box size="0.12 0.385 0.05"/>
      </geometry>
      <origin rpy="0 0 0" xyz="0 0.1925 0"/>
      <material name="grey">
        <color rgba=".8 .8 .8 1"/>
      </material>
    </visual>
  </link>
  <joint name="left_fixed_joint_10" type="fixed">
    <parent link="left_fan"/>
    <child link="left_strut_10"/>
    <origin rpy="1.762782546 0 0" xyz="0 0 0"/>
    <axis xyz="0 1 0"/>
  </joint>
  <link name="left_strut_11">
    <visual>
      <geometry>
        <box size="0.12 0.385 0.05"/>
      </geometry>
      <origin rpy="0 0 0" xyz="0 0.1925 0"/>
      <material name="grey">
        <color rgba=".8 .8 .8 1"/>
      </material>
    </visual>
  </link>
  <joint name="left_fixed_joint_11" type="fixed">
    <parent link="left_fan"/>
    <child link="left_strut_11"/>
    <origin rpy="1.890773358 0 0" xyz="0 0 0"/>
    <axis xyz="0 1 0"/>
  </joint>
  <link name="left_strut_12">
    <visual>
      <geometry>
        <box size="0.12 0.385 0.05"/>
      </geometry>
      <origin rpy="0 0 0" xyz="0 0.1925 0"/>
      <material name="grey">
        <color rgba=".8 .8 .8 1"/>
      </material>
    </visual>
  </link>
  <joint name="left_fixed_joint_12" type="fixed">
    <parent link="left_fan"/>
    <child link="left_strut_12"/>
    <origin rpy="2.01876417 0 0" xyz="0 0 0"/>
    <axis xyz="0 1 0"/>
  </joint>
  <link name="left_strut_13">
    <visual>
      <geometry>
        <box size="0.12 0.385 0.05"/>
      </geometry>
      <origin rpy="0 0 0" xyz="0 0.1925 0"/>
      <material name="grey">
        <color rgba=".8 .8 .8 1"/>
      </material>
    </visual>
  </link>
  <joint name="left_fixed_joint_13" type="fixed">
    <parent link="left_fan"/>
    <child link="left_strut_13"/>
    <origin rpy="2.146754982 0 0" xyz="0 0 0"/>
    <axis xyz="0 1 0"/>
  </joint>
  <link name="left_strut_14">
    <visual>
      <geometry>
        <box size="0.12 0.385 0.05"/>
      </geometry>
      <origin rpy="0 0 0" xyz="0 0.1925 0"/>
      <material name="grey">
        <color rgba=".8 .8 .8 1"/>
      </material>
    </visual>
  </link>
  <joint name="left_fixed_joint_14" type="fixed">
    <parent link="left_fan"/>
    <child link="left_strut_14"/>
    <origin rpy="2.274745794 0 0" xyz="0 0 0"/>
    <axis xyz="0 1 0"/>
  </joint>
  <link name="left_strut_15">
    <visual>
      <geometry>
        <box size="0.12 0.385 0.05"/>
      </geometry>
      <origin rpy="0 0 0" xyz="0 0.1925 0"/>
      <material name="grey">
        <color rgba=".8 .8 .8 1"/>
      </material>
    </visual>
  </link>
  <joint name="left_fixed_joint_15" type="fixed">
    <parent link="left_fan"/>
    <child link="left_strut_15"/>
    <origin rpy="2.402736606 0 0" xyz="0 0 0"/>
    <axis xyz="0 1 0"/>
  </joint>
  <link name="right_fan">
    <visual>
      <geometry>
        <cylinder length="0.12" radius="0.025"/>
      </geometry>
      <origin rpy="0 1.57075 0" xyz="0 0 0"/>
      <material name="grey">
        <color rgba=".8 .8 .8 1"/>
      </material>
    </visual>
  </link>
  <joint name="right_fan_fixed_joint" type="fixed">
    <parent link="base_link"/>
    <child link="right_fan"/>
    <origin rpy="0 0 0" xyz="-0.12 0 0"/>
    <axis xyz="0 1 0"/>
  </joint>
  <link name="right_strut_1">
    <visual>
      <geometry>
        <box size="0.12 0.385 0.05"/>
      </geometry>
      <origin rpy="0 0 0" xyz="0 0.1925 0"/>
      <material name="grey">
        <color rgba=".8 .8 .8 1"/>
      </material>
    </visual>
  </link>
  <joint name="right_fixed_joint_1" type="fixed">
    <parent link="right_fan"/>
    <child link="right_strut_1"/>
    <origin rpy="0.610865238 0 0" xyz="0 0 0"/>
    <axis xyz="0 1 0"/>
  </joint>
  <link name="right_strut_2">
    <visual>
      <geometry>
        <box size="0.12 0.385 0.05"/>
      </geometry>
      <origin rpy="0 0 0" xyz="0 0.1925 0"/>
      <material name="grey">
        <color rgba=".8 .8 .8 1"/>
      </material>
    </visual>
  </link>
  <joint name="right_fixed_joint_2" type="fixed">
    <parent link="right_fan"/>
    <child link="right_strut_2"/>
    <origin rpy="0.73885605 0 0" xyz="0 0 0"/>
    <axis xyz="0 1 0"/>
  </joint>
  <link name="right_strut_3">
    <visual>
      <geometry>
        <box size="0.12 0.385 0.05"/>
      </geometry>
      <origin rpy="0 0 0" xyz="0 0.1925 0"/>
      <material name="grey">
        <color rgba=".8 .8 .8 1"/>
      </material>
    </visual>
  </link>
  <joint name="right_fixed_joint_3" type="fixed">
    <parent link="right_fan"/>
    <child link="right_strut_3"/>
    <origin rpy="0.866846862 0 0" xyz="0 0 0"/>
    <axis xyz="0 1 0"/>
  </joint>
  <link name="right_strut_4">
    <visual>
      <geometry>
        <box size="0.12 0.385 0.05"/>
      </geometry>
      <origin rpy="0 0 0" xyz="0 0.1925 0"/>
      <material name="grey">
        <color rgba=".8 .8 .8 1"/>
      </material>
    </visual>
  </link>
  <joint name="right_fixed_joint_4" type="fixed">
    <parent link="right_fan"/>
    <child link="right_strut_4"/>
    <origin rpy="0.994837674 0 0" xyz="0 0 0"/>
    <axis xyz="0 1 0"/>
  </joint>
  <link name="right_strut_5">
    <visual>
      <geometry>
        <box size="0.12 0.385 0.05"/>
      </geometry>
      <origin rpy="0 0 0" xyz="0 0.1925 0"/>
      <material name="grey">
        <color rgba=".8 .8 .8 1"/>
      </material>
    </visual>
  </link>
  <joint name="right_fixed_joint_5" type="fixed">
    <parent link="right_fan"/>
    <child link="right_strut_5"/>
    <origin rpy="1.122828486 0 0" xyz="0 0 0"/>
    <axis xyz="0 1 0"/>
  </joint>
  <link name="right_strut_6">
    <visual>
      <geometry>
        <box size="0.12 0.385 0.05"/>
      </geometry>
      <origin rpy="0 0 0" xyz="0 0.1925 0"/>
      <material name="grey">
        <color rgba=".8 .8 .8 1"/>
      </material>
    </visual>
  </link>
  <joint name="right_fixed_joint_6" type="fixed">
    <parent link="right_fan"/>
    <child link="right_strut_6"/>
    <origin rpy="1.250819298 0 0" xyz="0 0 0"/>
    <axis xyz="0 1 0"/>
  </joint>
  <link name="right_strut_7">
    <visual>
      <geometry>
        <box size="0.12 0.385 0.05"/>
      </geometry>
      <origin rpy="0 0 0" xyz="0 0.1925 0"/>
      <material name="grey">
        <color rgba=".8 .8 .8 1"/>
      </material>
    </visual>
  </link>
  <joint name="right_fixed_joint_7" type="fixed">
    <parent link="right_fan"/>
    <child link="right_strut_7"/>
    <origin rpy="1.37881011 0 0" xyz="0 0 0"/>
    <axis xyz="0 1 0"/>
  </joint>
  <link name="right_strut_8">
    <visual>
      <geometry>
        <box size="0.12 0.385 0.05"/>
      </geometry>
      <origin rpy="0 0 0" xyz="0 0.1925 0"/>
      <material name="grey">
        <color rgba=".8 .8 .8 1"/>
      </material>
    </visual>
  </link>
  <joint name="right_fixed_joint_8" type="fixed">
    <parent link="right_fan"/>
    <child link="right_strut_8"/>
    <origin rpy="1.506800922 0 0" xyz="0 0 0"/>
    <axis xyz="0 1 0"/>
  </joint>
  <link name="right_strut_9">
    <visual>
      <geometry>
        <box size="0.12 0.385 0.05"/>
      </geometry>
      <origin rpy="0 0 0" xyz="0 0.1925 0"/>
      <material name="grey">
        <color rgba=".8 .8 .8 1"/>
      </material>
    </visual>
  </link>
  <joint name="right_fixed_joint_9" type="fixed">
    <parent link="right_fan"/>
    <child link="right_strut_9"/>
    <origin rpy="1.634791734 0 0" xyz="0 0 0"/>
    <axis xyz="0 1 0"/>
  </joint>
  <link name="right_strut_10">
    <visual>
      <geometry>
        <box size="0.12 0.385 0.05"/>
      </geometry>
      <origin rpy="0 0 0" xyz="0 0.1925 0"/>
      <material name="grey">
        <color rgba=".8 .8 .8 1"/>
      </material>
    </visual>
  </link>
  <joint name="right_fixed_joint_10" type="fixed">
    <parent link="right_fan"/>
    <child link="right_strut_10"/>
    <origin rpy="1.762782546 0 0" xyz="0 0 0"/>
    <axis xyz="0 1 0"/>
  </joint>
  <link name="right_strut_11">
    <visual>
      <geometry>
        <box size="0.12 0.385 0.05"/>
      </geometry>
      <origin rpy="0 0 0" xyz="0 0.1925 0"/>
      <material name="grey">
        <color rgba=".8 .8 .8 1"/>
      </material>
    </visual>
  </link>
  <joint name="right_fixed_joint_11" type="fixed">
    <parent link="right_fan"/>
    <child link="right_strut_11"/>
    <origin rpy="1.890773358 0 0" xyz="0 0 0"/>
    <axis xyz="0 1 0"/>
  </joint>
  <link name="right_strut_12">
    <visual>
      <geometry>
        <box size="0.12 0.385 0.05"/>
      </geometry>
      <origin rpy="0 0 0" xyz="0 0.1925 0"/>
      <material name="grey">
        <color rgba=".8 .8 .8 1"/>
      </material>
    </visual>
  </link>
  <joint name="right_fixed_joint_12" type="fixed">
    <parent link="right_fan"/>
    <child link="right_strut_12"/>
    <origin rpy="2.01876417 0 0" xyz="0 0 0"/>
    <axis xyz="0 1 0"/>
  </joint>
  <link name="right_strut_13">
    <visual>
      <geometry>
        <box size="0.12 0.385 0.05"/>
      </geometry>
      <origin rpy="0 0 0" xyz="0 0.1925 0"/>
      <material name="grey">
        <color rgba=".8 .8 .8 1"/>
      </material>
    </visual>
  </link>
  <joint name="right_fixed_joint_13" type="fixed">
    <parent link="right_fan"/>
    <child link="right_strut_13"/>
    <origin rpy="2.146754982 0 0" xyz="0 0 0"/>
    <axis xyz="0 1 0"/>
  </joint>
  <link name="right_strut_14">
    <visual>
      <geometry>
        <box size="0.12 0.385 0.05"/>
      </geometry>
      <origin rpy="0 0 0" xyz="0 0.1925 0"/>
      <material name="grey">
        <color rgba=".8 .8 .8 1"/>
      </material>
    </visual>
  </link>
  <joint name="right_fixed_joint_14" type="fixed">
    <parent link="right_fan"/>
    <child link="right_strut_14"/>
    <origin rpy="2.274745794 0 0" xyz="0 0 0"/>
    <axis xyz="0 1 0"/>
  </joint>
  <link name="right_strut_15">
    <visual>
      <geometry>
        <box size="0.12 0.385 0.05"/>
      </geometry>
      <origin rpy="0 0 0" xyz="0 0.1925 0"/>
      <material name="grey">
        <color rgba=".8 .8 .8 1"/>
      </material>
    </visual>
  </link>
  <joint name="right_fixed_joint_15" type="fixed">
    <parent link="right_fan"/>
    <child link="right_strut_15"/>
    <origin rpy="2.402736606 0 0" xyz="0 0 0"/>
    <axis xyz="0 1 0"/>
  </joint>
  <!-- Defines a ground contact point xacro-->
  <!-- Defines a leg xacro. Most of the action is here.-->
  <link name="right_upper_leg">
    <visual>
      <geometry>
        <cylinder length="0.42" radius="0.010875"/>
      </geometry>
      <origin rpy="0 1.57075 0" xyz="0.21 0 0"/>
      <material name="black">
        <color rgba="0 0 0 1"/>
      </material>
    </visual>
    <inertial>
      <origin rpy="0 0 0" xyz="0.21 0 0"/>
      <mass value="0.4598"/>
      <inertia ixx="0.01256" ixy="0" ixz="0" iyy="0.01256" iyz="0" izz="0.00013"/>
    </inertial>
  </link>
  <joint name="right_hip" type="continuous">
    <parent link="base_link"/>
    <child link="right_upper_leg"/>
    <origin rpy="0 1.57075 0" xyz="0.12 0 0"/>
    <axis xyz="0 1 0"/>
  </joint>
  <link name="right_lower_leg">
    <visual>
      <geometry>
        <cylinder length="0.42" radius="0.010875"/>
      </geometry>
      <origin rpy="0 1.57075 0" xyz="0.21 0 0"/>
      <material name="black">
        <color rgba="0 0 0 1"/>
      </material>
    </visual>
    <inertial>
      <origin rpy="0 0 0" xyz="0.21 0 0"/>
      <mass value="0.306"/>
      <inertia ixx="0.00952" ixy="0" ixz="0" iyy="0.00952" iyz="0" izz="5.67e-05"/>
    </inertial>
  </link>
  <joint name="right_knee" type="continuous">
    <parent link="right_upper_leg"/>
    <child link="right_lower_leg"/>
    <origin xyz="0.42 0 0"/>
    <axis xyz="0 1 0"/>
  </joint>
  <link name="right_foot">
    <visual>
      <geometry>
        <box size="0.03 0.23 0.04"/>
      </geometry>
      <origin rpy="0 0 0" xyz="0 -0.0575 0"/>
      <material name="grey">
        <color rgba=".8 .8 .8 1"/>
      </material>
    </visual>
    <inertial>
      <origin rpy="0 0 0" xyz="0 0 0"/>
      <mass value="0.3466"/>
      <inertia ixx="7.15e-05" ixy="0" ixz="0" iyy="0.0015" iyz="0" izz="0.0015"/>
    </inertial>
  </link>
  <joint name="right_ankle" type="continuous">
    <parent link="right_lower_leg"/>
    <child link="right_foot"/>
    <origin xyz="0.42 0 0"/>
    <axis xyz="0 1 0"/>
  </joint>
  <link name="right_forward_contact_point">
    <visual>
      <geometry>
        <sphere radius="0.025"/>
      </geometry>
      <material name="black">
        <color rgba="0 0 0 1"/>
      </material>
    </visual>
    <collision>
      <geometry>
        <sphere radius="0"/>
      </geometry>
    </collision>
  </link>
  <link name="right_rear_contact_point">
    <visual>
      <geometry>
        <sphere radius="0.025"/>
      </geometry>
      <material name="black">
        <color rgba="0 0 0 1"/>
      </material>
    </visual>
    <collision>
      <geometry>
        <sphere radius="0"/>
      </geometry>
    </collision>
  </link>
  <joint name="right_j1" type="fixed">
    <parent link="right_foot"/>
    <child link="right_forward_contact_point"/>
    <origin xyz="0 0.0575 0"/>
    <axis xyz="0 1 0"/>
  </joint>
  <joint name="right_j2" type="fixed">
    <parent link="right_foot"/>
    <child link="right_rear_contact_point"/>
    <origin xyz="0 -0.1725 0"/>
    <axis xyz="0 1 0"/>
  </joint>
  <link name="left_upper_leg">
    <visual>
      <geometry>
        <cylinder length="0.42" radius="0.010875"/>
      </geometry>
      <origin rpy="0 1.57075 0" xyz="0.21 0 0"/>
      <material name="black">
        <color rgba="0 0 0 1"/>
      </material>
    </visual>
    <inertial>
      <origin rpy="0 0 0" xyz="0.21 0 0"/>
      <mass value="0.4598"/>
      <inertia ixx="0.01256" ixy="0" ixz="0" iyy="0.01256" iyz="0" izz="0.00013"/>
    </inertial>
  </link>
  <joint name="left_hip" type="continuous">
    <parent link="base_link"/>
    <child link="left_upper_leg"/>
    <origin rpy="0 1.57075 0" xyz="-0.12 0 0"/>
    <axis xyz="0 1 0"/>
  </joint>
  <link name="left_lower_leg">
    <visual>
      <geometry>
        <cylinder length="0.42" radius="0.010875"/>
      </geometry>
      <origin rpy="0 1.57075 0" xyz="0.21 0 0"/>
      <material name="black">
        <color rgba="0 0 0 1"/>
      </material>
    </visual>
    <inertial>
      <origin rpy="0 0 0" xyz="0.21 0 0"/>
      <mass value="0.306"/>
      <inertia ixx="0.00952" ixy="0" ixz="0" iyy="0.00952" iyz="0" izz="5.67e-05"/>
    </inertial>
  </link>
  <joint name="left_knee" type="continuous">
    <parent link="left_upper_leg"/>
    <child link="left_lower_leg"/>
    <origin xyz="0.42 0 0"/>
    <axis xyz="0 1 0"/>
  </joint>
  <link name="left_foot">
    <visual>
      <geometry>
        <box size="0.03 0.23 0.04"/>
      </geometry>
      <origin rpy="0 0 0" xyz="0 -0.0575 0"/>
      <material name="grey">
        <color rgba=".8 .8 .8 1"/>
      </material>
    </visual>
    <inertial>
      <origin rpy="0 0 0" xyz="0 0 0"/>
      <mass value="0.3466"/>
      <inertia ixx="7.15e-05" ixy="0" ixz="0" iyy="0.0015" iyz="0" izz="0.0015"/>
    </inertial>
  </link>
  <joint name="left_ankle" type="continuous">
    <parent link="left_lower_leg"/>
    <child link="left_foot"/>
    <origin xyz="0.42 0 0"/>
    <axis xyz="0 1 0"/>
  </joint>
  <link name="left_forward_contact_point">
    <visual>
      <geometry>
        <sphere radius="0.025"/>
      </geometry>
      <material name="black">
        <color rgba="0 0 0 1"/>
      </material>
    </visual>
    <collision>
      <geometry>
        <sphere radius="0"/>
      </geometry>
    </collision>
  </link>
  <link name="left_rear_contact_point">
    <visual>
      <geometry>
        <sphere radius="0.025"/>
      </geometry>
      <material name="black">
        <color rgba="0 0 0 1"/>
      </material>
    </visual>
    <collision>
      <geometry>
        <sphere radius="0"/>
      </geometry>
    </collision>
  </link>
  <joint name="left_j1" type="fixed">
    <parent link="left_foot"/>
    <child link="left_forward_contact_point"/>
    <origin xyz="0 0.0575 0"/>
    <axis xyz="0 1 0"/>
  </joint>
  <joint name="left_j2" type="fixed">
    <parent link="left_foot"/>
    <child link="left_rear_contact_point"/>
    <origin xyz="0 -0.1725 0"/>
    <axis xyz="0 1 0"/>
  </joint>
</robot>

