<?xml version='1.0' ?>
<sdf version="1.6">
  <model name="prius_1">
    <pose>0 0 0 0 0 0</pose>
    <link name="chassis_floor">
      <pose>0 0 0.378326 0 0 0</pose>
      <inertial>
        <pose>0 0 0 0 0 0</pose>
        <!--  The 2015 Prius has a curb weight of 3,072 lbs. (~1,400 kg)
              based on the PDF linked below:
              https://pressroom.toyota.com/releases/
              toyota+2015+prius+product+specs.download -->
        <!-- Our simplified model as of now assumes that only six links have
             non-zero weight: the chassis_floor, the body, and the four wheels.
             The chassis_floor's share of the curb weight is set to 1,360 kg,
             and the only justification for this otherwise arbitrary value is to
             bring the center of mass reasonably low.  -->
        <!-- TODO(shensquared): Refine the weight distribution when the model is
             of higher fidelity. -->
        <mass>1360</mass>
        <!-- The inertia is calculated by assuming that the chassis_floor link
             is a cuboid, with its size as specified in the geometry/box/size
             tag below, and then using the formula from
             https://en.wikipedia.org/wiki/List_of_moments_of_inertia.-->
        <inertia>
          <ixx>63.858358934</ixx>
          <ixy>0</ixy>
          <ixz>0</ixz>
          <iyy>940.662671467</iyy>
          <iyz>0</iyz>
          <izz>1004.304312533</izz>
        </inertia>
      </inertial>
      <visual name="main">
        <pose>0 0 0 0 0 0</pose>
        <geometry>
          <box>
            <size>2.8808 0.75 0.030921</size>
          </box>
        </geometry>
        <material>
          <diffuse>1 1 1 1</diffuse>
        </material>
      </visual>
    </link>
    <link name="front_axle">
      <pose>1.40948 0 0.323342 0 0 0</pose>
      <visual name="visual">
        <pose>0 0 0 0 0 0</pose>
        <geometry>
          <box>
            <size>0.061842 1.05132 0.030921</size>
          </box>
        </geometry>
        <material>
          <diffuse>0 0 1 1</diffuse>
        </material>
      </visual>
    </link>
    <link name="left_tie_rod_arm">
      <pose>1.23701032 0.40850253 0.292422 0 0 0</pose>
      <visual name="v2">
        <pose>.06385963 0.03192981 0 0 0 0.463648</pose>
        <geometry>
          <box>
            <size>0.204637 0.061842 0.030921</size>
          </box>
        </geometry>
        <material>
          <diffuse>0 0.5 0 1</diffuse>
        </material>
      </visual>
      <visual name="v1">
        <pose>.17246863 0.10851978 0 0 -0 0</pose>
        <geometry>
          <box>
            <size>0.061842 0.140955 0.030921</size>
          </box>
        </geometry>
        <material>
          <diffuse>0 0.5 0 1</diffuse>
        </material>
      </visual>
    </link>
    <link name="left_hub">
      <pose>1.40948 0.61841 0.316482 1.570796326794896557998982 0 0</pose>
      <visual name="visual">
        <pose>0 0 0 0 0 0</pose>
        <geometry>
          <cylinder>
            <length>0.0618421</length>
            <radius>0.0154605</radius>
          </cylinder>
        </geometry>
        <material>
          <diffuse>0 0 1 1</diffuse>
        </material>
      </visual>
    </link>
    <link name="tie_rod">
      <pose>1.23702 0 0.323342 0 0 0</pose>
      <visual name="visual">
        <pose>0 0 0 0 0 0</pose>
        <geometry>
          <box>
            <size>0.061842 0.878847 0.030921</size>
          </box>
        </geometry>
        <material>
          <diffuse>0 0 1 1</diffuse>
        </material>
      </visual>
    </link>
    <link name="left_wheel">
      <pose>1.40948 0.801993 0.3164819999999999855511135
        1.570796326794896557998982 0 0</pose>
      <inertial>
        <mass>14.28</mass>
        <inertia>
          <ixx>0.499912</ixx>
          <ixy>0</ixy>
          <ixz>0</ixz>
          <iyy>0.778439</iyy>
          <iyz>0</iyz>
          <izz>0.499912</izz>
        </inertia>
      </inertial>
      <visual name="m2">
        <pose>0 0 -.1075 0 1.570796326794896557998982
          3.141592653589793115997963</pose>
        <material>
          <diffuse>0.9 0.9 0.9 1</diffuse>
        </material>
        <geometry>
          <box>
            <size>0.0025 0.0025 0.25</size>
          </box>
        </geometry>
      </visual>
      <visual name="wheel">
        <pose>0 0 0 0 0 0</pose>
        <geometry>
          <cylinder>
            <length>0.215</length>
            <radius>0.323342</radius>
          </cylinder>
        </geometry>
        <material>
          <diffuse>0.2 0.2 0.2 1</diffuse>
        </material>
      </visual>
      <visual name="m1">
        <pose>0 0 -.1075 0 1.570796326794896557998982
          1.570796326794896557998982</pose>
        <material>
          <diffuse>0.9 0.9 0.9 1</diffuse>
        </material>
        <geometry>
          <box>
            <size>0.0025 0.0025 0.25</size>
          </box>
        </geometry>
      </visual>
      <collision name="wheel">
        <pose>0 0 0 0 0 0</pose>
        <geometry>
          <cylinder>
            <radius>0.323342</radius>
            <length>0.215</length>
          </cylinder>
        </geometry>
      </collision>
    </link>
    <link name="right_tie_rod_arm">
      <pose>1.23701032 -0.40849616 0.292422 0 0 0</pose>
      <visual name="v1">
        <pose>.17246863 -0.10851978 0 0 -0 0</pose>
        <geometry>
          <box>
            <size>0.061842 0.140955 0.030921</size>
          </box>
        </geometry>
        <material>
          <diffuse>0 0.5 0 1</diffuse>
        </material>
      </visual>
      <visual name="v2">
        <pose>.06385963 -0.03192981 0 0 0 -0.463648</pose>
        <geometry>
          <box>
            <size>0.204637 0.061842 0.030921</size>
          </box>
        </geometry>
        <material>
          <diffuse>0 0.5 0 1</diffuse>
        </material>
      </visual>
    </link>
    <link name="right_hub">
      <pose>1.40948 -0.61841 0.316482 1.570796326794896557998982 0 0</pose>
      <visual name="visual">
        <pose>0 0 0 0 0 0</pose>
        <geometry>
          <cylinder>
            <length>0.0618421</length>
            <radius>0.0154605</radius>
          </cylinder>
        </geometry>
        <material>
          <diffuse>0 0 1 1</diffuse>
        </material>
      </visual>
    </link>
    <link name="right_wheel">
      <pose>1.40948 -0.80198 0.3164819999999999855511135
        1.570796326794896557998982 0 0</pose>
      <inertial>
        <mass>14.28</mass>
        <inertia>
          <ixx>0.499912</ixx>
          <ixy>0</ixy>
          <ixz>0</ixz>
          <iyy>0.778439</iyy>
          <iyz>0</iyz>
          <izz>0.499912</izz>
        </inertia>
      </inertial>
      <visual name="m2">
        <pose>0 0 .1075 0 1.570796326794896557998982
          3.141592653589793115997963</pose>
        <material>
          <diffuse>0.9 0.9 0.9 1</diffuse>
        </material>
        <geometry>
          <box>
            <size>0.0025 0.0025 0.25</size>
          </box>
        </geometry>
      </visual>
      <visual name="wheel">
        <pose>0 0 0 0 0 0</pose>
        <geometry>
          <cylinder>
            <length>0.215</length>
            <radius>0.323342</radius>
          </cylinder>
        </geometry>
        <material>
          <diffuse>0.2 0.2 0.2 1</diffuse>
        </material>
      </visual>
      <visual name="m1">
        <pose>0 0 0.1075 0 1.570796326794896557998982
          1.570796326794896557998982</pose>
        <material>
          <diffuse>0.9 0.9 0.9 1</diffuse>
        </material>
        <geometry>
          <box>
            <size>0.0025 0.0025 0.25</size>
          </box>
        </geometry>
      </visual>
      <collision name="wheel">
        <pose>0 0 0 0 0 0</pose>
        <geometry>
          <cylinder>
            <radius>0.323342</radius>
            <length>0.215</length>
          </cylinder>
        </geometry>
      </collision>
    </link>
    <link name="rear_axle">
      <pose>-1.40948 0 0.323342 0 0 0</pose>
      <visual name="visual">
        <pose>0 0 0 0 0 0</pose>
        <geometry>
          <box>
            <size>0.061842 1.38898 0.030921</size>
          </box>
        </geometry>
        <material>
          <diffuse>0 0 1 1</diffuse>
        </material>
      </visual>
    </link>
    <link name="left_wheel_rear">
      <pose>-1.40948 0.8019899999999999806732376 0.323342
        1.570796326794896557998982 0 0</pose>
      <inertial>
        <mass>14.28</mass>
        <inertia>
          <ixx>0.499912</ixx>
          <ixy>0</ixy>
          <ixz>0</ixz>
          <iyy>0.778439</iyy>
          <iyz>0</iyz>
          <izz>0.499912</izz>
        </inertia>
      </inertial>
      <visual name="m2">
        <pose>0 0 -.1075 0 1.570796326794896557998982
          3.141592653589793115997963</pose>
        <material>
          <diffuse>0.9 0.9 0.9 1</diffuse>
        </material>
        <geometry>
          <box>
            <size>0.0025 0.0025 0.25</size>
          </box>
        </geometry>
      </visual>
      <visual name="m1">
        <pose>0 0 -.1075 0 1.570796326794896557998982
          1.570796326794896557998982</pose>
        <material>
          <diffuse>0.9 0.9 0.9 1</diffuse>
        </material>
        <geometry>
          <box>
            <size>0.0025 0.0025 0.25</size>
          </box>
        </geometry>
      </visual>
      <visual name="wheel">
        <pose>0 0 0 0 0 0</pose>
        <geometry>
          <cylinder>
            <length>0.215</length>
            <radius>0.323342</radius>
          </cylinder>
        </geometry>
        <material>
          <diffuse>0.2 0.2 0.2 1</diffuse>
        </material>
      </visual>
      <collision name="wheel">
        <pose>0 0 0 0 0 0</pose>
        <geometry>
          <cylinder>
            <radius>0.323342</radius>
            <length>0.215</length>
          </cylinder>
        </geometry>
      </collision>
    </link>
    <link name="right_wheel_rear">
      <pose>-1.40948 -0.8019899999999999806732376 0.323342
        1.570796326794896557998982 0 0</pose>
      <inertial>
        <mass>14.28</mass>
        <inertia>
          <ixx>0.499912</ixx>
          <ixy>0</ixy>
          <ixz>0</ixz>
          <iyy>0.778439</iyy>
          <iyz>0</iyz>
          <izz>0.499912</izz>
        </inertia>
      </inertial>
      <visual name="m2">
        <pose>0 0 .1075 0 1.570796326794896557998982
          3.141592653589793115997963</pose>
        <material>
          <diffuse>0.9 0.9 0.9 1</diffuse>
        </material>
        <geometry>
          <box>
            <size>0.0025 0.0025 0.25</size>
          </box>
        </geometry>
      </visual>
      <visual name="wheel">
        <pose>0 0 0 0 0 0</pose>
        <geometry>
          <cylinder>
            <length>0.215</length>
            <radius>0.323342</radius>
          </cylinder>
        </geometry>
        <material>
          <diffuse>0.2 0.2 0.2 1</diffuse>
        </material>
      </visual>
      <visual name="m1">
        <pose>0 0 .1075 0 1.570796326794896557998982
          1.570796326794896557998982</pose>
        <material>
          <diffuse>0.9 0.9 0.9 1</diffuse>
        </material>
        <geometry>
          <box>
            <size>0.0025 0.0025 0.25</size>
          </box>
        </geometry>
      </visual>
      <collision name="wheel">
        <pose>0 0 0 0 0 0</pose>
        <geometry>
          <cylinder>
            <radius>0.323342</radius>
            <length>0.215</length>
          </cylinder>
        </geometry>
      </collision>
    </link>
    <link name="body">
      <pose>0 0 0.385184 0 0 0</pose>
      <inertial>
        <pose>0 0 0 0 0 0</pose>
        <mass>54.2794</mass>
        <!-- TODO(shensquared): Work with Steve to verify the inertia values
        below are reasonable. -->
        <inertia>
          <ixx>0.0216238</ixx>
          <ixy>0</ixy>
          <ixz>0</ixz>
          <iyy>5.00375</iyy>
          <iyz>0</iyz>
          <izz>5.01672</izz>
        </inertia>
      </inertial>
      <visual name="visual">
        <pose>-2.27 -0.91139 -0.21858 0 0 0</pose>
        <geometry>
          <mesh>
            <uri>prius.dae</uri>
          </mesh>
        </geometry>
        <material>
          <emissive>0 0 0 1</emissive>
        </material>
      </visual>
    </link>
    <joint name="chassis_floor_axle" type="fixed">
      <parent>chassis_floor</parent>
      <child>front_axle</child>
      <pose>0 0 0 0 0 0</pose>
    </joint>
    <joint name="steering" type="revolute">
      <parent>front_axle</parent>
      <child>left_tie_rod_arm</child>
      <pose>0.17246968 0.08622747 0 0 0 0</pose>
      <axis>
        <xyz>0 0 1</xyz>
        <limit>
          <lower>-0.401426</lower>
          <upper>0.5</upper>
        </limit>
      </axis>
    </joint>
    <joint name="left_hub" type="fixed">
      <parent>left_tie_rod_arm</parent>
      <child>left_hub</child>
      <pose>0 0 0 0 0 0</pose>
    </joint>
    <joint name="left_pin" type="revolute">
      <parent>left_tie_rod_arm</parent>
      <child>tie_rod</child>
      <pose>0 0.4085 0 0 0 0</pose>
      <axis>
        <xyz>0 0 1</xyz>
        <limit>
          <lower>-1.5</lower>
          <upper>1.5</upper>
          <effort>0</effort>
        </limit>
      </axis>
    </joint>
    <joint name="left_wheel_joint" type="revolute">
      <parent>left_hub</parent>
      <child>left_wheel</child>
      <pose>0 0 0 0 0 0</pose>
      <axis>
        <xyz>0 1 0</xyz>
        <use_parent_model_frame>1</use_parent_model_frame>
      </axis>
    </joint>
    <joint name="axle_tie_rod_arm" type="revolute">
      <parent>front_axle</parent>
      <child>right_tie_rod_arm</child>
      <pose>0.17246968 -0.08623384 0 0 0 0</pose>
      <axis>
        <xyz>0 0 1</xyz>
        <limit>
          <lower>-0.401426</lower>
          <upper>0.5</upper>
          <effort>0</effort>
        </limit>
      </axis>
    </joint>
    <joint name="right_hub" type="fixed">
      <parent>right_tie_rod_arm</parent>
      <child>right_hub</child>
      <pose>0 0 0 0 0 0</pose>
    </joint>
    <joint name="right_pin" type="revolute">
      <parent>right_tie_rod_arm</parent>
      <child>tie_rod</child>
      <pose>0 -0.817006 0 0 0 0</pose>
      <axis>
        <xyz>0 0 1</xyz>
        <limit>
          <lower>-3.141592653589793115997963</lower>
          <upper>3.141592653589793115997963</upper>
          <effort>0</effort>
        </limit>
      </axis>
    </joint>
    <joint name="right_wheel_joint" type="revolute">
      <parent>right_hub</parent>
      <child>right_wheel</child>
      <pose>0 0 0 0 0 0</pose>
      <axis>
        <xyz>0 1 0</xyz>
        <use_parent_model_frame>1</use_parent_model_frame>
      </axis>
    </joint>
    <joint name="chassis_rear_axle" type="fixed">
      <parent>chassis_floor</parent>
      <child>rear_axle</child>
      <pose>0 0 0 0 0 0</pose>
    </joint>
    <joint name="rear_left_wheel_joint" type="revolute">
      <parent>rear_axle</parent>
      <child>left_wheel_rear</child>
      <pose>0 0 0 0 0 0</pose>
      <axis>
        <xyz>0 1 0</xyz>
        <use_parent_model_frame>1</use_parent_model_frame>
        <limit>
          <effort>0</effort>
        </limit>
      </axis>
    </joint>
    <joint name="rear_right_wheel_joint" type="revolute">
      <parent>rear_axle</parent>
      <child>right_wheel_rear</child>
      <pose>0 0 0 0 0 0</pose>
      <axis>
        <xyz>0 1 0</xyz>
        <use_parent_model_frame>1</use_parent_model_frame>
        <limit>
          <effort>0</effort>
        </limit>
      </axis>
    </joint>
    <joint name="body" type="fixed">
      <parent>chassis_floor</parent>
      <child>body</child>
      <pose>0 0 0 0 0 0</pose>
    </joint>
  </model>
</sdf>
