<?xml version="1.0" ?>
<!-- =================================================================================== -->
<!-- |    This document was autogenerated by xacro from /home/aochiai/Projects/hsr_oss_ws/src/hsr_description/robots/hsrb4s.urdf.xacro | -->
<!-- |    EDITING THIS FILE BY HAND IS NOT RECOMMENDED                                 | -->
<!-- =================================================================================== -->
<!--
Copyright (c) 2017, Toyota Motor Corporation
All rights reserved.

Redistribution and use in source and binary forms, with or without
modification, are permitted provided that the following conditions are met:

 * Redistributions of source code must retain the above copyright notice,
   this list of conditions and the following disclaimer.
 * Redistributions in binary form must reproduce the above copyright
   notice, this list of conditions and the following disclaimer in the
   documentation and/or other materials provided with the distribution.
 * Neither the name of Toyota Motor Corporation nor the names of its
   contributors may be used to endorse or promote products derived from
   this software without specific prior written permission.

THIS SOFTWARE IS PROVIDED BY THE COPYRIGHT HOLDERS AND CONTRIBUTORS "AS IS"
AND ANY EXPRESS OR IMPLIED WARRANTIES, INCLUDING, BUT NOT LIMITED TO, THE
IMPLIED WARRANTIES OF MERCHANTABILITY AND FITNESS FOR A PARTICULAR PURPOSE
ARE DISCLAIMED. IN NO EVENT SHALL THE COPYRIGHT OWNER OR CONTRIBUTORS BE
LIABLE FOR ANY DIRECT, INDIRECT, INCIDENTAL, SPECIAL, EXEMPLARY, OR
CONSEQUENTIAL DAMAGES (INCLUDING, BUT NOT LIMITED TO, PROCUREMENT OF
SUBSTITUTE GOODS OR SERVICES; LOSS OF USE, DATA, OR PROFITS; OR BUSINESS
INTERRUPTION) HOWEVER CAUSED AND ON ANY THEORY OF LIABILITY, WHETHER IN
CONTRACT, STRICT LIABILITY, OR TORT (INCLUDING NEGLIGENCE OR OTHERWISE)
ARISING IN ANY WAY OUT OF THE USE OF THIS SOFTWARE, EVEN IF ADVISED OF THE
POSSIBILITY OF SUCH DAMAGE.
-->
<robot name="hsrb" xmlns:controller="http://playerstage.sourceforge.net/gazebo/xmlschema/#controller" xmlns:interface="http://playerstage.sourceforge.net/gazebo/xmlschema/#interface" xmlns:sensor="http://playerstage.sourceforge.net/gazebo/xmlschema/#sensor" xmlns:xacro="http://ros.org/wiki/xacro">
  <material name="body_main">
    <color rgba="1.0 0.0 0.0 1.0"/>
  </material>
  <material name="body_sub">
    <color rgba="0.3333 0.3333 0.3333 1.0"/>
  </material>
  <material name="wheel">
    <color rgba="0.2 0.2 0.2 1.0"/>
  </material>
  <material name="black">
    <color rgba="0.1 0.1 0.1 1.0"/>
  </material>
  <material name="tablet">
    <color rgba="0.1 0.1 0.2 1.0"/>
  </material>
  <!--
    ASUS Xtion PRO LIVE
    Specs from:
    http://www.asus.com/Multimedia/Xtion_PRO_LIVE/#specifications
    -->
  <link name="base_footprint"/>
  <joint name="base_footprint_joint" type="fixed">
    <parent link="base_footprint"/>
    <child link="base_link"/>
  </joint>
  <link name="base_link">
    <inertial>
      <mass value="50.00"/>
      <!-- use dummy weight to stabilize gazebo move base (real value: 11.017971)-->
      <origin xyz="-0.025978 -0.005498 0.17633"/>
      <inertia ixx="0.3742" ixy="0.000434172172" ixz="0.03088" iyy="0.3436" iyz="0.01775" izz="0.1509"/>
    </inertial>
    <visual>
      <geometry>
        <mesh filename="meshes/base_v2/base_light.obj"/>
      </geometry>
    </visual>
    <visual>
      <geometry>
        <mesh filename="meshes/base_v2/body_light.obj"/>
      </geometry>
    </visual>
    <visual>
      <geometry>
        <mesh filename="meshes/base_v2/torso_base.obj"/>
      </geometry>
    </visual>
    <collision>
      <geometry>
        <mesh filename="meshes/base_v2/base.obj"/>
      </geometry>
    </collision>
  </link>
  <joint name="base_roll_joint" type="continuous">
    <origin rpy="0.0 0.0 0.0" xyz="0.0 0.0 0.0"/>
    <axis xyz="0.0 0.0 1.0"/>
    <limit effort="34.46" velocity="2.5"/>
    <parent link="base_link"/>
    <child link="base_roll_link"/>
    <dynamics damping="0.7"/>
  </joint>
  <link name="base_roll_link">
    <inertial>
      <origin xyz="-0.01948200 0.00219100 0.07101300"/>
      <mass value="10.239419"/>
      <inertia ixx="0.07671000" ixy="-0.01005000" ixz="0.00174900" iyy="0.09057000" iyz="0.00154900" izz="0.14500000"/>
    </inertial>
  </link>
  <joint name="base_r_drive_wheel_joint" type="continuous">
    <origin rpy="0.0 0.0 0.0" xyz="-0.11 -0.133 0.04"/>
    <axis xyz="0.0 1.0 0.0"/>
    <limit effort="11.067" velocity="20.8"/>
    <parent link="base_roll_link"/>
    <child link="base_r_drive_wheel_link"/>
    <dynamics damping="1.0"/>
  </joint>
  <link name="base_r_drive_wheel_link">
    <visual>
      <origin rpy="1.5707963268 0.0 0.0" xyz="0.0 0.0 0.0"/>
      <geometry>
        <cylinder length="0.03" radius="0.04"/>
      </geometry>
      <material name="wheel"/>
    </visual>
    <collision>
      <origin rpy="1.5707963268 0.0 0.0" xyz="0.0 0.0 0.0"/>
      <geometry>
        <cylinder length="0.03" radius="0.04"/>
      </geometry>
    </collision>
    <inertial>
      <mass value="0.2"/>
      <origin xyz="0 0 0"/>
      <inertia ixx="0.015" ixy="0" ixz="0" iyy="0.015" iyz="0" izz="0.015"/>
    </inertial>
  </link>
  <joint name="base_l_drive_wheel_joint" type="continuous">
    <origin rpy="0.0 0.0 0.0" xyz="-0.11 0.133 0.04"/>
    <axis xyz="0.0 1.0 0.0"/>
    <limit effort="11.067" velocity="20.8"/>
    <parent link="base_roll_link"/>
    <child link="base_l_drive_wheel_link"/>
    <dynamics damping="1.0"/>
  </joint>
  <link name="base_l_drive_wheel_link">
    <visual>
      <origin rpy="1.5707963268 0.0 0.0" xyz="0.0 0.0 0.0"/>
      <geometry>
        <cylinder length="0.03" radius="0.04"/>
      </geometry>
      <material name="wheel"/>
    </visual>
    <collision>
      <origin rpy="1.5707963268 0.0 0.0" xyz="0.0 0.0 0.0"/>
      <geometry>
        <cylinder length="0.03" radius="0.04"/>
      </geometry>
    </collision>
    <inertial>
      <mass value="0.2"/>
      <origin xyz="0 0 0"/>
      <inertia ixx="0.015" ixy="0" ixz="0" iyy="0.015" iyz="0" izz="0.015"/>
    </inertial>
  </link>
  <joint name="base_r_passive_wheel_x_frame_joint" type="continuous">
    <origin rpy="0.0 0.0 0.0" xyz="0.1495                 -0.055                 0.03"/>
    <axis xyz="1.0 0.0 0.0"/>
    <limit effort="1.0" velocity="3.0"/>
    <parent link="base_roll_link"/>
    <child link="base_r_passive_wheel_x_frame"/>
    <dynamics damping="1.0"/>
  </joint>
  <link name="base_r_passive_wheel_x_frame">
    <inertial>
      <mass value="0.2"/>
      <origin xyz="0 0 0"/>
      <inertia ixx="0.015" ixy="0" ixz="0" iyy="0.015" iyz="0" izz="0.015"/>
    </inertial>
  </link>
  <joint name="base_r_passive_wheel_y_frame_joint" type="continuous">
    <axis xyz="0.0 1.0 0.0"/>
    <limit effort="8.85" velocity="10.0"/>
    <parent link="base_r_passive_wheel_x_frame"/>
    <child link="base_r_passive_wheel_y_frame"/>
  </joint>
  <link name="base_r_passive_wheel_y_frame">
    <inertial>
      <mass value="0.2"/>
      <origin xyz="0 0 0"/>
      <inertia ixx="0.015" ixy="0" ixz="0" iyy="0.015" iyz="0" izz="0.015"/>
    </inertial>
  </link>
  <joint name="base_r_passive_wheel_z_joint" type="continuous">
    <axis xyz="0.0 0.0 1.0"/>
    <limit effort="8.85" velocity="10.0"/>
    <parent link="base_r_passive_wheel_y_frame"/>
    <child link="base_r_passive_wheel_z_link"/>
  </joint>
  <link name="base_r_passive_wheel_z_link">
    <visual>
      <geometry>
        <sphere radius="0.03"/>
      </geometry>
      <material name="wheel"/>
    </visual>
    <collision>
      <geometry>
        <sphere radius="0.03"/>
      </geometry>
    </collision>
    <inertial>
      <mass value="0.2"/>
      <origin xyz="0 0 0"/>
      <inertia ixx="0.015" ixy="0" ixz="0" iyy="0.015" iyz="0" izz="0.015"/>
    </inertial>
  </link>
  <joint name="base_l_passive_wheel_x_frame_joint" type="continuous">
    <origin rpy="0.0 0.0 0.0" xyz="0.1495                 0.055                 0.03"/>
    <axis xyz="1.0 0.0 0.0"/>
    <limit effort="1.0" velocity="3.0"/>
    <parent link="base_roll_link"/>
    <child link="base_l_passive_wheel_x_frame"/>
    <dynamics damping="1.0"/>
  </joint>
  <link name="base_l_passive_wheel_x_frame">
    <inertial>
      <mass value="0.2"/>
      <origin xyz="0 0 0"/>
      <inertia ixx="0.015" ixy="0" ixz="0" iyy="0.015" iyz="0" izz="0.015"/>
    </inertial>
  </link>
  <joint name="base_l_passive_wheel_y_frame_joint" type="continuous">
    <axis xyz="0.0 1.0 0.0"/>
    <limit effort="8.85" velocity="10.0"/>
    <parent link="base_l_passive_wheel_x_frame"/>
    <child link="base_l_passive_wheel_y_frame"/>
  </joint>
  <link name="base_l_passive_wheel_y_frame">
    <inertial>
      <mass value="0.2"/>
      <origin xyz="0 0 0"/>
      <inertia ixx="0.015" ixy="0" ixz="0" iyy="0.015" iyz="0" izz="0.015"/>
    </inertial>
  </link>
  <joint name="base_l_passive_wheel_z_joint" type="continuous">
    <axis xyz="0.0 0.0 1.0"/>
    <limit effort="8.85" velocity="10.0"/>
    <parent link="base_l_passive_wheel_y_frame"/>
    <child link="base_l_passive_wheel_z_link"/>
  </joint>
  <link name="base_l_passive_wheel_z_link">
    <visual>
      <geometry>
        <sphere radius="0.03"/>
      </geometry>
      <material name="wheel"/>
    </visual>
    <collision>
      <geometry>
        <sphere radius="0.03"/>
      </geometry>
    </collision>
    <inertial>
      <mass value="0.2"/>
      <origin xyz="0 0 0"/>
      <inertia ixx="0.015" ixy="0" ixz="0" iyy="0.015" iyz="0" izz="0.015"/>
    </inertial>
  </link>
  <joint name="base_range_sensor_joint" type="fixed">
    <origin rpy="0.0 0.0 0.0" xyz="0.1675 0.0 0.1844"/>
    <parent link="base_link"/>
    <child link="base_range_sensor_link"/>
  </joint>
  <link name="base_range_sensor_link">
    <visual>
      <geometry>
        <mesh filename="meshes/sensors/laser.obj"/>
      </geometry>
    </visual>
    <collision>
      <geometry>
        <mesh filename="meshes/sensors/laser.obj"/>
      </geometry>
    </collision>
  </link>
  <gazebo reference="base_range_sensor_link">
    <sensor name="base_range_sensor" type="ray">
      <pose>0 0 0 0 0 0</pose>
      <update_rate>30.0</update_rate>
      <visualize>true</visualize>
      <ray>
        <scan>
          <horizontal>
            <samples>721</samples>
            <resolution>1</resolution>
            <min_angle>-2.1</min_angle>
            <max_angle>2.1</max_angle>
          </horizontal>
        </scan>
        <range>
          <min>0.05</min>
          <max>60</max>
          <resolution>0.001</resolution>
        </range>
      </ray>
      <plugin filename="libgazebo_ros_laser.so" name="laser">
        <topicName>hsrb/base_scan</topicName>
        <frameName>base_range_sensor_link</frameName>
      </plugin>
    </sensor>
  </gazebo>
  <joint name="base_imu_frame_joint" type="fixed">
    <origin rpy="3.14159265359 0.0 0.0" xyz="0.0005 0.1296 0.181"/>
    <parent link="base_link"/>
    <child link="base_imu_frame"/>
  </joint>
  <link name="base_imu_frame"/>
  <gazebo reference="base_imu_frame">
    <sensor name="base_imu" type="imu">
      <update_rate>10.0</update_rate>
      <imu>
        <noise>
          <type>gaussian</type>
          <rate>
            <mean>0.0</mean>
            <stddev>2e-4</stddev>
            <bias_mean>0.0000075</bias_mean>
            <bias_stddev>0.0000008</bias_stddev>
          </rate>
          <accel>
            <mean>0.0</mean>
            <stddev>1.7e-2</stddev>
            <bias_mean>0.1</bias_mean>
            <bias_stddev>0.001</bias_stddev>
          </accel>
        </noise>
      </imu>
    </sensor>
  </gazebo>
  <gazebo>
    <!-- IMU Plugin is a model plugin. Then it should be atached to HSR-B model. -->
    <plugin filename="libgazebo_ros_imu.so" name="base_imu_plugin">
      <imuName>base_imu</imuName>
      <topicName>base_imu/data</topicName>
      <serviceName>base_imu/calibrate</serviceName>
      <frameName>base_imu_frame</frameName>
      <bodyName>base_link</bodyName>
      <robotNamespace>hsrb</robotNamespace>
    </plugin>
  </gazebo>
  <gazebo reference="base_link">
    <selfCollide>false</selfCollide>
    <gravity>true</gravity>
    <mu1>0.9</mu1>
    <mu2>0.9</mu2>
  </gazebo>
  <gazebo reference="base_roll_link">
    <selfCollide>false</selfCollide>
    <gravity>true</gravity>
    <mu1>0.9</mu1>
    <mu2>0.9</mu2>
  </gazebo>
  <gazebo reference="base_r_drive_wheel_link">
    <selfCollide>false</selfCollide>
    <gravity>true</gravity>
    <turnGravityOff>false</turnGravityOff>
    <kp>1000000.0</kp>
    <kd>10.0</kd>
    <mu1>1.0</mu1>
    <mu2>1.0</mu2>
    <fdir1>1 0 0</fdir1>
    <maxVel>1.0</maxVel>
    <minDepth>0.00</minDepth>
    <material value="Gazebo/FlatBlack"/>
  </gazebo>
  <gazebo reference="base_l_drive_wheel_link">
    <selfCollide>false</selfCollide>
    <gravity>true</gravity>
    <turnGravityOff>false</turnGravityOff>
    <kp>1000000.0</kp>
    <kd>10.0</kd>
    <mu1>1.0</mu1>
    <mu2>1.0</mu2>
    <fdir1>1 0 0</fdir1>
    <maxVel>1.0</maxVel>
    <minDepth>0.00</minDepth>
    <material value="Gazebo/FlatBlack"/>
  </gazebo>
  <gazebo reference="base_r_passive_wheel_z_link">
    <selfCollide>false</selfCollide>
    <gravity>true</gravity>
    <mu1>0.1</mu1>
    <mu2>0.1</mu2>
    <maxVel>1.0</maxVel>
    <material value="Gazebo/FlatBlack"/>
  </gazebo>
  <gazebo reference="base_l_passive_wheel_z_link">
    <selfCollide>false</selfCollide>
    <gravity>true</gravity>
    <mu1>0.1</mu1>
    <mu2>0.1</mu2>
    <maxVel>1.0</maxVel>
    <material value="Gazebo/FlatBlack"/>
  </gazebo>
  <gazebo reference="base_range_sensor_link">
    <selfCollide>false</selfCollide>
    <gravity>true</gravity>
    <mu1>0.9</mu1>
    <mu2>0.9</mu2>
  </gazebo>
  <gazebo reference="base_imu_frame">
    <selfCollide>false</selfCollide>
    <gravity>true</gravity>
    <mu1>0.9</mu1>
    <mu2>0.9</mu2>
  </gazebo>
  <transmission name="base_transmission">
    <type>transmission_interface/SimpleTransmission</type>
    <joint name="base_r_drive_wheel_joint">
      <hardwareInterface>VelocityJointInterface</hardwareInterface>
    </joint>
    <actuator name="base_r_drive_wheel_joint_actuator">
      <hardwareInterface>VelocityJointInterface</hardwareInterface>
      <mechanicalReduction>1</mechanicalReduction>
    </actuator>
  </transmission>
  <transmission name="base_transmission">
    <type>transmission_interface/SimpleTransmission</type>
    <joint name="base_l_drive_wheel_joint">
      <hardwareInterface>VelocityJointInterface</hardwareInterface>
    </joint>
    <actuator name="base_l_drive_wheel_joint_actuator">
      <hardwareInterface>VelocityJointInterface</hardwareInterface>
      <mechanicalReduction>1</mechanicalReduction>
    </actuator>
  </transmission>
  <transmission name="base_roll_joint_transmission">
    <type>transmission_interface/SimpleTransmission</type>
    <joint name="base_roll_joint">
      <hardwareInterface>PositionJointInterface</hardwareInterface>
    </joint>
    <actuator name="base_roll_joint_actuator">
      <hardwareInterface>PositionJointInterface</hardwareInterface>
      <mechanicalReduction>1</mechanicalReduction>
    </actuator>
  </transmission>
  <joint name="torso_lift_joint" type="prismatic">
    <origin rpy="0.0 0.0 0.0" xyz="0.0 0.0 0.752"/>
    <!-- <origin xyz="0.0 0.0 0.752" rpy="0.0 0.0 0.0" /> -->
    <axis xyz="0.0 0.0 1.0"/>
    <limit effort="100.0" lower="0.0" upper="0.345" velocity="0.1"/>
    <parent link="base_link"/>
    <child link="torso_lift_link"/>
    <mimic joint="arm_lift_joint" multiplier="0.5"/>
    <dynamics damping="500.0"/>
  </joint>
  <link name="torso_lift_link">
    <inertial>
      <mass value="3.420779"/>
      <origin xyz="-0.051142 0.003454 -0.2905"/>
      <inertia ixx="0.1045" ixy="-0.000460884801" ixz="0.000101130383" iyy="0.105" iyz="0.002941" izz="0.01284"/>
    </inertial>
    <visual>
      <geometry>
        <mesh filename="meshes/torso_v0/torso_light.obj"/>
      </geometry>
    </visual>
    <collision>
      <geometry>
        <mesh filename="meshes/torso_v0/torso.obj"/>
      </geometry>
    </collision>
  </link>
  <gazebo reference="torso_lift_link">
    <selfCollide>false</selfCollide>
    <gravity>true</gravity>
    <mu1>0.9</mu1>
    <mu2>0.9</mu2>
  </gazebo>
  <gazebo reference="torso_lift_joint">
    </gazebo>
  <gazebo>
        </gazebo>
  <joint name="head_pan_joint" type="revolute">
    <origin rpy="0.0 0.0 0.0" xyz="0.0 0.0 0.0"/>
    <axis xyz="0.0 0.0 1.0"/>
    <limit effort="100.0" lower="-3.84" upper="1.75" velocity="1.0"/>
    <parent link="torso_lift_link"/>
    <child link="head_pan_link"/>
    <dynamics damping="1.0"/>
  </joint>
  <link name="head_pan_link">
    <inertial>
      <mass value="0.571903"/>
      <origin xyz="0.001724 -0.001969 -0.028886"/>
      <inertia ixx="0.0009711421" ixy="0.00006179487" ixz="-0.000113923121" iyy="0.00065335493" iyz="0.000069036305" izz="0.000765202576"/>
    </inertial>
    <visual>
      <geometry>
        <mesh filename="meshes/head_v1/head_pan.obj"/>
      </geometry>
    </visual>
    <collision>
      <geometry>
        <mesh filename="meshes/head_v1/head_pan.obj"/>
      </geometry>
    </collision>
  </link>
  <joint name="head_tilt_joint" type="revolute">
    <origin rpy="0.0 0.0 0.0" xyz="0.02 0.0 0.0"/>
    <axis xyz="0.0 -1.0 0.0"/>
    <limit effort="100.0" lower="-1.57" upper="0.52" velocity="1.0"/>
    <parent link="head_pan_link"/>
    <child link="head_tilt_link"/>
    <dynamics damping="10.0"/>
  </joint>
  <link name="head_tilt_link">
    <inertial>
      <mass value="2.123802"/>
      <origin xyz="-0.055376 -0.002436 0.117733"/>
      <inertia ixx="0.01941" ixy="-0.000138091054" ixz="0.005035" iyy="0.01498" iyz="0.000087492537" izz="0.01167"/>
    </inertial>
    <visual>
      <geometry>
        <mesh filename="meshes/head_v1/head_upper.obj"/>
      </geometry>
    </visual>
    <visual>
      <geometry>
        <mesh filename="meshes/head_v1/head_tilt.obj"/>
      </geometry>
    </visual>
    <visual>
      <geometry>
        <mesh filename="meshes/head_v1/tablet_base.obj"/>
      </geometry>
    </visual>
    <collision>
      <geometry>
        <mesh filename="meshes/head_v1/head.obj"/>
      </geometry>
    </collision>
    <collision>
      <geometry>
        <mesh filename="meshes/head_v1/tablet.obj"/>
      </geometry>
    </collision>
  </link>
  <joint name="head_l_stereo_camera_joint" type="fixed">
    <origin rpy="-1.5707963268 0.0 -1.5707963268" xyz="0.02 0.07 0.061"/>
    <parent link="head_tilt_link"/>
    <child link="head_l_stereo_camera_link"/>
  </joint>
  <link name="head_l_stereo_camera_link">
    <visual>
      <origin rpy="0.0 0.0 0.0" xyz="0 0 0"/>
      <geometry>
        <mesh filename="meshes/sensors/head_camera.obj"/>
      </geometry>
    </visual>
  </link>
  <joint name="head_l_stereo_camera_gazebo_frame_joint" type="fixed">
    <origin rpy="1.5707963268 -1.5707963268 0.0" xyz="0 0 0"/>
    <parent link="head_l_stereo_camera_link"/>
    <child link="head_l_stereo_camera_gazebo_frame"/>
  </joint>
  <link name="head_l_stereo_camera_gazebo_frame"/>
  <gazebo reference="head_l_stereo_camera_gazebo_frame">
    <sensor name="head_l_stereo_camera" type="camera">
      <update_rate>4.0</update_rate>
      <camera name="head_l_stereo_camera">
        <horizontal_fov>1.16762527</horizontal_fov>
        <image>
          <width>1280</width>
          <height>960</height>
          <format>R8G8B8</format>
        </image>
        <clip>
          <near>0.05</near>
          <far>100</far>
        </clip>
        <noise>
          <type>gaussian</type>
          <mean>0.0</mean>
          <stddev>0.007</stddev>
        </noise>
      </camera>
      <plugin filename="libgazebo_ros_camera.so" name="camera_controller">
        <alwaysOn>0</alwaysOn>
        <updateRate>0.0</updateRate>
        <cameraName>head_l_stereo_camera</cameraName>
        <imageTopicName>image_rect_color</imageTopicName>
        <cameraInfoTopicName>camera_info</cameraInfoTopicName>
        <frameName>head_l_stereo_camera_frame</frameName>
        <robotNamespace>hsrb</robotNamespace>
        <hackBaseline>0.0</hackBaseline>
        <distortionK1>0.0</distortionK1>
        <distortionK2>0.0</distortionK2>
        <distortionK3>0.0</distortionK3>
        <distortionT1>0.0</distortionT1>
        <distortionT2>0.0</distortionT2>
      </plugin>
    </sensor>
  </gazebo>
  <joint name="head_r_stereo_camera_joint" type="fixed">
    <origin rpy="-1.5707963268 0.0 -1.5707963268" xyz="0.02 -0.07 0.061"/>
    <parent link="head_tilt_link"/>
    <child link="head_r_stereo_camera_link"/>
  </joint>
  <link name="head_r_stereo_camera_link">
    <visual>
      <origin rpy="0.0 0.0 0.0" xyz="0 0 0"/>
      <geometry>
        <mesh filename="meshes/sensors/head_camera.obj"/>
      </geometry>
    </visual>
  </link>
  <joint name="head_r_stereo_camera_gazebo_frame_joint" type="fixed">
    <origin rpy="1.5707963268 -1.5707963268 0.0" xyz="0 0 0"/>
    <parent link="head_r_stereo_camera_link"/>
    <child link="head_r_stereo_camera_gazebo_frame"/>
  </joint>
  <link name="head_r_stereo_camera_gazebo_frame"/>
  <gazebo reference="head_r_stereo_camera_gazebo_frame">
    <sensor name="head_r_stereo_camera" type="camera">
      <update_rate>4.0</update_rate>
      <camera name="head_r_stereo_camera">
        <horizontal_fov>1.16762527</horizontal_fov>
        <image>
          <width>1280</width>
          <height>960</height>
          <format>R8G8B8</format>
        </image>
        <clip>
          <near>0.05</near>
          <far>100</far>
        </clip>
        <noise>
          <type>gaussian</type>
          <mean>0.0</mean>
          <stddev>0.007</stddev>
        </noise>
      </camera>
      <plugin filename="libgazebo_ros_camera.so" name="camera_controller">
        <alwaysOn>0</alwaysOn>
        <updateRate>0.0</updateRate>
        <cameraName>head_r_stereo_camera</cameraName>
        <imageTopicName>image_rect_color</imageTopicName>
        <cameraInfoTopicName>camera_info</cameraInfoTopicName>
        <frameName>head_r_stereo_camera_frame</frameName>
        <robotNamespace>hsrb</robotNamespace>
        <hackBaseline>0.14</hackBaseline>
        <distortionK1>0.0</distortionK1>
        <distortionK2>0.0</distortionK2>
        <distortionK3>0.0</distortionK3>
        <distortionT1>0.0</distortionT1>
        <distortionT2>0.0</distortionT2>
      </plugin>
    </sensor>
  </gazebo>
  <joint name="head_center_camera_frame_joint" type="fixed">
    <origin rpy="-1.5707963268 0.0 -1.5707963268" xyz="0.0195 0.0 0.061"/>
    <parent link="head_tilt_link"/>
    <child link="head_center_camera_frame"/>
  </joint>
  <link name="head_center_camera_frame"/>
  <joint name="head_center_camera_gazebo_frame_joint" type="fixed">
    <origin rpy="1.5707963268 -1.5707963268 0.0" xyz="0 0 0"/>
    <parent link="head_center_camera_frame"/>
    <child link="head_center_camera_gazebo_frame"/>
  </joint>
  <link name="head_center_camera_gazebo_frame"/>
  <gazebo reference="head_center_camera_gazebo_frame">
    <sensor name="head_center_camera" type="camera">
      <update_rate>10.0</update_rate>
      <camera name="head_center_camera">
        <horizontal_fov>2.00</horizontal_fov>
        <image>
          <width>640</width>
          <height>480</height>
          <format>R8G8B8</format>
        </image>
        <clip>
          <near>0.05</near>
          <far>100</far>
        </clip>
        <noise>
          <type>gaussian</type>
          <mean>0.0</mean>
          <stddev>0.007</stddev>
        </noise>
      </camera>
      <plugin filename="libhsrb_gazebo_ros_camera.so" name="camera_controller">
        <robotNamespace>hsrb</robotNamespace>
        <alwaysOn>0</alwaysOn>
        <updateRate>0.0</updateRate>
        <cameraName>head_center_camera</cameraName>
        <imageTopicName>image_raw</imageTopicName>
        <cameraInfoTopicName>camera_info</cameraInfoTopicName>
        <frameName>head_center_camera_frame</frameName>
        <hackBaseline>0.07</hackBaseline>
        <distortionK1>0.0</distortionK1>
        <distortionK2>0.0</distortionK2>
        <distortionK3>0.0</distortionK3>
        <distortionT1>0.0</distortionT1>
        <distortionT2>0.0</distortionT2>
      </plugin>
    </sensor>
  </gazebo>
  <joint name="head_rgbd_sensor_joint" type="fixed">
    <origin rpy="-1.5707963268 0.0 -1.5707963268" xyz="-0.079796 0.022 0.215172"/>
    <parent link="head_tilt_link"/>
    <child link="head_rgbd_sensor_link"/>
  </joint>
  <link name="head_rgbd_sensor_link">
    <visual>
      <origin rpy="0.0 0.0 0.0" xyz="0 0 0"/>
      <geometry>
        <mesh filename="meshes/sensors/rgbd_light.obj"/>
      </geometry>
    </visual>
    <collision>
      <origin rpy="0.0 0.0 0.0" xyz="0 0 0"/>
      <geometry>
        <mesh filename="meshes/sensors/rgbd.obj"/>
      </geometry>
    </collision>
  </link>
  <joint name="head_rgbd_sensor_gazebo_frame_joint" type="fixed">
    <origin rpy="1.5707963268 -1.5707963268 0.0" xyz="0 0 0"/>
    <parent link="head_rgbd_sensor_link"/>
    <child link="head_rgbd_sensor_gazebo_frame"/>
  </joint>

        `

  <link name="head_rgbd_sensor_gazebo_frame"/>
  <gazebo reference="head_rgbd_sensor_gazebo_frame">
    <sensor name="openni_camera_camera" type="depth">
      <always_on>0</always_on>
      <update_rate>30</update_rate>
      <visualize>true</visualize>
      <camera>
        <horizontal_fov>1.047</horizontal_fov>
        <image>
          <width>640</width>
          <height>480</height>
          <format>B8G8R8</format>
        </image>
        <depth_camera>
                    </depth_camera>
        <clip>
          <near>0.1</near>
          <far>100</far>
        </clip>
      </camera>
      <plugin filename="libgazebo_ros_openni_kinect.so" name="head_rgbd_sensor_controller">
        <alwaysOn>true</alwaysOn>
        <baseline>0.2</baseline>
        <updateRate>1.0</updateRate>
        <cameraName>head_rgbd_sensor</cameraName>
        <frameName>head_rgbd_sensor_rgb_frame</frameName>
        <imageTopicName>/hsrb/head_rgbd_sensor/rgb/image_rect_color</imageTopicName>
        <cameraInfoTopicName>/hsrb/head_rgbd_sensor/rgb/camera_info</cameraInfoTopicName>
        <depthImageTopicName>/hsrb/head_rgbd_sensor/depth_registered/image_rect_raw</depthImageTopicName>
        <pointCloudTopicName>/hsrb/head_rgbd_sensor/depth_registered/rectified_points</pointCloudTopicName>
        <depthImageCameraInfoTopicName>/hsrb/head_rgbd_sensor/depth_registered/camera_info</depthImageCameraInfoTopicName>
        <pointCloudCutoff>0.5</pointCloudCutoff>
        <pointCloudCutoffMax>9.2</pointCloudCutoffMax>
        <distortionK1>0.0</distortionK1>
        <distortionK2>0.0</distortionK2>
        <distortionK3>0.0</distortionK3>
        <distortionT1>0.0</distortionT1>
        <distortionT2>0.0</distortionT2>
        <CxPrime>0.0</CxPrime>
        <Cx>0.0</Cx>
        <Cy>0.0</Cy>
        <focalLength>0.0</focalLength>
        <hackBaseline>0</hackBaseline>
      </plugin>
    </sensor>
  </gazebo>
  <gazebo reference="head_pan_link">
    <selfCollide>false</selfCollide>
    <gravity>true</gravity>
    <mu1>0.9</mu1>
    <mu2>0.9</mu2>
  </gazebo>
  <gazebo reference="head_tilt_link">
    <selfCollide>false</selfCollide>
    <gravity>true</gravity>
    <mu1>0.9</mu1>
    <mu2>0.9</mu2>
  </gazebo>
  <gazebo reference="head_l_stereo_camera_link">
    <selfCollide>false</selfCollide>
    <gravity>true</gravity>
    <mu1>0.9</mu1>
    <mu2>0.9</mu2>
  </gazebo>
  <gazebo reference="head_r_stereo_camera_link">
    <selfCollide>false</selfCollide>
    <gravity>true</gravity>
    <mu1>0.9</mu1>
    <mu2>0.9</mu2>
  </gazebo>
  <gazebo reference="head_center_camera_frame">
    <selfCollide>false</selfCollide>
    <gravity>false</gravity>
    <mu1>0.9</mu1>
    <mu2>0.9</mu2>
  </gazebo>
  <gazebo reference="head_rgbd_sensor_link">
    <selfCollide>false</selfCollide>
    <gravity>true</gravity>
    <mu1>0.9</mu1>
    <mu2>0.9</mu2>
  </gazebo>
  <gazebo reference="head_pan_joint">
  </gazebo>
  <gazebo reference="head_tilt_joint">
  </gazebo>
  <transmission name="head_pan_joint_transmission">
    <type>transmission_interface/SimpleTransmission</type>
    <joint name="head_pan_joint">
      <hardwareInterface>PositionJointInterface</hardwareInterface>
    </joint>
    <actuator name="head_pan_joint_actuator">
      <hardwareInterface>PositionJointInterface</hardwareInterface>
      <mechanicalReduction>1</mechanicalReduction>
    </actuator>
  </transmission>
  <transmission name="head_tilt_joint_transmission">
    <type>transmission_interface/SimpleTransmission</type>
    <joint name="head_tilt_joint">
      <hardwareInterface>PositionJointInterface</hardwareInterface>
    </joint>
    <actuator name="head_tilt_joint_actuator">
      <hardwareInterface>PositionJointInterface</hardwareInterface>
      <mechanicalReduction>1</mechanicalReduction>
    </actuator>
  </transmission>
  <joint name="arm_lift_joint" type="prismatic">
    <origin rpy="0.0 0.0 0.0" xyz="0.0 0.0 0.340"/>
    <axis xyz="0.0 0.0 1.0"/>
    <limit effort="100.0" lower="0.0" upper="0.69" velocity="0.2"/>
    <parent link="base_link"/>
    <child link="arm_lift_link"/>
    <dynamics damping="1.0"/>
  </joint>
  <link name="arm_lift_link">
    <inertial>
      <mass value="1.275819"/>
      <origin xyz="0.051549 0.042438 -0.064145"/>
      <inertia ixx="0.004633" ixy="0.000475272668" ixz="-0.002403" iyy="0.008065" iyz="-0.000100268629" izz="0.007672"/>
    </inertial>
    <visual>
      <geometry>
        <mesh filename="meshes/arm_v0/shoulder.obj"/>
      </geometry>
    </visual>
    <collision>
      <geometry>
        <mesh filename="meshes/arm_v0/shoulder.obj"/>
      </geometry>
    </collision>
  </link>
  <joint name="arm_flex_joint" type="revolute">
    <origin rpy="0.0 0.0 0.0" xyz="0.141 0.078 0.0"/>
    <axis xyz="0.0 -1.0 0.0"/>
    <limit effort="100.0" lower="-2.62" upper="0.0" velocity="1.2"/>
    <parent link="arm_lift_link"/>
    <child link="arm_flex_link"/>
    <dynamics damping="1.0"/>
  </joint>
  <link name="arm_flex_link">
    <inertial>
      <mass value="1.339295"/>
      <origin xyz="0.000632 0.006404 0.118529"/>
      <inertia ixx="0.0085" ixy="-0.000020284207" ixz="-0.000022947194" iyy="0.007102" iyz="-0.000091796075" izz="0.001552"/>
    </inertial>
    <visual>
      <geometry>
        <mesh filename="meshes/arm_v0/arm_flex_light.obj"/>
      </geometry>
    </visual>
    <collision>
      <geometry>
        <mesh filename="meshes/arm_v0/arm_flex.obj"/>
      </geometry>
    </collision>
  </link>
  <joint name="arm_roll_joint" type="revolute">
    <origin rpy="0.0 0.0 0.0" xyz="0.005 0.0 0.345"/>
    <axis xyz="0.0 0.0 1.0"/>
    <limit effort="100.0" lower="-2.09" upper="3.84" velocity="2.0"/>
    <parent link="arm_flex_link"/>
    <child link="arm_roll_link"/>
    <dynamics damping="0.1"/>
  </joint>
  <link name="arm_roll_link">
    <inertial>
      <mass value="0.247936"/>
      <origin xyz="-0.006927 0.002039 -0.064837"/>
      <inertia ixx="0.004267" ixy="-0.000018322199" ixz="0.000017984455" iyy="0.000780923828" iyz="-0.00001392334" izz="0.00412"/>
    </inertial>
    <visual>
      <geometry>
        <mesh filename="meshes/arm_v0/arm_roll_light.obj"/>
      </geometry>
    </visual>
    <collision>
      <geometry>
        <mesh filename="meshes/arm_v0/arm_roll.obj"/>
      </geometry>
    </collision>
  </link>
  <gazebo reference="arm_lift_link">
    <selfCollide>false</selfCollide>
    <gravity>true</gravity>
    <mu1>0.9</mu1>
    <mu2>0.9</mu2>
  </gazebo>
  <gazebo reference="arm_flex_link">
    <selfCollide>false</selfCollide>
    <gravity>true</gravity>
    <mu1>0.9</mu1>
    <mu2>0.9</mu2>
  </gazebo>
  <gazebo reference="arm_roll_link">
    <selfCollide>false</selfCollide>
    <gravity>true</gravity>
    <mu1>0.9</mu1>
    <mu2>0.9</mu2>
  </gazebo>
  <gazebo reference="arm_lift_joint">
  </gazebo>
  <gazebo reference="arm_flex_joint">
  </gazebo>
  <gazebo reference="arm_roll_joint">
  </gazebo>
  <transmission name="arm_lift_joint_transmission">
    <type>transmission_interface/SimpleTransmission</type>
    <joint name="arm_lift_joint">
      <hardwareInterface>PositionJointInterface</hardwareInterface>
    </joint>
    <actuator name="arm_lift_joint_actuator">
      <hardwareInterface>PositionJointInterface</hardwareInterface>
      <mechanicalReduction>1</mechanicalReduction>
    </actuator>
  </transmission>
  <transmission name="arm_flex_joint_transmission">
    <type>transmission_interface/SimpleTransmission</type>
    <joint name="arm_flex_joint">
      <hardwareInterface>PositionJointInterface</hardwareInterface>
    </joint>
    <actuator name="arm_flex_joint_actuator">
      <hardwareInterface>PositionJointInterface</hardwareInterface>
      <mechanicalReduction>1</mechanicalReduction>
    </actuator>
  </transmission>
  <transmission name="arm_roll_joint_transmission">
    <type>transmission_interface/SimpleTransmission</type>
    <joint name="arm_roll_joint">
      <hardwareInterface>PositionJointInterface</hardwareInterface>
    </joint>
    <actuator name="arm_roll_joint_actuator">
      <hardwareInterface>PositionJointInterface</hardwareInterface>
      <mechanicalReduction>1</mechanicalReduction>
    </actuator>
  </transmission>
  <joint name="wrist_flex_joint" type="revolute">
    <origin rpy="0.0 0.0 0.0" xyz="0.0 0.0 0.0"/>
    <axis xyz="0.0 -1.0 0.0"/>
    <limit effort="100.0" lower="-1.92" upper="1.22" velocity="1.5"/>
    <parent link="arm_roll_link"/>
    <child link="wrist_flex_link"/>
    <dynamics damping="1.0"/>
  </joint>
  <link name="wrist_flex_link">
    <inertial>
      <mass value="0.681225"/>
      <origin xyz="0.000131 -0.003929 0.00217"/>
      <inertia ixx="0.000074353558" ixy="0.000000494515" ixz="0.000000022937" iyy="0.000038432887" iyz="-0.00000255576" izz="0.000064680918"/>
    </inertial>
    <visual>
      <geometry>
        <mesh filename="meshes/wrist_v0/wrist_flex.obj"/>
      </geometry>
      <material name="body_sub"/>
    </visual>
    <visual>
      <origin rpy="0.0 0.0 0.0" xyz="0.0 0.0 0.04"/>
      <geometry>
        <cylinder length="0.02" radius="0.017"/>
      </geometry>
      <material name="body_sub"/>
    </visual>
    <collision>
      <origin rpy="0.0 0.0 0.0" xyz="0.0 0.0 0.03"/>
      <geometry>
        <cylinder length="0.04" radius="0.017"/>
      </geometry>
    </collision>
  </link>
  <joint name="wrist_roll_joint" type="revolute">
    <origin rpy="0.0 0.0 0.0" xyz="0.0 0.0 0.0"/>
    <axis xyz="0.0 0.0 1.0"/>
    <limit effort="100.0" lower="-1.92" upper="3.67" velocity="1.5"/>
    <parent link="wrist_flex_link"/>
    <child link="wrist_roll_link"/>
    <dynamics damping="1.0"/>
  </joint>
  <link name="wrist_roll_link">
    <inertial>
      <mass value="0.761692"/>
      <origin xyz="-0.001416 -0.001547 0.081689"/>
      <inertia ixx="0.000805633819" ixy="-0.000014431758" ixz="0.000028204659" iyy="0.000768077165" iyz="0.000022460226" izz="0.000453406611"/>
    </inertial>
    <visual>
      <geometry>
        <mesh filename="meshes/wrist_v0/wrist_roll.obj"/>
      </geometry>
    </visual>
    <collision>
      <geometry>
        <mesh filename="meshes/wrist_v0/wrist_roll.obj"/>
      </geometry>
    </collision>
  </link>
  <joint name="wrist_ft_sensor_frame_joint" type="fixed">
    <origin rpy="3.14159265359 0.0 0.0" xyz="0.0 0.0 0.0735"/>
    <parent link="wrist_roll_link"/>
    <child link="wrist_ft_sensor_frame"/>
  </joint>
  <link name="wrist_ft_sensor_frame"/>
  <gazebo reference="wrist_roll_joint">
    <provideFeedback>true</provideFeedback>
  </gazebo>
  <gazebo>
    <plugin filename="libgazebo_ros_force.so" name="ft_sensor">
      <updateRate>30.0</updateRate>
      <topicName>wrist_wrench</topicName>
      <jointName>wrist_roll_joint</jointName>
      <bodyName>wrist_roll_link</bodyName>
      <robotNamespace>hsrb</robotNamespace>
    </plugin>
  </gazebo>
  <gazebo reference="wrist_flex_link">
    <selfCollide>false</selfCollide>
    <gravity>true</gravity>
    <mu1>0.9</mu1>
    <mu2>0.9</mu2>
  </gazebo>
  <gazebo reference="wrist_roll_link">
    <selfCollide>false</selfCollide>
    <gravity>true</gravity>
    <mu1>0.9</mu1>
    <mu2>0.9</mu2>
  </gazebo>
  <gazebo reference="wrist_ft_sensor_frame">
    <selfCollide>false</selfCollide>
    <gravity>true</gravity>
    <mu1>0.9</mu1>
    <mu2>0.9</mu2>
  </gazebo>
  <gazebo reference="wrist_flex_joint">
  </gazebo>
  <gazebo reference="wrist_roll_joint">
  </gazebo>
  <transmission name="wrist_flex_joint_transmission">
    <type>transmission_interface/SimpleTransmission</type>
    <joint name="wrist_flex_joint">
      <hardwareInterface>PositionJointInterface</hardwareInterface>
    </joint>
    <actuator name="wrist_flex_joint_actuator">
      <hardwareInterface>PositionJointInterface</hardwareInterface>
      <mechanicalReduction>1</mechanicalReduction>
    </actuator>
  </transmission>
  <transmission name="wrist_roll_joint_transmission">
    <type>transmission_interface/SimpleTransmission</type>
    <joint name="wrist_roll_joint">
      <hardwareInterface>PositionJointInterface</hardwareInterface>
    </joint>
    <actuator name="wrist_roll_joint_actuator">
      <hardwareInterface>PositionJointInterface</hardwareInterface>
      <mechanicalReduction>1</mechanicalReduction>
    </actuator>
  </transmission>
  <joint name="hand_palm_joint" type="fixed">
    <origin rpy="0.0 0.0 3.14159265359" xyz="0.012 0.0 0.1405"/>
    <parent link="wrist_roll_link"/>
    <child link="hand_palm_link"/>
  </joint>
  <link name="hand_palm_link">
    <inertial>
      <mass value="0.15"/>
      <inertia ixx="0.015" ixy="0.0" ixz="0.0" iyy="0.015" iyz="0.0" izz="0.015"/>
    </inertial>
    <visual>
      <geometry>
        <mesh filename="meshes/hand_v0/palm.obj"/>
      </geometry>
      <material name="body_sub"/>
    </visual>
    <collision>
      <geometry>
        <mesh filename="meshes/hand_v0/palm.obj"/>
      </geometry>
    </collision>
  </link>
  <joint name="hand_motor_joint" type="revolute">
    <axis xyz="1.0 0.0 0.0"/>
    <limit effort="100.0" lower="-0.798" upper="1.24" velocity="1.0"/>
    <parent link="hand_palm_link"/>
    <child link="hand_motor_dummy_link"/>
    <dynamics damping="1.0"/>
  </joint>
  <link name="hand_motor_dummy_link">
    <inertial>
      <mass value="0.15"/>
      <inertia ixx="0.015" ixy="0.0" ixz="0.0" iyy="0.015" iyz="0.0" izz="0.015"/>
    </inertial>
  </link>
  <joint name="hand_l_proximal_joint" type="revolute">
    <origin rpy="0.0 0.0 0.0" xyz="-0.01675 -0.0245 -0.0175"/>
    <axis xyz="1.0 0.0 0.0"/>
    <limit effort="100.0" lower="-0.798" upper="1.24" velocity="1.0"/>
    <parent link="hand_palm_link"/>
    <child link="hand_l_proximal_link"/>
    <mimic joint="hand_motor_joint"/>
    <dynamics damping="1.0"/>
  </joint>
  <link name="hand_l_proximal_link">
    <inertial>
      <mass value="0.15"/>
      <inertia ixx="0.015" ixy="0.0" ixz="0.0" iyy="0.015" iyz="0.0" izz="0.015"/>
    </inertial>
  </link>
  <joint name="hand_l_spring_proximal_joint" type="revolute">
    <axis xyz="1.0 0.0 0.0"/>
    <limit effort="100.0" lower="0.0" upper="0.698" velocity="1.0"/>
    <parent link="hand_l_proximal_link"/>
    <child link="hand_l_spring_proximal_link"/>
    <dynamics damping="1.0"/>
  </joint>
  <link name="hand_l_spring_proximal_link">
    <inertial>
      <mass value="0.043589"/>
      <origin xyz="0.021418 0.00248 0.022688"/>
      <inertia ixx="0.000026033886" ixy="-0.000000144078" ixz="-0.00000198241" iyy="0.000028824811" iyz="-0.000001268421" izz="0.000005135919"/>
    </inertial>
    <visual>
      <geometry>
        <mesh filename="meshes/hand_v0/l_proximal.obj"/>
      </geometry>
      <material name="body_sub"/>
    </visual>
    <collision>
      <geometry>
        <mesh filename="meshes/hand_v0/l_proximal.obj"/>
      </geometry>
    </collision>
  </link>
  <joint name="hand_l_mimic_distal_joint" type="revolute">
    <origin xyz="0.0 0.0 0.07"/>
    <axis xyz="1.0 0.0 0.0"/>
    <limit effort="100.0" lower="-0.698" upper="-0.0" velocity="1.0"/>
    <parent link="hand_l_spring_proximal_link"/>
    <child link="hand_l_mimic_distal_link"/>
    <mimic joint="hand_l_spring_proximal_joint" multiplier="-1.0"/>
    <dynamics damping="1.0"/>
  </joint>
  <link name="hand_l_mimic_distal_link">
    <inertial>
      <mass value="0.15"/>
      <inertia ixx="0.015" ixy="0.0" ixz="0.0" iyy="0.015" iyz="0.0" izz="0.015"/>
    </inertial>
  </link>
  <joint name="hand_l_distal_joint" type="revolute">
    <axis xyz="1.0 0.0 0.0"/>
    <limit effort="100.0" lower="-1.24" upper="0.798" velocity="1.0"/>
    <parent link="hand_l_mimic_distal_link"/>
    <child link="hand_l_distal_link"/>
    <mimic joint="hand_motor_joint" multiplier="-1.0" offset="-0.087"/>
    <dynamics damping="1.0"/>
  </joint>
  <link name="hand_l_distal_link">
    <inertial>
      <mass value="0.027731"/>
      <origin xyz="0.011116 0.005679 0.017532"/>
      <inertia ixx="0.00000307518" ixy="-0.00000004954" ixz="0.000000009481" iyy="0.000004074079" iyz="-0.000000843648" izz="0.000002807795"/>
    </inertial>
    <visual>
      <geometry>
        <mesh filename="meshes/hand_v0/l_distal.obj"/>
      </geometry>
      <material name="body_sub"/>
    </visual>
    <collision>
      <geometry>
        <mesh filename="meshes/hand_v0/l_distal.obj"/>
      </geometry>
    </collision>
  </link>
  <joint name="hand_l_finger_tip_frame_joint" type="fixed">
    <origin rpy="-1.5707963268 0.0 0.0" xyz="0.01675 0.0193 0.0379"/>
    <parent link="hand_l_distal_link"/>
    <child link="hand_l_finger_tip_frame"/>
  </joint>
  <link name="hand_l_finger_tip_frame">
    <inertial>
      <mass value="0.15"/>
      <inertia ixx="0.015" ixy="0.0" ixz="0.0" iyy="0.015" iyz="0.0" izz="0.015"/>
    </inertial>
  </link>
  <joint name="hand_l_finger_vacuum_frame_joint" type="fixed">
    <origin rpy="0.785398163398 0.0 0.0" xyz="0.00475 -0.011539 0.03322"/>
    <parent link="hand_l_distal_link"/>
    <child link="hand_l_finger_vacuum_frame"/>
  </joint>
  <link name="hand_l_finger_vacuum_frame">
    <inertial>
      <mass value="0.15"/>
      <inertia ixx="0.015" ixy="0.0" ixz="0.0" iyy="0.015" iyz="0.0" izz="0.015"/>
    </inertial>
    <visual>
      <origin rpy="0.0 0.0 0.0" xyz="0.0 0.0 -0.01"/>
      <geometry>
        <box size="0.008 0.008 0.02"/>
      </geometry>
      <material name="body_sub"/>
    </visual>
  </link>
  <joint name="hand_r_proximal_joint" type="revolute">
    <origin rpy="0.0 0.0 0.0" xyz="-0.01675 0.0245 -0.0175"/>
    <axis xyz="-1.0 0.0 0.0"/>
    <limit effort="100.0" lower="-0.798" upper="1.24" velocity="1.0"/>
    <parent link="hand_palm_link"/>
    <child link="hand_r_proximal_link"/>
    <mimic joint="hand_motor_joint"/>
    <dynamics damping="1.0"/>
  </joint>
  <link name="hand_r_proximal_link">
    <inertial>
      <mass value="0.15"/>
      <inertia ixx="0.015" ixy="0.0" ixz="0.0" iyy="0.015" iyz="0.0" izz="0.015"/>
    </inertial>
  </link>
  <joint name="hand_r_spring_proximal_joint" type="revolute">
    <axis xyz="-1.0 0.0 0.0"/>
    <limit effort="100.0" lower="0.0" upper="0.698" velocity="1.0"/>
    <parent link="hand_r_proximal_link"/>
    <child link="hand_r_spring_proximal_link"/>
    <dynamics damping="1.0"/>
  </joint>
  <link name="hand_r_spring_proximal_link">
    <inertial>
      <mass value="0.043956"/>
      <origin xyz="0.013203 0.002096 0.023311"/>
      <inertia ixx="0.00002623664" ixy="0.00000001631" ixz="0.000001281845" iyy="0.000028838232" iyz="-0.000001621709" izz="0.000004957151"/>
    </inertial>
    <visual>
      <geometry>
        <mesh filename="meshes/hand_v0/r_proximal.obj"/>
      </geometry>
      <material name="body_sub"/>
    </visual>
    <collision>
      <geometry>
        <mesh filename="meshes/hand_v0/r_proximal.obj"/>
      </geometry>
    </collision>
  </link>
  <joint name="hand_r_mimic_distal_joint" type="revolute">
    <origin xyz="0.0 0.0 0.07"/>
    <axis xyz="-1.0 0.0 0.0"/>
    <limit effort="100.0" lower="-0.698" upper="-0.0" velocity="1.0"/>
    <parent link="hand_r_spring_proximal_link"/>
    <child link="hand_r_mimic_distal_link"/>
    <mimic joint="hand_r_spring_proximal_joint" multiplier="-1.0"/>
    <dynamics damping="1.0"/>
  </joint>
  <link name="hand_r_mimic_distal_link">
    <inertial>
      <mass value="0.15"/>
      <inertia ixx="0.015" ixy="0.0" ixz="0.0" iyy="0.015" iyz="0.0" izz="0.015"/>
    </inertial>
  </link>
  <joint name="hand_r_distal_joint" type="revolute">
    <axis xyz="-1.0 0.0 0.0"/>
    <limit effort="100.0" lower="-1.24" upper="0.798" velocity="1.0"/>
    <parent link="hand_r_mimic_distal_link"/>
    <child link="hand_r_distal_link"/>
    <mimic joint="hand_motor_joint" multiplier="-1.0" offset="-0.087"/>
    <dynamics damping="1.0"/>
  </joint>
  <link name="hand_r_distal_link">
    <inertial>
      <mass value="0.020927"/>
      <origin xyz="0.014256 -0.008321 0.015591"/>
      <inertia ixx="0.00000307518" ixy="-0.00000004954" ixz="0.000000009481" iyy="0.000004074079" iyz="0.000000843648" izz="0.000002807795"/>
    </inertial>
    <visual>
      <geometry>
        <mesh filename="meshes/hand_v0/r_distal.obj"/>
      </geometry>
      <material name="body_sub"/>
    </visual>
    <collision>
      <geometry>
        <mesh filename="meshes/hand_v0/r_distal.obj"/>
      </geometry>
    </collision>
  </link>
  <joint name="hand_r_finger_tip_frame_joint" type="fixed">
    <origin rpy="1.5707963268 0.0 0.0" xyz="0.01675 -0.0193 0.0379"/>
    <parent link="hand_r_distal_link"/>
    <child link="hand_r_finger_tip_frame"/>
  </joint>
  <link name="hand_r_finger_tip_frame">
    <inertial>
      <mass value="0.15"/>
      <inertia ixx="0.015" ixy="0.0" ixz="0.0" iyy="0.015" iyz="0.0" izz="0.015"/>
    </inertial>
  </link>
  <joint name="hand_camera_frame_joint" type="fixed">
    <origin rpy="0.0 0.0 0.0" xyz="0.039 0.0 -0.0045"/>
    <parent link="hand_palm_link"/>
    <child link="hand_camera_frame"/>
  </joint>
  <link name="hand_camera_frame"/>
  <joint name="hand_camera_gazebo_frame_joint" type="fixed">
    <origin rpy="1.5707963268 -1.5707963268 0" xyz="0 0 0"/>
    <parent link="hand_camera_frame"/>
    <child link="hand_camera_gazebo_frame"/>
  </joint>
  <link name="hand_camera_gazebo_frame"/>
  <gazebo reference="hand_camera_gazebo_frame">
    <sensor name="hand_camera" type="camera">
      <update_rate>10.0</update_rate>
      <camera name="hand_camera">
        <horizontal_fov>2.00</horizontal_fov>
        <image>
          <width>640</width>
          <height>480</height>
          <format>R8G8B8</format>
        </image>
        <clip>
          <near>0.05</near>
          <far>100</far>
        </clip>
        <noise>
          <type>gaussian</type>
          <mean>0.0</mean>
          <stddev>0.007</stddev>
        </noise>
      </camera>
      <plugin filename="libhsrb_gazebo_ros_camera.so" name="camera_controller">
        <robotNamespace>hsrb</robotNamespace>
        <alwaysOn>0</alwaysOn>
        <updateRate>0.0</updateRate>
        <cameraName>hand_camera</cameraName>
        <imageTopicName>image_raw</imageTopicName>
        <cameraInfoTopicName>camera_info</cameraInfoTopicName>
        <frameName>hand_camera_frame</frameName>
        <hackBaseline>0.07</hackBaseline>
        <distortionK1>0.0</distortionK1>
        <distortionK2>0.0</distortionK2>
        <distortionK3>0.0</distortionK3>
        <distortionT1>0.0</distortionT1>
        <distortionT2>0.0</distortionT2>
      </plugin>
    </sensor>
  </gazebo>
  <gazebo reference="hand_palm_link">
    <selfCollide>false</selfCollide>
    <gravity>true</gravity>
    <mu1>0.9</mu1>
    <mu2>0.9</mu2>
  </gazebo>
  <gazebo reference="hand_camera_frame">
    <selfCollide>false</selfCollide>
    <gravity>false</gravity>
    <mu1>0.9</mu1>
    <mu2>0.9</mu2>
  </gazebo>
  <gazebo reference="hand_l_proximal_link">
    <selfCollide>false</selfCollide>
    <gravity>true</gravity>
    <mu1>1.0</mu1>
    <mu2>1.0</mu2>
  </gazebo>
  <gazebo reference="hand_l_spring_proximal_link">
    <selfCollide>false</selfCollide>
    <gravity>true</gravity>
    <mu1>1.0</mu1>
    <mu2>1.0</mu2>
  </gazebo>
  <gazebo reference="hand_l_mimic_distal_link">
    <selfCollide>false</selfCollide>
    <gravity>true</gravity>
    <mu1>1.0</mu1>
    <mu2>1.0</mu2>
  </gazebo>
  <gazebo reference="hand_l_distal_link">
    <selfCollide>false</selfCollide>
    <gravity>true</gravity>
    <mu1>1.0</mu1>
    <mu2>1.0</mu2>
  </gazebo>
  <gazebo reference="hand_l_finger_tip_frame">
    <selfCollide>false</selfCollide>
    <gravity>false</gravity>
    <mu1>1.0</mu1>
    <mu2>1.0</mu2>
  </gazebo>
  <gazebo reference="hand_l_finger_vacuum_frame">
    <selfCollide>false</selfCollide>
    <gravity>false</gravity>
    <mu1>1.0</mu1>
    <mu2>1.0</mu2>
  </gazebo>
  <gazebo reference="hand_r_proximal_link">
    <selfCollide>false</selfCollide>
    <gravity>true</gravity>
    <mu1>1.0</mu1>
    <mu2>1.0</mu2>
  </gazebo>
  <gazebo reference="hand_r_spring_proximal_link">
    <selfCollide>false</selfCollide>
    <gravity>true</gravity>
    <mu1>1.0</mu1>
    <mu2>1.0</mu2>
  </gazebo>
  <gazebo reference="hand_r_mimic_distal_link">
    <selfCollide>false</selfCollide>
    <gravity>true</gravity>
    <mu1>1.0</mu1>
    <mu2>1.0</mu2>
  </gazebo>
  <gazebo reference="hand_r_distal_link">
    <selfCollide>false</selfCollide>
    <gravity>false</gravity>
    <mu1>1.0</mu1>
    <mu2>1.0</mu2>
  </gazebo>
  <gazebo reference="hand_r_finger_tip_frame">
    <selfCollide>false</selfCollide>
    <gravity>false</gravity>
    <mu1>1.0</mu1>
    <mu2>1.0</mu2>
  </gazebo>
  <gazebo reference="hand_palm_joint">
  </gazebo>
  <gazebo reference="hand_motor_joint">
  </gazebo>
  <gazebo reference="hand_l_proximal_joint">
  </gazebo>
  <gazebo reference="hand_l_spring_proximal_joint">
  </gazebo>
  <gazebo reference="hand_l_mimic_distal_joint">
  </gazebo>
  <gazebo reference="hand_l_distal_joint">
  </gazebo>
  <gazebo reference="hand_r_proximal_joint">
  </gazebo>
  <gazebo reference="hand_r_spring_proximal_joint">
  </gazebo>
  <gazebo reference="hand_r_mimic_distal_joint">
  </gazebo>
  <gazebo reference="hand_r_distal_joint">
  </gazebo>
  <gazebo>
        </gazebo>
  <transmission name="hand_motor_joint_transmission">
    <type>transmission_interface/SimpleTransmission</type>
    <joint name="hand_motor_joint">
      <hardwareInterface>EffortJointInterface</hardwareInterface>
    </joint>
    <actuator name="hand_motor_joint_actuator">
      <hardwareInterface>EffortJointInterface</hardwareInterface>
      <mechanicalReduction>1</mechanicalReduction>
    </actuator>
  </transmission>
  <transmission name="hand_l_spring_proximal_joint_transmission">
    <type>transmission_interface/SimpleTransmission</type>
    <joint name="hand_l_spring_proximal_joint">
      <hardwareInterface>EffortJointInterface</hardwareInterface>
    </joint>
    <actuator name="hand_l_spring_proximal_joint_actuator">
      <hardwareInterface>EffortJointInterface</hardwareInterface>
      <mechanicalReduction>1</mechanicalReduction>
    </actuator>
  </transmission>
  <transmission name="hand_r_spring_proximal_joint_transmission">
    <type>transmission_interface/SimpleTransmission</type>
    <joint name="hand_r_spring_proximal_joint">
      <hardwareInterface>EffortJointInterface</hardwareInterface>
    </joint>
    <actuator name="hand_r_spring_proximal_joint_actuator">
      <hardwareInterface>EffortJointInterface</hardwareInterface>
      <mechanicalReduction>1</mechanicalReduction>
    </actuator>
  </transmission>
  <gazebo>
    <plugin filename="libhsrb_gazebo_ros_control.so" name="hsrb_ros_control">
      <robotNamespace>hsrb</robotNamespace>
    </plugin>
    <plugin filename="libgazebo_ros_p3d.so" name="hsrb_p3d_ground_truth">
      <robotNamespace>hsrb</robotNamespace>
      <bodyName>base_footprint</bodyName>
      <topicName>odom_ground_truth</topicName>
      <frameName>map</frameName>
      <updateRate>30</updateRate>
    </plugin>
  </gazebo>
</robot>
