<?xml version="1.0" encoding="utf-8"?>
<!-- =================================================================================== -->
<!-- |    This document was autogenerated by xacro from planar_gripper.xacro           | -->
<!-- |    EDITING THIS FILE BY HAND IS NOT RECOMMENDED                                 | -->
<!-- =================================================================================== -->
<sdf version="1.6" xmlns:xacro="http://www.ros.org/wiki/xacro">
  <model name="planar_gripper">
    <link name="finger1_base">
      <visual name="base_visual">
        <pose>0 0 0 0 0 0</pose>
        <geometry>
          <box>
            <size>0.08 0.08 0.008</size>
          </box>
        </geometry>
        <material>
          <diffuse>0.1 0.1 0.1 1</diffuse>
        </material>
      </visual>
    </link>
    <link name="finger1_link1">
      <pose>0 0 0 0 0 0</pose>
      <inertial>
        <pose>0 0 -0.0425 0 0 0</pose>
        <mass>0.1</mass>
        <inertia>
          <ixx>0.0083</ixx>
          <iyy>0.0083</iyy>
          <izz>5e-7</izz>
          <ixy>0</ixy>
          <ixz>0</ixz>
          <iyz>0</iyz>
        </inertia>
      </inertial>
      <visual name="link1_visual">
        <pose>0 0 -0.0425 0 0 0</pose>
        <geometry>
          <cylinder>
            <length>0.085</length>
            <radius>0.011</radius>
          </cylinder>
        </geometry>
        <material>
          <diffuse>1 0 0 1</diffuse>
        </material>
      </visual>
      <visual name="link1_joint_visual">
        <pose>0 0 -0.085 0 0 0</pose>
        <geometry>
          <sphere>
            <radius>0.0132</radius>
          </sphere>
        </geometry>
        <material>
          <diffuse>.1 .1 .1 1</diffuse>
        </material>
      </visual>
    </link>
    <joint name="finger1_BaseJoint" type="revolute">
      <child>finger1_link1</child>
      <parent>finger1_base</parent>
      <axis>
        <xyz>1 0 0</xyz>
        <limit>
          <!-- Drake parses a zero effort joint as an un-actuated joint. -->
          <effort>75</effort>
          <lower>-1.57</lower>
          <upper>1.57</upper>
        </limit>
        <dynamics>
          <damping>0.1</damping>
        </dynamics>
        <use_parent_model_frame>1</use_parent_model_frame>
      </axis>
    </joint>
    <link name="finger1_link2">
      <!-- The origin of the Link2 frame is defined to be coincident with
       the origin of the x-z plane in the elbow joint frame. -->
      <pose>0 0 -0.085 0 0 0</pose>
      <inertial>
        <pose>0 0 -0.02015 0 0 0</pose>
        <mass>0.1</mass>
        <!-- This inertia is based on a solid cylinder with
               radius=1.0 meters and height=2.0 meters. -->
        <!-- For this model we could make izz = 0 however, sdformat will throw
               an exception. -->
        <inertia>
          <ixx>0.0083</ixx>
          <iyy>0.0083</iyy>
          <izz>5e-7</izz>
          <ixy>0</ixy>
          <ixz>0</ixz>
          <iyz>0</iyz>
        </inertia>
      </inertial>
      <visual name="link2_visual">
        <pose>0 0 -0.02015 0 0 0</pose>
        <geometry>
          <cylinder>
            <length>0.0403</length>
            <radius>0.011</radius>
          </cylinder>
        </geometry>
        <material>
          <diffuse>1 0 0 1</diffuse>
        </material>
      </visual>
      <!--The link 2 collision element extends up to the sphere fingertip-->
      <collision name="link2_collision">
        <pose>0 0 -0.0299 0 0 0</pose>
        <geometry>
          <cylinder>
            <length>0.0598</length>
            <radius>0.011</radius>
          </cylinder>
        </geometry>
        <material>
          <diffuse>1 0 1 1</diffuse>
        </material>
      </collision>
      <visual name="link2_sensor_visual">
        <pose>0 0 -0.04455 0 0 0</pose>
        <geometry>
          <box>
            <size>0.02 0.02 0.0085</size>
          </box>
        </geometry>
        <material>
          <diffuse>.1 .1 .1 1</diffuse>
        </material>
      </visual>
      <visual name="tip_adapter_visual">
        <pose>0 0 -0.05255 0 0 0</pose>
        <geometry>
          <cylinder>
            <length>0.0075</length>
            <radius>0.0145</radius>
          </cylinder>
        </geometry>
        <material>
          <diffuse>.1 .1 .1 1</diffuse>
        </material>
      </visual>
      <visual name="tip_cylinder_visual">
        <pose>0 0 -0.05805 0 0 0</pose>
        <geometry>
          <cylinder>
            <length>0.0035</length>
            <radius>0.01</radius>
          </cylinder>
        </geometry>
        <material>
          <diffuse>.1 .1 .1 1</diffuse>
        </material>
      </visual>
      <visual name="tip_sphere_visual">
        <pose>0 0 -0.0713 0 0 0</pose>
        <geometry>
          <sphere>
            <radius>0.015</radius>
          </sphere>
        </geometry>
        <material>
          <diffuse>1 1 1 1</diffuse>
        </material>
      </visual>
      <collision name="tip_sphere_collision">
        <pose>0 0 -0.0713 0 0 0</pose>
        <geometry>
          <sphere>
            <radius>0.015</radius>
          </sphere>
        </geometry>
        <material>
          <diffuse>1 1 1 1</diffuse>
        </material>
      </collision>
    </link>
    <joint name="finger1_MidJoint" type="revolute">
      <parent>finger1_link1</parent>
      <child>finger1_link2</child>
      <!-- Pose X_CJ of the joint frame J in the frame C of the child link -->
      <pose>0 0 0 0 0 0</pose>
      <axis>
        <xyz>1 0 0</xyz>
        <limit>
          <effort>75</effort>
          <lower>-1.57</lower>
          <upper>1.57</upper>
        </limit>
        <dynamics>
          <damping>0.1</damping>
        </dynamics>
        <use_parent_model_frame>1</use_parent_model_frame>
      </axis>
    </joint>
    <link name="finger2_base">
      <visual name="base_visual">
        <pose>0 0 0 0 0 0</pose>
        <geometry>
          <box>
            <size>0.08 0.08 0.008</size>
          </box>
        </geometry>
        <material>
          <diffuse>0.1 0.1 0.1 1</diffuse>
        </material>
      </visual>
    </link>
    <link name="finger2_link1">
      <pose>0 0 0 0 0 0</pose>
      <inertial>
        <pose>0 0 -0.0425 0 0 0</pose>
        <mass>0.1</mass>
        <inertia>
          <ixx>0.0083</ixx>
          <iyy>0.0083</iyy>
          <izz>5e-7</izz>
          <ixy>0</ixy>
          <ixz>0</ixz>
          <iyz>0</iyz>
        </inertia>
      </inertial>
      <visual name="link1_visual">
        <pose>0 0 -0.0425 0 0 0</pose>
        <geometry>
          <cylinder>
            <length>0.085</length>
            <radius>0.011</radius>
          </cylinder>
        </geometry>
        <material>
          <diffuse>1 0 0 1</diffuse>
        </material>
      </visual>
      <visual name="link1_joint_visual">
        <pose>0 0 -0.085 0 0 0</pose>
        <geometry>
          <sphere>
            <radius>0.0132</radius>
          </sphere>
        </geometry>
        <material>
          <diffuse>.1 .1 .1 1</diffuse>
        </material>
      </visual>
    </link>
    <joint name="finger2_BaseJoint" type="revolute">
      <child>finger2_link1</child>
      <parent>finger2_base</parent>
      <axis>
        <xyz>1 0 0</xyz>
        <limit>
          <!-- Drake parses a zero effort joint as an un-actuated joint. -->
          <effort>75</effort>
          <lower>-1.57</lower>
          <upper>1.57</upper>
        </limit>
        <dynamics>
          <damping>0.1</damping>
        </dynamics>
        <use_parent_model_frame>1</use_parent_model_frame>
      </axis>
    </joint>
    <link name="finger2_link2">
      <!-- The origin of the Link2 frame is defined to be coincident with
       the origin of the x-z plane in the elbow joint frame. -->
      <pose>0 0 -0.085 0 0 0</pose>
      <inertial>
        <pose>0 0 -0.02015 0 0 0</pose>
        <mass>0.1</mass>
        <!-- This inertia is based on a solid cylinder with
               radius=1.0 meters and height=2.0 meters. -->
        <!-- For this model we could make izz = 0 however, sdformat will throw
               an exception. -->
        <inertia>
          <ixx>0.0083</ixx>
          <iyy>0.0083</iyy>
          <izz>5e-7</izz>
          <ixy>0</ixy>
          <ixz>0</ixz>
          <iyz>0</iyz>
        </inertia>
      </inertial>
      <visual name="link2_visual">
        <pose>0 0 -0.02015 0 0 0</pose>
        <geometry>
          <cylinder>
            <length>0.0403</length>
            <radius>0.011</radius>
          </cylinder>
        </geometry>
        <material>
          <diffuse>1 0 0 1</diffuse>
        </material>
      </visual>
      <!--The link 2 collision element extends up to the sphere fingertip-->
      <collision name="link2_collision">
        <pose>0 0 -0.0299 0 0 0</pose>
        <geometry>
          <cylinder>
            <length>0.0598</length>
            <radius>0.011</radius>
          </cylinder>
        </geometry>
        <material>
          <diffuse>1 0 1 1</diffuse>
        </material>
      </collision>
      <visual name="link2_sensor_visual">
        <pose>0 0 -0.04455 0 0 0</pose>
        <geometry>
          <box>
            <size>0.02 0.02 0.0085</size>
          </box>
        </geometry>
        <material>
          <diffuse>.1 .1 .1 1</diffuse>
        </material>
      </visual>
      <visual name="tip_adapter_visual">
        <pose>0 0 -0.05255 0 0 0</pose>
        <geometry>
          <cylinder>
            <length>0.0075</length>
            <radius>0.0145</radius>
          </cylinder>
        </geometry>
        <material>
          <diffuse>.1 .1 .1 1</diffuse>
        </material>
      </visual>
      <visual name="tip_cylinder_visual">
        <pose>0 0 -0.05805 0 0 0</pose>
        <geometry>
          <cylinder>
            <length>0.0035</length>
            <radius>0.01</radius>
          </cylinder>
        </geometry>
        <material>
          <diffuse>.1 .1 .1 1</diffuse>
        </material>
      </visual>
      <visual name="tip_sphere_visual">
        <pose>0 0 -0.0713 0 0 0</pose>
        <geometry>
          <sphere>
            <radius>0.015</radius>
          </sphere>
        </geometry>
        <material>
          <diffuse>1 1 1 1</diffuse>
        </material>
      </visual>
      <collision name="tip_sphere_collision">
        <pose>0 0 -0.0713 0 0 0</pose>
        <geometry>
          <sphere>
            <radius>0.015</radius>
          </sphere>
        </geometry>
        <material>
          <diffuse>1 1 1 1</diffuse>
        </material>
      </collision>
    </link>
    <joint name="finger2_MidJoint" type="revolute">
      <parent>finger2_link1</parent>
      <child>finger2_link2</child>
      <!-- Pose X_CJ of the joint frame J in the frame C of the child link -->
      <pose>0 0 0 0 0 0</pose>
      <axis>
        <xyz>1 0 0</xyz>
        <limit>
          <effort>75</effort>
          <lower>-1.57</lower>
          <upper>1.57</upper>
        </limit>
        <dynamics>
          <damping>0.1</damping>
        </dynamics>
        <use_parent_model_frame>1</use_parent_model_frame>
      </axis>
    </joint>
    <link name="finger3_base">
      <visual name="base_visual">
        <pose>0 0 0 0 0 0</pose>
        <geometry>
          <box>
            <size>0.08 0.08 0.008</size>
          </box>
        </geometry>
        <material>
          <diffuse>0.1 0.1 0.1 1</diffuse>
        </material>
      </visual>
    </link>
    <link name="finger3_link1">
      <pose>0 0 0 0 0 0</pose>
      <inertial>
        <pose>0 0 -0.0425 0 0 0</pose>
        <mass>0.1</mass>
        <inertia>
          <ixx>0.0083</ixx>
          <iyy>0.0083</iyy>
          <izz>5e-7</izz>
          <ixy>0</ixy>
          <ixz>0</ixz>
          <iyz>0</iyz>
        </inertia>
      </inertial>
      <visual name="link1_visual">
        <pose>0 0 -0.0425 0 0 0</pose>
        <geometry>
          <cylinder>
            <length>0.085</length>
            <radius>0.011</radius>
          </cylinder>
        </geometry>
        <material>
          <diffuse>1 0 0 1</diffuse>
        </material>
      </visual>
      <visual name="link1_joint_visual">
        <pose>0 0 -0.085 0 0 0</pose>
        <geometry>
          <sphere>
            <radius>0.0132</radius>
          </sphere>
        </geometry>
        <material>
          <diffuse>.1 .1 .1 1</diffuse>
        </material>
      </visual>
    </link>
    <joint name="finger3_BaseJoint" type="revolute">
      <child>finger3_link1</child>
      <parent>finger3_base</parent>
      <axis>
        <xyz>1 0 0</xyz>
        <limit>
          <!-- Drake parses a zero effort joint as an un-actuated joint. -->
          <effort>75</effort>
          <lower>-1.57</lower>
          <upper>1.57</upper>
        </limit>
        <dynamics>
          <damping>0.1</damping>
        </dynamics>
        <use_parent_model_frame>1</use_parent_model_frame>
      </axis>
    </joint>
    <link name="finger3_link2">
      <!-- The origin of the Link2 frame is defined to be coincident with
       the origin of the x-z plane in the elbow joint frame. -->
      <pose>0 0 -0.085 0 0 0</pose>
      <inertial>
        <pose>0 0 -0.02015 0 0 0</pose>
        <mass>0.1</mass>
        <!-- This inertia is based on a solid cylinder with
               radius=1.0 meters and height=2.0 meters. -->
        <!-- For this model we could make izz = 0 however, sdformat will throw
               an exception. -->
        <inertia>
          <ixx>0.0083</ixx>
          <iyy>0.0083</iyy>
          <izz>5e-7</izz>
          <ixy>0</ixy>
          <ixz>0</ixz>
          <iyz>0</iyz>
        </inertia>
      </inertial>
      <visual name="link2_visual">
        <pose>0 0 -0.02015 0 0 0</pose>
        <geometry>
          <cylinder>
            <length>0.0403</length>
            <radius>0.011</radius>
          </cylinder>
        </geometry>
        <material>
          <diffuse>1 0 0 1</diffuse>
        </material>
      </visual>
      <!--The link 2 collision element extends up to the sphere fingertip-->
      <collision name="link2_collision">
        <pose>0 0 -0.0299 0 0 0</pose>
        <geometry>
          <cylinder>
            <length>0.0598</length>
            <radius>0.011</radius>
          </cylinder>
        </geometry>
        <material>
          <diffuse>1 0 1 1</diffuse>
        </material>
      </collision>
      <visual name="link2_sensor_visual">
        <pose>0 0 -0.04455 0 0 0</pose>
        <geometry>
          <box>
            <size>0.02 0.02 0.0085</size>
          </box>
        </geometry>
        <material>
          <diffuse>.1 .1 .1 1</diffuse>
        </material>
      </visual>
      <visual name="tip_adapter_visual">
        <pose>0 0 -0.05255 0 0 0</pose>
        <geometry>
          <cylinder>
            <length>0.0075</length>
            <radius>0.0145</radius>
          </cylinder>
        </geometry>
        <material>
          <diffuse>.1 .1 .1 1</diffuse>
        </material>
      </visual>
      <visual name="tip_cylinder_visual">
        <pose>0 0 -0.05805 0 0 0</pose>
        <geometry>
          <cylinder>
            <length>0.0035</length>
            <radius>0.01</radius>
          </cylinder>
        </geometry>
        <material>
          <diffuse>.1 .1 .1 1</diffuse>
        </material>
      </visual>
      <visual name="tip_sphere_visual">
        <pose>0 0 -0.0713 0 0 0</pose>
        <geometry>
          <sphere>
            <radius>0.015</radius>
          </sphere>
        </geometry>
        <material>
          <diffuse>1 1 1 1</diffuse>
        </material>
      </visual>
      <collision name="tip_sphere_collision">
        <pose>0 0 -0.0713 0 0 0</pose>
        <geometry>
          <sphere>
            <radius>0.015</radius>
          </sphere>
        </geometry>
        <material>
          <diffuse>1 1 1 1</diffuse>
        </material>
      </collision>
    </link>
    <joint name="finger3_MidJoint" type="revolute">
      <parent>finger3_link1</parent>
      <child>finger3_link2</child>
      <!-- Pose X_CJ of the joint frame J in the frame C of the child link -->
      <pose>0 0 0 0 0 0</pose>
      <axis>
        <xyz>1 0 0</xyz>
        <limit>
          <effort>75</effort>
          <lower>-1.57</lower>
          <upper>1.57</upper>
        </limit>
        <dynamics>
          <damping>0.1</damping>
        </dynamics>
        <use_parent_model_frame>1</use_parent_model_frame>
      </axis>
    </joint>
  </model>
</sdf>
