<sdf version='1.4'>
  <model name='iiwa7'>
    <link name='iiwa_link_0'>
      <pose frame=''>0 0 0 0 -0 0</pose>
      <inertial>
        <pose frame=''>-0.1 0 0.07 0 -0 0</pose>
        <mass>5</mass>
        <inertia>
          <ixx>0.05</ixx>
          <ixy>0</ixy>
          <ixz>0</ixz>
          <iyy>0.06</iyy>
          <iyz>0</iyz>
          <izz>0.03</izz>
        </inertia>
      </inertial>
      <visual name='iiwa_link_0_visual'>
        <pose frame=''>0 0 0 0 -0 0</pose>
        <geometry>
          <mesh>
            <scale>1 1 1</scale>
            <uri>link_0.obj</uri>
          </mesh>
        </geometry>
        <material>
	       <diffuse>0.4 0.4 0.4 1.0</diffuse>
        </material>
      </visual>
      <gravity>1</gravity>
      <velocity_decay/>
      <self_collide>0</self_collide>
    </link>

    <link name='iiwa_link_1'>
      <pose frame=''>0 0 0.15 0 -0 0</pose>
      <inertial>
        <pose frame=''>0 -0.03 0.12 0 -0 0</pose>
        <mass>3.4525</mass>
        <inertia>
          <ixx>0.02183</ixx>
          <ixy>0</ixy>
          <ixz>0</ixz>
          <iyy>0.007703</iyy>
          <iyz>-0.003887</iyz>
          <izz>0.02083</izz>
        </inertia>
      </inertial>

      <visual name='iiwa_link_1_visual'>
        <pose frame=''>0 0 0.0075 0 -0 0</pose>
        <geometry>
          <mesh>
            <scale>1 1 1</scale>
            <uri>link_1.obj</uri>
          </mesh>
        </geometry>
        <material>
	       <diffuse>0.4 0.4 0.4 1.0</diffuse>
        </material>
      </visual>
      <gravity>1</gravity>
      <velocity_decay/>
      <self_collide>0</self_collide>
    </link>

    <joint name='iiwa_joint_1' type='revolute'>
      <child>iiwa_link_1</child>
      <parent>iiwa_link_0</parent>
      <axis>
        <xyz>0 0 1</xyz>
        <limit>
          <lower>-2.96706</lower>
          <upper>2.96706</upper>
          <effort>300</effort>
          <velocity>10</velocity>
        </limit>
        <dynamics>
          <damping>0.0</damping>
        </dynamics>
      </axis>
    </joint>

    <link name='iiwa_link_2'>
      <pose frame=''>0 0 0.34 1.5708 -0 -3.14159</pose>
      <inertial>
        <pose frame=''>0.0003 0.059 0.042 0 -0 0</pose>
        <mass>3.4821</mass>
        <inertia>
          <ixx>0.02076</ixx>
          <ixy>0</ixy>
          <ixz>-0.003626</ixz>
          <iyy>0.02179</iyy>
          <iyz>0</iyz>
          <izz>0.00779</izz>
        </inertia>
      </inertial>

      <visual name='iiwa_link_2_visual'>
        <pose frame=''>0 0 -0.006 0 -0 0</pose>
        <geometry>
          <mesh>
            <scale>1 1 1</scale>
            <!-- TODO(russt): Break these into separate meshes to support
            materials (elbow patches, silver bands, Kuka logo) as was done
            for the iiwa14 model in #9300 -->
            <uri>link_2.obj</uri>
          </mesh>
        </geometry>
        <material>
	       <diffuse>1.0 0.423529411765 0.0392156862745 1.0</diffuse>
        </material>
      </visual>
      <gravity>1</gravity>
      <velocity_decay/>
      <self_collide>0</self_collide>
    </link>

    <joint name='iiwa_joint_2' type='revolute'>
      <child>iiwa_link_2</child>
      <parent>iiwa_link_1</parent>
      <axis>
        <xyz>0 1 0</xyz>
        <limit>
          <lower>-2.0944</lower>
          <upper>2.0944</upper>
          <effort>300</effort>
          <velocity>10</velocity>
        </limit>
        <dynamics>
          <damping>0.0</damping>
        </dynamics>
      </axis>
    </joint>

    <link name='iiwa_link_3'>
      <pose frame=''>0 -0 0.55 0 0 0</pose>
      <inertial>
        <pose frame=''>0 0.03 0.13 0 -0 0</pose>
        <mass>4.05623</mass>
        <inertia>
          <ixx>0.03204</ixx>
          <ixy>0</ixy>
          <ixz>0</ixz>
          <iyy>0.00972</iyy>
          <iyz>0.006227</iyz>
          <izz>0.03042</izz>
        </inertia>
      </inertial>

      <visual name='iiwa_link_3_visual'>
        <pose frame=''>0 -0.005 -0.026 0 -0 0</pose>
        <geometry>
          <mesh>
            <scale>1 1 1</scale>
            <uri>link_3.obj</uri>
          </mesh>
        </geometry>
        <material>
	       <diffuse>0.4 0.4 0.4 1.0</diffuse>
        </material>
      </visual>
      <gravity>1</gravity>
      <velocity_decay/>
      <self_collide>0</self_collide>
    </link>

    <joint name='iiwa_joint_3' type='revolute'>
      <child>iiwa_link_3</child>
      <parent>iiwa_link_2</parent>
      <axis>
        <xyz>0 0 1</xyz>
        <limit>
          <lower>-2.96706</lower>
          <upper>2.96706</upper>
          <effort>300</effort>
          <velocity>10</velocity>
        </limit>
        <dynamics>
          <damping>0.0</damping>
        </dynamics>
      </axis>
    </joint>

    <link name='iiwa_link_4'>
      <pose frame=''>0 -0 0.74 1.5708 0 0</pose>
      <inertial>
        <pose frame=''>0 0.067 0.034 0 -0 0</pose>
        <mass>3.4822</mass>
        <inertia>
          <ixx>0.02178</ixx>
          <ixy>0</ixy>
          <ixz>0</ixz>
          <iyy>0.02075</iyy>
          <iyz>-0.003625</iyz>
          <izz>0.007785</izz>
        </inertia>
      </inertial>

      <visual name='iiwa_link_4_visual'>
        <pose frame=''>0 0 0 0 -0 0</pose>
        <geometry>
          <mesh>
            <scale>1 1 1</scale>
            <uri>link_4.obj</uri>
          </mesh>
        </geometry>
        <material>
	       <diffuse>1.0 0.423529411765 0.0392156862745 1.0</diffuse>
        </material>
      </visual>
      <gravity>1</gravity>
      <velocity_decay/>
      <self_collide>0</self_collide>
    </link>

    <joint name='iiwa_joint_4' type='revolute'>
      <child>iiwa_link_4</child>
      <parent>iiwa_link_3</parent>
      <axis>
        <xyz>0 -1 0</xyz>
        <limit>
          <lower>-2.0944</lower>
          <upper>2.0944</upper>
          <effort>300</effort>
          <velocity>10</velocity>
        </limit>
        <dynamics>
          <damping>0.0</damping>
        </dynamics>
      </axis>
    </joint>

    <link name='iiwa_link_5'>
      <pose frame=''>0 0 0.95 0 0 0</pose>
      <inertial>
        <pose frame=''>0.0001 0.021 0.076 0 -0 0</pose>
        <mass>2.1633</mass>
        <inertia>
          <ixx>0.01287</ixx>
          <ixy>0</ixy>
          <ixz>0</ixz>
          <iyy>0.005708</iyy>
          <iyz>-0.003946</iyz>
          <izz>0.01112</izz>
        </inertia>
      </inertial>

      <visual name='iiwa_link_5_visual'>
        <pose frame=''>0 0 -0.026 0 -0 0</pose>
        <geometry>
          <mesh>
            <scale>1 1 1</scale>
            <uri>link_5.obj</uri>
          </mesh>
        </geometry>
        <material>
	       <diffuse>0.4 0.4 0.4 1.0</diffuse>
        </material>
      </visual>
      <gravity>1</gravity>
      <velocity_decay/>
      <self_collide>0</self_collide>
    </link>

    <joint name='iiwa_joint_5' type='revolute'>
      <child>iiwa_link_5</child>
      <parent>iiwa_link_4</parent>
      <axis>
        <xyz>0 0 1</xyz>
        <limit>
          <lower>-2.96706</lower>
          <upper>2.96706</upper>
          <effort>300</effort>
          <velocity>10</velocity>
        </limit>
        <dynamics>
          <damping>0.0</damping>
        </dynamics>
      </axis>
    </joint>

    <link name='iiwa_link_6'>
      <pose frame=''>0 -0.0607 1.14 1.5708 0 -3.14159</pose>
      <inertial>
        <pose frame=''>0 0.0006 0.0004 0 -0 0</pose>
        <mass>2.3466</mass>
        <inertia>
          <ixx>0.006509</ixx>
          <ixy>0</ixy>
          <ixz>0</ixz>
          <iyy>0.006259</iyy>
          <iyz>0.00031891</iyz>
          <izz>0.004527</izz>
        </inertia>
      </inertial>

      <visual name='iiwa_link_6_visual'>
        <pose frame=''>0 0 0.121 0 3.14159 0</pose>
        <geometry>
          <mesh>
            <scale>1 1 1</scale>
            <uri>link_6.obj</uri>
          </mesh>
        </geometry>
        <material>
	       <diffuse>1.0 0.423529411765 0.0392156862745 1.0</diffuse>
        </material>
      </visual>
      <gravity>1</gravity>
      <velocity_decay/>
      <self_collide>0</self_collide>
    </link>

    <joint name='iiwa_joint_6' type='revolute'>
      <child>iiwa_link_6</child>
      <parent>iiwa_link_5</parent>
      <axis>
        <xyz>-0 1 -0</xyz>
        <limit>
          <lower>-2.0944</lower>
          <upper>2.0944</upper>
          <effort>300</effort>
          <velocity>10</velocity>
        </limit>
        <dynamics>
          <damping>0.0</damping>
        </dynamics>
      </axis>
    </joint>

    <link name='iiwa_link_7'>
      <pose frame=''>0 0 1.221 0 0 0</pose>
      <inertial>
        <pose frame=''>0 0 0.02 0 -0 0</pose>
        <mass>3.129</mass>
        <inertia>
          <ixx>0.01464</ixx>
          <ixy>0.0005912</ixy>
          <ixz>0</ixz>
          <iyy>0.01465</iyy>
          <iyz>0</iyz>
          <izz>0.002872</izz>
        </inertia>
      </inertial>

      <visual name='iiwa_link_7_visual'>
        <pose frame=''>0 0 -0.0005 0 -0 0</pose>
        <geometry>
          <mesh>
            <scale>1 1 1</scale>
            <uri>link_7.obj</uri>
          </mesh>
        </geometry>
        <material>
	       <diffuse>0.4 0.4 0.4 1.0</diffuse>
        </material>
      </visual>
      <gravity>1</gravity>
      <velocity_decay/>
      <self_collide>0</self_collide>
    </link>
    <joint name='iiwa_joint_7' type='revolute'>
      <child>iiwa_link_7</child>
      <parent>iiwa_link_6</parent>
      <axis>
        <xyz>0 0 1</xyz>
        <limit>
          <lower>-3.05433</lower>
          <upper>3.05433</upper>
          <effort>300</effort>
          <velocity>10</velocity>
        </limit>
        <dynamics>
          <damping>0.0</damping>
        </dynamics>
      </axis>
    </joint>
    <static>0</static>
  </model>
</sdf>
