<?xml version="1.0"?>
<sdf version="1.7">
  <model name="iiwa7">
    <link name="iiwa_link_0">
      <inertial>
        <pose>-0.013 0 0.07 0 0 0</pose>
        <mass>3.863</mass>
        <inertia>
          <ixx>0.0141</ixx>
          <ixy>0</ixy>
          <ixz>0</ixz>
          <iyy>0.0171</iyy>
          <iyz>0</iyz>
          <izz>0.0178</izz>
        </inertia>
      </inertial>
      <visual name="iiwa_link_0_visual">
        <geometry>
          <mesh>
            <scale>1 1 1</scale>
            <uri>package://drake_models/iiwa_description/meshes/iiwa7/visual/link_0.gltf</uri>
          </mesh>
        </geometry>
      </visual>
      <collision name="iiwa_link_0_collision">
        <pose>-0.004563 0 0.07875 0 0 0</pose>
        <geometry>
          <box>
            <size>0.216874 0.207874 0.1575</size>
          </box>
        </geometry>
      </collision>
    </link>
    <link name="iiwa_link_1">
      <pose>0 0 0.1575 0 0 0</pose>
      <inertial>
        <pose>0 -0.0347 0.113 0 0 0</pose>
        <mass>2.7025</mass>
        <inertia>
          <ixx>0.0171</ixx>
          <ixy>0</ixy>
          <ixz>0</ixz>
          <iyy>0.0163</iyy>
          <iyz>0</iyz>
          <izz>0.006</izz>
        </inertia>
      </inertial>
      <visual name="iiwa_link_1_visual">
        <geometry>
          <mesh>
            <scale>1 1 1</scale>
            <uri>package://drake_models/iiwa_description/meshes/iiwa7/visual/link_1.gltf</uri>
          </mesh>
        </geometry>
      </visual>
      <collision name="iiwa_link_1_collision">
        <pose>0 -0.023301 0.127997 0 0 0</pose>
        <geometry>
          <box>
            <size>0.13596 0.182584 0.260995</size>
          </box>
        </geometry>
      </collision>
    </link>
    <joint name="iiwa_joint_1" type="revolute">
      <child>iiwa_link_1</child>
      <parent>iiwa_link_0</parent>
      <axis>
        <xyz expressed_in="__model__">0 0 1</xyz>
        <limit>
          <lower>-2.96706</lower>
          <upper>2.96706</upper>
          <effort>176</effort>
          <velocity>1.7104226670</velocity>
          <drake:acceleration>8.65</drake:acceleration>
        </limit>
        <dynamics>
          <damping>0.0</damping>
          <friction>0</friction>
          <spring_reference>0</spring_reference>
          <spring_stiffness>0</spring_stiffness>
        </dynamics>
      </axis>
      <drake:gear_ratio>160.0</drake:gear_ratio>
      <drake:rotor_inertia>0.00007171875</drake:rotor_inertia>
    </joint>
    <link name="iiwa_link_2">
      <pose>0 0 0.3405 1.5708 0 -3.14159</pose>
      <inertial>
        <pose>0.000 0.0668 0.0344 0 0 0</pose>
        <mass>2.7258</mass>
        <inertia>
          <ixx>0.0170</ixx>
          <ixy>0</ixy>
          <ixz>0</ixz>
          <iyy>0.0061</iyy>
          <iyz>0</iyz>
          <izz>0.0162</izz>
        </inertia>
      </inertial>
      <visual name="iiwa_link_2_visual">
        <geometry>
          <mesh>
            <scale>1 1 1</scale>
            <uri>package://drake_models/iiwa_description/meshes/iiwa7/visual/link_2.gltf</uri>
          </mesh>
        </geometry>
      </visual>
      <collision name="iiwa_link_2_collision">
        <pose>0 0.0580045 0.0173035 0 0 0</pose>
        <geometry>
          <box>
            <size>0.135988 0.251991 0.182605</size>
          </box>
        </geometry>
      </collision>
    </link>
    <joint name="iiwa_joint_2" type="revolute">
      <child>iiwa_link_2</child>
      <parent>iiwa_link_1</parent>
      <axis>
        <xyz expressed_in="__model__">-0 1 0</xyz>
        <limit>
          <lower>-2.0944</lower>
          <upper>2.0944</upper>
          <effort>176</effort>
          <velocity>1.7104226670</velocity>
          <drake:acceleration>5.44</drake:acceleration>
        </limit>
        <dynamics>
          <damping>0</damping>
          <friction>0</friction>
          <spring_reference>0</spring_reference>
          <spring_stiffness>0</spring_stiffness>
        </dynamics>
      </axis>
      <drake:gear_ratio>160.0</drake:gear_ratio>
      <drake:rotor_inertia>0.0001737109</drake:rotor_inertia>
    </joint>
    <link name="iiwa_link_3">
      <pose>0 0 0.5245 0 0 0</pose>
      <inertial>
        <pose>0 0.0296 0.1265 0 0 0</pose>
        <mass>3.175</mass>
        <inertia>
          <ixx>0.025</ixx>
          <ixy>0</ixy>
          <ixz>0</ixz>
          <iyy>0.0238</iyy>
          <iyz>0</iyz>
          <izz>0.0076</izz>
        </inertia>
      </inertial>
      <visual name="iiwa_link_3_visual">
        <geometry>
          <mesh>
            <scale>1 1 1</scale>
            <uri>package://drake_models/iiwa_description/meshes/iiwa7/visual/link_3.gltf</uri>
          </mesh>
        </geometry>
      </visual>
      <collision name="iiwa_link_3_collision">
        <pose>0 0.0182965 0.11073 0 0 0</pose>
        <geometry>
          <box>
            <size>0.135987 0.182593 0.29346</size>
          </box>
        </geometry>
      </collision>
    </link>
    <joint name="iiwa_joint_3" type="revolute">
      <child>iiwa_link_3</child>
      <parent>iiwa_link_2</parent>
      <axis>
        <xyz expressed_in="__model__">0 0 1</xyz>
        <limit>
          <lower>-2.96706</lower>
          <upper>2.96706</upper>
          <effort>110</effort>
          <velocity>1.7453292520</velocity>
          <drake:acceleration>5.69</drake:acceleration>
        </limit>
        <dynamics>
          <damping>0</damping>
          <friction>0</friction>
          <spring_reference>0</spring_reference>
          <spring_stiffness>0</spring_stiffness>
        </dynamics>
      </axis>
      <drake:gear_ratio>160.0</drake:gear_ratio>
      <drake:rotor_inertia>0.0001266406</drake:rotor_inertia>
    </joint>
    <link name="iiwa_link_4">
      <pose>0 0 0.74 1.5708 0 0</pose>
      <inertial>
        <pose>0 0.067 0.034 0 0 0</pose>
        <mass>2.73</mass>
        <inertia>
          <ixx>0.017</ixx>
          <ixy>0</ixy>
          <ixz>0</ixz>
          <iyy>0.0061</iyy>
          <iyz>0</iyz>
          <izz>0.0162</izz>
        </inertia>
      </inertial>
      <visual name="iiwa_link_4_visual">
        <geometry>
          <mesh>
            <scale>1 1 1</scale>
            <uri>package://drake_models/iiwa_description/meshes/iiwa7/visual/link_4.gltf</uri>
          </mesh>
        </geometry>
      </visual>
      <collision name="iiwa_link_4_collision">
        <pose>0 0.0580045 0.0233035 0 0 0</pose>
        <geometry>
          <box>
            <size>0.135988 0.251991 0.182605</size>
          </box>
        </geometry>
      </collision>
    </link>
    <joint name="iiwa_joint_4" type="revolute">
      <child>iiwa_link_4</child>
      <parent>iiwa_link_3</parent>
      <axis>
        <xyz expressed_in="__model__">0 -1 0</xyz>
        <limit>
          <lower>-2.0944</lower>
          <upper>2.0944</upper>
          <effort>110</effort>
          <velocity>2.2689280276</velocity>
          <drake:acceleration>11.01</drake:acceleration>
        </limit>
        <dynamics>
          <damping>0</damping>
          <friction>0</friction>
          <spring_reference>0</spring_reference>
          <spring_stiffness>0</spring_stiffness>
        </dynamics>
      </axis>
      <drake:gear_ratio>160.0</drake:gear_ratio>
      <drake:rotor_inertia>0.0000709765</drake:rotor_inertia>
    </joint>
    <link name="iiwa_link_5">
      <pose>0 0 0.924 0 0 -3.14159</pose>
      <inertial>
        <pose>0.0001 0.021 0.076 0 0 0</pose>
        <mass>1.69</mass>
        <inertia>
          <ixx>0.01</ixx>
          <ixy>0</ixy>
          <ixz>0</ixz>
          <iyy>0.0087</iyy>
          <iyz>0</iyz>
          <izz>0.00449</izz>
        </inertia>
      </inertial>
      <visual name="iiwa_link_5_visual">
        <geometry>
          <mesh>
            <scale>1 1 1</scale>
            <uri>package://drake_models/iiwa_description/meshes/iiwa7/visual/link_5.gltf</uri>
          </mesh>
        </geometry>
      </visual>
      <collision name="iiwa_link_5_collision">
        <pose>0 0.015546 0.102458 0 0 0</pose>
        <geometry>
          <box>
            <size>0.135999 0.167092 0.276916</size>
          </box>
        </geometry>
      </collision>
    </link>
    <joint name="iiwa_joint_5" type="revolute">
      <child>iiwa_link_5</child>
      <parent>iiwa_link_4</parent>
      <axis>
        <xyz expressed_in="__model__">0 0 1</xyz>
        <limit>
          <lower>-2.96706</lower>
          <upper>2.96706</upper>
          <effort>110</effort>
          <velocity>2.4434609528</velocity>
          <drake:acceleration>11.78</drake:acceleration>
        </limit>
        <dynamics>
          <damping>0</damping>
          <friction>0</friction>
          <spring_reference>0</spring_reference>
          <spring_stiffness>0</spring_stiffness>
        </dynamics>
      </axis>
      <drake:gear_ratio>160.0</drake:gear_ratio>
      <drake:rotor_inertia>0.000054375</drake:rotor_inertia>
    </joint>
    <link name="iiwa_link_6">
      <pose>0 0 1.1395 1.5708 0 -3.14159</pose>
      <inertial>
        <pose>0 0.0026 0.0005 0 0 0</pose>
        <mass>1.8</mass>
        <inertia>
          <ixx>0.0051</ixx>
          <ixy>0</ixy>
          <ixz>0</ixz>
          <iyy>0.0049</iyy>
          <iyz>0</iyz>
          <izz>0.0035</izz>
        </inertia>
      </inertial>
      <visual name="iiwa_link_6_visual">
        <pose>0 0 -0.060700 0 0 0</pose>
        <geometry>
          <mesh>
            <scale>1 1 1</scale>
            <uri>package://drake_models/iiwa_description/meshes/iiwa7/visual/link_6.gltf</uri>
          </mesh>
        </geometry>
      </visual>
      <collision name="iiwa_link_6_collision">
        <geometry>
          <box>
            <size>0.132334 0.177387 0.137409</size>
          </box>
        </geometry>
      </collision>
    </link>
    <joint name="iiwa_joint_6" type="revolute">
      <child>iiwa_link_6</child>
      <parent>iiwa_link_5</parent>
      <axis>
        <xyz expressed_in="__model__">-0 1 -0</xyz>
        <limit>
          <lower>-2.0944</lower>
          <upper>2.0944</upper>
          <effort>40</effort>
          <velocity>3.1415926536</velocity>
          <drake:acceleration>13.76</drake:acceleration>
        </limit>
        <dynamics>
          <damping>0</damping>
          <friction>0</friction>
          <spring_reference>0</spring_reference>
          <spring_stiffness>0</spring_stiffness>
        </dynamics>
      </axis>
      <drake:gear_ratio>160.0</drake:gear_ratio>
      <drake:rotor_inertia>0.000054765</drake:rotor_inertia>
    </joint>
    <link name="iiwa_link_7">
      <pose>0 0 1.22 0 0 0</pose>
      <inertial>
        <pose>0 0 0.0294 0 0 0</pose>
        <mass>.4</mass>
        <inertia>
          <ixx>0.0004</ixx>
          <ixy>0</ixy>
          <ixz>0</ixz>
          <iyy>0.0004</iyy>
          <iyz>0</iyz>
          <izz>0.0005</izz>
        </inertia>
      </inertial>
      <visual name="iiwa_link_7_visual">
        <geometry>
          <mesh>
            <scale>1 1 1</scale>
            <uri>package://drake_models/iiwa_description/meshes/iiwa7/visual/link_7.gltf</uri>
          </mesh>
        </geometry>
      </visual>
      <collision name="iiwa_link_7_collision">
        <pose>0 0 0.021997 0 0 0</pose>
        <geometry>
          <box>
            <size>0.10385 0.103885 0.045</size>
          </box>
        </geometry>
      </collision>
    </link>
    <joint name="iiwa_joint_7" type="revolute">
      <child>iiwa_link_7</child>
      <parent>iiwa_link_6</parent>
      <axis>
        <xyz expressed_in="__model__">0 0 1</xyz>
        <limit>
          <lower>-3.05433</lower>
          <upper>3.05433</upper>
          <effort>40</effort>
          <velocity>3.1415926536</velocity>
          <drake:acceleration>13.17</drake:acceleration>
        </limit>
        <dynamics>
          <damping>0</damping>
          <friction>0</friction>
          <spring_reference>0</spring_reference>
          <spring_stiffness>0</spring_stiffness>
        </dynamics>
      </axis>
      <drake:gear_ratio>160.0</drake:gear_ratio>
      <drake:rotor_inertia>0.000054375</drake:rotor_inertia>
    </joint>
    <static>0</static>
  </model>
</sdf>
