<?xml version="1.0" ?>
<!-- =================================================================================== -->
<!-- |    This document was autogenerated by xacro from urdf/allegro_hand_description_right.xacro | -->
<!-- |    EDITING THIS FILE BY HAND IS NOT RECOMMENDED                                 | -->
<!-- =================================================================================== -->
<robot name="allegro_hand_right" xmlns:xacro="http://www.ros.org/wiki/xacro">
  <!-- ============================================================================= -->
  <!-- Base link -->
  <link name="hand_root">
    <origin xyz="0 0 0"/>
  </link>
  <joint name="root_to_base" type="fixed">
    <parent link="hand_root"/>
    <child link="palm_link"/>
    <origin xyz="0 0 0.095"/>
  </joint>
  <!-- PALM -->
  <link name="palm_link">
    <visual>
      <geometry>
        <mesh filename="package://allegro_hand_description/meshes/base_link.obj"/>
      </geometry>
      <origin rpy="0 0 0" xyz="0 0 0 "/>
      <material name="black">
        <color rgba="0.2 0.2 0.2 1"/>
      </material>
    </visual>
    <collision>
      <origin rpy="0 0 0" xyz="-0.009300 0 -0.0475"/>
      <geometry>
        <box size="0.0408 0.1130 0.095"/>
      </geometry>
    </collision>
    <inertial>
      <origin rpy="0 0 0" xyz="0 0 0.0475"/>
      <mass value="0.4154"/>
      <inertia ixx="1e-4" ixy="0.0" ixz="0.0" iyy="1e-4" iyz="0.0" izz="1e-4"/>
    </inertial>
  </link>
  <!-- [LINK 0, 4, 8] -->
  <link name="link_0">
    <visual>
      <geometry>
        <mesh filename="package://allegro_hand_description/meshes/link_0.0.obj"/>
      </geometry>
      <material name="black"/>
    </visual>
    <collision>
      <geometry>
        <box size="0.0196 0.0275 0.0164"/>
      </geometry>
      <origin rpy="0 0 0" xyz="0 0 0.0082"/>
    </collision>
    <inertial>
      <mass value="0.0119"/>
      <origin rpy="0 0 0" xyz="0 0 0"/>
      <inertia ixx="1.01666658333e-06" ixy="0.0" ixz="0.0" iyy="6.47677333333e-07" iyz="0.0" izz="1.01666658333e-06"/>
    </inertial>
  </link>
  <joint name="joint_0" type="revolute">
    <axis xyz="0 0 1"/>
    <limit effort="15" lower="-0.47" upper="0.47" velocity="7"/>
    <parent link="palm_link"/>
    <child link="link_0"/>
    <origin rpy="-0.08726646255 0 0" xyz="0 0.0435 -0.001542"/>
    <dynamics damping="3" friction="10"/>
  </joint>
  <!-- [LINK 1, 5, 9] -->
  <link name="link_1">
    <visual>
      <geometry>
        <mesh filename="package://allegro_hand_description/meshes/link_1.0.obj"/>
      </geometry>
      <material name="black"/>
    </visual>
    <collision>
      <geometry>
        <box size="0.0196 0.0275 0.054"/>
      </geometry>
      <origin rpy="0 0 0" xyz="0 0 0.027"/>
    </collision>
    <inertial>
      <mass value="0.065"/>
      <origin rpy="0 0 0" xyz="0 0 0"/>
      <inertia ixx="7.95654166667e-05" ixy="1.7199e-05" ixz="8.75875e-06" iyy="2.47088833333e-05" iyz="2.413125e-05" izz="7.95654166667e-05"/>
    </inertial>
  </link>
  <joint name="joint_1" type="revolute">
    <limit effort="15" lower="-0.196" upper="1.61" velocity="7"/>
    <axis xyz="0 1 0"/>
    <parent link="link_0"/>
    <child link="link_1"/>
    <origin xyz="0 0 0.0164"/>
    <dynamics damping="3" friction="5"/>
  </joint>
  <!-- [LINK 2, 6, 10]-->
  <link name="link_2">
    <visual>
      <geometry>
        <mesh filename="package://allegro_hand_description/meshes/link_2.0.obj"/>
      </geometry>
      <material name="black"/>
    </visual>
    <collision>
      <geometry>
        <box size="0.0196 0.0275 0.0384"/>
      </geometry>
      <origin rpy="0 0 0" xyz="0 0 0.0192"/>
    </collision>
    <inertial>
      <mass value="0.0355"/>
      <origin rpy="0 0 0" xyz="0 0 0"/>
      <inertia ixx="2.63979183333e-05" ixy="6.67968e-06" ixz="4.783625e-06" iyy="1.34948516667e-05" iyz="9.372e-06" izz="2.63979183333e-05"/>
    </inertial>
  </link>
  <joint name="joint_2" type="revolute">
    <axis xyz="0 1 0"/>
    <limit effort="15" lower="-0.174" upper="1.709" velocity="7"/>
    <parent link="link_1"/>
    <child link="link_2"/>
    <origin xyz="0 0 0.054"/>
    <dynamics damping="8" friction="10"/>
  </joint>
  <!-- [LINK 3, 7, 11] -->
  <link name="link_3">
    <visual>
      <geometry>
        <mesh filename="package://allegro_hand_description/meshes/link_3.0.obj"/>
      </geometry>
      <material name="black"/>
    </visual>
    <collision>
      <geometry>
        <box size="0.0196 0.0275 0.0267"/>
      </geometry>
      <origin rpy="0 0 0" xyz="0 0 0.01335"/>
    </collision>
    <inertial>
      <mass value="0.0096"/>
      <origin rpy="0 0 0" xyz="0 0 0"/>
      <inertia ixx="4.701248e-06" ixy="1.255968e-06" ixz="1.2936e-06" iyy="3.649312e-06" iyz="1.7622e-06" izz="4.701248e-06"/>
    </inertial>
  </link>
  <joint name="joint_3" type="revolute">
    <axis xyz="0 1 0"/>
    <limit effort="15" lower="-0.227" upper="1.618" velocity="7"/>
    <parent link="link_2"/>
    <child link="link_3"/>
    <origin xyz="0 0 0.0384"/>
    <dynamics damping="10" friction="12"/>
  </joint>
  <!-- [FINGER TIP] -->
  <link name="link_3_tip">
    <visual>
      <geometry>
        <mesh filename="package://allegro_hand_description/meshes/link_3.0_tip.obj"/>
      </geometry>
      <material name="white">
        <color rgba=".9 .9 .9 1"/>
      </material>
    </visual>
    <collision>
      <geometry>
        <sphere radius="0.012"/>
      </geometry>
    </collision>
    <inertial>
      <mass value="0.0168"/>
      <origin rpy="0 0 0" xyz="0 0 0"/>
      <inertia ixx="9.68e-07" ixy="0" ixz="0" iyy="9.68e-07" iyz="0" izz="9.68e-07"/>
    </inertial>
  </link>
  <joint name="joint_3_tip" type="fixed">
    <parent link="link_3"/>
    <child link="link_3_tip"/>
    <origin rpy="0 0 0" xyz="0 0 0.0267"/>
  </joint>
  <!-- [LINK 0, 4, 8] -->
  <link name="link_4">
    <visual>
      <geometry>
        <mesh filename="package://allegro_hand_description/meshes/link_0.0.obj"/>
      </geometry>
      <material name="black"/>
    </visual>
    <collision>
      <geometry>
        <box size="0.0196 0.0275 0.0164"/>
      </geometry>
      <origin rpy="0 0 0" xyz="0 0 0.0082"/>
    </collision>
    <inertial>
      <mass value="0.0119"/>
      <origin rpy="0 0 0" xyz="0 0 0"/>
      <inertia ixx="1.01666658333e-06" ixy="0.0" ixz="0.0" iyy="6.47677333333e-07" iyz="0.0" izz="1.01666658333e-06"/>
    </inertial>
  </link>
  <joint name="joint_4" type="revolute">
    <axis xyz="0 0 1"/>
    <limit effort="15" lower="-0.47" upper="0.47" velocity="7"/>
    <parent link="palm_link"/>
    <child link="link_4"/>
    <origin rpy="0.0 0 0" xyz="0 0 0.0007"/>
    <dynamics damping="3" friction="10"/>
  </joint>
  <!-- [LINK 1, 5, 9] -->
  <link name="link_5">
    <visual>
      <geometry>
        <mesh filename="package://allegro_hand_description/meshes/link_1.0.obj"/>
      </geometry>
      <material name="black"/>
    </visual>
    <collision>
      <geometry>
        <box size="0.0196 0.0275 0.054"/>
      </geometry>
      <origin rpy="0 0 0" xyz="0 0 0.027"/>
    </collision>
    <inertial>
      <mass value="0.065"/>
      <origin rpy="0 0 0" xyz="0 0 0"/>
      <inertia ixx="7.95654166667e-05" ixy="1.7199e-05" ixz="8.75875e-06" iyy="2.47088833333e-05" iyz="2.413125e-05" izz="7.95654166667e-05"/>
    </inertial>
  </link>
  <joint name="joint_5" type="revolute">
    <limit effort="15" lower="-0.196" upper="1.61" velocity="7"/>
    <axis xyz="0 1 0"/>
    <parent link="link_4"/>
    <child link="link_5"/>
    <origin xyz="0 0 0.0164"/>
    <dynamics damping="3" friction="5"/>
  </joint>
  <!-- [LINK 2, 6, 10]-->
  <link name="link_6">
    <visual>
      <geometry>
        <mesh filename="package://allegro_hand_description/meshes/link_2.0.obj"/>
      </geometry>
      <material name="black"/>
    </visual>
    <collision>
      <geometry>
        <box size="0.0196 0.0275 0.0384"/>
      </geometry>
      <origin rpy="0 0 0" xyz="0 0 0.0192"/>
    </collision>
    <inertial>
      <mass value="0.0355"/>
      <origin rpy="0 0 0" xyz="0 0 0"/>
      <inertia ixx="2.63979183333e-05" ixy="6.67968e-06" ixz="4.783625e-06" iyy="1.34948516667e-05" iyz="9.372e-06" izz="2.63979183333e-05"/>
    </inertial>
  </link>
  <joint name="joint_6" type="revolute">
    <axis xyz="0 1 0"/>
    <limit effort="15" lower="-0.174" upper="1.709" velocity="7"/>
    <parent link="link_5"/>
    <child link="link_6"/>
    <origin xyz="0 0 0.054"/>
    <dynamics damping="8" friction="10"/>
  </joint>
  <!-- [LINK 3, 7, 11] -->
  <link name="link_7">
    <visual>
      <geometry>
        <mesh filename="package://allegro_hand_description/meshes/link_3.0.obj"/>
      </geometry>
      <material name="black"/>
    </visual>
    <collision>
      <geometry>
        <box size="0.0196 0.0275 0.0267"/>
      </geometry>
      <origin rpy="0 0 0" xyz="0 0 0.01335"/>
    </collision>
    <inertial>
      <mass value="0.0096"/>
      <origin rpy="0 0 0" xyz="0 0 0"/>
      <inertia ixx="4.701248e-06" ixy="1.255968e-06" ixz="1.2936e-06" iyy="3.649312e-06" iyz="1.7622e-06" izz="4.701248e-06"/>
    </inertial>
  </link>
  <joint name="joint_7" type="revolute">
    <axis xyz="0 1 0"/>
    <limit effort="15" lower="-0.227" upper="1.618" velocity="7"/>
    <parent link="link_6"/>
    <child link="link_7"/>
    <origin xyz="0 0 0.0384"/>
    <dynamics damping="10" friction="12"/>
  </joint>
  <!-- [FINGER TIP] -->
  <link name="link_7_tip">
    <visual>
      <geometry>
        <mesh filename="package://allegro_hand_description/meshes/link_3.0_tip.obj"/>
      </geometry>
      <material name="white">
        <color rgba=".9 .9 .9 1"/>
      </material>
    </visual>
    <collision>
      <geometry>
        <sphere radius="0.012"/>
      </geometry>
    </collision>
    <inertial>
      <mass value="0.0168"/>
      <origin rpy="0 0 0" xyz="0 0 0"/>
      <inertia ixx="9.68e-07" ixy="0" ixz="0" iyy="9.68e-07" iyz="0" izz="9.68e-07"/>
    </inertial>
  </link>
  <joint name="joint_7_tip" type="fixed">
    <parent link="link_7"/>
    <child link="link_7_tip"/>
    <origin rpy="0 0 0" xyz="0 0 0.0267"/>
  </joint>
  <!-- [LINK 0, 4, 8] -->
  <link name="link_8">
    <visual>
      <geometry>
        <mesh filename="package://allegro_hand_description/meshes/link_0.0.obj"/>
      </geometry>
      <material name="black"/>
    </visual>
    <collision>
      <geometry>
        <box size="0.0196 0.0275 0.0164"/>
      </geometry>
      <origin rpy="0 0 0" xyz="0 0 0.0082"/>
    </collision>
    <inertial>
      <mass value="0.0119"/>
      <origin rpy="0 0 0" xyz="0 0 0"/>
      <inertia ixx="1.01666658333e-06" ixy="0.0" ixz="0.0" iyy="6.47677333333e-07" iyz="0.0" izz="1.01666658333e-06"/>
    </inertial>
  </link>
  <joint name="joint_8" type="revolute">
    <axis xyz="0 0 1"/>
    <limit effort="15" lower="-0.47" upper="0.47" velocity="7"/>
    <parent link="palm_link"/>
    <child link="link_8"/>
    <origin rpy="0.08726646255 0 0" xyz="0 -0.0435 -0.001542"/>
    <dynamics damping="3" friction="10"/>
  </joint>
  <!-- [LINK 1, 5, 9] -->
  <link name="link_9">
    <visual>
      <geometry>
        <mesh filename="package://allegro_hand_description/meshes/link_1.0.obj"/>
      </geometry>
      <material name="black"/>
    </visual>
    <collision>
      <geometry>
        <box size="0.0196 0.0275 0.054"/>
      </geometry>
      <origin rpy="0 0 0" xyz="0 0 0.027"/>
    </collision>
    <inertial>
      <mass value="0.065"/>
      <origin rpy="0 0 0" xyz="0 0 0"/>
      <inertia ixx="7.95654166667e-05" ixy="1.7199e-05" ixz="8.75875e-06" iyy="2.47088833333e-05" iyz="2.413125e-05" izz="7.95654166667e-05"/>
    </inertial>
  </link>
  <joint name="joint_9" type="revolute">
    <limit effort="15" lower="-0.196" upper="1.61" velocity="7"/>
    <axis xyz="0 1 0"/>
    <parent link="link_8"/>
    <child link="link_9"/>
    <origin xyz="0 0 0.0164"/>
    <dynamics damping="3" friction="5"/>
  </joint>
  <!-- [LINK 2, 6, 10]-->
  <link name="link_10">
    <visual>
      <geometry>
        <mesh filename="package://allegro_hand_description/meshes/link_2.0.obj"/>
      </geometry>
      <material name="black"/>
    </visual>
    <collision>
      <geometry>
        <box size="0.0196 0.0275 0.0384"/>
      </geometry>
      <origin rpy="0 0 0" xyz="0 0 0.0192"/>
    </collision>
    <inertial>
      <mass value="0.0355"/>
      <origin rpy="0 0 0" xyz="0 0 0"/>
      <inertia ixx="2.63979183333e-05" ixy="6.67968e-06" ixz="4.783625e-06" iyy="1.34948516667e-05" iyz="9.372e-06" izz="2.63979183333e-05"/>
    </inertial>
  </link>
  <joint name="joint_10" type="revolute">
    <axis xyz="0 1 0"/>
    <limit effort="15" lower="-0.174" upper="1.709" velocity="7"/>
    <parent link="link_9"/>
    <child link="link_10"/>
    <origin xyz="0 0 0.054"/>
    <dynamics damping="8" friction="10"/>
  </joint>
  <!-- [LINK 3, 7, 11] -->
  <link name="link_11">
    <visual>
      <geometry>
        <mesh filename="package://allegro_hand_description/meshes/link_3.0.obj"/>
      </geometry>
      <material name="black"/>
    </visual>
    <collision>
      <geometry>
        <box size="0.0196 0.0275 0.0267"/>
      </geometry>
      <origin rpy="0 0 0" xyz="0 0 0.01335"/>
    </collision>
    <inertial>
      <mass value="0.0096"/>
      <origin rpy="0 0 0" xyz="0 0 0"/>
      <inertia ixx="4.701248e-06" ixy="1.255968e-06" ixz="1.2936e-06" iyy="3.649312e-06" iyz="1.7622e-06" izz="4.701248e-06"/>
    </inertial>
  </link>
  <joint name="joint_11" type="revolute">
    <axis xyz="0 1 0"/>
    <limit effort="15" lower="-0.227" upper="1.618" velocity="7"/>
    <parent link="link_10"/>
    <child link="link_11"/>
    <origin xyz="0 0 0.0384"/>
    <dynamics damping="10" friction="12"/>
  </joint>
  <!-- [FINGER TIP] -->
  <link name="link_11_tip">
    <visual>
      <geometry>
        <mesh filename="package://allegro_hand_description/meshes/link_3.0_tip.obj"/>
      </geometry>
      <material name="white">
        <color rgba=".9 .9 .9 1"/>
      </material>
    </visual>
    <collision>
      <geometry>
        <sphere radius="0.012"/>
      </geometry>
    </collision>
    <inertial>
      <mass value="0.0168"/>
      <origin rpy="0 0 0" xyz="0 0 0"/>
      <inertia ixx="9.68e-07" ixy="0" ixz="0" iyy="9.68e-07" iyz="0" izz="9.68e-07"/>
    </inertial>
  </link>
  <joint name="joint_11_tip" type="fixed">
    <parent link="link_11"/>
    <child link="link_11_tip"/>
    <origin rpy="0 0 0" xyz="0 0 0.0267"/>
  </joint>
  <!-- [LINK 12] -->
  <link name="link_12">
    <visual>
      <geometry>
        <mesh filename="package://allegro_hand_description/meshes/link_12.0_right.obj"/>
      </geometry>
      <material name="black">
        <color rgba=".2 .2 .2 1"/>
      </material>
      <origin rpy="3.1415926518 0 0" xyz="0 0 0"/>
    </visual>
    <collision>
      <geometry>
        <box size="0.0358 0.034 0.0455"/>
      </geometry>
      <origin rpy="0 0 0" xyz="-0.0179 0.009 0.0145"/>
    </collision>
    <inertial>
      <mass value="0.0176"/>
      <origin rpy="0 0 0" xyz="0 0 0"/>
      <inertia ixx="1.89273333333e-5" ixy="7.16716e-06" ixz="5.35568e-06" iyy="1.43008213333e-05" iyz="6.8068e-06" izz="1.89273333333e-05"/>
    </inertial>
  </link>
  <joint name="joint_12" type="revolute">
    <axis xyz="-1 0 0"/>
    <limit effort="15" lower="0.263" upper="1.396" velocity="7"/>
    <parent link="palm_link"/>
    <child link="link_12"/>
    <origin rpy="0 -1.65806278845 -1.5707963259" xyz="-0.0182 0.019333 -0.045987"/>
    <dynamics damping="3" friction="10"/>
  </joint>
  <!-- [LINK 13] -->
  <link name="link_13">
    <visual>
      <geometry>
        <mesh filename="package://allegro_hand_description/meshes/link_13.0.obj"/>
      </geometry>
      <material name="black">
        <color rgba=".2 .2 .2 1"/>
      </material>
    </visual>
    <collision>
      <geometry>
        <box size="0.0196 0.0275 0.0177"/>
      </geometry>
      <origin rpy="0 0 0" xyz="0 0 0.00885"/>
    </collision>
    <inertial>
      <mass value="0.0119"/>
      <origin rpy="0 0 0" xyz="0 0 0"/>
      <inertia ixx="4.24250866667e-06" ixy="1.032087e-06" ixz="1.603525e-06" iyy="4.52362633333e-06" iyz="1.44808125e-06" izz="4.24250866667e-06"/>
    </inertial>
  </link>
  <joint name="joint_13" type="revolute">
    <axis xyz="0 0 1"/>
    <limit effort="15" lower="-0.105" upper="1.163" velocity="7"/>
    <parent link="link_12"/>
    <child link="link_13"/>
    <origin xyz="-0.027 0.005 0.0399"/>
    <dynamics damping="3" friction="5"/>
  </joint>
  <!-- [LINK 14] -->
  <link name="link_14">
    <visual>
      <geometry>
        <mesh filename="package://allegro_hand_description/meshes/link_14.0.obj"/>
      </geometry>
      <material name="black">
                </material>
    </visual>
    <collision>
      <geometry>
        <box size="0.0196 0.0275 0.0514"/>
      </geometry>
      <origin rpy="0 0 0" xyz="0 0 0.0257"/>
    </collision>
    <inertial>
      <mass value="0.038"/>
      <origin rpy="0 0 0" xyz="0 0 0"/>
      <inertia ixx="4.30439933333e-05" ixy="9.57068e-06" ixz="5.1205e-06" iyy="1.44451933333e-05" iyz="1.342825e-05" izz="4.30439933333e-05"/>
    </inertial>
  </link>
  <joint name="joint_14" type="revolute">
    <axis xyz="0 1 0"/>
    <limit effort="15" lower="-0.189" upper="1.644" velocity="7"/>
    <parent link="link_13"/>
    <child link="link_14"/>
    <origin xyz="0 0 0.0177"/>
    <dynamics damping="3" friction="10"/>
  </joint>
  <!-- [LINK 15] -->
  <link name="link_15">
    <visual>
      <geometry>
        <mesh filename="package://allegro_hand_description/meshes/link_15.0.obj"/>
      </geometry>
      <material name="black">
                </material>
    </visual>
    <collision>
      <geometry>
        <box size="0.0196 0.0275 0.0423"/>
      </geometry>
      <origin rpy="0 0 0" xyz="0 0 0.02115"/>
    </collision>
    <inertial>
      <mass value="0.0388"/>
      <origin rpy="0 0 0" xyz="0 0 0"/>
      <inertia ixx="3.29223173333e-05" ixy="8.042076e-06" ixz="5.2283e-06" iyy="1.47493026667e-5" iyz="1.1283525e-5" izz="3.29223173333e-05"/>
    </inertial>
  </link>
  <joint name="joint_15" type="revolute">
    <axis xyz="0 1 0"/>
    <limit effort="15" lower="-0.162" upper="1.719" velocity="7"/>
    <parent link="link_14"/>
    <child link="link_15"/>
    <origin xyz="0 0 0.0514"/>
    <dynamics damping="3" friction="12"/>
  </joint>
  <!-- [FINGER TIP] -->
  <link name="link_15_tip">
    <visual>
      <geometry>
        <mesh filename="package://allegro_hand_description/meshes/link_15.0_tip.obj"/>
      </geometry>
      <material name="white">
        <color rgba=".9 .9 .9 1"/>
      </material>
    </visual>
    <collision>
      <geometry>
        <sphere radius="0.012"/>
      </geometry>
      <origin rpy="0 0 0" xyz="0 0 0"/>
    </collision>
    <inertial>
      <mass value="0.0168"/>
      <origin rpy="0 0 0" xyz="0 0 0"/>
      <inertia ixx="9.68e-07" ixy="0" ixz="0" iyy="9.68e-07" iyz="0" izz="9.68e-07"/>
    </inertial>
  </link>
  <joint name="joint_15_tip" type="fixed">
    <parent link="link_15"/>
    <child link="link_15_tip"/>
    <origin rpy="0 0 0" xyz="0 0 0.0423"/>
  </joint>
  <!-- ============================================================================= -->
  <!-- END THUMB MACRO -->
  <!-- [[END]] THREE FINGER MACRO -->
</robot>
