<?xml version="1.0" ?>
<!-- =================================================================================== -->
<!-- |    This document was autogenerated by xacro from s-model_articulated.xacro      | -->
<!-- |    EDITING THIS FILE BY HAND IS NOT RECOMMENDED                                 | -->
<!-- =================================================================================== -->
<!-- 
s-model_articulated - articulated version of the robotiq s-model,
3 fingered gripper.                                                
-->
<robot name="s-model_articulated" xmlns:xacro="http://ros.org/wiki/xacro">
  <link name="finger_1_link_0">
    <visual>
      <origin rpy="0 0 0" xyz="0.020 0 0"/>
      <geometry>
        <mesh filename="../meshes/s-model_articulated/visual/link_0.STL"/>
      </geometry>
      <material name="black">
        <color rgba=".2 .2 .2 1"/>
      </material>
    </visual>
    <!--<collision>	
				<origin xyz="-0.0455 0.0414 0.036" rpy="0 3.1416 -1.57"/>
				<geometry>
					<mesh filename="../meshes/s-model_articulated/collision/link_0.STL" />
				</geometry>
				<material name="yellow">
					<color rgba="0 1 1 1"/>
				</material>
			</collision>-->
    <inertial>
      <origin rpy="0 0 0" xyz="0 0 0"/>
      <mass value="0.05"/>
      <inertia ixx="0.01" ixy="-0.00002" ixz="0.00001" iyy="0.0008" iyz="0" izz="0.001"/>
    </inertial>
  </link>
  <link name="finger_1_link_1">
    <visual>
      <origin rpy="0 0 -0.52" xyz="0.050 -.028 0"/>
      <geometry>
        <mesh filename="../meshes/s-model_articulated/visual/link_1.STL"/>
      </geometry>
      <material name="black"/>
    </visual>
    <!--<collision>
				<origin xyz="0.050 -.028 0" rpy="0 0 -0.52"/>
				<geometry>
					<mesh filename="../meshes/s-model_articulated/collision/link_1.STL" />
				</geometry>
				<material name="yellow"/>
			</collision>-->
    <inertial>
      <origin rpy="0 0 0" xyz="0 0 0"/>
      <mass value="0.15"/>
      <inertia ixx="0.001859" ixy="-0.000376" ixz="0.000028" iyy="0.012756" iyz="0" izz="0.0024"/>
    </inertial>
  </link>
  <link name="finger_1_link_2">
    <!--
			NOTE: This link has an offset in the z-direction based on the models that were
			used to generate grap-it poses.  With the offset below the model appears visually
			correct, but it is suspect.
			-->
    <visual>
      <origin rpy="0 0 0" xyz="0.039 0 0.0075"/>
      <geometry>
        <mesh filename="../meshes/s-model_articulated/visual/link_2.STL"/>
      </geometry>
      <material name="black"/>
    </visual>
    <!--<collision>
				<origin xyz="0.039 0 0.0075" rpy="0 0 0"/>
				<geometry>
					<mesh filename="../meshes/s-model_articulated/collision/link_2.STL" />
				</geometry>
				<material name="yellow"/>
			</collision>-->
    <inertial>
      <origin rpy="0 0 0" xyz="0 0 0"/>
      <mass value="0.15"/>
      <inertia ixx="0.001859" ixy="-0.000376" ixz="0.000028" iyy="0.012756" iyz="0" izz="0.0024"/>
    </inertial>
  </link>
  <link name="finger_1_link_3">
    <visual>
      <origin rpy="0 0 0.52" xyz="0 0 0"/>
      <geometry>
        <mesh filename="../meshes/s-model_articulated/visual/link_3.STL"/>
      </geometry>
      <material name="black"/>
    </visual>
    <!--<collision>
				<origin xyz="0 0 0" rpy="0 0 0.52"/>
				<geometry>
					<mesh filename="../meshes/s-model_articulated/collision/link_3.STL" />
				</geometry>
				<material name="yellow"/>
			</collision>-->
    <inertial>
      <origin rpy="0 0 0" xyz="0 0 0"/>
      <mass value="0.05"/>
      <inertia ixx="0.001239" ixy="-0.000251" ixz="0.000019" iyy="0.00085" iyz="0" izz="0.001632"/>
    </inertial>
  </link>
  <link name="finger_1_fourbar_0_link_0">
    <inertial>
      <mass value="0.000001"/>
      <inertia ixx="0.00000000001" ixy="0" ixz="0" iyy="0.00000000001" iyz="0" izz="0.00000000001"/>
    </inertial>
    <visual>
      <origin rpy="0 1.57 0" xyz="0.01429 0 0"/>
			<!--<geometry>
        <cylinder length="0.02858" radius="0.01"/>
			</geometry>-->
    </visual>
  </link>
  <link name="finger_1_fourbar_0_link_1">
    <inertial>
      <mass value="0.000001"/>
      <inertia ixx="0.00000000001" ixy="0" ixz="0" iyy="0.00000000001" iyz="0" izz="0.00000000001"/>
    </inertial>
    <visual>
      <origin rpy="0 1.57 0" xyz="0.02699 0 0"/>
			<!--<geometry>
        <cylinder length="0.05398" radius="0.01"/>
			</geometry>-->
    </visual>
  </link>
  <link name="finger_1_fourbar_0_link_2">
    <inertial>
      <mass value="0.000001"/>
      <inertia ixx="0.00000000001" ixy="0" ixz="0" iyy="0.00000000001" iyz="0" izz="0.00000000001"/>
    </inertial>
    <visual>
      <origin rpy="0 1.57 0" xyz="0.007365 0 0"/>
			<!--<geometry>
        <cylinder length="0.01473" radius="0.01"/>
			</geometry>-->
    </visual>
  </link>
  <joint name="finger_1_fourbar_0_joint_1" type="continuous">
    <parent link="finger_1_link_1"/>
    <child link="finger_1_fourbar_0_link_0"/>
    <origin rpy="0 0 0" xyz="0 0 0"/>
    <axis xyz="0 0 1"/>
  </joint>
  <joint name="finger_1_fourbar_0_joint_2" type="continuous">
    <parent link="finger_1_fourbar_0_link_0"/>
    <child link="finger_1_fourbar_0_link_1"/>
    <origin rpy="0 0 0" xyz="0.02858 0 0"/>
    <axis xyz="0 0 1"/>
  </joint>
  <joint name="finger_1_fourbar_0_joint_3" type="continuous">
    <parent link="finger_1_fourbar_0_link_1"/>
    <child link="finger_1_fourbar_0_link_2"/>
    <origin rpy="0 0 0" xyz="0.05398 0 0"/>
    <axis xyz="0 0 1"/>
  </joint>
  <loop_joint name="finger_1_fourbar_0_joint_4" type="continuous">
    <link1 link="finger_1_fourbar_0_link_1" rpy="0 0 0" xyz="0 0 0"/>
    <link2 link="finger_1_link_2" rpy="0 0 0" xyz="0 0 0"/>
    <axis xyz="0 0 1"/>
  </loop_joint>
  <joint name="finger_1_joint_1" type="revolute">
    <parent link="finger_1_link_0"/>
    <child link="finger_1_link_1"/>
    <axis xyz="0 0 1"/>
    <origin rpy="0 0 0" xyz="0.020 0 0"/>
    <limit effort="100" lower="0" upper="3.1416" velocity="100"/>
  </joint>
  <joint name="finger_1_joint_2" type="revolute">
    <parent link="finger_1_link_1"/>
    <child link="finger_1_link_2"/>
    <axis xyz="0 0 1"/>
    <origin rpy="0 0 -0.52" xyz="0.050 -.028 0"/>
    <limit effort="100" lower="0" upper="3.1416" velocity="100"/>
  </joint>
  <joint name="finger_1_joint_3" type="revolute">
    <parent link="finger_1_link_2"/>
    <child link="finger_1_link_3"/>
    <axis xyz="0 0 1"/>
    <origin rpy="0 0 0" xyz="0.039 0 0"/>
    <limit effort="100" lower="0" upper="3.1416" velocity="100"/>
  </joint>
  <gazebo reference="finger_1_link_0">
    <material>Gazebo/FlatBlack</material>
    <turnGravityOff>true</turnGravityOff>
  </gazebo>
  <gazebo reference="finger_1_link_1">
    <material>Gazebo/FlatBlack</material>
    <turnGravityOff>true</turnGravityOff>
  </gazebo>
  <gazebo reference="finger_1_link_2">
    <material>Gazebo/FlatBlack</material>
    <turnGravityOff>true</turnGravityOff>
  </gazebo>
  <gazebo reference="finger_1_link_3">
    <material>Gazebo/FlatBlack</material>
    <turnGravityOff>true</turnGravityOff>
  </gazebo>
  <link name="finger_2_link_0">
    <visual>
      <origin rpy="0 0 0" xyz="0.020 0 0"/>
      <geometry>
        <mesh filename="../meshes/s-model_articulated/visual/link_0.STL"/>
      </geometry>
      <material name="black">
        <color rgba=".2 .2 .2 1"/>
      </material>
    </visual>
    <!--<collision>	
				<origin xyz="-0.0455 0.0414 0.036" rpy="0 3.1416 -1.57"/>
				<geometry>
					<mesh filename="../meshes/s-model_articulated/collision/link_0.STL" />
				</geometry>
				<material name="yellow">
					<color rgba="0 1 1 1"/>
				</material>
			</collision>-->
    <inertial>
      <origin rpy="0 0 0" xyz="0 0 0"/>
      <mass value="0.05"/>
      <inertia ixx="0.01" ixy="-0.00002" ixz="0.00001" iyy="0.0008" iyz="0" izz="0.001"/>
    </inertial>
  </link>
  <link name="finger_2_link_1">
    <visual>
      <origin rpy="0 0 -0.52" xyz="0.050 -.028 0"/>
      <geometry>
        <mesh filename="../meshes/s-model_articulated/visual/link_1.STL"/>
      </geometry>
      <material name="black"/>
    </visual>
    <!--<collision>
				<origin xyz="0.050 -.028 0" rpy="0 0 -0.52"/>
				<geometry>
					<mesh filename="../meshes/s-model_articulated/collision/link_1.STL" />
				</geometry>
				<material name="yellow"/>
			</collision>-->
    <inertial>
      <origin rpy="0 0 0" xyz="0 0 0"/>
      <mass value="0.15"/>
      <inertia ixx="0.001859" ixy="-0.000376" ixz="0.000028" iyy="0.012756" iyz="0" izz="0.0024"/>
    </inertial>
  </link>
  <link name="finger_2_link_2">
    <!--
			NOTE: This link has an offset in the z-direction based on the models that were
			used to generate grap-it poses.  With the offset below the model appears visually
			correct, but it is suspect.
			-->
    <visual>
      <origin rpy="0 0 0" xyz="0.039 0 0.0075"/>
      <geometry>
        <mesh filename="../meshes/s-model_articulated/visual/link_2.STL"/>
      </geometry>
      <material name="black"/>
    </visual>
    <!--<collision>
				<origin xyz="0.039 0 0.0075" rpy="0 0 0"/>
				<geometry>
					<mesh filename="../meshes/s-model_articulated/collision/link_2.STL" />
				</geometry>
				<material name="yellow"/>
			</collision>-->
    <inertial>
      <origin rpy="0 0 0" xyz="0 0 0"/>
      <mass value="0.15"/>
      <inertia ixx="0.001859" ixy="-0.000376" ixz="0.000028" iyy="0.012756" iyz="0" izz="0.0024"/>
    </inertial>
  </link>
  <link name="finger_2_link_3">
    <visual>
      <origin rpy="0 0 0.52" xyz="0 0 0"/>
      <geometry>
        <mesh filename="../meshes/s-model_articulated/visual/link_3.STL"/>
      </geometry>
      <material name="black"/>
    </visual>
    <!--<collision>
				<origin xyz="0 0 0" rpy="0 0 0.52"/>
				<geometry>
					<mesh filename="../meshes/s-model_articulated/collision/link_3.STL" />
				</geometry>
				<material name="yellow"/>
			</collision>-->
    <inertial>
      <origin rpy="0 0 0" xyz="0 0 0"/>
      <mass value="0.05"/>
      <inertia ixx="0.001239" ixy="-0.000251" ixz="0.000019" iyy="0.00085" iyz="0" izz="0.001632"/>
    </inertial>
  </link>
  <link name="finger_2_fourbar_0_link_0">
    <inertial>
      <mass value="0.000001"/>
      <inertia ixx="0.00000000001" ixy="0" ixz="0" iyy="0.00000000001" iyz="0" izz="0.00000000001"/>
    </inertial>
    <visual>
      <origin rpy="0 1.57 0" xyz="0.01429 0 0"/>
			<!--<geometry>
        <cylinder length="0.02858" radius="0.01"/>
			</geometry>-->
    </visual>
  </link>
  <link name="finger_2_fourbar_0_link_1">
    <inertial>
      <mass value="0.000001"/>
      <inertia ixx="0.00000000001" ixy="0" ixz="0" iyy="0.00000000001" iyz="0" izz="0.00000000001"/>
    </inertial>
    <visual>
      <origin rpy="0 1.57 0" xyz="0.02699 0 0"/>
			<!--<geometry>
        <cylinder length="0.05398" radius="0.01"/>
			</geometry>-->
    </visual>
  </link>
  <link name="finger_2_fourbar_0_link_2">
    <inertial>
      <mass value="0.000001"/>
      <inertia ixx="0.00000000001" ixy="0" ixz="0" iyy="0.00000000001" iyz="0" izz="0.00000000001"/>
    </inertial>
    <visual>
      <origin rpy="0 1.57 0" xyz="0.007365 0 0"/>
			<!--<geometry>
        <cylinder length="0.01473" radius="0.01"/>
			</geometry>-->
    </visual>
  </link>
  <joint name="finger_2_fourbar_0_joint_1" type="continuous">
    <parent link="finger_2_link_1"/>
    <child link="finger_2_fourbar_0_link_0"/>
    <origin rpy="0 0 0" xyz="0 0 0"/>
    <axis xyz="0 0 1"/>
  </joint>
  <joint name="finger_2_fourbar_0_joint_2" type="continuous">
    <parent link="finger_2_fourbar_0_link_0"/>
    <child link="finger_2_fourbar_0_link_1"/>
    <origin rpy="0 0 0" xyz="0.02858 0 0"/>
    <axis xyz="0 0 1"/>
  </joint>
  <joint name="finger_2_fourbar_0_joint_3" type="continuous">
    <parent link="finger_2_fourbar_0_link_1"/>
    <child link="finger_2_fourbar_0_link_2"/>
    <origin rpy="0 0 0" xyz="0.05398 0 0"/>
    <axis xyz="0 0 1"/>
  </joint>
  <loop_joint name="finger_2_fourbar_0_joint_4" type="continuous">
    <link1 link="finger_2_fourbar_0_link_1" rpy="0 0 0" xyz="0 0 0"/>
    <link2 link="finger_2_link_2" rpy="0 0 0" xyz="0 0 0"/>
    <axis xyz="0 0 1"/>
  </loop_joint>
  <joint name="finger_2_joint_1" type="revolute">
    <parent link="finger_2_link_0"/>
    <child link="finger_2_link_1"/>
    <axis xyz="0 0 1"/>
    <origin rpy="0 0 0" xyz="0.020 0 0"/>
    <limit effort="100" lower="0" upper="3.1416" velocity="100"/>
  </joint>
  <joint name="finger_2_joint_2" type="revolute">
    <parent link="finger_2_link_1"/>
    <child link="finger_2_link_2"/>
    <axis xyz="0 0 1"/>
    <origin rpy="0 0 -0.52" xyz="0.050 -.028 0"/>
    <limit effort="100" lower="0" upper="3.1416" velocity="100"/>
  </joint>
  <joint name="finger_2_joint_3" type="revolute">
    <parent link="finger_2_link_2"/>
    <child link="finger_2_link_3"/>
    <axis xyz="0 0 1"/>
    <origin rpy="0 0 0" xyz="0.039 0 0"/>
    <limit effort="100" lower="0" upper="3.1416" velocity="100"/>
  </joint>
  <gazebo reference="finger_2_link_0">
    <material>Gazebo/FlatBlack</material>
    <turnGravityOff>true</turnGravityOff>
  </gazebo>
  <gazebo reference="finger_2_link_1">
    <material>Gazebo/FlatBlack</material>
    <turnGravityOff>true</turnGravityOff>
  </gazebo>
  <gazebo reference="finger_2_link_2">
    <material>Gazebo/FlatBlack</material>
    <turnGravityOff>true</turnGravityOff>
  </gazebo>
  <gazebo reference="finger_2_link_3">
    <material>Gazebo/FlatBlack</material>
    <turnGravityOff>true</turnGravityOff>
  </gazebo>
  <link name="finger_middle_link_0">
    <visual>
      <origin rpy="0 0 0" xyz="0.020 0 0"/>
      <geometry>
        <mesh filename="../meshes/s-model_articulated/visual/link_0.STL"/>
      </geometry>
      <material name="black">
        <color rgba=".2 .2 .2 1"/>
      </material>
    </visual>
    <!--<collision>	
				<origin xyz="-0.0455 0.0414 0.036" rpy="0 3.1416 -1.57"/>
				<geometry>
					<mesh filename="../meshes/s-model_articulated/collision/link_0.STL" />
				</geometry>
				<material name="yellow">
					<color rgba="0 1 1 1"/>
				</material>
			</collision>-->
    <inertial>
      <origin rpy="0 0 0" xyz="0 0 0"/>
      <mass value="0.05"/>
      <inertia ixx="0.01" ixy="-0.00002" ixz="0.00001" iyy="0.0008" iyz="0" izz="0.001"/>
    </inertial>
  </link>
  <link name="finger_middle_link_1">
    <visual>
      <origin rpy="0 0 -0.52" xyz="0.050 -.028 0"/>
      <geometry>
        <mesh filename="../meshes/s-model_articulated/visual/link_1.STL"/>
      </geometry>
      <material name="black"/>
    </visual>
    <!--<collision>
				<origin xyz="0.050 -.028 0" rpy="0 0 -0.52"/>
				<geometry>
					<mesh filename="../meshes/s-model_articulated/collision/link_1.STL" />
				</geometry>
				<material name="yellow"/>
			</collision>-->
    <inertial>
      <origin rpy="0 0 0" xyz="0 0 0"/>
      <mass value="0.15"/>
      <inertia ixx="0.001859" ixy="-0.000376" ixz="0.000028" iyy="0.012756" iyz="0" izz="0.0024"/>
    </inertial>
  </link>
  <link name="finger_middle_link_2">
    <!--
			NOTE: This link has an offset in the z-direction based on the models that were
			used to generate grap-it poses.  With the offset below the model appears visually
			correct, but it is suspect.
			-->
    <visual>
      <origin rpy="0 0 0" xyz="0.039 0 0.0075"/>
      <geometry>
        <mesh filename="../meshes/s-model_articulated/visual/link_2.STL"/>
      </geometry>
      <material name="black"/>
    </visual>
    <!--<collision>
				<origin xyz="0.039 0 0.0075" rpy="0 0 0"/>
				<geometry>
					<mesh filename="../meshes/s-model_articulated/collision/link_2.STL" />
				</geometry>
				<material name="yellow"/>
			</collision>-->
    <inertial>
      <origin rpy="0 0 0" xyz="0 0 0"/>
      <mass value="0.15"/>
      <inertia ixx="0.001859" ixy="-0.000376" ixz="0.000028" iyy="0.012756" iyz="0" izz="0.0024"/>
    </inertial>
  </link>
  <link name="finger_middle_link_3">
    <visual>
      <origin rpy="0 0 0.52" xyz="0 0 0"/>
      <geometry>
        <mesh filename="../meshes/s-model_articulated/visual/link_3.STL"/>
      </geometry>
      <material name="black"/>
    </visual>
    <!--<collision>
				<origin xyz="0 0 0" rpy="0 0 0.52"/>
				<geometry>
					<mesh filename="../meshes/s-model_articulated/collision/link_3.STL" />
				</geometry>
				<material name="yellow"/>
			</collision>-->
    <inertial>
      <origin rpy="0 0 0" xyz="0 0 0"/>
      <mass value="0.05"/>
      <inertia ixx="0.001239" ixy="-0.000251" ixz="0.000019" iyy="0.00085" iyz="0" izz="0.001632"/>
    </inertial>
  </link>
  <link name="finger_middle_fourbar_0_link_0">
    <inertial>
      <mass value="0.000001"/>
      <inertia ixx="0.00000000001" ixy="0" ixz="0" iyy="0.00000000001" iyz="0" izz="0.00000000001"/>
    </inertial>
    <visual>
      <origin rpy="0 1.57 0" xyz="0.01429 0 0"/>
			<!--<geometry>
        <cylinder length="0.02858" radius="0.01"/>
			</geometry>-->
    </visual>
  </link>
  <link name="finger_middle_fourbar_0_link_1">
    <inertial>
      <mass value="0.000001"/>
      <inertia ixx="0.00000000001" ixy="0" ixz="0" iyy="0.00000000001" iyz="0" izz="0.00000000001"/>
    </inertial>
    <visual>
      <origin rpy="0 1.57 0" xyz="0.02699 0 0"/>
			<!--<geometry>
        <cylinder length="0.05398" radius="0.01"/>
			</geometry>-->
    </visual>
  </link>
  <link name="finger_middle_fourbar_0_link_2">
    <inertial>
      <mass value="0.000001"/>
      <inertia ixx="0.00000000001" ixy="0" ixz="0" iyy="0.00000000001" iyz="0" izz="0.00000000001"/>
    </inertial>
    <visual>
      <origin rpy="0 1.57 0" xyz="0.007365 0 0"/>
			<!--<geometry>
        <cylinder length="0.01473" radius="0.01"/>
			</geometry>-->
    </visual>
  </link>
  <joint name="finger_middle_fourbar_0_joint_1" type="continuous">
    <parent link="finger_middle_link_1"/>
    <child link="finger_middle_fourbar_0_link_0"/>
    <origin rpy="0 0 0" xyz="0 0 0"/>
    <axis xyz="0 0 1"/>
  </joint>
  <joint name="finger_middle_fourbar_0_joint_2" type="continuous">
    <parent link="finger_middle_fourbar_0_link_0"/>
    <child link="finger_middle_fourbar_0_link_1"/>
    <origin rpy="0 0 0" xyz="0.02858 0 0"/>
    <axis xyz="0 0 1"/>
  </joint>
  <joint name="finger_middle_fourbar_0_joint_3" type="continuous">
    <parent link="finger_middle_fourbar_0_link_1"/>
    <child link="finger_middle_fourbar_0_link_2"/>
    <origin rpy="0 0 0" xyz="0.05398 0 0"/>
    <axis xyz="0 0 1"/>
  </joint>
  <loop_joint name="finger_middle_fourbar_0_joint_4" type="continuous">
    <link1 link="finger_middle_fourbar_0_link_1" rpy="0 0 0" xyz="0 0 0"/>
    <link2 link="finger_middle_link_2" rpy="0 0 0" xyz="0 0 0"/>
    <axis xyz="0 0 1"/>
  </loop_joint>
  <joint name="finger_middle_joint_1" type="revolute">
    <parent link="finger_middle_link_0"/>
    <child link="finger_middle_link_1"/>
    <axis xyz="0 0 1"/>
    <origin rpy="0 0 0" xyz="0.020 0 0"/>
    <limit effort="100" lower="0" upper="3.1416" velocity="100"/>
  </joint>
  <joint name="finger_middle_joint_2" type="revolute">
    <parent link="finger_middle_link_1"/>
    <child link="finger_middle_link_2"/>
    <axis xyz="0 0 1"/>
    <origin rpy="0 0 -0.52" xyz="0.050 -.028 0"/>
    <limit effort="100" lower="0" upper="3.1416" velocity="100"/>
  </joint>
  <joint name="finger_middle_joint_3" type="revolute">
    <parent link="finger_middle_link_2"/>
    <child link="finger_middle_link_3"/>
    <axis xyz="0 0 1"/>
    <origin rpy="0 0 0" xyz="0.039 0 0"/>
    <limit effort="100" lower="0" upper="3.1416" velocity="100"/>
  </joint>
  <gazebo reference="finger_middle_link_0">
    <material>Gazebo/FlatBlack</material>
    <turnGravityOff>true</turnGravityOff>
  </gazebo>
  <gazebo reference="finger_middle_link_1">
    <material>Gazebo/FlatBlack</material>
    <turnGravityOff>true</turnGravityOff>
  </gazebo>
  <gazebo reference="finger_middle_link_2">
    <material>Gazebo/FlatBlack</material>
    <turnGravityOff>true</turnGravityOff>
  </gazebo>
  <gazebo reference="finger_middle_link_3">
    <material>Gazebo/FlatBlack</material>
    <turnGravityOff>true</turnGravityOff>
  </gazebo>
  <link name="palm">
    <visual>
      <geometry>
        <mesh filename="../meshes/s-model_articulated/visual/palm.STL"/>
      </geometry>
      <material name="black">
        <color rgba=".2 .2 .2 1"/>
      </material>
    </visual>
    <!--<collision>
				<geometry>
					<mesh filename="../meshes/s-model_articulated/collision/palm.STL" />
				</geometry>
				<material name="yellow">
					<color rgba="0 1 1 1"/>
				</material>
			</collision>-->
  </link>
  <inertial>
    <origin rpy="0 0 0" xyz="0 0 0"/>
    <mass value="1.3"/>
    <inertia ixx="0.006012" ixy="0.000079" ixz="-0.00024" iyy="0.012892" iyz="0" izz="0.002435"/>
  </inertial>
  <joint name="palm_finger_1_joint" type="revolute">
    <parent link="palm"/>
    <child link="finger_1_link_0"/>
    <axis xyz="0 1 0"/>
    <origin rpy="0 3.1416 -1.57" xyz="-0.0455 0.0214 0.036"/>
    <limit effort="100" lower="-0.16" upper="0.25" velocity="100"/>
  </joint>
  <joint name="palm_finger_2_joint" type="revolute">
    <parent link="palm"/>
    <child link="finger_2_link_0"/>
    <axis xyz="0 1 0"/>
    <origin rpy="0 3.1416 -1.57" xyz="-0.0455 0.0214 -0.036"/>
    <limit effort="100" lower="-0.25" upper="0.16" velocity="100"/>
  </joint>
  <joint name="palm_finger_middle_joint" type="fixed">
    <parent link="palm"/>
    <child link="finger_middle_link_0"/>
    <axis xyz="0 0 1"/>
    <origin rpy="0 0 1.57" xyz="0.0455 0.0214 0"/>
  </joint>
  <gazebo reference="palm">
    <material>Gazebo/FlatBlack</material>
    <turnGravityOff>true</turnGravityOff>
  </gazebo>
  <!--
	<include filename="$(find robotiq_s_model_visualization)/cfg/s-model_finger_articulated_macro.xacro" />
	<xacro:s-model_finger_articulated prefix=""/>
-->
</robot>

