<?xml version="1.0" ?>
<robot
  name="IRB140_-_M2004C_Complete_base.SLDASM">
  <link
    name="base_link">
    <inertial>
      <origin
        xyz="-0.0820393251688425 -0.0599247343482246 0.000402028640224033"
        rpy="-1.57079 0 0" />
      <mass
        value="12.409016159487" />
      <inertia
        ixx="0.104502176006253"
        ixy="0.00734284655670482"
        ixz="1.00520827530156E-05"
        iyy="0.246486764065977"
        iyz="0.000843006810157312"
        izz="0.16727784258504" />
    </inertial>
    <visual>
      <origin
        xyz="0 0 0"
        rpy="-1.57079 0 0" />
      <geometry>
        <mesh
          filename="package://IRB140/urdf/meshes/base_link.stl" />
      </geometry>
      <material
        name="">
        <color
          rgba="0.890196078431373 0.411764705882353 0.125490196078431 1" />
      </material>
    </visual>
    <collision>
      <origin
        xyz="0 0 0"
        rpy="-1.57079 0 0" />
      <geometry>
        <mesh
          filename="package://IRB140/urdf/meshes/base_link.stl" />
      </geometry>
    </collision>
  </link>
  <collision_filter_group name="base">
	  <member link="base_link"/>
  </collision_filter_group>
  <collision_filter_group name="ignore_base">
	  <member link="link_1"/>
  </collision_filter_group>
  <link
    name="link_1">
    <inertial>
      <origin
        xyz="0.0281052735195531 -0.263404021764231 0.0438145912936454"
        rpy="0 0 0" />
      <mass
        value="16.287755696602" />
      <inertia
        ixx="0.239763088891016"
        ixy="-0.0247090810274521"
        ixz="0.000698689923332581"
        iyy="0.215279593840589"
        iyz="-0.0324602456686847"
        izz="0.21738294278782" />
    </inertial>
    <visual>
      <origin
        xyz="0 0.1095 0"
        rpy="0 0 0" />
      <geometry>
        <mesh
          filename="package://IRB140/urdf/meshes/link1.stl" />
      </geometry>
      <material
        name="">
        <color
          rgba="0.890196078431373 0.411764705882353 0.125490196078431 1" />
      </material>
    </visual>
    <collision>
      <origin
        xyz="0 0.1095 0"
        rpy="0 0 0" />
      <geometry>
        <mesh
          filename="package://IRB140/urdf/meshes/link1.stl" />
      </geometry>
    </collision>
  </link>
  <link
    name="link_2">
    <inertial>
      <origin
        xyz="0.0602722328661623 -0.550288012476887 -0.0924337165442594"
        rpy="0 0 0" />
      <mass
        value="7.58037424484438" />
      <inertia
        ixx="0.155736578403723"
        ixy="-0.0018292494088038"
        ixz="-0.000516100043145016"
        iyy="0.0449374006069967"
        iyz="0.0179772597993246"
        izz="0.131499062854069" />
    </inertial>
    <visual>
      <origin
        xyz="-0.07 0.352 0"
        rpy="0 0 0" />
      <geometry>
        <mesh
          filename="package://IRB140/urdf/meshes/link2.stl" />
      </geometry>
      <material
        name="">
        <color
          rgba="0.890196078431373 0.411764705882353 0.125490196078431 1" />
      </material>
    </visual>
    <collision>
      <origin
        xyz="-0.07 0.352 0"
        rpy="0 0 0" />
      <geometry>
        <mesh
          filename="package://IRB140/urdf/meshes/link2.stl" />
      </geometry>
    </collision>
  </link>
  <link
    name="link_3">
    <inertial>
      <origin
        xyz="0.0895840773879386 -0.706321963929838 0.00750781548417993"
        rpy="0 0 0" />
      <mass
        value="8.03072730997701" />
      <inertia
        ixx="0.0322819185861096"
        ixy="0.00189304098071818"
        ixz="-0.00301812650515099"
        iyy="0.0862439596837411"
        iyz="0.000363121583074651"
        izz="0.0941344479457789" />
    </inertial>
    <visual>
      <origin
        xyz="-0.07 0.712 0"
        rpy="0 0 0" />
      <geometry>
        <mesh
          filename="package://IRB140/urdf/meshes/link3.stl" />
      </geometry>
      <material
        name="">
        <color
          rgba="0.890196078431373 0.411764705882353 0.125490196078431 1" />
      </material>
    </visual>
    <collision>
      <origin
        xyz="-0.07  0.712 0"
        rpy="0 0 0" />
      <geometry>
        <mesh
          filename="package://IRB140/urdf/meshes/link3.stl" />
      </geometry>
    </collision>
  </link>
  <link
    name="link_4">
    <inertial>
      <origin
        xyz="0.381567778909365 -0.710566670346653 -0.0012125731023236"
        rpy="0 0 0" />
      <mass
        value="1.7702548022269" />
      <inertia
        ixx="0.00345886724545012"
        ixy="-5.89845314013543E-05"
        ixz="-0.000204665310780048"
        iyy="0.00814796317500158"
        iyz="3.05102860299544E-06"
        izz="0.00727417938725734" />
    </inertial>
    <visual>
      <origin
        xyz="-0.2885 0.712 0"
        rpy="0 0 0" />
      <geometry>
        <mesh
          filename="package://IRB140/urdf/meshes/link4.stl" />
      </geometry>
      <material
        name="">
        <color
          rgba="0.890196078431373 0.411764705882353 0.125490196078431 1" />
      </material>
    </visual>
    <collision>
      <origin
        xyz="-0.2885 0.712 0"
        rpy="0 0 0" />
      <geometry>
        <mesh
          filename="package://IRB140/urdf/meshes/link4.stl" />
      </geometry>
    </collision>
  </link>
  <link
    name="link_5">
    <inertial>
      <origin
        xyz="0.4486171436144 -0.711838316531129 0.000617034654940496"
        rpy="0 0 0" />
      <mass
        value="0.145550520315438" />
      <inertia
        ixx="7.1482542749252E-05"
        ixy="4.08865519403599E-07"
        ixz="1.24002244883737E-07"
        iyy="6.88353185385481E-05"
        iyz="-1.00702333671187E-08"
        izz="0.000112132445217078" />
    </inertial>
    <visual>
      <origin
        xyz="-0.450 0.712 0"
        rpy="0 0 0" />
      <geometry>
        <mesh
          filename="package://IRB140/urdf/meshes/link5.stl" />
      </geometry>
      <material
        name="">
        <color
          rgba="0.890196078431373 0.411764705882353 0.125490196078431 1" />
      </material>
    </visual>
    <collision>
      <origin
        xyz="-0.450 0.712 0"
        rpy="0 0 0" />
      <geometry>
        <mesh
          filename="package://IRB140/urdf/meshes/link5.stl" />
      </geometry>
    </collision>
  </link>
    <link
    name="link_6">
    <inertial>
      <origin
        xyz="0.502059432845099 -0.711774967143511 2.38785136319277E-10"
        rpy="0 0 0" />
      <mass
        value="0.0258654328719498" />
      <inertia
        ixx="5.9822143548355E-06"
        ixy="4.58244484401765E-08"
        ixz="-3.33091906738059E-13"
        iyy="6.2921914507958E-06"
        iyz="6.75626369217644E-13"
        izz="6.17479327327778E-06" />
    </inertial>
    <visual>
      <origin
        xyz="-0.515 0.712 0"
        rpy="0 0 0" />
      <geometry>
        <mesh
          filename="package://IRB140/urdf/meshes/link6.stl" />
      </geometry>
      <material
        name="">
        <color
          rgba="0.796078431372549 0.823529411764706 0.937254901960784 1" />
      </material>
    </visual>
    <collision>
      <origin
        xyz="-0.515 0.712 0"
        rpy="0 0 0" />
      <geometry>
        <mesh
          filename="package://IRB140/urdf/meshes/link6.stl" />
      </geometry>
    </collision>
  </link>
  <joint name="joint1" type="revolute">
    <parent link="base_link"/>
    <child link="link_1"/>
    <limit effort="300" lower="-3.14159265359" upper="3.14159265359" velocity="4.36"/>
    <axis xyz="0 -1 0"/>
    <origin rpy="-1.57079 0 0" xyz="0 0 0.1095"/>
  </joint>
  <joint name="joint2" type="revolute">
    <parent link="link_1"/>
    <child link="link_2"/>
    <limit effort="300" lower="-1.57079633" upper="1.91986218" velocity="4.36"/>
    <axis xyz="0 0 1"/>
    <origin rpy="0 0 0" xyz="0.07 -0.2425 0"/>
  </joint>
  <joint name="joint3" type="revolute">
    <parent link="link_2"/>
    <child link="link_3"/>
    <limit effort="300" lower="-4.01425728" upper="0.87266463" velocity="4.36"/>
    <axis xyz="0 0 1"/>
    <origin rpy="0 0 0" xyz="0 -0.360 0"/>
  </joint>
  <joint name="joint4" type="revolute">
    <parent link="link_3"/>
    <child link="link_4"/>
    <limit effort="300" lower="-3.49065850" upper="3.49065850" velocity="5.58"/>
    <axis xyz="1 0 0"/>
    <origin rpy="0 0 0" xyz="0.2185 0 0"/>
  </joint>
  <joint name="joint5" type="revolute">
    <parent link="link_4"/>
    <child link="link_5"/>
    <limit effort="300" lower="-2.09439510" upper="2.09439510" velocity="5.58"/>
    <axis xyz="0 0 -1"/>
    <origin rpy="0 0 0" xyz="0.1615 0 0"/>
  </joint>
  <joint name="joint6" type="revolute">
    <parent link="link_5"/>
    <child link="link_6"/>
    <limit effort="300" lower="-6.98131701" upper="6.98131701" velocity="7.33"/>
    <axis xyz="1 0 0"/>
    <origin rpy="0 0 0" xyz="0.065 0 0"/>
  </joint>

  <transmission name="joint1_trans" type="SimpleTransmission">
    <joint name="joint1"/>
    <actuator name="joint1_motor"/>
    <mechanicalReduction>1</mechanicalReduction>
  </transmission>

  <transmission name="joint2_trans" type="SimpleTransmission">
    <joint name="joint2"/>
    <actuator name="joint2_motor"/>
    <mechanicalReduction>1</mechanicalReduction>
  </transmission>

  <transmission name="joint3_trans" type="SimpleTransmission">
    <joint name="joint3"/>
    <actuator name="joint3_motor"/>
    <mechanicalReduction>1</mechanicalReduction>
  </transmission>

  <transmission name="joint4_trans" type="SimpleTransmission">
    <joint name="joint4"/>
    <actuator name="joint4_motor"/>
    <mechanicalReduction>1</mechanicalReduction>
  </transmission>

  <transmission name="joint5_trans" type="SimpleTransmission">
    <joint name="joint5"/>
    <actuator name="joint5_motor"/>
    <mechanicalReduction>1</mechanicalReduction>
  </transmission>
  
  <transmission name="joint6_trans" type="SimpleTransmission">
    <joint name="joint6"/>
    <actuator name="joint6_motor"/>
    <mechanicalReduction>1</mechanicalReduction>
  </transmission>
  
</robot>
