<?xml version="1.0" ?>
<!-- =================================================================================== -->
<!-- |    This document was autogenerated by xacro from urdf/wsg_50_mesh_collision.urdf.xacro | -->
<!-- |    EDITING THIS FILE BY HAND IS NOT RECOMMENDED                                 | -->
<!-- =================================================================================== -->
<!-- ===================================================================== -->
<!-- This xacro file calls the wsg_50 macro defined in wsg_50.urdf.xacro. It
     instantiates a WSG 50 URDF model that uses meshes for its collision model.
     Meshes are more accurate than primitive shapes or convex hulls but are also
     more computationally demanding.

     Note that if no mesh specification appears below, it's because the wsg_50
     macro automatically defaults to use mesh collision models.-->
<!-- ===================================================================== -->
<robot name="wsg_50" xmlns:controller="http://playerstage.sourceforge.net/gazebo/xmlschema/#controller" xmlns:interface="http://playerstage.sourceforge.net/gazebo/xmlschema/#interface" xmlns:sensor="http://playerstage.sourceforge.net/gazebo/xmlschema/#sensor" xmlns:xacro="http://www.ros.org/wiki/xacro">
  <!-- Instantiates a WSG 50 URDF model by calling the wsg_50 macro. -->
  <link name="world"/>
  <joint name="wsg_50_anterior_gripper_joint" type="fixed">
    <origin rpy="0 0 0" xyz="0 0 0"/>
    <parent link="world"/>
    <child link="wsg_50_base_link"/>
  </joint>
  <!-- BASE LINK -->
  <link name="wsg_50_base_link">
    <inertial>
      <mass value="1.2"/>
      <origin xyz="0 0 0"/>
      <inertia ixx="1.0" ixy="0.0" ixz="0.0" iyy="1.0" iyz="0.0" izz="1.0"/>
    </inertial>
    <visual>
      <origin rpy="0 0 0" xyz="0.0 0 0"/>
      <geometry>
        <mesh filename="package://wsg_50_description/meshes/WSG50_110.obj" scale="1 1 1"/>
      </geometry>
      <material name="grey">
        <color rgba="0.5 0.5 0.5 1"/>
      </material>
    </visual>
    <collision>
      <origin rpy="0 0 0" xyz="0.0 0 0"/>
      <geometry>
        <mesh filename="package://wsg_50_description/meshes/WSG50_110.obj" scale="1 1 1"/>
      </geometry>
    </collision>
  </link>
  <gazebo reference="wsg_50_base_link">
    <material>Gazebo/Grey</material>
    <turnGravityOff>false</turnGravityOff>
  </gazebo>
  <!-- GRIPPER LEFT -->
  <joint name="wsg_50_base_joint_gripper_left" type="prismatic">
    <limit effort="1.0" lower="-0.055" upper="-0.0027" velocity="1.0"/>
    <origin rpy="0 0 0" xyz="0 0 0"/>
    <!--origin xyz="-0.0067 0 0.049" rpy="0 0 0" /-->
    <parent link="wsg_50_base_link"/>
    <child link="wsg_50_gripper_left"/>
    <dynamics damping="100" friction="100"/>
    <axis xyz="1 0 0"/>
    <limit effort="100" velocity="100"/>
  </joint>
  <transmission name="wsg_50_base_trans_left" type="pr2_mechanism_model/SimpleTransmission">
    <actuator name="wsg_50_base_motor_left"/>
    <joint name="wsg_50_base_joint_gripper_left"/>
    <mechanicalReduction>1</mechanicalReduction>
    <motorTorqueConstant>1</motorTorqueConstant>
  </transmission>
  <link name="wsg_50_gripper_left">
    <inertial>
      <mass value="0.1"/>
      <origin xyz="0 0 0"/>
      <inertia ixx="1.0" ixy="0.0" ixz="0.0" iyy="1.0" iyz="0.0" izz="1.0"/>
    </inertial>
    <visual>
      <origin rpy="0 0 0" xyz="0.0 0 0"/>
      <geometry>
        <mesh filename="package://wsg_50_description/meshes/GUIDE_WSG50_110.obj" scale="0.001 0.001 0.001"/>
      </geometry>
      <material name="black">
        <color rgba="0 0 0 1"/>
      </material>
    </visual>
    <collision>
      <origin rpy="0 0 0" xyz="0 0 0"/>
      <geometry>
        <mesh filename="package://wsg_50_description/meshes/GUIDE_WSG50_110.obj" scale="0.001 0.001 0.001"/>
      </geometry>
    </collision>
    <contact_coefficients kd="1.0" kp="1000.0" mu="0"/>
  </link>
  <gazebo reference="wsg_50_gripper_left">
    <material>Gazebo/Blue</material>
    <turnGravityOff>false</turnGravityOff>
  </gazebo>
  <!-- LEFT FINGER -->
  <joint name="wsg_50_guide_joint_finger_left" type="fixed">
    <origin rpy="0 0 0" xyz="0 0 0.023"/>
    <parent link="wsg_50_gripper_left"/>
    <child link="wsg_50_finger_left"/>
    <dynamics damping="100" friction="100"/>
    <axis xyz="1 0 0"/>
    <limit effort="100" velocity="100"/>
  </joint>
  <link name="wsg_50_finger_left">
    <inertial>
      <mass value="0.1"/>
      <origin xyz="0 0 0"/>
      <inertia ixx="1.0" ixy="0.0" ixz="0.0" iyy="1.0" iyz="0.0" izz="1.0"/>
    </inertial>
    <visual>
      <origin rpy="0 0 0" xyz="0.0 0 0"/>
      <geometry>
        <mesh filename="package://wsg_50_description/meshes/WSG-FMF.obj" scale="0.001 0.001 0.001"/>
      </geometry>
      <material name="black">
        <color rgba="0 0 0 1"/>
      </material>
    </visual>
    <collision>
      <origin rpy="0 0 0" xyz="0 0 0"/>
      <geometry>
        <mesh filename="package://wsg_50_description/meshes/WSG-FMF.obj" scale="0.001 0.001 0.001"/>
      </geometry>
    </collision>
    <contact_coefficients kd="1.0" kp="1000.0" mu="0"/>
  </link>
  <gazebo reference="wsg_50_finger_left">
    <material>Gazebo/Blue</material>
    <turnGravityOff>false</turnGravityOff>
  </gazebo>
  <!-- GRIPPER RIGHT -->
  <joint name="wsg_50_base_joint_gripper_right" type="prismatic">
    <limit effort="1.0" lower="0.0027" upper="0.055" velocity="1.0"/>
    <origin rpy="0 0 3.14159" xyz="0 0 0"/>
    <parent link="wsg_50_base_link"/>
    <child link="wsg_50_gripper_right"/>
    <axis xyz="-1 0 0"/>
    <dynamics damping="100" friction="100"/>
    <limit effort="100" velocity="100"/>
  </joint>
  <transmission name="wsg_50_base_trans_right" type="pr2_mechanism_model/SimpleTransmission">
    <actuator name="wsg_50_base_motor_right"/>
    <joint name="wsg_50_base_joint_gripper_right"/>
    <mechanicalReduction>1</mechanicalReduction>
    <motorTorqueConstant>1</motorTorqueConstant>
  </transmission>
  <link name="wsg_50_gripper_right">
    <inertial>
      <mass value="0.1"/>
      <origin xyz="0 0 0"/>
      <inertia ixx="1.0" ixy="0.0" ixz="0.0" iyy="1.0" iyz="0.0" izz="1.0"/>
    </inertial>
    <visual>
      <origin rpy="0 0 0" xyz="0.0 0 0"/>
      <geometry>
        <mesh filename="package://wsg_50_description/meshes/GUIDE_WSG50_110.obj" scale="0.001 0.001 0.001"/>
      </geometry>
      <material name="black">
        <color rgba="0 0 0 1"/>
      </material>
    </visual>
    <collision>
      <origin rpy="0 0 0" xyz="0 0 0"/>
      <geometry>
        <mesh filename="package://wsg_50_description/meshes/GUIDE_WSG50_110.obj" scale="0.001 0.001 0.001"/>
      </geometry>
    </collision>
    <contact_coefficients kd="1.0" kp="1000.0" mu="0"/>
  </link>
  <gazebo reference="gripper_right">
    <material>Gazebo/White</material>
    <turnGravityOff>false</turnGravityOff>
  </gazebo>
  <!-- RIGHT FINGER -->
  <joint name="wsg_50_guide_joint_finger_right" type="fixed">
    <origin rpy="0 0 0" xyz="0 0 0.023"/>
    <parent link="wsg_50_gripper_right"/>
    <child link="wsg_50_finger_right"/>
    <dynamics damping="100" friction="100"/>
    <axis xyz="1 0 0"/>
    <limit effort="100" velocity="100"/>
  </joint>
  <link name="wsg_50_finger_right">
    <inertial>
      <mass value="0.1"/>
      <origin xyz="0 0 0"/>
      <inertia ixx="1.0" ixy="0.0" ixz="0.0" iyy="1.0" iyz="0.0" izz="1.0"/>
    </inertial>
    <visual>
      <origin rpy="0 0 0" xyz="0.0 0 0"/>
      <geometry>
        <mesh filename="package://wsg_50_description/meshes/WSG-FMF.obj" scale="0.001 0.001 0.001"/>
      </geometry>
      <material name="black">
        <color rgba="0 0 0 1"/>
      </material>
    </visual>
    <collision>
      <origin rpy="0 0 0" xyz="0 0 0"/>
      <geometry>
        <mesh filename="package://wsg_50_description/meshes/WSG-FMF.obj" scale="0.001 0.001 0.001"/>
      </geometry>
    </collision>
    <contact_coefficients kd="1.0" kp="1000.0" mu="0"/>
  </link>
  <gazebo reference="wsg_50_finger_right">
    <material>Gazebo/White</material>
    <turnGravityOff>false</turnGravityOff>
  </gazebo>
</robot>
