<?xml version="1.0"?>
<!-- This is the main xacro file that defines a model of Schunk's WSG 50 robot
  gripper. It provides a macro called "wsg_50" that accepts several input
  parameters including:

  1. name - A prefix that is added to all joint and link names.
  2. parent - The name of the parent body to which the gripper's base body is
     attached.
  3. origin - X_PG where P is the parent body's frame and G is
     the gripper's base frame.

  Since this file only defines a macro, it is not meant to be used directly with
  the xacro executable. Instead, another xacro file must call this macro while
  supplying the necessary parameters. See, for example, the other *.urdf.xacro
  files in this directory.
-->
<robot name="wsg_50" xmlns:controller="http://playerstage.sourceforge.net/gazebo/xmlschema/#controller" xmlns:interface="http://playerstage.sourceforge.net/gazebo/xmlschema/#interface" xmlns:sensor="http://playerstage.sourceforge.net/gazebo/xmlschema/#sensor" xmlns:xacro="http://ros.org/wiki/xacro">
  <xacro:macro name="wsg_50" params="name parent *origin">
    <joint name="${name}_anterior_gripper_joint" type="fixed">
      <insert_block name="origin"/>
      <parent link="${parent}"/>
      <child link="${name}_base_link"/>
    </joint>
    <!-- BASE LINK -->
    <link name="${name}_base_link">
      <inertial>
        <mass value="1.2"/>
        <origin xyz="0 0 0"/>
        <inertia ixx="1.0" ixy="0.0" ixz="0.0" iyy="1.0" iyz="0.0" izz="1.0"/>
      </inertial>
      <visual>
        <origin rpy="0 0 0" xyz="0.0 0 0"/>
        <geometry>
          <mesh filename="package://wsg_50_description/meshes/WSG50_110.obj" scale="1 1 1"/>
        </geometry>
        <material name="grey">
          <color rgba="0.5 0.5 0.5 1"/>
        </material>
      </visual>
      <collision>
        <origin rpy="0 0 0" xyz="0.0 0 0"/>
        <geometry>
          <mesh filename="package://wsg_50_description/meshes/WSG50_110.obj" scale="1 1 1"/>
        </geometry>
      </collision>
    </link>
    <gazebo reference="${name}_base_link">
      <material>Gazebo/Grey</material>
      <turnGravityOff>false</turnGravityOff>
    </gazebo>
    <!-- GRIPPER LEFT -->
    <joint name="${name}_base_joint_gripper_left" type="prismatic">
      <limit effort="1.0" lower="-0.055" upper="-0.0027" velocity="1.0"/>
      <origin rpy="0 0 0" xyz="0 0 0"/>
      <!--origin xyz="-0.0067 0 0.049" rpy="0 0 0" /-->
      <parent link="${name}_base_link"/>
      <child link="${name}_gripper_left"/>
      <dynamics damping="100" friction="100"/>
      <axis xyz="1 0 0"/>
      <limit effort="100" velocity="100"/>
    </joint>
    <transmission name="${name}_base_trans_left" type="pr2_mechanism_model/SimpleTransmission">
      <actuator name="${name}_base_motor_left"/>
      <joint name="${name}_base_joint_gripper_left"/>
      <mechanicalReduction>1</mechanicalReduction>
      <motorTorqueConstant>1</motorTorqueConstant>
    </transmission>
    <link name="${name}_gripper_left">
      <inertial>
        <mass value="0.1"/>
        <origin xyz="0 0 0"/>
        <inertia ixx="1.0" ixy="0.0" ixz="0.0" iyy="1.0" iyz="0.0" izz="1.0"/>
      </inertial>
      <visual>
        <origin rpy="0 0 0" xyz="0.0 0 0"/>
        <geometry>
          <mesh filename="package://wsg_50_description/meshes/GUIDE_WSG50_110.obj" scale="0.001 0.001 0.001"/>
        </geometry>
        <material name="black">
          <color rgba="0 0 0 1"/>
        </material>
      </visual>
      <collision>
        <origin rpy="0 0 0" xyz="0 0 0"/>
        <geometry>
          <mesh filename="package://wsg_50_description/meshes/GUIDE_WSG50_110.obj" scale="0.001 0.001 0.001"/>
        </geometry>
      </collision>
      <contact_coefficients kd="1.0" kp="1000.0" mu="0"/>
    </link>
    <gazebo reference="${name}_gripper_left">
      <material>Gazebo/Blue</material>
      <turnGravityOff>false</turnGravityOff>
    </gazebo>
    <!-- LEFT FINGER -->
    <joint name="${name}_guide_joint_finger_left" type="fixed">
      <origin rpy="0 0 0" xyz="0 0 0.023"/>
      <parent link="${name}_gripper_left"/>
      <child link="${name}_finger_left"/>
      <dynamics damping="100" friction="100"/>
      <axis xyz="1 0 0"/>
      <limit effort="100" velocity="100"/>
    </joint>
    <link name="${name}_finger_left">
      <inertial>
        <mass value="0.1"/>
        <origin xyz="0 0 0"/>
        <inertia ixx="1.0" ixy="0.0" ixz="0.0" iyy="1.0" iyz="0.0" izz="1.0"/>
      </inertial>
      <visual>
        <origin rpy="0 0 0" xyz="0.0 0 0"/>
        <geometry>
          <mesh filename="package://wsg_50_description/meshes/WSG-FMF.obj" scale="0.001 0.001 0.001"/>
        </geometry>
        <material name="black">
          <color rgba="0 0 0 1"/>
        </material>
      </visual>
      <collision>
        <origin rpy="0 0 0" xyz="0 0 0"/>
        <geometry>
          <mesh filename="package://wsg_50_description/meshes/WSG-FMF.obj" scale="0.001 0.001 0.001"/>
        </geometry>
      </collision>
      <contact_coefficients kd="1.0" kp="1000.0" mu="0"/>
    </link>
    <gazebo reference="${name}_finger_left">
      <material>Gazebo/Blue</material>
      <turnGravityOff>false</turnGravityOff>
    </gazebo>
    <!-- GRIPPER RIGHT -->
    <joint name="${name}_base_joint_gripper_right" type="prismatic">
      <limit effort="1.0" lower="0.0027" upper="0.055" velocity="1.0"/>
      <origin rpy="0 0 3.14159" xyz="0 0 0"/>
      <parent link="${name}_base_link"/>
      <child link="${name}_gripper_right"/>
      <axis xyz="-1 0 0"/>
      <dynamics damping="100" friction="100"/>
      <limit effort="100" velocity="100"/>
    </joint>
    <transmission name="${name}_base_trans_right" type="pr2_mechanism_model/SimpleTransmission">
      <actuator name="${name}_base_motor_right"/>
      <joint name="${name}_base_joint_gripper_right"/>
      <mechanicalReduction>1</mechanicalReduction>
      <motorTorqueConstant>1</motorTorqueConstant>
    </transmission>
    <link name="${name}_gripper_right">
      <inertial>
        <mass value="0.1"/>
        <origin xyz="0 0 0"/>
        <inertia ixx="1.0" ixy="0.0" ixz="0.0" iyy="1.0" iyz="0.0" izz="1.0"/>
      </inertial>
      <visual>
        <origin rpy="0 0 0" xyz="0.0 0 0"/>
        <geometry>
          <mesh filename="package://wsg_50_description/meshes/GUIDE_WSG50_110.obj" scale="0.001 0.001 0.001"/>
        </geometry>
        <material name="black">
          <color rgba="0 0 0 1"/>
        </material>
      </visual>
      <collision>
        <origin rpy="0 0 0" xyz="0 0 0"/>
        <geometry>
          <mesh filename="package://wsg_50_description/meshes/GUIDE_WSG50_110.obj" scale="0.001 0.001 0.001"/>
        </geometry>
      </collision>
      <contact_coefficients kd="1.0" kp="1000.0" mu="0"/>
    </link>
    <gazebo reference="gripper_right">
      <material>Gazebo/White</material>
      <turnGravityOff>false</turnGravityOff>
    </gazebo>
    <!-- RIGHT FINGER -->
    <joint name="${name}_guide_joint_finger_right" type="fixed">
      <origin rpy="0 0 0" xyz="0 0 0.023"/>
      <parent link="${name}_gripper_right"/>
      <child link="${name}_finger_right"/>
      <dynamics damping="100" friction="100"/>
      <axis xyz="1 0 0"/>
      <limit effort="100" velocity="100"/>
    </joint>
    <link name="${name}_finger_right">
      <inertial>
        <mass value="0.1"/>
        <origin xyz="0 0 0"/>
        <inertia ixx="1.0" ixy="0.0" ixz="0.0" iyy="1.0" iyz="0.0" izz="1.0"/>
      </inertial>
      <visual>
        <origin rpy="0 0 0" xyz="0.0 0 0"/>
        <geometry>
          <mesh filename="package://wsg_50_description/meshes/WSG-FMF.obj" scale="0.001 0.001 0.001"/>
        </geometry>
        <material name="black">
          <color rgba="0 0 0 1"/>
        </material>
      </visual>
      <collision>
        <origin rpy="0 0 0" xyz="0 0 0"/>
        <geometry>
          <mesh filename="package://wsg_50_description/meshes/WSG-FMF.obj" scale="0.001 0.001 0.001"/>
        </geometry>
      </collision>
      <contact_coefficients kd="1.0" kp="1000.0" mu="0"/>
    </link>
    <gazebo reference="${name}_finger_right">
      <material>Gazebo/White</material>
      <turnGravityOff>false</turnGravityOff>
    </gazebo>
  </xacro:macro>
</robot>
