<?xml version='1.0'?>
<sdf version='1.6'>
  <model name='allegro_finger_1'>
    <link name='hand_root'>
      <pose frame=''>0 0 0 0 -0 0</pose>
      <inertial>
        <pose frame=''>0 0 0.1425 0 -0 0</pose>
        <mass>0.4154</mass>
        <inertia>
          <ixx>0.0001</ixx>
          <ixy>0</ixy>
          <ixz>0</ixz>
          <iyy>0.0001</iyy>
          <iyz>0</iyz>
          <izz>0.0001</izz>
        </inertia>
      </inertial>
      <collision name='hand_root_fixed_joint_lump__palm_link_collision'>
        <pose frame=''>-0.0093 0 0.0475 0 -0 0</pose>
        <geometry>
          <box>
            <size>0.0408 0.113 0.095</size>
          </box>
        </geometry>
      </collision>
      <visual name='hand_root_fixed_joint_lump__palm_link_visual'>
        <pose frame=''>0 0 0.095 0 -0 0</pose>
        <geometry>
          <mesh>
            <scale>1 1 1</scale>
            <uri>../meshes/base_link.obj</uri>
          </mesh>
        </geometry>
      </visual>
    </link>
    <link name='link_0'>
      <pose frame=''>0 0.0435 0.093458 -0.087267 0 0</pose>
      <inertial>
        <pose frame=''>0 0 0 0 -0 0</pose>
        <mass>0.0119</mass>
        <inertia>
          <ixx>1.01667e-06</ixx>
          <ixy>0</ixy>
          <ixz>0</ixz>
          <iyy>6.47677e-07</iyy>
          <iyz>0</iyz>
          <izz>1.01667e-06</izz>
        </inertia>
      </inertial>
<!--      <collision name='link_0_collision'>
        <pose frame=''>0 0 0.0082 0 -0 0</pose>
        <geometry>
          <box>
            <size>0.0196 0.0275 0.0164</size>
          </box>
        </geometry>
      </collision>   -->
      <visual name='link_0_visual'>
        <pose frame=''>0 0 0 0 -0 0</pose>
        <geometry>
          <mesh>
            <scale>1 1 1</scale>
            <uri>../meshes/link_0.0.obj</uri>
          </mesh>
        </geometry>
      </visual>
    </link>
    <joint name='joint_0' type='revolute'>
      <child>link_0</child>
      <parent>hand_root</parent>
      <axis>
        <xyz>0 0.087156 0.996195</xyz>
        <limit>
          <lower>-0.47</lower>
          <upper>0.47</upper>
          <effort>15</effort>
          <velocity>7</velocity>
        </limit>
        <dynamics>
          <damping>3</damping>
          <friction>10</friction>
          <spring_reference>0</spring_reference>
          <spring_stiffness>0</spring_stiffness>
        </dynamics>
        <use_parent_model_frame>1</use_parent_model_frame>
      </axis>
    </joint>
    <link name='link_1'>
      <pose frame=''>0 0.044929 0.109796 -0.087267 0 0</pose>
      <inertial>
        <pose frame=''>0 0 0 0 -0 0</pose>
        <mass>0.065</mass>
        <inertia>
          <ixx>7.95654e-05</ixx>
          <ixy>1.7199e-050</ixy>
          <ixz>8.75875e-060</ixz>
          <iyy>2.47089e-05</iyy>
          <iyz>2.41313e-050</iyz>
          <izz>7.95654e-05</izz>
        </inertia>
      </inertial>
      <collision name='link_1_collision'>
        <pose frame=''>0 0 0.027 0 -0 0</pose>
        <geometry>
          <box>
            <size>0.0196 0.0275 0.054</size>
          </box>
        </geometry>
      </collision>
      <visual name='link_1_visual'>
        <pose frame=''>0 0 0 0 -0 0</pose>
        <geometry>
          <mesh>
            <scale>1 1 1</scale>
            <uri>../meshes/link_1.0.obj</uri>
          </mesh>
        </geometry>
      </visual>
    </link>
    <joint name='joint_1' type='revolute'>
      <child>link_1</child>
      <parent>link_0</parent>
      <axis>
        <xyz>0 0.996195 -0.087156</xyz>
        <limit>
          <lower>-0.196</lower>
          <upper>1.61</upper>
          <effort>15</effort>
          <velocity>7</velocity>
        </limit>
        <dynamics>
          <damping>3</damping>
          <friction>5</friction>
          <spring_reference>0</spring_reference>
          <spring_stiffness>0</spring_stiffness>
        </dynamics>
        <use_parent_model_frame>1</use_parent_model_frame>
      </axis>
    </joint>
    <link name='link_2'>
      <pose frame=''>0 0.049636 0.16359 -0.087267 0 0</pose>
      <inertial>
        <pose frame=''>0 0 0 0 -0 0</pose>
        <mass>0.0355</mass>
        <inertia>
          <ixx>2.63979e-05</ixx>
          <ixy>6.67968e-060</ixy>
          <ixz>4.78363e-060</ixz>
          <iyy>1.34949e-05</iyy>
          <iyz>9.372e-06.</iyz>
          <izz>2.63979e-05</izz>
        </inertia>
      </inertial>
      <collision name='link_2_collision'>
        <pose frame=''>0 0 0.0192 0 -0 0</pose>
        <geometry>
          <box>
            <size>0.0196 0.0275 0.0384</size>
          </box>
        </geometry>
      </collision>
      <visual name='link_2_visual'>
        <pose frame=''>0 0 0 0 -0 0</pose>
        <geometry>
          <mesh>
            <scale>1 1 1</scale>
            <uri>../meshes/link_2.0.obj</uri>
          </mesh>
        </geometry>
      </visual>
    </link>
    <joint name='joint_2' type='revolute'>
      <child>link_2</child>
      <parent>link_1</parent>
      <axis>
        <xyz>0 0.996195 -0.087156</xyz>
        <limit>
          <lower>-0.174</lower>
          <upper>1.709</upper>
          <effort>15</effort>
          <velocity>7</velocity>
        </limit>
        <dynamics>
          <damping>8</damping>
          <friction>10</friction>
          <spring_reference>0</spring_reference>
          <spring_stiffness>0</spring_stiffness>
        </dynamics>
        <use_parent_model_frame>1</use_parent_model_frame>
      </axis>
    </joint>
    <link name='link_3'>
      <pose frame=''>0 0.052983 0.201844 -0.087267 0 0</pose>
      <inertial>
        <pose frame=''>0 0 0.016991 0 -0 0</pose>
        <mass>0.0264</mass>
        <inertia>
          <ixx>1.00244e-05</ixx>
          <ixy>1.25597e-06</ixy>
          <ixz>1.2936e-06</ixz>
          <iyy>8.97242e-06</iyy>
          <iyz>1.7622e-06</iyz>
          <izz>5.66925e-06</izz>
        </inertia>
      </inertial>
      <collision name='link_3_collision'>
        <pose frame=''>0 0 0.01335 0 -0 0</pose>
        <geometry>
          <box>
            <size>0.0196 0.0275 0.0267</size>
          </box>
        </geometry>
      </collision>
      <collision name='link_3_tip_collision_1'>
        <pose frame=''>0 0 0.0267 0 -0 0</pose>
        <geometry>
          <sphere>
            <radius>0.012</radius>
          </sphere>
        </geometry>
      </collision>
      <visual name='link_3_visual'>
        <pose frame=''>0 0 0 0 -0 0</pose>
        <geometry>
          <mesh>
            <scale>1 1 1</scale>
            <uri>../meshes/link_3.0.obj</uri>
          </mesh>
        </geometry>
      </visual>
      <visual name='link_3_tip_visual_1'>
        <pose frame=''>0 0 0.0267 0 -0 0</pose>
        <geometry>
          <mesh>
            <scale>1 1 1</scale>
            <uri>../meshes/link_3.0_tip.obj</uri>
          </mesh>
        </geometry>
      </visual>
    </link>
    <joint name='joint_3' type='revolute'>
      <child>link_3</child>
      <parent>link_2</parent>
      <axis>
        <xyz>0 0.996195 -0.087156</xyz>
        <limit>
          <lower>-0.227</lower>
          <upper>1.618</upper>
          <effort>15</effort>
          <velocity>7</velocity>
        </limit>
        <dynamics>
          <damping>10</damping>
          <friction>12</friction>
          <spring_reference>0</spring_reference>
          <spring_stiffness>0</spring_stiffness>
        </dynamics>
        <use_parent_model_frame>1</use_parent_model_frame>
      </axis>
    </joint>
  </model>
</sdf>
