<?xml version='1.0'?>
<sdf version='1.6'>
  <model name='allegro_hand_right'>
    <joint name='weld_base' type='fixed'>
      <parent>world</parent>
      <child>hand_root</child>
      <pose>0 0 0 0 0 0</pose>
    </joint>
    
    <link name='hand_root'>
      <pose frame=''>0 0 0 0 -0 0</pose>
      <inertial>
        <pose frame=''>0 0 0.1425 0 -0 0</pose>
        <mass>0.4154</mass>
        <inertia>
          <ixx>0.0001</ixx>
          <ixy>0</ixy>
          <ixz>0</ixz>
          <iyy>0.0001</iyy>
          <iyz>0</iyz>
          <izz>0.0001</izz>
        </inertia>
      </inertial>      
      <collision name='hand_root_fixed_joint_lump__palm_link_collision'>
        <pose frame=''>-0.0093 0 0.0475 0 -0 0</pose>
        <geometry>
          <box>
            <size>0.0408 0.113 0.095</size>
          </box>
        </geometry>
      </collision>
      <visual name='hand_root_fixed_joint_lump__palm_link_visual'>
        <pose frame=''>0 0 0.095 0 -0 0</pose>
        <geometry>
          <mesh>
            <scale>1 1 1</scale>
            <uri>../meshes/base_link.obj</uri>
          </mesh>
        </geometry>
      </visual>
    </link>
    <link name='link_0'>
      <pose frame=''>0 0.0435 0.093458 -0.087267 0 0</pose>
      <inertial>
        <pose frame=''>0 0 0 0 -0 0</pose>
        <mass>0.0119</mass>
        <inertia>
          <ixx>1.01667e-06</ixx>
          <ixy>0</ixy>
          <ixz>0</ixz>
          <iyy>6.47677e-07</iyy>
          <iyz>0</iyz>
          <izz>1.01667e-06</izz>
        </inertia>
      </inertial>
      <collision name='link_0_collision'>
        <pose frame=''>0 0 0.0082 0 -0 0</pose>
        <geometry>
          <box>
            <size>0.0196 0.0275 0.0164</size>
          </box>
        </geometry>
      </collision>   
      <visual name='link_0_visual'>
        <pose frame=''>0 0 0 0 -0 0</pose>
        <geometry>
          <mesh>
            <scale>1 1 1</scale>
            <uri>../meshes/link_0.0.obj</uri>
          </mesh>
        </geometry>
      </visual>
    </link>
    <joint name='joint_0' type='revolute'>
      <child>link_0</child>
      <parent>hand_root</parent>
      <axis>
        <xyz>0 0.087156 0.996195</xyz>
        <limit>
          <lower>-0.47</lower>
          <upper>0.47</upper>
          <effort>15</effort>
          <velocity>7</velocity>
        </limit>
        <dynamics>
          <damping>3e-3</damping>
          <friction>10</friction>
          <spring_reference>0</spring_reference>
          <spring_stiffness>0</spring_stiffness>
        </dynamics>
        <use_parent_model_frame>1</use_parent_model_frame>
      </axis>
    </joint>
    <link name='link_1'>
      <pose frame=''>0 0.044929 0.109796 -0.087267 0 0</pose>
      <inertial>
        <pose frame=''>0 0 0 0 -0 0</pose>
        <mass>0.065</mass>
        <inertia>
          <ixx>7.95654e-05</ixx>
          <ixy>1.7199e-050</ixy>
          <ixz>8.75875e-060</ixz>
          <iyy>2.47089e-05</iyy>
          <iyz>2.41313e-050</iyz>
          <izz>7.95654e-05</izz>
        </inertia>
      </inertial>
      
      <collision name='link_1_collision'>
        <pose frame=''>0 0 0.027 0 -0 0</pose>
        <geometry>
          <box>
            <size>0.0196 0.0275 0.054</size>
          </box>
        </geometry>
      </collision>
      <visual name='link_1_visual'>
        <pose frame=''>0 0 0 0 -0 0</pose>
        <geometry>
          <mesh>
            <scale>1 1 1</scale>
            <uri>../meshes/link_1.0.obj</uri>
          </mesh>
        </geometry>
      </visual>
    </link>
    <joint name='joint_1' type='revolute'>
      <child>link_1</child>
      <parent>link_0</parent>
      <axis>
        <xyz>0 0.996195 -0.087156</xyz>
        <limit>
          <lower>-0.196</lower>
          <upper>1.61</upper>
          <effort>15</effort>
          <velocity>7</velocity>
        </limit>
        <dynamics>
          <damping>3e-3</damping>
          <friction>5</friction>
          <spring_reference>0</spring_reference>
          <spring_stiffness>0</spring_stiffness>
        </dynamics>
        <use_parent_model_frame>1</use_parent_model_frame>
      </axis>
    </joint>
    <link name='link_2'>
      <pose frame=''>0 0.049636 0.16359 -0.087267 0 0</pose>
      <inertial>
        <pose frame=''>0 0 0 0 -0 0</pose>
        <mass>0.0355</mass>
        <inertia>
          <ixx>2.63979e-05</ixx>
          <ixy>6.67968e-060</ixy>
          <ixz>4.78363e-060</ixz>
          <iyy>1.34949e-05</iyy>
          <iyz>9.372e-06.</iyz>
          <izz>2.63979e-05</izz>
        </inertia>
      </inertial>
      
      <collision name='link_2_collision'>
        <pose frame=''>0 0 0.0192 0 -0 0</pose>
        <geometry>
          <box>
            <size>0.0196 0.0275 0.0384</size>
          </box>
        </geometry>
      </collision>
      <visual name='link_2_visual'>
        <pose frame=''>0 0 0 0 -0 0</pose>
        <geometry>
          <mesh>
            <scale>1 1 1</scale>
            <uri>../meshes/link_2.0.obj</uri>
          </mesh>
        </geometry>
      </visual>
    </link>
    <joint name='joint_2' type='revolute'>
      <child>link_2</child>
      <parent>link_1</parent>
      <axis>
        <xyz>0 0.996195 -0.087156</xyz>
        <limit>
          <lower>-0.174</lower>
          <upper>1.709</upper>
          <effort>15</effort>
          <velocity>7</velocity>
        </limit>
        <dynamics>
          <damping>8e-3</damping>
          <friction>10</friction>
          <spring_reference>0</spring_reference>
          <spring_stiffness>0</spring_stiffness>
        </dynamics>
        <use_parent_model_frame>1</use_parent_model_frame>
      </axis>
    </joint>
    <link name='link_3'>
      <pose frame=''>0 0.052983 0.201844 -0.087267 0 0</pose>
      <inertial>
        <pose frame=''>0 0 0.016991 0 -0 0</pose>
        <mass>0.0264</mass>
        <inertia>
          <ixx>1.00244e-05</ixx>
          <ixy>1.25597e-06</ixy>
          <ixz>1.2936e-06</ixz>
          <iyy>8.97242e-06</iyy>
          <iyz>1.7622e-06</iyz>
          <izz>5.66925e-06</izz>
        </inertia>
      </inertial>
      
      <collision name='link_3_collision'>
        <pose frame=''>0 0 0.01335 0 -0 0</pose>
        <geometry>
          <box>
            <size>0.0196 0.0275 0.0267</size>
          </box>
        </geometry>
	    </collision>
      
      <collision name='link_3_tip_collision_1'>
        <pose frame=''>0 0 0.0267 0 -0 0</pose>
        <geometry>
          <sphere>
            <radius>0.012</radius>
          </sphere>
        </geometry>
      </collision>
      <visual name='link_3_visual'>
        <pose frame=''>0 0 0 0 -0 0</pose>
        <geometry>
          <mesh>
            <scale>1 1 1</scale>
            <uri>../meshes/link_3.0.obj</uri>
          </mesh>
        </geometry>
      </visual>
      <visual name='link_3_tip_visual_1'>
        <pose frame=''>0 0 0.0267 0 -0 0</pose>
        <geometry>
          <mesh>
            <scale>1 1 1</scale>
            <uri>../meshes/link_3.0_tip.obj</uri>
          </mesh>
        </geometry>
      </visual>
    </link>
    <joint name='joint_3' type='revolute'>
      <child>link_3</child>
      <parent>link_2</parent>
      <axis>
        <xyz>0 0.996195 -0.087156</xyz>
        <limit>
          <lower>-0.227</lower>
          <upper>1.618</upper>
          <effort>15</effort>
          <velocity>7</velocity>
        </limit>
        <dynamics>
          <damping>10e-3</damping>
          <friction>12</friction>
          <spring_reference>0</spring_reference>
          <spring_stiffness>0</spring_stiffness>
        </dynamics>
        <use_parent_model_frame>1</use_parent_model_frame>
      </axis>
    </joint>

    <link name='link_12'>
      <pose frame=''>-0.0182 0.019333 0.049013 3.14159 -1.48353 1.5708</pose>
      <inertial>
        <pose frame=''>0 0 0 0 -0 0</pose>
        <mass>0.0176</mass>
        <inertia>
          <ixx>1.89273e-05</ixx>
          <ixy>7.16716e-060</ixy>
          <ixz>5.35568e-060</ixz>
          <iyy>1.43008e-05</iyy>
          <iyz>6.8068e-060</iyz>
          <izz>1.89273e-05</izz>
        </inertia>
      </inertial>
      
      <collision name='link_12_collision'>
        <pose frame=''>-0.0179 0.009 0.0145 0 -0 0</pose>
        <geometry>
          <box>
            <size>0.0358 0.034 0.0455</size>
          </box>
        </geometry>
      </collision>
      <visual name='link_12_visual'>
        <pose frame=''>0 0 0 0 -0 0</pose>
        <geometry>
          <mesh>
            <scale>1 1 1</scale>
            <uri>../meshes/link_12.0_right.obj</uri>
          </mesh>
        </geometry>
      </visual>
    </link>
    <joint name='joint_12' type='revolute'>
      <child>link_12</child>
      <parent>hand_root</parent>
      <axis>
        <xyz>0 -0.087156 -0.996195</xyz>
        <limit>
          <lower>0.263</lower>
          <upper>1.396</upper>
          <effort>15</effort>
          <velocity>7</velocity>
        </limit>
        <dynamics>
          <damping>3e-3</damping>
          <friction>10</friction>
          <spring_reference>0</spring_reference>
          <spring_stiffness>0</spring_stiffness>
        </dynamics>
        <use_parent_model_frame>1</use_parent_model_frame>
      </axis>
    </joint>
    <link name='link_13'>
      <pose frame=''>-0.0132 0.056728 0.018638 3.14159 -1.48353 1.5708</pose>
      <inertial>
        <pose frame=''>0 0 0 0 -0 0</pose>
        <mass>0.0119</mass>
        <inertia>
          <ixx>4.24251e-06</ixx>
          <ixy>1.03209e-060</ixy>
          <ixz>1.60353e-060</ixz>
          <iyy>4.52363e-06</iyy>
          <iyz>1.44808e-060</iyz>
          <izz>4.24251e-06</izz>
        </inertia>
      </inertial>
      <collision name='link_13_collision'>
        <pose frame=''>0 0 0.00885 0 -0 0</pose>
        <geometry>
          <box>
            <size>0.0196 0.0275 0.0177</size>
          </box>
        </geometry>
      </collision>  
      <visual name='link_13_visual'>
        <pose frame=''>0 0 0 0 -0 0</pose>
        <geometry>
          <mesh>
            <scale>1 1 1</scale>
            <uri>../meshes/link_13.0.obj</uri>
          </mesh>
        </geometry>
      </visual>
    </link>
    <joint name='joint_13' type='revolute'>
      <child>link_13</child>
      <parent>link_12</parent>
      <axis>
        <xyz>-0 0.996195 -0.087156</xyz>
        <limit>
          <lower>-0.105</lower>
          <upper>1.163</upper>
          <effort>15</effort>
          <velocity>7</velocity>
        </limit>
        <dynamics>
          <damping>3e-3</damping>
          <friction>5</friction>
          <spring_reference>0</spring_reference>
          <spring_stiffness>0</spring_stiffness>
        </dynamics>
        <use_parent_model_frame>1</use_parent_model_frame>
      </axis>
    </joint>
   <link name='link_14'>
      <pose frame=''>-0.0132 0.074361 0.017096 3.14159 -1.48353 1.5708</pose>
      <inertial>
        <pose frame=''>0 0 0 0 -0 0</pose>
        <mass>0.038</mass>
        <inertia>
          <ixx>4.3044e-05</ixx>
          <ixy>9.57068e-060</ixy>
          <ixz>5.1205e-060</ixz>
          <iyy>1.44452e-05</iyy>
          <iyz>1.34282e-050</iyz>
          <izz>4.3044e-05</izz>
        </inertia>
      </inertial>
      
      <collision name='link_14_collision'>
        <pose frame=''>0 0 0.0257 0 -0 0</pose>
        <geometry>
          <box>
            <size>0.0196 0.0275 0.0514</size>
          </box>
        </geometry>
      </collision>
      <visual name='link_14_visual'>
        <pose frame=''>0 0 0 0 -0 0</pose>
        <geometry>
          <mesh>
            <scale>1 1 1</scale>
            <uri>../meshes/link_14.0.obj</uri>
          </mesh>
        </geometry>
      </visual>
    </link>
    <joint name='joint_14' type='revolute'>
      <child>link_14</child>
      <parent>link_13</parent>
      <axis>
        <xyz>1 0 0</xyz>
        <limit>
          <lower>-0.189</lower>
          <upper>1.644</upper>
          <effort>15</effort>
          <velocity>7</velocity>
        </limit>
        <dynamics>
          <damping>3e-3</damping>
          <friction>10</friction>
          <spring_reference>0</spring_reference>
          <spring_stiffness>0</spring_stiffness>
        </dynamics>
        <use_parent_model_frame>1</use_parent_model_frame>
      </axis>
    </joint>
    <link name='link_15'>
      <pose frame=''>-0.0132 0.125565 0.012616 3.14159 -1.48353 1.5708</pose>
      <inertial>
        <pose frame=''>0 0 0.012781 0 -0 0</pose>
        <mass>0.0556</mass>
        <inertia>
          <ixx>5.48675e-05</ixx>
          <ixy>8.04208e-06</ixy>
          <ixz>5.2283e-06</ixz>
          <iyy>3.66945e-05</iyy>
          <iyz>1.12835e-05</iyz>
          <izz>3.38903e-05</izz>
        </inertia>
      </inertial>
      
      <collision name='link_15_collision'>
        <pose frame=''>0 0 0.02115 0 -0 0</pose>
        <geometry>
          <box>
            <size>0.0196 0.0275 0.0423</size>
          </box>
        </geometry>
	   </collision>
      
      <collision name='link_15_tip_collision_1'>
        <pose frame=''>0 0 0.0423 0 -0 0</pose>
        <geometry>
          <sphere>
            <radius>0.012</radius>
          </sphere>
        </geometry>
      </collision>
      <visual name='link_15_visual'>
        <pose frame=''>0 0 0 0 -0 0</pose>
        <geometry>
          <mesh>
            <scale>1 1 1</scale>
            <uri>../meshes/link_15.0.obj</uri>
          </mesh>
        </geometry>
      </visual>
      <visual name='link_15_tip_visual_1'>
        <pose frame=''>0 0 0.0423 0 -0 0</pose>
        <geometry>
          <mesh>
            <scale>1 1 1</scale>
            <uri>../meshes/link_15.0_tip.obj</uri>
          </mesh>
        </geometry>
      </visual>
    </link>
    <joint name='joint_15' type='revolute'>
      <child>link_15</child>
      <parent>link_14</parent>
      <axis>
        <xyz>1 0 0</xyz>
        <limit>
          <lower>-0.162</lower>
          <upper>1.719</upper>
          <effort>15</effort>
          <velocity>7</velocity>
        </limit>
        <dynamics>
          <damping>3e-3</damping>
          <friction>12</friction>
          <spring_reference>0</spring_reference>
          <spring_stiffness>0</spring_stiffness>
        </dynamics>
        <use_parent_model_frame>1</use_parent_model_frame>
      </axis>
    </joint>

    <link name='link_4'>
      <pose frame=''>0 0 0.0957 0 -0 0</pose>
      <inertial>
        <pose frame=''>0 0 0 0 -0 0</pose>
        <mass>0.0119</mass>
        <inertia>
          <ixx>1.01667e-06</ixx>
          <ixy>0</ixy>
          <ixz>0</ixz>
          <iyy>6.47677e-07</iyy>
          <iyz>0</iyz>
          <izz>1.01667e-06</izz>
        </inertia>
      </inertial>
      <collision name='link_4_collision'>
        <pose frame=''>0 0 0.0082 0 -0 0</pose>
        <geometry>
          <box>
            <size>0.0196 0.0275 0.0164</size>
          </box>
        </geometry>
      </collision>  
      <visual name='link_4_visual'>
        <pose frame=''>0 0 0 0 -0 0</pose>
        <geometry>
          <mesh>
            <scale>1 1 1</scale>
            <uri>../meshes/link_0.0.obj</uri>
          </mesh>
        </geometry>
      </visual>
    </link>
    <joint name='joint_4' type='revolute'>
      <child>link_4</child>
      <parent>hand_root</parent>
      <axis>
        <xyz>0 0 1</xyz>
        <limit>
          <lower>-0.47</lower>
          <upper>0.47</upper>
          <effort>15</effort>
          <velocity>7</velocity>
        </limit>
        <dynamics>
          <damping>3e-3</damping>
          <friction>10</friction>
          <spring_reference>0</spring_reference>
          <spring_stiffness>0</spring_stiffness>
        </dynamics>
        <use_parent_model_frame>1</use_parent_model_frame>
      </axis>
    </joint>
    <link name='link_5'>
      <pose frame=''>0 0 0.1121 0 -0 0</pose>
      <inertial>
        <pose frame=''>0 0 0 0 -0 0</pose>
        <mass>0.065</mass>
        <inertia>
          <ixx>7.95654e-05</ixx>
          <ixy>1.7199e-050</ixy>
          <ixz>8.75875e-060</ixz>
          <iyy>2.47089e-05</iyy>
          <iyz>2.41313e-050</iyz>
          <izz>7.95654e-05</izz>
        </inertia>
      </inertial>
      
      <collision name='link_5_collision'>
        <pose frame=''>0 0 0.027 0 -0 0</pose>
        <geometry>
          <box>
            <size>0.0196 0.0275 0.054</size>
          </box>
        </geometry>
      </collision>
      <visual name='link_5_visual'>
        <pose frame=''>0 0 0 0 -0 0</pose>
        <geometry>
          <mesh>
            <scale>1 1 1</scale>
            <uri>../meshes/link_1.0.obj</uri>
          </mesh>
        </geometry>
      </visual>
    </link>
    <joint name='joint_5' type='revolute'>
      <child>link_5</child>
      <parent>link_4</parent>
      <axis>
        <xyz>0 1 0</xyz>
        <limit>
          <lower>-0.196</lower>
          <upper>1.61</upper>
          <effort>15</effort>
          <velocity>7</velocity>
        </limit>
        <dynamics>
          <damping>3e-3</damping>
          <friction>5</friction>
          <spring_reference>0</spring_reference>
          <spring_stiffness>0</spring_stiffness>
        </dynamics>
        <use_parent_model_frame>1</use_parent_model_frame>
      </axis>
    </joint>


  <link name='link_6'>
      <pose frame=''>0 0 0.1661 0 -0 0</pose>
      <inertial>
        <pose frame=''>0 0 0 0 -0 0</pose>
        <mass>0.0355</mass>
        <inertia>
          <ixx>2.63979e-05</ixx>
          <ixy>6.67968e-060</ixy>
          <ixz>4.78363e-060</ixz>
          <iyy>1.34949e-05</iyy>
          <iyz>9.372e-060</iyz>
          <izz>2.63979e-05</izz>
        </inertia>
      </inertial>
      <collision name='link_6_collision'>
        <pose frame=''>0 0 0.0192 0 -0 0</pose>
        <geometry>
          <box>
            <size>0.0196 0.0275 0.0384</size>
          </box>
        </geometry>
      </collision>
      <visual name='link_6_visual'>
        <pose frame=''>0 0 0 0 -0 0</pose>
        <geometry>
          <mesh>
            <scale>1 1 1</scale>
            <uri>../meshes/link_2.0.obj</uri>
          </mesh>
        </geometry>
      </visual>
    </link>
    <joint name='joint_6' type='revolute'>
      <child>link_6</child>
      <parent>link_5</parent>
      <axis>
        <xyz>0 1 0</xyz>
        <limit>
          <lower>-0.174</lower>
          <upper>1.709</upper>
          <effort>15</effort>
          <velocity>7</velocity>
        </limit>
        <dynamics>
          <damping>8e-3</damping>
          <friction>10</friction>
          <spring_reference>0</spring_reference>
          <spring_stiffness>0</spring_stiffness>
        </dynamics>
        <use_parent_model_frame>1</use_parent_model_frame>
      </axis>
    </joint>


        
    <link name='link_7'>
      <pose frame=''>0 0 0.2045 0 -0 0</pose>
      <inertial>
        <pose frame=''>0 0 0.016991 0 -0 0</pose>
        <mass>0.0264</mass>
        <inertia>
          <ixx>1.00244e-05</ixx>
          <ixy>1.25597e-06</ixy>
          <ixz>1.2936e-06</ixz>
          <iyy>8.97242e-06</iyy>
          <iyz>1.7622e-06</iyz>
          <izz>5.66925e-06</izz>
        </inertia>
      </inertial>
      
      <collision name='link_7_collision'>
        <pose frame=''>0 0 0.01335 0 -0 0</pose>
        <geometry>
          <box>
            <size>0.0196 0.0275 0.0267</size>
          </box>
        </geometry>
	   </collision>
      
      <collision name='link_7_tip_collision_1'>
        <pose frame=''>0 0 0.0267 0 -0 0</pose>
        <geometry>
          <sphere>
            <radius>0.012</radius>
          </sphere>
        </geometry>
      </collision>
      <visual name='link_7_visual'>
        <pose frame=''>0 0 0 0 -0 0</pose>
        <geometry>
          <mesh>
            <scale>1 1 1</scale>
            <uri>../meshes/link_3.0.obj</uri>
          </mesh>
        </geometry>
      </visual>
      <visual name='link_7_tip_visual_1'>
        <pose frame=''>0 0 0.0267 0 -0 0</pose>
        <geometry>
          <mesh>
            <scale>1 1 1</scale>
            <uri>../meshes/link_3.0_tip.obj</uri>
          </mesh>
        </geometry>
      </visual>
    </link>
    <joint name='joint_7' type='revolute'>
      <child>link_7</child>
      <parent>link_6</parent>
      <axis>
        <xyz>0 1 0</xyz>
        <limit>
          <lower>-0.227</lower>
          <upper>1.618</upper>
          <effort>15</effort>
          <velocity>7</velocity>
        </limit>
        <dynamics>
          <damping>10e-3</damping>
          <friction>12</friction>
          <spring_reference>0</spring_reference>
          <spring_stiffness>0</spring_stiffness>
        </dynamics>
        <use_parent_model_frame>1</use_parent_model_frame>
      </axis>
    </joint>

    <link name='link_8'>
      <pose frame=''>0 -0.0435 0.093458 0.087267 -0 0</pose>
      <inertial>
        <pose frame=''>0 0 0 0 -0 0</pose>
        <mass>0.0119</mass>
        <inertia>
          <ixx>1.01667e-06</ixx>
          <ixy>0</ixy>
          <ixz>0</ixz>
          <iyy>6.47677e-07</iyy>
          <iyz>0</iyz>
          <izz>1.01667e-06</izz>
        </inertia>
      </inertial>
      <collision name='link_8_collision'>
        <pose frame=''>0 0 0.0082 0 -0 0</pose>
        <geometry>
          <box>
            <size>0.0196 0.0275 0.0164</size>
          </box>
        </geometry>
      </collision>   
      <visual name='link_8_visual'>
        <pose frame=''>0 0 0 0 -0 0</pose>
        <geometry>
          <mesh>
            <scale>1 1 1</scale>
            <uri>../meshes/link_0.0.obj</uri>
          </mesh>
        </geometry>
      </visual>
    </link>
    <joint name='joint_8' type='revolute'>
      <child>link_8</child>
      <parent>hand_root</parent>
      <axis>
        <xyz>0 -0.087156 0.996195</xyz>
        <limit>
          <lower>-0.47</lower>
          <upper>0.47</upper>
          <effort>15</effort>
          <velocity>7</velocity>
        </limit>
        <dynamics>
          <damping>3e-3</damping>
          <friction>10</friction>
          <spring_reference>0</spring_reference>
          <spring_stiffness>0</spring_stiffness>
        </dynamics>
        <use_parent_model_frame>1</use_parent_model_frame>
      </axis>
    </joint>

   <link name='link_9'>
      <pose frame=''>0 -0.044929 0.109796 0.087267 -0 0</pose>
      <inertial>
        <pose frame=''>0 0 0 0 -0 0</pose>
        <mass>0.065</mass>
        <inertia>
          <ixx>7.95654e-05</ixx>
          <ixy>1.7199e-050</ixy>
          <ixz>8.75875e-060</ixz>
          <iyy>2.47089e-05</iyy>
          <iyz>2.41313e-050</iyz>
          <izz>7.95654e-05</izz>
        </inertia>
      </inertial>
      
      <collision name='link_9_collision'>
        <pose frame=''>0 0 0.027 0 -0 0</pose>
        <geometry>
          <box>
            <size>0.0196 0.0275 0.054</size>
          </box>
        </geometry>
      </collision>
      <visual name='link_9_visual'>
        <pose frame=''>0 0 0 0 -0 0</pose>
        <geometry>
          <mesh>
            <scale>1 1 1</scale>
            <uri>../meshes/link_1.0.obj</uri>
          </mesh>
        </geometry>
      </visual>
    </link>
    <joint name='joint_9' type='revolute'>
      <child>link_9</child>
      <parent>link_8</parent>
      <axis>
        <xyz>0 0.996195 0.087156</xyz>
        <limit>
          <lower>-0.196</lower>
          <upper>1.61</upper>
          <effort>15</effort>
          <velocity>7</velocity>
        </limit>
        <dynamics>
          <damping>3e-3</damping>
          <friction>5</friction>
          <spring_reference>0</spring_reference>
          <spring_stiffness>0</spring_stiffness>
        </dynamics>
        <use_parent_model_frame>1</use_parent_model_frame>
      </axis>
    </joint>
    <link name='link_10'>
      <pose frame=''>0 -0.049636 0.16359 0.087267 -0 0</pose>
      <inertial>
        <pose frame=''>0 0 0 0 -0 0</pose>
        <mass>0.0355</mass>
        <inertia>
          <ixx>2.63979e-05</ixx>
          <ixy>6.67968e-060</ixy>
          <ixz>4.78363e-060</ixz>
          <iyy>1.34949e-05</iyy>
          <iyz>9.372e-060</iyz>
          <izz>2.63979e-05</izz>
        </inertia>
      </inertial>
      
      <collision name='link_10_collision'>
        <pose frame=''>0 0 0.0192 0 -0 0</pose>
        <geometry>
          <box>
            <size>0.0196 0.0275 0.0384</size>
          </box>
        </geometry>
      </collision>
      <visual name='link_10_visual'>
        <pose frame=''>0 0 0 0 -0 0</pose>
        <geometry>
          <mesh>
            <scale>1 1 1</scale>
            <uri>../meshes/link_2.0.obj</uri>
          </mesh>
        </geometry>
      </visual>
    </link>
    <joint name='joint_10' type='revolute'>
      <child>link_10</child>
      <parent>link_9</parent>
      <axis>
        <xyz>0 0.996195 0.087156</xyz>
        <limit>
          <lower>-0.174</lower>
          <upper>1.709</upper>
          <effort>15</effort>
          <velocity>7</velocity>
        </limit>
        <dynamics>
          <damping>8e-3</damping>
          <friction>10</friction>
          <spring_reference>0</spring_reference>
          <spring_stiffness>0</spring_stiffness>
        </dynamics>
        <use_parent_model_frame>1</use_parent_model_frame>
      </axis>
    </joint>
    <link name='link_11'>
      <pose frame=''>0 -0.052983 0.201844 0.087267 -0 0</pose>
      <inertial>
        <pose frame=''>0 0 0.016991 0 -0 0</pose>
        <mass>0.0264</mass>
        <inertia>
          <ixx>1.00244e-05</ixx>
          <ixy>1.25597e-06</ixy>
          <ixz>1.2936e-06</ixz>
          <iyy>8.97242e-06</iyy>
          <iyz>1.7622e-06</iyz>
          <izz>5.66925e-06</izz>
        </inertia>
      </inertial>
      
      <collision name='link_11_collision'>
        <pose frame=''>0 0 0.01335 0 -0 0</pose>
        <geometry>
          <box>
            <size>0.0196 0.0275 0.0267</size>
          </box>
        </geometry>
	    </collision>
      
      <collision name='link_11_tip_collision_1'>
        <pose frame=''>0 0 0.0267 0 -0 0</pose>
        <geometry>
          <sphere>
            <radius>0.012</radius>
          </sphere>
        </geometry>
      </collision>
      <visual name='link_11_visual'>
        <pose frame=''>0 0 0 0 -0 0</pose>
        <geometry>
          <mesh>
            <scale>1 1 1</scale>
            <uri>../meshes/link_3.0.obj</uri>
          </mesh>
        </geometry>
      </visual>
      <visual name='link_11_tip_visual_1'>
        <pose frame=''>0 0 0.0267 0 -0 0</pose>
        <geometry>
          <mesh>
            <scale>1 1 1</scale>
            <uri>../meshes/link_3.0_tip.obj</uri>
          </mesh>
        </geometry>
      </visual>
    </link>
    <joint name='joint_11' type='revolute'>
      <child>link_11</child>
      <parent>link_10</parent>
      <axis>
        <xyz>0 0.996195 0.087156</xyz>
        <limit>
          <lower>-0.227</lower>
          <upper>1.618</upper>
          <effort>15</effort>
          <velocity>7</velocity>
        </limit>
        <dynamics>
          <damping>10e-3</damping>
          <friction>12</friction>
          <spring_reference>0</spring_reference>
          <spring_stiffness>0</spring_stiffness>
        </dynamics>
        <use_parent_model_frame>1</use_parent_model_frame>
      </axis>
    </joint>
  </model>
</sdf>
