<sdf version='1.6'>
  <model name='acrobot'>
    <!-- This sdf file produces a model with the default parameters documented
         in AcrobotParameters in make_acrobot_plant.h.
         They MUST be kept in sync. -->
    <link name='Cart'>
      <pose>0 0 0 0 0 0</pose>
      <inertial>
        <mass>10.0</mass>
	<!-- For this model case, with the cart not having any rotational
	     degrees of freedom, the values of the inertia matrix do not
	     participate in the model. Therefore we just set them to zero.
	-->
        <inertia>
	  <ixx>1.0e-20</ixx><iyy>1.0e-20</iyy><izz>1.0e-20</izz>
          <ixy>0</ixy><ixz>0</ixz><iyz>0</iyz>
        </inertia>
      </inertial>
    </link>
    <link name='Pole'>
      <!-- The pole is modeled as a point mass at the end of the pole. -->
      <!-- The length of the pole is 0.5 meters. -->
      <pose>0 0 -0.5 0 0 0</pose>
      <inertial>
        <mass>1.0</mass>
	<!-- A point mass has zero rotational inertia.
	     We must specify small values since otherwise sdformat throws an exception. -->
        <inertia>
          <ixx>1.0e-20</ixx><iyy>1.0e-20</iyy><izz>1.0e-20</izz>
          <ixy>0</ixy><ixz>0</ixz><iyz>0</iyz>
        </inertia>
      </inertial>
    </link>
    <joint name='CartSlider' type='prismatic'>
      <parent>world</parent>
      <child>Cart</child>
      <axis>
        <xyz>1.0 0.0 0.0</xyz>
      </axis>
    </joint>
    <joint name='PolePin' type='revolute'>
      <pose>0 0 0 0 0 0</pose>
      <parent>Cart</parent>
      <child>Pole</child>
      <axis>
        <xyz>0.0 -1.0 0.0</xyz>
      </axis>
    </joint>
  </model>
</sdf>
