<?xml version="1.0"?>
<robot xmlns:xacro="http://ros.org/wiki/xacro" name="s-model_articulated">
  <parameter name="spring_stiffness" value="1"/>
  <link name="finger_1_link_0">
    <visual>
      <origin rpy="0 0 0" xyz="0.020 0 0"/>
      <geometry>
        <mesh filename="package://drake/examples/atlas/urdf/meshes/s-model_articulated/visual/link_0.STL"/>
      </geometry>
      <material name="black">
        <color rgba=".2 .2 .2 1"/>
      </material>
    </visual>
    <inertial>
      <origin rpy="0 0 0" xyz="0 0 0"/>
      <mass value="0.05"/>
      <inertia ixx="0.01" ixy="-0.00002" ixz="0.00001" iyy="0.0008" iyz="0" izz="0.001"/>
    </inertial>
  </link>
  <link name="finger_1_link_1">
    <visual>
      <origin rpy="0 0 -0.52" xyz="0.050 -.028 0"/>
      <geometry>
        <mesh filename="package://drake/examples/atlas/urdf/meshes/s-model_articulated/visual/link_1.STL"/>
      </geometry>
      <material name="black"/>
    </visual>
    <collision>
      <origin rpy="0 0 -0.52" xyz="0.03 -0.0145 0"/>
      <geometry>
        <box size=".028 .01 .03"/>
      </geometry>
      <material name="yellow">
        <color rgba="0 1 1 1"/>
      </material>
    </collision>
    <inertial>
      <origin rpy="0 0 0" xyz="0 0 0"/>
      <mass value="0.15"/>
      <inertia ixx="0.001859" ixy="-0.000376" ixz="0.000028" iyy="0.012756" iyz="0" izz="0.0024"/>
    </inertial>
  </link>
  <link name="finger_1_link_2">
    <!--
      NOTE: This link has an offset in the z-direction based on the models that were
      used to generate grap-it poses.  With the offset below the model appears visually
      correct, but it is suspect.
      -->
    <visual>
      <origin rpy="0 0 0" xyz="0.039 0 0.0075"/>
      <geometry>
        <mesh filename="package://drake/examples/atlas/urdf/meshes/s-model_articulated/visual/link_2.STL"/>
      </geometry>
      <material name="black"/>
    </visual>
    <collision>
      <origin rpy="0 0 0" xyz="0.02 0.0025 -0.0005"/>
      <geometry>
        <box size=".018 .01 .03"/>
      </geometry>
      <material name="yellow"/>
    </collision>
    <inertial>
      <origin rpy="0 0 0" xyz="0 0 0"/>
      <mass value="0.15"/>
      <inertia ixx="0.001859" ixy="-0.000376" ixz="0.000028" iyy="0.012756" iyz="0" izz="0.0024"/>
    </inertial>
  </link>
  <link name="finger_1_link_3">
    <visual>
      <origin rpy="0 0 0.52" xyz="0 0 0"/>
      <geometry>
        <mesh filename="package://drake/examples/atlas/urdf/meshes/s-model_articulated/visual/link_3.STL"/>
      </geometry>
      <material name="black"/>
    </visual>
    <collision>
      <origin rpy="0 0 .52" xyz="0.02 0.015 0"/>
      <geometry>
        <box size=".025 .01 .03"/>
      </geometry>
      <material name="yellow"/>
    </collision>
    <inertial>
      <origin rpy="0 0 0" xyz="0 0 0"/>
      <mass value="0.05"/>
      <inertia ixx="0.001239" ixy="-0.000251" ixz="0.000019" iyy="0.00085" iyz="0" izz="0.001632"/>
    </inertial>
  </link>
  <joint name="finger_1_joint_0" type="continuous">
    <parent link="finger_1_link_0"/>
    <child link="finger_1_link_1"/>
    <axis xyz="0 0 1"/>
    <origin rpy="0 0 0" xyz="0.020 0 0"/>
    <!-- <limit effort="100" lower="0" upper="1.055"/> -->
    <dynamics friction="0.0" damping="0.1"/>
  </joint>
  <joint name="finger_1_joint_1" type="continuous">
    <parent link="finger_1_link_1"/>
    <child link="finger_1_link_2"/>
    <axis xyz="0 0 1"/>
    <origin rpy="0 0 -0.52" xyz="0.050 -.028 0"/>
    <!-- <limit effort="100" lower="0" upper="1.5708" /> -->
    <dynamics friction="0.0" damping="0.1"/>
  </joint>
  <joint name="finger_1_joint_2" type="continuous">
    <parent link="finger_1_link_2"/>
    <child link="finger_1_link_3"/>
    <axis xyz="0 0 1"/>
    <origin rpy="0 0 0" xyz="0.039 0 0"/>
    <!-- <limit effort="100" lower="-0.7854" upper="3.1416" /> -->
    <dynamics friction="0.0" damping="0.1"/>
  </joint>
  <link name="finger_2_link_0">
    <visual>
      <origin rpy="0 0 0" xyz="0.020 0 0"/>
      <geometry>
        <mesh filename="package://drake/examples/atlas/urdf/meshes/s-model_articulated/visual/link_0.STL"/>
      </geometry>
      <material name="black">
        <color rgba=".2 .2 .2 1"/>
      </material>
    </visual>
    <inertial>
      <origin rpy="0 0 0" xyz="0 0 0"/>
      <mass value="0.05"/>
      <inertia ixx="0.01" ixy="-0.00002" ixz="0.00001" iyy="0.0008" iyz="0" izz="0.001"/>
    </inertial>
  </link>
  <link name="finger_2_link_1">
    <visual>
      <origin rpy="0 0 -0.52" xyz="0.050 -.028 0"/>
      <geometry>
        <mesh filename="package://drake/examples/atlas/urdf/meshes/s-model_articulated/visual/link_1.STL"/>
      </geometry>
      <material name="black"/>
    </visual>
    <collision>
      <origin rpy="0 0 -0.52" xyz="0.03 -0.0145 0"/>
      <geometry>
        <box size=".028 .01 .03"/>
      </geometry>
      <material name="yellow"/>
    </collision>
    <inertial>
      <origin rpy="0 0 0" xyz="0 0 0"/>
      <mass value="0.15"/>
      <inertia ixx="0.001859" ixy="-0.000376" ixz="0.000028" iyy="0.012756" iyz="0" izz="0.0024"/>
    </inertial>
  </link>
  <link name="finger_2_link_2">
    <!--
      NOTE: This link has an offset in the z-direction based on the models that were
      used to generate grap-it poses.  With the offset below the model appears visually
      correct, but it is suspect.
      -->
    <visual>
      <origin rpy="0 0 0" xyz="0.039 0 0.0075"/>
      <geometry>
        <mesh filename="package://drake/examples/atlas/urdf/meshes/s-model_articulated/visual/link_2.STL"/>
      </geometry>
      <material name="black"/>
    </visual>
    <collision>
      <origin rpy="0 0 0" xyz="0.02 0.0025 -0.0005"/>
      <geometry>
        <box size=".018 .01 .03"/>
      </geometry>
      <material name="yellow"/>
    </collision>
    <inertial>
      <origin rpy="0 0 0" xyz="0 0 0"/>
      <mass value="0.15"/>
      <inertia ixx="0.001859" ixy="-0.000376" ixz="0.000028" iyy="0.012756" iyz="0" izz="0.0024"/>
    </inertial>
  </link>
  <link name="finger_2_link_3">
    <visual>
      <origin rpy="0 0 0.52" xyz="0 0 0"/>
      <geometry>
        <mesh filename="package://drake/examples/atlas/urdf/meshes/s-model_articulated/visual/link_3.STL"/>
      </geometry>
      <material name="black"/>
    </visual>
    <collision>
      <origin rpy="0 0 .52" xyz="0.02 0.015 0"/>
      <geometry>
        <box size=".025 .01 .03"/>
      </geometry>
      <material name="yellow"/>
    </collision>
    <inertial>
      <origin rpy="0 0 0" xyz="0 0 0"/>
      <mass value="0.05"/>
      <inertia ixx="0.001239" ixy="-0.000251" ixz="0.000019" iyy="0.00085" iyz="0" izz="0.001632"/>
    </inertial>
  </link>
  <joint name="finger_2_joint_0" type="continuous">
    <parent link="finger_2_link_0"/>
    <child link="finger_2_link_1"/>
    <axis xyz="0 0 1"/>
    <origin rpy="0 0 0" xyz="0.020 0 0"/>
    <!-- <limit effort="100" lower="0" upper="1.055" /> -->
    <dynamics friction="0.0" damping="0.1"/>
  </joint>
  <joint name="finger_2_joint_1" type="continuous">
    <parent link="finger_2_link_1"/>
    <child link="finger_2_link_2"/>
    <axis xyz="0 0 1"/>
    <origin rpy="0 0 -0.52" xyz="0.050 -.028 0"/>
    <!-- <limit effort="100" lower="0" upper="1.5708" /> -->
    <dynamics friction="0.0" damping="0.1"/>
  </joint>
  <joint name="finger_2_joint_2" type="continuous">
    <parent link="finger_2_link_2"/>
    <child link="finger_2_link_3"/>
    <axis xyz="0 0 1"/>
    <origin rpy="0 0 0" xyz="0.039 0 0"/>
    <!-- <limit effort="100" lower="-0.7854" upper="3.1416" /> -->
    <dynamics friction="0.0" damping="0.1"/>
  </joint>
  <link name="finger_middle_link_0">
    <visual>
      <origin rpy="0 0 0" xyz="0.020 0 0"/>
      <geometry>
        <mesh filename="package://drake/examples/atlas/urdf/meshes/s-model_articulated/visual/link_0.STL"/>
      </geometry>
      <material name="black">
        <color rgba=".2 .2 .2 1"/>
      </material>
    </visual>
    <!--<collision>
        <origin xyz="-0.0455 0.0414 0.036" rpy="0 3.1416 -1.57"/>
        <geometry>
          <mesh filename="package://drake/examples/atlas/urdf/meshes/s-model_articulated/collision/link_0.STL" />
        </geometry>
        <material name="yellow">
          <color rgba="0 1 1 1"/>
        </material>
      </collision>-->
    <inertial>
      <origin rpy="0 0 0" xyz="0 0 0"/>
      <mass value="0.05"/>
      <inertia ixx="0.01" ixy="-0.00002" ixz="0.00001" iyy="0.0008" iyz="0" izz="0.001"/>
    </inertial>
  </link>
  <link name="finger_middle_link_1">
    <visual>
      <origin rpy="0 0 -0.52" xyz="0.050 -.028 0"/>
      <geometry>
        <mesh filename="package://drake/examples/atlas/urdf/meshes/s-model_articulated/visual/link_1.STL"/>
      </geometry>
      <material name="black"/>
    </visual>
    <collision>
      <origin rpy="0 0 -0.52" xyz="0.03 -0.0145 0"/>
      <geometry>
        <box size=".028 .01 .03"/>
      </geometry>
      <material name="yellow"/>
    </collision>
    <inertial>
      <origin rpy="0 0 0" xyz="0 0 0"/>
      <mass value="0.15"/>
      <inertia ixx="0.001859" ixy="-0.000376" ixz="0.000028" iyy="0.012756" iyz="0" izz="0.0024"/>
    </inertial>
  </link>
  <link name="finger_middle_link_2">
    <!--
      NOTE: This link has an offset in the z-direction based on the models that were
      used to generate grap-it poses.  With the offset below the model appears visually
      correct, but it is suspect.
      -->
    <visual>
      <origin rpy="0 0 0" xyz="0.039 0 0.0075"/>
      <geometry>
        <mesh filename="package://drake/examples/atlas/urdf/meshes/s-model_articulated/visual/link_2.STL"/>
      </geometry>
      <material name="black"/>
    </visual>
    <collision>
      <origin rpy="0 0 0" xyz="0.02 0.0025 -0.0005"/>
      <geometry>
        <box size=".018 .01 .03"/>
      </geometry>
      <material name="yellow"/>
    </collision>
    <inertial>
      <origin rpy="0 0 0" xyz="0 0 0"/>
      <mass value="0.15"/>
      <inertia ixx="0.001859" ixy="-0.000376" ixz="0.000028" iyy="0.012756" iyz="0" izz="0.0024"/>
    </inertial>
  </link>
  <link name="finger_middle_link_3">
    <visual>
      <origin rpy="0 0 0.52" xyz="0 0 0"/>
      <geometry>
        <mesh filename="package://drake/examples/atlas/urdf/meshes/s-model_articulated/visual/link_3.STL"/>
      </geometry>
      <material name="black"/>
    </visual>
    <collision>
      <origin rpy="0 0 .52" xyz="0.02 0.015 0"/>
      <geometry>
        <box size=".025 .01 .03"/>
      </geometry>
      <material name="yellow"/>
    </collision>
    <inertial>
      <origin rpy="0 0 0" xyz="0 0 0"/>
      <mass value="0.05"/>
      <inertia ixx="0.001239" ixy="-0.000251" ixz="0.000019" iyy="0.00085" iyz="0" izz="0.001632"/>
    </inertial>
  </link>
  <joint name="finger_middle_joint_0" type="continuous">
    <parent link="finger_middle_link_0"/>
    <child link="finger_middle_link_1"/>
    <axis xyz="0 0 1"/>
    <origin rpy="0 0 0" xyz="0.020 0 0"/>
    <!-- <limit effort="100" lower="0" upper="1.055" /> -->
    <dynamics friction="0.0" damping="0.1"/>
  </joint>
  <joint name="finger_middle_joint_1" type="continuous">
    <parent link="finger_middle_link_1"/>
    <child link="finger_middle_link_2"/>
    <axis xyz="0 0 1"/>
    <origin rpy="0 0 -0.52" xyz="0.050 -.028 0"/>
    <!-- <limit effort="100" lower="0" upper="1.5708" /> -->
    <dynamics friction="0.0" damping="0.1"/>
  </joint>
  <joint name="finger_middle_joint_2" type="continuous">
    <parent link="finger_middle_link_2"/>
    <child link="finger_middle_link_3"/>
    <axis xyz="0 0 1"/>
    <origin rpy="0 0 0" xyz="0.039 0 0"/>
    <!-- <limit effort="100" lower="-0.7854" upper="3.1416" /> -->
    <dynamics friction="0.0" damping="0.1"/>
  </joint>
  <force_element name="finger1_joint_0_spring">
    <torsional_spring stiffness="$spring_stiffness">
      <joint name="finger_1_joint_0"/>
    </torsional_spring>
  </force_element>
  <force_element name="finger1_joint_1_spring">
    <torsional_spring stiffness="$spring_stiffness">
      <joint name="finger_1_joint_1"/>
    </torsional_spring>
  </force_element>
  <force_element name="finger1_joint_2_spring">
    <torsional_spring stiffness="$spring_stiffness">
      <joint name="finger_1_joint_2"/>
    </torsional_spring>
  </force_element>
  <force_element name="finger2_joint_0_spring">
    <torsional_spring stiffness="$spring_stiffness">
      <joint name="finger_2_joint_0"/>
    </torsional_spring>
  </force_element>
  <force_element name="finger2_joint_1_spring">
    <torsional_spring stiffness="$spring_stiffness">
      <joint name="finger_2_joint_1"/>
    </torsional_spring>
  </force_element>
  <force_element name="finger2_joint_2_spring">
    <torsional_spring stiffness="$spring_stiffness">
      <joint name="finger_2_joint_2"/>
    </torsional_spring>
  </force_element>
  <force_element name="finger_middle_joint_0_spring">
    <torsional_spring stiffness="$spring_stiffness">
      <joint name="finger_middle_joint_0"/>
    </torsional_spring>
  </force_element>
  <force_element name="finger_middle_joint_1_spring">
    <torsional_spring stiffness="$spring_stiffness">
      <joint name="finger_middle_joint_1"/>
    </torsional_spring>
  </force_element>
  <force_element name="finger_middle_joint_2_spring">
    <torsional_spring stiffness="$spring_stiffness">
      <joint name="finger_middle_joint_2"/>
    </torsional_spring>
  </force_element>
  <link name="palm">
    <visual>
      <geometry>
        <mesh filename="package://drake/examples/atlas/urdf/meshes/s-model_articulated/visual/palm.STL"/>
      </geometry>
      <material name="black">
        <color rgba=".2 .2 .2 1"/>
      </material>
    </visual>
    <collision>
      <origin rpy="0 0 0" xyz="0 .046 0"/>
      <geometry>
        <box size=".1 .01 .1"/>
      </geometry>
      <material name="yellow">
        <color rgba="0 1 1 1"/>
      </material>
    </collision>
  </link>
  <inertial>
    <origin rpy="0 0 0" xyz="0 0 0"/>
    <mass value="1.3"/>
    <inertia ixx="0.006012" ixy="0.000079" ixz="-0.00024" iyy="0.012892" iyz="0" izz="0.002435"/>
  </inertial>
  <joint name="palm_finger_1_joint" type="fixed">
    <parent link="palm"/>
    <child link="finger_1_link_0"/>
    <axis xyz="0 1 0"/>
    <origin rpy="0 3.1416 -1.57" xyz="-0.0455 0.0214 0.036"/>
    <!--<limit lower="-0.16" upper="0.25" effort="100" />-->
  </joint>
  <joint name="palm_finger_2_joint" type="fixed">
    <parent link="palm"/>
    <child link="finger_2_link_0"/>
    <axis xyz="0 1 0"/>
    <origin rpy="0 3.1416 -1.57" xyz="-0.0455 0.0214 -0.036"/>
    <!--<limit lower="-0.25" upper="0.16" effort="100" />-->
  </joint>
  <joint name="palm_finger_middle_joint" type="fixed">
    <parent link="palm"/>
    <child link="finger_middle_link_0"/>
    <axis xyz="0 0 1"/>
    <origin rpy="0 0 1.57" xyz="0.0455 0.0214 0"/>
  </joint>
  <link name="finger_tensioner">
    <inertial>
      <mass value="0.1"/>
      <inertia ixx="0.01" ixy="0.01" ixz="0.01" iyy="0.01" iyz="0.01" izz="0.01"/>
    </inertial>
    <visual>
      <material name="orange"/>
      <origin xyz="0 0.0 0" rpy="0 0 0"/>
      <geometry>
        <sphere radius="0.01"/>
      </geometry>
    </visual>
  </link>
  <joint name="finger_tensioner" type="prismatic">
    <origin xyz="0 0 0"/>
    <axis xyz="0 1 0"/>
    <parent link="palm"/>
    <child link="finger_tensioner"/>
    <limit lower="-0.02" upper="0.1"/>
  </joint>
  <cable name="finger1_cable" min_length="0.1" max_length="0.1">
    <terminator link="finger_1_link_3" xyz="0 0 0"/>
    <!-- <pulley link="finger_1_link_2" xyz="0 0 0" radius="0"/>  -->
    <terminator link="finger_tensioner" xyz="0 0 0"/>
  </cable>
  <cable name="finger2_cable" min_length="0.1" max_length="0.1">
    <terminator link="finger_2_link_3" xyz="0 0 0"/>
    <!-- <pulley link="finger_1_link_2" xyz="0 0 0" radius="0"/>  -->
    <terminator link="finger_tensioner" xyz="0 0 0"/>
  </cable>
  <cable name="finger_middle_cable" min_length="0.1" max_length="0.1">
    <terminator link="finger_middle_link_3" xyz="0 0 0"/>
    <!-- <pulley link="finger_1_link_2" xyz="0 0 0" radius="0"/>  -->
    <terminator link="finger_tensioner" xyz="0 0 0"/>
  </cable>
  <transmission name="gripper" type="SimpleTransmission">
    <actuator name="gripper"/>
    <joint name="finger_tensioner"/>
    <mechanicalReduction>100</mechanicalReduction>
  </transmission>
</robot>
