<?xml version="1.0" ?>
<!-- =================================================================================== -->
<!-- |    This document was autogenerated by xacro from atlas.urdf.xacro               | -->
<!-- |    EDITING THIS FILE BY HAND IS NOT RECOMMENDED                                 | -->
<!-- =================================================================================== -->
<robot name="atlas" xmlns:xacro="http://www.ros.org/wiki/xacro">
  <link name="l_foot">
    <inertial>
      <mass value="2.05"/>
      <origin rpy="0 -0 0" xyz="0.027 0 -0.067"/>
      <inertia ixx="0.002" ixy="0" ixz="0" iyy="0.007" iyz="0" izz="0.008"/>
    </inertial>
    <visual>
      <origin rpy="0 -0 0" xyz="0 0 0"/>
      <geometry>
        <mesh filename="meshes/l_foot.wrl" scale="1 1 1"/>
      </geometry>
    </visual>
    <collision group="heel">
      <origin rpy="0 0 0" xyz="-0.082 0.0624435 -0.081119"/>
      <geometry>
        <sphere radius="0"/>
      </geometry>
    </collision>
    <visual>
      <origin rpy="0 0 0" xyz="-0.082 0.0624435 -0.081119"/>
      <geometry>
        <sphere radius="0.01"/>
      </geometry>
    </visual>
    <collision group="heel">
      <origin rpy="0 0 0" xyz="-0.082 -0.0624435 -0.081119"/>
      <geometry>
        <sphere radius="0"/>
      </geometry>
    </collision>
    <visual>
      <origin rpy="0 0 0" xyz="-0.082 -0.0624435 -0.081119"/>
      <geometry>
        <sphere radius="0.01"/>
      </geometry>
    </visual>
    <collision group="toe">
      <origin rpy="0 0 0" xyz="0.178 0.0624435 -0.081119"/>
      <geometry>
        <sphere radius="0"/>
      </geometry>
    </collision>
    <visual>
      <origin rpy="0 0 0" xyz="0.178 0.0624435 -0.081119"/>
      <geometry>
        <sphere radius="0.01"/>
      </geometry>
    </visual>  
    <collision group="toe">
      <origin rpy="0 0 0" xyz="0.178 -0.0624435 -0.081119"/>
      <geometry>
        <sphere radius="0"/>
      </geometry>
    </collision>
    <visual>
      <origin rpy="0 0 0" xyz="0.178 -0.0624435 -0.081119"/>
      <geometry>
        <sphere radius="0.01"/>
      </geometry>
    </visual>  
  </link>
  <link name="l_lglut">
    <inertial>
      <mass value="0.866"/>
      <origin rpy="0 -0 0" xyz="0.0133341 0.0170484 -0.0312052"/>
      <inertia ixx="0.000691326" ixy="-2.24344e-05" ixz="2.50508e-06" iyy="0.00126856" iyz="0.000137862" izz="0.00106487"/>
    </inertial>
    <visual>
      <origin rpy="0 -0 0" xyz="0 0 0"/>
      <geometry>
        <mesh filename="meshes/l_lglut.wrl" scale="1 1 1"/>
      </geometry>
    </visual>
  </link>
  <link name="l_lleg">
    <inertial>
      <mass value="5.479"/>
      <origin rpy="0 -0 0" xyz="0.001 0 -0.187"/>
      <inertia ixx="0.077" ixy="0" ixz="-0.003" iyy="0.076" iyz="0" izz="0.01"/>
    </inertial>
    <visual>
      <origin rpy="0 -0 0" xyz="0 0 0"/>
      <geometry>
        <mesh filename="meshes/l_lleg.wrl" scale="1 1 1"/>
      </geometry>
    </visual>
  </link>
  <link name="l_talus">
    <inertial>
      <mass value="0.125"/>
      <origin rpy="0 -0 0" xyz="0 0 0"/>
      <inertia ixx="1.01674e-05" ixy="0" ixz="0" iyy="8.42775e-06" iyz="0" izz="1.30101e-05"/>
    </inertial>
    <visual>
      <origin rpy="0 -0 0" xyz="0 0 0"/>
      <geometry>
        <mesh filename="meshes/l_talus.wrl" scale="1 1 1"/>
      </geometry>
    </visual>
  </link>
  <link name="l_uglut">
    <inertial>
      <mass value="0.648"/>
      <origin rpy="0 -0 0" xyz="0.00529262 -0.00344732 0.00313046"/>
      <inertia ixx="0.00074276" ixy="-3.79607e-08" ixz="-2.79549e-05" iyy="0.000688179" iyz="-3.2735e-08" izz="0.00041242"/>
    </inertial>
    <visual>
      <origin rpy="0 -0 0" xyz="0 0 0"/>
      <geometry>
        <mesh filename="meshes/l_uglut.wrl" scale="1 1 1"/>
      </geometry>
    </visual>
  </link>
  <link name="l_uleg">
    <inertial>
      <mass value="9.209"/>
      <origin rpy="0 -0 0" xyz="0 0 -0.21"/>
      <inertia ixx="0.09" ixy="0" ixz="0" iyy="0.09" iyz="0" izz="0.02"/>
    </inertial>
    <visual>
      <origin rpy="0 -0 0" xyz="0 0 0"/>
      <geometry>
        <mesh filename="meshes/l_uleg.wrl" scale="1 1 1"/>
      </geometry>
    </visual>
  </link>
  <link name="ltorso">
    <inertial>
      <mass value="2.409"/>
      <origin rpy="0 -0 0" xyz="-0.0112984 -3.15366e-06 0.0746835"/>
      <inertia ixx="0.0039092" ixy="-5.04491e-08" ixz="-0.000342157" iyy="0.00341694" iyz="4.87119e-07" izz="0.00174492"/>
    </inertial>
    <visual>
      <origin rpy="0 -0 0" xyz="0 0 0"/>
      <geometry>
        <mesh filename="meshes/ltorso.wrl" scale="1 1 1"/>
      </geometry>
    </visual>
  </link>
  <link name="mtorso">
    <inertial>
      <mass value="0.69"/>
      <origin rpy="0 -0 0" xyz="-0.00816266 -0.0131245 0.0305974"/>
      <inertia ixx="0.000454181" ixy="-6.10764e-05" ixz="3.94009e-05" iyy="0.000483282" iyz="5.27463e-05" izz="0.000444215"/>
    </inertial>
    <visual>
      <origin rpy="0 -0 0" xyz="0 0 0"/>
      <geometry>
        <mesh filename="meshes/mtorso.wrl" scale="1 1 1"/>
      </geometry>
    </visual>
  </link>
  <link name="pelvis">
    <inertial>
      <mass value="17.882"/>
      <origin rpy="0 -0 0" xyz="0.0111 0 0.0271"/>
      <inertia ixx="0.1244" ixy="0.0008" ixz="-0.0007" iyy="0.0958" iyz="-0.0005" izz="0.1167"/>
    </inertial>
    <visual>
      <origin rpy="0 -0 0" xyz="0 0 0"/>
      <geometry>
        <mesh filename="meshes/pelvis.wrl" scale="1 1 1"/>
      </geometry>
    </visual>
  </link>
  <link name="r_foot">
    <inertial>
      <mass value="2.05"/>
      <origin rpy="0 -0 0" xyz="0.027 0 -0.067"/>
      <inertia ixx="0.002" ixy="0" ixz="0" iyy="0.007" iyz="0" izz="0.008"/>
    </inertial>
    <visual>
      <origin rpy="0 -0 0" xyz="0 0 0"/>
      <geometry>
        <mesh filename="meshes/r_foot.wrl" scale="1 1 1"/>
      </geometry>
    </visual>
    <collision group="heel">
      <origin rpy="0 0 0" xyz="-0.082 0.0624435 -0.081119"/>
      <geometry>
        <sphere radius="0"/>
      </geometry>
    </collision>
    <visual>
      <origin rpy="0 0 0" xyz="-0.082 0.0624435 -0.081119"/>
      <geometry>
        <sphere radius="0.01"/>
      </geometry>
    </visual>
    <collision group="heel">
      <origin rpy="0 0 0" xyz="-0.082 -0.0624435 -0.081119"/>
      <geometry>
        <sphere radius="0"/>
      </geometry>
    </collision>
    <visual>
      <origin rpy="0 0 0" xyz="-0.082 -0.0624435 -0.081119"/>
      <geometry>
        <sphere radius="0.01"/>
      </geometry>
    </visual>
    <collision group="toe">
      <origin rpy="0 0 0" xyz="0.178 0.0624435 -0.081119"/>
      <geometry>
        <sphere radius="0"/>
      </geometry>
    </collision>
    <visual>
      <origin rpy="0 0 0" xyz="0.178 0.0624435 -0.081119"/>
      <geometry>
        <sphere radius="0.01"/>
      </geometry>
    </visual>
    <collision group="toe">
      <origin rpy="0 0 0" xyz="0.178 -0.0624435 -0.081119"/>
      <geometry>
        <sphere radius="0"/>
      </geometry>
    </collision>
    <visual>
      <origin rpy="0 0 0" xyz="0.178 -0.0624435 -0.081119"/>
      <geometry>
        <sphere radius="0.01"/>
      </geometry>
    </visual>
    <!--<xacro:collision_point group="heel_mid" xyz="-0.082 0 -0.081119" visualize="1"/>-->
    <!--<xacro:collision_point group="toe_mid" xyz="0.178 0 -0.081119" visualize="1"/>-->
    <!--    <xacro:collision_point group="inner" xyz="-0.08 0.055 -0.081119" visualize="1"/>-->
    <!--    <xacro:collision_point group="inner" xyz="-0.08 -0.055 -0.081119" visualize="1"/>-->
    <!--    <xacro:collision_point group="inner" xyz="0.06 0.055 -0.081119" visualize="1"/>-->
    <!--    <xacro:collision_point group="inner" xyz="0.06 -0.055 -0.081119" visualize="1"/>-->
  </link>
  <frame link="l_foot" name="l_foot_sole" rpy="0 0 0" xyz="0.0426  0.0017 -0.07645"/>
  <frame link="r_foot" name="r_foot_sole" rpy="0 0 0" xyz="0.0426 -0.0017 -0.07645"/>
  <frame link="l_foot" name="l_foot_toe" rpy="0 0 0" xyz="0.1728 0.0017 -0.07645"/>
  <frame link="r_foot" name="r_foot_toe" rpy="0 0 0" xyz="0.1728 -0.0017 -0.07645"/>
  <link name="r_lglut">
    <inertial>
      <mass value="0.866"/>
      <origin rpy="0 -0 0" xyz="0.0133341 -0.0170484 -0.0312052"/>
      <inertia ixx="0.000691326" ixy="2.24344e-05" ixz="2.50508e-06" iyy="0.00126856" iyz="-0.000137862" izz="0.00106487"/>
    </inertial>
    <visual>
      <origin rpy="0 -0 0" xyz="0 0 0"/>
      <geometry>
        <mesh filename="meshes/r_lglut.wrl" scale="1 1 1"/>
      </geometry>
    </visual>
  </link>
  <link name="r_lleg">
    <inertial>
      <mass value="5.479"/>
      <origin rpy="0 -0 0" xyz="0.001 0 -0.187"/>
      <inertia ixx="0.077" ixy="-0" ixz="-0.003" iyy="0.076" iyz="-0" izz="0.01"/>
    </inertial>
    <visual>
      <origin rpy="0 -0 0" xyz="0 0 0"/>
      <geometry>
        <mesh filename="meshes/r_lleg.wrl" scale="1 1 1"/>
      </geometry>
    </visual>
  </link>
  <link name="r_talus">
    <inertial>
      <mass value="0.125"/>
      <origin rpy="0 -0 0" xyz="0 0 0"/>
      <inertia ixx="1.01674e-05" ixy="0" ixz="0" iyy="8.42775e-06" iyz="0" izz="1.30101e-05"/>
    </inertial>
    <visual>
      <origin rpy="0 -0 0" xyz="0 0 0"/>
      <geometry>
        <mesh filename="meshes/r_talus.wrl" scale="1 1 1"/>
      </geometry>
    </visual>
  </link>
  <link name="r_uglut">
    <inertial>
      <mass value="0.648"/>
      <origin rpy="0 -0 0" xyz="0.00529262 0.00344732 0.00313046"/>
      <inertia ixx="0.00074276" ixy="3.79607e-08" ixz="-2.79549e-05" iyy="0.000688179" iyz="3.2735e-08" izz="0.00041242"/>
    </inertial>
    <visual>
      <origin rpy="0 -0 0" xyz="0 0 0"/>
      <geometry>
        <mesh filename="meshes/r_uglut.wrl" scale="1 1 1"/>
      </geometry>
    </visual>
  </link>
  <link name="r_uleg">
    <inertial>
      <mass value="9.209"/>
      <origin rpy="0 -0 0" xyz="0 0 -0.21"/>
      <inertia ixx="0.09" ixy="0" ixz="0" iyy="0.09" iyz="0" izz="0.02"/>
    </inertial>
    <visual>
      <origin rpy="0 -0 0" xyz="0 0 0"/>
      <geometry>
        <mesh filename="meshes/r_uleg.wrl" scale="1 1 1"/>
      </geometry>
    </visual>
  </link>
  <link name="utorso">
    <inertial>
      <mass value="52"/>
      <origin rpy="0 -0 0" xyz="-0.0923 0 0.3"/>
      <inertia ixx="1.466" ixy="0.00362" ixz="0.336" iyy="1.51" iyz="0.001" izz="1.3"/>
    </inertial>
    <visual>
      <origin rpy="0 -0 0" xyz="0 0 0"/>
      <geometry>
        <mesh filename="meshes/utorso.wrl" scale="1 1 1"/>
      </geometry>
    </visual>
    <visual>
      <origin rpy="0 -0 0" xyz="0 0 0"/>
      <geometry>
        <mesh filename="meshes/utorso_pack.wrl" scale="1 1 1"/>
      </geometry>
    </visual>
  </link>
  <joint name="back_bkx" type="revolute">
    <origin rpy="0 -0 0" xyz="0 0 0.05"/>
    <axis xyz="1 0 0"/>
    <parent link="mtorso"/>
    <child link="utorso"/>
    <dynamics damping="0.1" friction="0"/>
    <limit effort="200" lower="-0.698132" upper="0.698132" velocity="12"/>
    <safety_controller k_position="100" k_velocity="100" soft_lower_limit="-10.6981" soft_upper_limit="10.6981"/>
  </joint>
  <joint name="back_bky" type="revolute">
    <origin rpy="0 -0 0" xyz="0 0 0.16197"/>
    <axis xyz="0 1 0"/>
    <parent link="ltorso"/>
    <child link="mtorso"/>
    <dynamics damping="0.1" friction="0"/>
    <limit effort="206.843" lower="-0.262" upper="0.524" velocity="12"/>
    <safety_controller k_position="100" k_velocity="100" soft_lower_limit="-10.6107" soft_upper_limit="10.4384"/>
  </joint>
  <joint name="back_bkz" type="revolute">
    <origin rpy="0 -0 0" xyz="-0.0125 0 0"/>
    <axis xyz="0 0 1"/>
    <parent link="pelvis"/>
    <child link="ltorso"/>
    <dynamics damping="0.1" friction="0"/>
    <limit effort="114" lower="-0.663225" upper="0.663225" velocity="12"/>
    <safety_controller k_position="100" k_velocity="100" soft_lower_limit="-10.6632" soft_upper_limit="10.6632"/>
  </joint>
  <joint name="l_leg_akx" type="revolute">
    <origin rpy="0 -0 0" xyz="0 0 0"/>
    <axis xyz="1 0 0"/>
    <parent link="l_talus"/>
    <child link="l_foot"/>
    <dynamics damping="1.0" friction="0"/>
    <limit effort="130" lower="-0.8" upper="0.8" velocity="12"/>
    <safety_controller k_position="100" k_velocity="100" soft_lower_limit="-10.8" soft_upper_limit="10.8"/>
  </joint>
  <joint name="l_leg_aky" type="revolute">
    <origin rpy="0 -0 0" xyz="0 0 -0.422"/>
    <axis xyz="0 1 0"/>
    <parent link="l_lleg"/>
    <child link="l_talus"/>
    <dynamics damping="1.0" friction="0"/>
    <limit effort="70" lower="-1.3" upper="1" velocity="12"/>
    <safety_controller k_position="100" k_velocity="100" soft_lower_limit="-11" soft_upper_limit="10.7"/>
  </joint>
  <joint name="l_leg_hpx" type="revolute">
    <origin rpy="0 -0 0" xyz="0 0 0"/>
    <axis xyz="1 0 0"/>
    <parent link="l_uglut"/>
    <child link="l_lglut"/>
    <dynamics damping="0.1" friction="0"/>
    <limit effort="250" effort_max="250" effort_min="-343" lower="-0.523599" upper="0.523599" velocity="12"/>
    <safety_controller k_position="100" k_velocity="100" soft_lower_limit="-10.5236" soft_upper_limit="10.5236"/>
  </joint>
  <joint name="l_leg_hpy" type="revolute">
    <origin rpy="0 -0 0" xyz="0.05 0 -0.05"/>
    <axis xyz="0 1 0"/>
    <parent link="l_lglut"/>
    <child link="l_uleg"/>
    <dynamics damping="0.1" friction="0"/>
    <limit effort="260" effort_max="353" effort_min="-260" lower="-1.72072" upper="0.524821" velocity="12"/>
    <safety_controller k_position="100" k_velocity="100" soft_lower_limit="-11.7207" soft_upper_limit="10.5248"/>
  </joint>
  <joint name="l_leg_hpz" type="revolute">
    <origin rpy="0 -0 0" xyz="0 0.089 0"/>
    <axis xyz="0 0 1"/>
    <parent link="pelvis"/>
    <child link="l_uglut"/>
    <dynamics damping="0.1" friction="0"/>
    <limit effort="68" effort_max="68" effort_min="-105" lower="-0.174533" upper="1.22173" velocity="12"/>
    <safety_controller k_position="100" k_velocity="100" soft_lower_limit="-10.1745" soft_upper_limit="11.2217"/>
  </joint>
  <joint name="l_leg_kny" type="revolute">
    <origin rpy="0 -0 0" xyz="-0.05 0 -0.374"/>
    <axis xyz="0 1 0"/>
    <parent link="l_uleg"/>
    <child link="l_lleg"/>
    <dynamics damping="0.1" friction="0"/>
    <limit effort="220" effort_max="220" effort_min="-300" lower="0" upper="2.38569" velocity="12"/>
    <safety_controller k_position="100" k_velocity="100" soft_lower_limit="-10" soft_upper_limit="12.3857"/>
  </joint>
  <joint name="r_leg_akx" type="revolute">
    <origin rpy="0 -0 0" xyz="0 0 0"/>
    <axis xyz="1 0 0"/>
    <parent link="r_talus"/>
    <child link="r_foot"/>
    <dynamics damping="1.0" friction="0"/>
    <limit effort="130" lower="-0.8" upper="0.8" velocity="12"/>
    <safety_controller k_position="100" k_velocity="100" soft_lower_limit="-10.8" soft_upper_limit="10.8"/>
  </joint>
  <joint name="r_leg_aky" type="revolute">
    <origin rpy="0 -0 0" xyz="0 0 -0.422"/>
    <axis xyz="0 1 0"/>
    <parent link="r_lleg"/>
    <child link="r_talus"/>
    <dynamics damping="1.0" friction="0"/>
    <limit effort="70" lower="-1.3" upper="1" velocity="12"/>
    <safety_controller k_position="100" k_velocity="100" soft_lower_limit="-11" soft_upper_limit="10.7"/>
  </joint>
  <joint name="r_leg_hpx" type="revolute">
    <origin rpy="0 -0 0" xyz="0 0 0"/>
    <axis xyz="1 0 0"/>
    <parent link="r_uglut"/>
    <child link="r_lglut"/>
    <dynamics damping="0.1" friction="0"/>
    <limit effort="250" effort_max="343" effort_min="-250" lower="-0.523599" upper="0.523599" velocity="12"/>
    <safety_controller k_position="100" k_velocity="100" soft_lower_limit="-10.5236" soft_upper_limit="10.5236"/>
  </joint>
  <joint name="r_leg_hpy" type="revolute">
    <origin rpy="0 -0 0" xyz="0.05 0 -0.05"/>
    <axis xyz="0 1 0"/>
    <parent link="r_lglut"/>
    <child link="r_uleg"/>
    <dynamics damping="0.1" friction="0"/>
    <limit effort="260" effort_max="353" effort_min="-260" lower="-1.72072" upper="0.524821" velocity="12"/>
    <safety_controller k_position="100" k_velocity="100" soft_lower_limit="-11.7207" soft_upper_limit="10.5248"/>
  </joint>
  <joint name="r_leg_hpz" type="revolute">
    <origin rpy="0 -0 0" xyz="0 -0.089 0"/>
    <axis xyz="0 0 1"/>
    <parent link="pelvis"/>
    <child link="r_uglut"/>
    <dynamics damping="0.1" friction="0"/>
    <limit effort="68" effort_max="105" effort_min="-68" lower="-1.22173" upper="0.174533" velocity="12"/>
    <safety_controller k_position="100" k_velocity="100" soft_lower_limit="-11.2217" soft_upper_limit="10.1745"/>
  </joint>
  <joint name="r_leg_kny" type="revolute">
    <origin rpy="0 -0 0" xyz="-0.05 0 -0.374"/>
    <axis xyz="0 1 0"/>
    <parent link="r_uleg"/>
    <child link="r_lleg"/>
    <dynamics damping="0.1" friction="0"/>
    <limit effort="220" effort_max="220" effort_min="-300" lower="0" upper="2.38569" velocity="12"/>
    <safety_controller k_position="100" k_velocity="100" soft_lower_limit="-10" soft_upper_limit="12.3857"/>
  </joint>
  <transmission name="back_bkz_trans" type="pr2_mechanism_model/SimpleTransmission">
    <joint name="back_bkz"/>
    <actuator name="back_bkz_motor"/>
    <mechanicalReduction>1</mechanicalReduction>
  </transmission>
  <transmission name="back_bky_trans" type="pr2_mechanism_model/SimpleTransmission">
    <actuator name="back_bky_motor"/>
    <joint name="back_bky"/>
    <mechanicalReduction>1</mechanicalReduction>
  </transmission>
  <transmission name="back_bkx_trans" type="pr2_mechanism_model/SimpleTransmission">
    <actuator name="back_bkx_motor"/>
    <joint name="back_bkx"/>
    <mechanicalReduction>1</mechanicalReduction>
  </transmission>
  <transmission name="l_leg_kny_trans" type="pr2_mechanism_model/SimpleTransmission">
    <actuator name="l_leg_kny_motor"/>
    <joint name="l_leg_kny"/>
    <mechanicalReduction>1</mechanicalReduction>
  </transmission>
  <transmission name="l_leg_akx_trans" type="pr2_mechanism_model/SimpleTransmission">
    <actuator name="l_leg_akx_motor"/>
    <joint name="l_leg_akx"/>
    <mechanicalReduction>1</mechanicalReduction>
  </transmission>
  <transmission name="l_leg_hpy_trans" type="pr2_mechanism_model/SimpleTransmission">
    <actuator name="l_leg_hpy_motor"/>
    <joint name="l_leg_hpy"/>
    <mechanicalReduction>1</mechanicalReduction>
  </transmission>
  <transmission name="l_leg_hpx_trans" type="pr2_mechanism_model/SimpleTransmission">
    <actuator name="l_leg_hpx_motor"/>
    <joint name="l_leg_hpx"/>
    <mechanicalReduction>1</mechanicalReduction>
  </transmission>
  <transmission name="l_leg_aky_trans" type="pr2_mechanism_model/SimpleTransmission">
    <actuator name="l_leg_aky_motor"/>
    <joint name="l_leg_aky"/>
    <mechanicalReduction>1</mechanicalReduction>
  </transmission>
  <transmission name="l_leg_hpz_trans" type="pr2_mechanism_model/SimpleTransmission">
    <actuator name="l_leg_hpz_motor"/>
    <joint name="l_leg_hpz"/>
    <mechanicalReduction>1</mechanicalReduction>
  </transmission>
  <transmission name="r_leg_kny_trans" type="pr2_mechanism_model/SimpleTransmission">
    <actuator name="r_leg_kny_motor"/>
    <joint name="r_leg_kny"/>
    <mechanicalReduction>1</mechanicalReduction>
  </transmission>
  <transmission name="r_leg_akx_trans" type="pr2_mechanism_model/SimpleTransmission">
    <actuator name="r_leg_akx_motor"/>
    <joint name="r_leg_akx"/>
    <mechanicalReduction>1</mechanicalReduction>
  </transmission>
  <transmission name="r_leg_hpy_trans" type="pr2_mechanism_model/SimpleTransmission">
    <actuator name="r_leg_hpy_motor"/>
    <joint name="r_leg_hpy"/>
    <mechanicalReduction>1</mechanicalReduction>
  </transmission>
  <transmission name="r_leg_hpx_trans" type="pr2_mechanism_model/SimpleTransmission">
    <actuator name="r_leg_hpx_motor"/>
    <joint name="r_leg_hpx"/>
    <mechanicalReduction>1</mechanicalReduction>
  </transmission>
  <transmission name="r_leg_aky_trans" type="pr2_mechanism_model/SimpleTransmission">
    <actuator name="r_leg_aky_motor"/>
    <joint name="r_leg_aky"/>
    <mechanicalReduction>1</mechanicalReduction>
  </transmission>
  <transmission name="r_leg_hpz_trans" type="pr2_mechanism_model/SimpleTransmission">
    <actuator name="r_leg_hpz_motor"/>
    <joint name="r_leg_hpz"/>
    <mechanicalReduction>1</mechanicalReduction>
  </transmission>


  <!-- <force_element name="r_leg_aky_spring">
    <torsional_spring stiffness="5" rest_angle="0.0">
      <joint name="r_leg_aky" />
    </torsional_spring>
  </force_element>
  <force_element name="l_leg_aky_spring">
    <torsional_spring stiffness="5" rest_angle="0.0">
      <joint name="l_leg_aky" />
    </torsional_spring>
  </force_element> -->

</robot>
