<?xml version="1.0" ?>
<!-- =================================================================================== -->
<!-- |    This document was autogenerated by xacro from spring_flamingo.xacro          | -->
<!-- |    EDITING THIS FILE BY HAND IS NOT RECOMMENDED                                 | -->
<!-- =================================================================================== -->
<!-- spring_flamingo revision 3 for questions/bugs/etc. email woursler@gmail.com-->
<robot name="spring_flamingo" xmlns:xacro="http://www.ros.org/wiki/xacro">
  <!-- body property xacros -->
  <!--measured relative to the center of the line connecting the hips-->
  <!-- upper leg property xacros -->
  <!-- lower leg property xacros -->
  <!-- foot property xacros -->
  <!-- Encapsulates the body code.-->
  <!-- Defines a ground contact point xacro-->
  <!-- Defines a leg xacro. Most of the action is here.-->
  <link name="base_link">
    <inertial>
      <origin rpy="0 0 0" xyz="0 0 0.20"/>
      <mass value="12"/>
      <inertia ixx=".25" ixy="0" ixz="0" iyy=".25" iyz="0" izz=".25"/>
    </inertial>
  </link>
  <link name="left_fan">
  </link>
  <joint name="left_fan_fixed_joint" type="fixed">
    <parent link="base_link"/>
    <child link="left_fan"/>
    <origin rpy="0 0 0" xyz="0 -0.12 0"/>
    <axis xyz="0 1 0"/>
  </joint>
  <link name="left_strut_1">
    <visual>
      <geometry>
        <box size="0.05 0.12 0.385"/>
      </geometry>
      <origin rpy="0 0 0" xyz="0 0 0.1925"/>
      <material name="grey">
        <color rgba=".8 .8 .8 1"/>
      </material>
    </visual>
  </link>
  <joint name="left_fixed_joint_1" type="fixed">
    <parent link="left_fan"/>
    <child link="left_strut_1"/>
    <origin rpy="0 -0.959931089 0" xyz="0 0 0"/>
    <axis xyz="0 1 0"/>
  </joint>
  <link name="left_strut_2">
    <visual>
      <geometry>
        <box size="0.05 0.12 0.385"/>
      </geometry>
      <origin rpy="0 0 0" xyz="0 0 0.1925"/>
      <material name="grey">
        <color rgba=".8 .8 .8 1"/>
      </material>
    </visual>
  </link>
  <joint name="left_fixed_joint_2" type="fixed">
    <parent link="left_fan"/>
    <child link="left_strut_2"/>
    <origin rpy="0 -0.831940277 0" xyz="0 0 0"/>
    <axis xyz="0 1 0"/>
  </joint>
  <link name="left_strut_3">
    <visual>
      <geometry>
        <box size="0.05 0.12 0.385"/>
      </geometry>
      <origin rpy="0 0 0" xyz="0 0 0.1925"/>
      <material name="grey">
        <color rgba=".8 .8 .8 1"/>
      </material>
    </visual>
  </link>
  <joint name="left_fixed_joint_3" type="fixed">
    <parent link="left_fan"/>
    <child link="left_strut_3"/>
    <origin rpy="0 -0.703949465 0" xyz="0 0 0"/>
    <axis xyz="0 1 0"/>
  </joint>
  <link name="left_strut_4">
    <visual>
      <geometry>
        <box size="0.05 0.12 0.385"/>
      </geometry>
      <origin rpy="0 0 0" xyz="0 0 0.1925"/>
      <material name="grey">
        <color rgba=".8 .8 .8 1"/>
      </material>
    </visual>
  </link>
  <joint name="left_fixed_joint_4" type="fixed">
    <parent link="left_fan"/>
    <child link="left_strut_4"/>
    <origin rpy="0 -0.575958653 0" xyz="0 0 0"/>
    <axis xyz="0 1 0"/>
  </joint>
  <link name="left_strut_5">
    <visual>
      <geometry>
        <box size="0.05 0.12 0.385"/>
      </geometry>
      <origin rpy="0 0 0" xyz="0 0 0.1925"/>
      <material name="grey">
        <color rgba=".8 .8 .8 1"/>
      </material>
    </visual>
  </link>
  <joint name="left_fixed_joint_5" type="fixed">
    <parent link="left_fan"/>
    <child link="left_strut_5"/>
    <origin rpy="0 -0.447967841 0" xyz="0 0 0"/>
    <axis xyz="0 1 0"/>
  </joint>
  <link name="left_strut_6">
    <visual>
      <geometry>
        <box size="0.05 0.12 0.385"/>
      </geometry>
      <origin rpy="0 0 0" xyz="0 0 0.1925"/>
      <material name="grey">
        <color rgba=".8 .8 .8 1"/>
      </material>
    </visual>
  </link>
  <joint name="left_fixed_joint_6" type="fixed">
    <parent link="left_fan"/>
    <child link="left_strut_6"/>
    <origin rpy="0 -0.319977029 0" xyz="0 0 0"/>
    <axis xyz="0 1 0"/>
  </joint>
  <link name="left_strut_7">
    <visual>
      <geometry>
        <box size="0.05 0.12 0.385"/>
      </geometry>
      <origin rpy="0 0 0" xyz="0 0 0.1925"/>
      <material name="grey">
        <color rgba=".8 .8 .8 1"/>
      </material>
    </visual>
  </link>
  <joint name="left_fixed_joint_7" type="fixed">
    <parent link="left_fan"/>
    <child link="left_strut_7"/>
    <origin rpy="0 -0.191986217 0" xyz="0 0 0"/>
    <axis xyz="0 1 0"/>
  </joint>
  <link name="left_strut_8">
    <visual>
      <geometry>
        <box size="0.05 0.12 0.385"/>
      </geometry>
      <origin rpy="0 0 0" xyz="0 0 0.1925"/>
      <material name="grey">
        <color rgba=".8 .8 .8 1"/>
      </material>
    </visual>
  </link>
  <joint name="left_fixed_joint_8" type="fixed">
    <parent link="left_fan"/>
    <child link="left_strut_8"/>
    <origin rpy="0 -0.063995405 0" xyz="0 0 0"/>
    <axis xyz="0 1 0"/>
  </joint>
  <link name="left_strut_9">
    <visual>
      <geometry>
        <box size="0.05 0.12 0.385"/>
      </geometry>
      <origin rpy="0 0 0" xyz="0 0 0.1925"/>
      <material name="grey">
        <color rgba=".8 .8 .8 1"/>
      </material>
    </visual>
  </link>
  <joint name="left_fixed_joint_9" type="fixed">
    <parent link="left_fan"/>
    <child link="left_strut_9"/>
    <origin rpy="0 0.063995407 0" xyz="0 0 0"/>
    <axis xyz="0 1 0"/>
  </joint>
  <link name="left_strut_10">
    <visual>
      <geometry>
        <box size="0.05 0.12 0.385"/>
      </geometry>
      <origin rpy="0 0 0" xyz="0 0 0.1925"/>
      <material name="grey">
        <color rgba=".8 .8 .8 1"/>
      </material>
    </visual>
  </link>
  <joint name="left_fixed_joint_10" type="fixed">
    <parent link="left_fan"/>
    <child link="left_strut_10"/>
    <origin rpy="0 0.191986219 0" xyz="0 0 0"/>
    <axis xyz="0 1 0"/>
  </joint>
  <link name="left_strut_11">
    <visual>
      <geometry>
        <box size="0.05 0.12 0.385"/>
      </geometry>
      <origin rpy="0 0 0" xyz="0 0 0.1925"/>
      <material name="grey">
        <color rgba=".8 .8 .8 1"/>
      </material>
    </visual>
  </link>
  <joint name="left_fixed_joint_11" type="fixed">
    <parent link="left_fan"/>
    <child link="left_strut_11"/>
    <origin rpy="0 0.319977031 0" xyz="0 0 0"/>
    <axis xyz="0 1 0"/>
  </joint>
  <link name="left_strut_12">
    <visual>
      <geometry>
        <box size="0.05 0.12 0.385"/>
      </geometry>
      <origin rpy="0 0 0" xyz="0 0 0.1925"/>
      <material name="grey">
        <color rgba=".8 .8 .8 1"/>
      </material>
    </visual>
  </link>
  <joint name="left_fixed_joint_12" type="fixed">
    <parent link="left_fan"/>
    <child link="left_strut_12"/>
    <origin rpy="0 0.447967843 0" xyz="0 0 0"/>
    <axis xyz="0 1 0"/>
  </joint>
  <link name="left_strut_13">
    <visual>
      <geometry>
        <box size="0.05 0.12 0.385"/>
      </geometry>
      <origin rpy="0 0 0" xyz="0 0 0.1925"/>
      <material name="grey">
        <color rgba=".8 .8 .8 1"/>
      </material>
    </visual>
  </link>
  <joint name="left_fixed_joint_13" type="fixed">
    <parent link="left_fan"/>
    <child link="left_strut_13"/>
    <origin rpy="0 0.575958655 0" xyz="0 0 0"/>
    <axis xyz="0 1 0"/>
  </joint>
  <link name="left_strut_14">
    <visual>
      <geometry>
        <box size="0.05 0.12 0.385"/>
      </geometry>
      <origin rpy="0 0 0" xyz="0 0 0.1925"/>
      <material name="grey">
        <color rgba=".8 .8 .8 1"/>
      </material>
    </visual>
  </link>
  <joint name="left_fixed_joint_14" type="fixed">
    <parent link="left_fan"/>
    <child link="left_strut_14"/>
    <origin rpy="0 0.703949467 0" xyz="0 0 0"/>
    <axis xyz="0 1 0"/>
  </joint>
  <link name="left_strut_15">
    <visual>
      <geometry>
        <box size="0.05 0.12 0.385"/>
      </geometry>
      <origin rpy="0 0 0" xyz="0 0 0.1925"/>
      <material name="grey">
        <color rgba=".8 .8 .8 1"/>
      </material>
    </visual>
  </link>
  <joint name="left_fixed_joint_15" type="fixed">
    <parent link="left_fan"/>
    <child link="left_strut_15"/>
    <origin rpy="0 0.831940279 0" xyz="0 0 0"/>
    <axis xyz="0 1 0"/>
  </joint>
  <link name="right_upper_leg">
    <visual>
      <geometry>
        <cylinder length="0.42" radius=".00565"/>
      </geometry>
      <origin rpy="0 1.57075 0" xyz="0.21 0 0"/>
      <material name="grey">
        <color rgba=".8 .8 .8 1"/>
      </material>
    </visual>
    <inertial>
      <origin rpy="0 0 0" xyz="0.21 0 0"/>
      <mass value="0.4598"/>
      <inertia ixx="0.01256" ixy="0" ixz="0" iyy="0.01256" iyz="0" izz="0.00013"/>
    </inertial>
  </link>
  <joint name="right_hip" type="continuous">
    <parent link="base_link"/>
    <child link="right_upper_leg"/>
    <origin rpy="0 1.57075 0" xyz="0 0.12 0"/>
    <axis xyz="0 1 0"/>
  </joint>
  <transmission name="right_hip_motor" type="SimpleTransmission">
    <actuator name="right_hip_motor"/>
    <joint name="right_hip"/>
    <mechanicalReduction>1</mechanicalReduction>
  </transmission>
  <link name="right_upper_leg2">
    <visual>
      <geometry>
        <cylinder length=".054" radius=".0125"/>
      </geometry>
    </visual>
  </link>
  <joint name="right_upper_legj2" type="fixed">
    <parent link="right_upper_leg"/>
    <child link="right_upper_leg2"/>
    <origin rpy="0 1.57075 0" xyz="0.393 0 0"/>
  </joint>
  <link name="right_upper_leg3">
    <visual>
      <geometry>
        <cylinder length="0.0478" radius=".0125"/>
      </geometry>
    </visual>
  </link>
  <joint name="right_upper_legj3" type="fixed">
    <parent link="right_upper_leg"/>
    <child link="right_upper_leg3"/>
    <origin rpy="0 1.57075 0" xyz="0.0349 0 0"/>
  </joint>
  <link name="right_lower_leg">
    <visual>
      <geometry>
        <cylinder length="0.42" radius=".00565"/>
      </geometry>
      <origin rpy="0 1.57075 0" xyz="0.21 0 0"/>
    </visual>
    <inertial>
      <origin rpy="0 0 0" xyz="0.21 0 0"/>
      <mass value="0.306"/>
      <inertia ixx="0.00952" ixy="0" ixz="0" iyy="0.00952" iyz="0" izz="5.67e-05"/>
    </inertial>
  </link>
  <joint name="right_knee" type="continuous">
    <parent link="right_upper_leg"/>
    <child link="right_lower_leg"/>
    <origin xyz="0.42 0 0"/>
    <axis xyz="0 1 0"/>
  </joint>
  <transmission name="right_knee_motor" type="SimpleTransmission">
    <actuator name="right_knee_motor"/>
    <joint name="right_knee"/>
    <mechanicalReduction>1</mechanicalReduction>
  </transmission>
  <link name="right_lower_leg2">
    <visual>
      <geometry>
        <cylinder length=".04" radius=".0125"/>
      </geometry>
    </visual>
  </link>
  <joint name="right_lower_legj2" type="fixed">
    <parent link="right_lower_leg"/>
    <child link="right_lower_leg2"/>
    <origin rpy="0 1.57075 0" xyz="0.4 0 0"/>
  </joint>
  <link name="right_lower_leg3">
    <visual>
      <geometry>
        <cylinder length="0.062" radius=".0125"/>
      </geometry>
    </visual>
  </link>
  <joint name="right_lower_legj3" type="fixed">
    <parent link="right_lower_leg"/>
    <child link="right_lower_leg3"/>
    <origin rpy="0 1.57075 0" xyz="0.01 0 0"/>
  </joint>
  <link name="right_foot">
    <visual>
      <geometry>
        <box size=".01 .1 .23"/>
      </geometry>
      <origin rpy="0 0 0" xyz=".035 0 -0.0575"/>
      <material name="grey">
        <color rgba=".8 .8 .8 1"/>
      </material>
    </visual>
    <inertial>
      <origin rpy="0 0 0" xyz=".035 0 -0.0575"/>
      <mass value="0.3466"/>
      <inertia ixx="7.15e-05" ixy="0" ixz="0" iyy="0.0015" iyz="0" izz="0.0015"/>
    </inertial>
  </link>
  <joint name="right_ankle" type="continuous">
    <parent link="right_lower_leg"/>
    <child link="right_foot"/>
    <origin xyz="0.42 0 0"/>
    <axis xyz="0 1 0"/>
    <dynamics damping=".1" />
  </joint>
  <force_element name="spring">
    <torsional_spring stiffness=".1" rest_angle="0">
      <joint name="right_ankle" />
    </torsional_spring>
  </force_element>
  <link name="right_foot2">
    <visual>
      <geometry>
        <cylinder length=".03" radius=".014"/>
      </geometry>
    </visual>
  </link>
  <joint name="right_footj2" type="fixed">
    <parent link="right_foot"/>
    <child link="right_foot2"/>
    <origin rpy="0 1.57075 0" xyz="0.015 0 0"/>
  </joint>
  <link name="right_forward_contact_point">
    <visual>
      <geometry>
        <sphere radius="0.01"/>
      </geometry>
      <material name="black">
        <color rgba="0 0 0 1"/>
      </material>
    </visual>
    <collision group="toe">
      <geometry>
        <sphere radius="0"/>
      </geometry>
    </collision>
  </link>
  <link name="right_rear_contact_point">
    <visual>
      <geometry>
        <sphere radius="0.01"/>
      </geometry>
      <material name="black">
        <color rgba="0 0 0 1"/>
      </material>
    </visual>
    <collision group="heel">
      <geometry>
        <sphere radius="0"/>
      </geometry>
    </collision>
  </link>
  <joint name="right_j1" type="fixed">
    <parent link="right_foot"/>
    <child link="right_forward_contact_point"/>
    <origin xyz=".035 0 -0.1725"/>
    <axis xyz="0 1 0"/>
  </joint>
  <joint name="right_j2" type="fixed">
    <parent link="right_foot"/>
    <child link="right_rear_contact_point"/>
    <origin xyz="0.035 0 0.0575"/>
    <axis xyz="0 1 0"/>
  </joint>
  <link name="left_upper_leg">
    <visual>
      <geometry>
        <cylinder length="0.42" radius=".00565"/>
      </geometry>
      <origin rpy="0 1.57075 0" xyz="0.21 0 0"/>
      <material name="grey">
        <color rgba=".8 .8 .8 1"/>
      </material>
    </visual>
    <inertial>
      <origin rpy="0 0 0" xyz="0.21 0 0"/>
      <mass value="0.4598"/>
      <inertia ixx="0.01256" ixy="0" ixz="0" iyy="0.01256" iyz="0" izz="0.00013"/>
    </inertial>
  </link>
  <joint name="left_hip" type="continuous">
    <parent link="base_link"/>
    <child link="left_upper_leg"/>
    <origin rpy="0 1.57075 0" xyz="0 -0.12 0"/>
    <axis xyz="0 1 0"/>
  </joint>
  <transmission name="left_hip_motor" type="SimpleTransmission">
    <actuator name="left_hip_motor"/>
    <joint name="left_hip"/>
    <mechanicalReduction>1</mechanicalReduction>
  </transmission>
  <link name="left_upper_leg2">
    <visual>
      <geometry>
        <cylinder length=".054" radius=".0125"/>
      </geometry>
    </visual>
  </link>
  <joint name="left_upper_legj2" type="fixed">
    <parent link="left_upper_leg"/>
    <child link="left_upper_leg2"/>
    <origin rpy="0 1.57075 0" xyz="0.393 0 0"/>
  </joint>
  <link name="left_upper_leg3">
    <visual>
      <geometry>
        <cylinder length="0.0478" radius=".0125"/>
      </geometry>
    </visual>
  </link>
  <joint name="left_upper_legj3" type="fixed">
    <parent link="left_upper_leg"/>
    <child link="left_upper_leg3"/>
    <origin rpy="0 1.57075 0" xyz="0.0349 0 0"/>
  </joint>
  <link name="left_lower_leg">
    <visual>
      <geometry>
        <cylinder length="0.42" radius=".00565"/>
      </geometry>
      <origin rpy="0 1.57075 0" xyz="0.21 0 0"/>
    </visual>
    <inertial>
      <origin rpy="0 0 0" xyz="0.21 0 0"/>
      <mass value="0.306"/>
      <inertia ixx="0.00952" ixy="0" ixz="0" iyy="0.00952" iyz="0" izz="5.67e-05"/>
    </inertial>
  </link>
  <joint name="left_knee" type="continuous">
    <parent link="left_upper_leg"/>
    <child link="left_lower_leg"/>
    <origin xyz="0.42 0 0"/>
    <axis xyz="0 1 0"/>
  </joint>
  <transmission name="left_knee_motor" type="SimpleTransmission">
    <actuator name="left_knee_motor"/>
    <joint name="left_knee"/>
    <mechanicalReduction>1</mechanicalReduction>
  </transmission>
  <link name="left_lower_leg2">
    <visual>
      <geometry>
        <cylinder length=".04" radius=".0125"/>
      </geometry>
    </visual>
  </link>
  <joint name="left_lower_legj2" type="fixed">
    <parent link="left_lower_leg"/>
    <child link="left_lower_leg2"/>
    <origin rpy="0 1.57075 0" xyz="0.4 0 0"/>
  </joint>
  <link name="left_lower_leg3">
    <visual>
      <geometry>
        <cylinder length="0.062" radius=".0125"/>
      </geometry>
    </visual>
  </link>
  <joint name="left_lower_legj3" type="fixed">
    <parent link="left_lower_leg"/>
    <child link="left_lower_leg3"/>
    <origin rpy="0 1.57075 0" xyz="0.01 0 0"/>
  </joint>
  <link name="left_foot">
    <visual>
      <geometry>
        <box size=".01 .1 .23"/>
      </geometry>
      <origin rpy="0 0 0" xyz=".035 0 -0.0575"/>
      <material name="grey">
        <color rgba=".8 .8 .8 1"/>
      </material>
    </visual>
    <inertial>
      <origin rpy="0 0 0" xyz=".035 0 -0.0575"/>
      <mass value="0.3466"/>
      <inertia ixx="7.15e-05" ixy="0" ixz="0" iyy="0.0015" iyz="0" izz="0.0015"/>
    </inertial>
  </link>
  <joint name="left_ankle" type="continuous">
    <parent link="left_lower_leg"/>
    <child link="left_foot"/>
    <origin xyz="0.42 0 0"/>
    <axis xyz="0 1 0"/>
    <dynamics damping=".1" />
  </joint>
  <force_element name="spring">
    <torsional_spring stiffness=".1" rest_angle="0">
      <joint name="left_ankle" />
    </torsional_spring>
  </force_element>
  <link name="left_foot2">
    <visual>
      <geometry>
        <cylinder length=".03" radius=".014"/>
      </geometry>
    </visual>
  </link>
  <joint name="left_footj2" type="fixed">
    <parent link="left_foot"/>
    <child link="left_foot2"/>
    <origin rpy="0 1.57075 0" xyz="0.015 0 0"/>
  </joint>
  <link name="left_forward_contact_point">
    <visual>
      <geometry>
        <sphere radius="0.01"/>
      </geometry>
      <material name="black">
        <color rgba="0 0 0 1"/>
      </material>
    </visual>
    <collision group="toe">
      <geometry>
        <sphere radius="0"/>
      </geometry>
    </collision>
  </link>
  <link name="left_rear_contact_point">
    <visual>
      <geometry>
        <sphere radius="0.01"/>
      </geometry>
      <material name="black">
        <color rgba="0 0 0 1"/>
      </material>
    </visual>
    <collision group="heel">
      <geometry>
        <sphere radius="0"/>
      </geometry>
    </collision>
  </link>
  <joint name="left_j1" type="fixed">
    <parent link="left_foot"/>
    <child link="left_forward_contact_point"/>
    <origin xyz=".035 0 -0.1725"/>
    <axis xyz="0 1 0"/>
  </joint>
  <joint name="left_j2" type="fixed">
    <parent link="left_foot"/>
    <child link="left_rear_contact_point"/>
    <origin xyz="0.035 0 0.0575"/>
    <axis xyz="0 1 0"/>
  </joint>
</robot>

