<?xml version='1.0'?>
<sdf version='1.6'>
  <model name='Schunk_Gripper'>
    <!--To enable faster simulation, the collision geometry in this model
         consists of multiple spheres. These are arranged in a line along each
         finger, with two additional spheres forming a triangle at each finger
         tip.-->
    <link name='body'>
      <pose frame=''>0 -0.049133 0 0 -0 0</pose>
      <inertial>
        <mass>0.988882</mass>
        <inertia>
          <ixx>0.162992</ixx>
          <ixy>0</ixy>
          <ixz>0</ixz>
          <iyy>0.162992</iyy>
          <iyz>0</iyz>
          <izz>0.164814</izz>
        </inertia>
        <pose frame=''>0 0 0 0 -0 0</pose>
      </inertial>
      <self_collide>0</self_collide>
      <kinematic>0</kinematic>
      <visual name='visual'>
        <pose frame=''>0 0 0 0 -0 0</pose>
        <geometry>
          <box>
            <size>0.146 0.0725 0.049521</size>
          </box>
        </geometry>
        <material>
          <lighting>1</lighting>
          <script>
            <uri>file://media/materials/scripts/gazebo.material</uri>
            <name>Gazebo/Grey</name>
          </script>
          <ambient>0.3 0.3 0.3 1</ambient>
          <diffuse>0.7 0.7 0.7 1</diffuse>
          <specular>0.01 0.01 0.01 1</specular>
          <emissive>0 0 0 1</emissive>
          <shader type='vertex'>
            <normal_map>__default__</normal_map>
          </shader>
        </material>
        <cast_shadows>1</cast_shadows>
        <transparency>0</transparency>
      </visual>
      <collision name='collision'>
        <laser_retro>0</laser_retro>
        <max_contacts>10</max_contacts>
        <pose frame=''>0 0 0 0 -0 0</pose>
        <geometry>
          <box>
            <size>0.146 0.0725 0.049521</size>
          </box>
        </geometry>
        <surface>
          <friction>
            <ode>
              <mu>1</mu>
              <mu2>1</mu2>
              <fdir1>0 0 0</fdir1>
              <slip1>0</slip1>
              <slip2>0</slip2>
            </ode>
            <torsional>
              <coefficient>1</coefficient>
              <patch_radius>0</patch_radius>
              <surface_radius>0</surface_radius>
              <use_patch_radius>1</use_patch_radius>
              <ode>
                <slip>0</slip>
              </ode>
            </torsional>
          </friction>
          <bounce>
            <restitution_coefficient>0</restitution_coefficient>
            <threshold>1e+06</threshold>
          </bounce>
          <contact>
            <collide_without_contact>0</collide_without_contact>
            <collide_without_contact_bitmask>1</collide_without_contact_bitmask>
            <collide_bitmask>1</collide_bitmask>
            <ode>
              <soft_cfm>0</soft_cfm>
              <soft_erp>0.2</soft_erp>
              <kp>1e+13</kp>
              <kd>1</kd>
              <max_vel>0.01</max_vel>
              <min_depth>0</min_depth>
            </ode>
            <bullet>
              <split_impulse>1</split_impulse>
              <split_impulse_penetration_threshold>-0.01</split_impulse_penetration_threshold>
              <soft_cfm>0</soft_cfm>
              <soft_erp>0.2</soft_erp>
              <kp>1e+13</kp>
              <kd>1</kd>
            </bullet>
          </contact>
        </surface>
      </collision>
    </link>
    <frame name='body_frame'>
      <link>body</link>
      <pose frame=''>0 0 0 0 0 0</pose>
    </frame>
    <link name='left_finger'>
      <pose frame=''>-0.008 0.029 0 0 -0 0</pose>
      <inertial>
        <mass>0.05</mass>
        <inertia>
          <ixx>0.16</ixx>
          <ixy>0</ixy>
          <ixz>0</ixz>
          <iyy>0.16</iyy>
          <iyz>0</iyz>
          <izz>0.16</izz>
        </inertia>
        <pose frame=''>0 0 0 0 -0 0</pose>
      </inertial>
      <self_collide>0</self_collide>
      <kinematic>0</kinematic>
      <visual name='visual'>
        <pose frame=''>0 0 0 0 -0 0</pose>
        <geometry>
          <box>
            <size>0.016 0.083 0.02</size>
          </box>
        </geometry>
        <material>
          <lighting>1</lighting>
          <script>
            <uri>file://media/materials/scripts/gazebo.material</uri>
            <name>Gazebo/Grey</name>
          </script>
          <ambient>0.3 0.3 0.3 1</ambient>
          <diffuse>0.7 0.7 0.7 1</diffuse>
          <specular>0.01 0.01 0.01 1</specular>
          <emissive>0 0 0 1</emissive>
          <shader type='vertex'>
            <normal_map>__default__</normal_map>
          </shader>
        </material>
        <cast_shadows>1</cast_shadows>
        <transparency>0</transparency>
      </visual>
      <!-- A sequence of spaced spheres the *width* of the finger from the tip
      towards the base. -->
      <collision name='collision'>
        <pose frame=''>0 -0.0209 0 0 0 0</pose>
        <geometry>
          <sphere>
            <radius>0.008</radius>
          </sphere>
        </geometry>
      </collision>
      <collision name='collision'>
        <pose frame=''>0 -0.0049 0 0 0 0</pose>
        <geometry>
          <sphere>
            <radius>0.008</radius>
          </sphere>
        </geometry>
      </collision>
      <collision name='collision'>
        <pose frame=''>0 0.0112 0 0 0 0</pose>
        <geometry>
          <sphere>
            <radius>0.008</radius>
          </sphere>
        </geometry>
      </collision>
      <collision name='collision'>
        <pose frame=''>0 0.0271 0 0 0 0</pose>
        <geometry>
          <sphere>
            <radius>0.008</radius>
          </sphere>
        </geometry>
      </collision>
      <!-- Two more spheres that form a triangle with the tip-most sphere
           above. -->
      <collision name='collision'>
        <pose frame=''>0.0040 0.0375 0.0060 0 0 0</pose>
        <geometry>
          <sphere>
            <radius>0.004</radius>
          </sphere>
        </geometry>
      </collision>
      <collision name='collision'>
        <pose frame=''>0.0040 0.0375 -0.0060 0 0 0</pose>
        <geometry>
          <sphere>
            <radius>0.004</radius>
          </sphere>
        </geometry>
      </collision>
    </link>
    <link name='left_pusher'>
      <pose frame=''>0.028 0.037 0 0 0 -0.909</pose>
      <inertial>
        <mass>0</mass>
        <inertia>
          <ixx>0.0001</ixx>
          <ixy>0</ixy>
          <ixz>0</ixz>
          <iyy>0.0001</iyy>
          <iyz>0</iyz>
          <izz>0.0001</izz>
        </inertia>
        <pose frame=''>0 0 0 0 -0 0</pose>
      </inertial>
      <self_collide>0</self_collide>
      <kinematic>0</kinematic>
      <gravity>1</gravity>
    </link>
    <link name='nonphysical_rotor'>
      <pose frame=''>0 0 0 0 -0 0.785398</pose>
      <inertial>
        <mass>0</mass>
        <inertia>
          <ixx>0.0001</ixx>
          <ixy>0</ixy>
          <ixz>0</ixz>
          <iyy>0.0001</iyy>
          <iyz>0</iyz>
          <izz>0.0001</izz>
        </inertia>
        <pose frame=''>0 0 0 0 -0 0</pose>
      </inertial>
      <self_collide>0</self_collide>
      <kinematic>0</kinematic>
      <gravity>1</gravity>
    </link>
    <link name='right_finger'>
      <pose frame=''>0.008 0.029 0 0 -0 0</pose>
      <inertial>
        <mass>0.05</mass>
        <inertia>
          <ixx>0.16</ixx>
          <ixy>0</ixy>
          <ixz>0</ixz>
          <iyy>0.16</iyy>
          <iyz>0</iyz>
          <izz>0.16</izz>
        </inertia>
        <pose frame=''>0 0 0 0 -0 0</pose>
      </inertial>
      <self_collide>0</self_collide>
      <kinematic>0</kinematic>
      <visual name='visual'>
        <pose frame=''>0 0 0 0 -0 0</pose>
        <geometry>
          <box>
            <size>0.016 0.083 0.02</size>
          </box>
        </geometry>
        <material>
          <lighting>1</lighting>
          <script>
            <uri>file://media/materials/scripts/gazebo.material</uri>
            <name>Gazebo/Grey</name>
          </script>
          <ambient>0.3 0.3 0.3 1</ambient>
          <diffuse>0.7 0.7 0.7 1</diffuse>
          <specular>0.01 0.01 0.01 1</specular>
          <emissive>0 0 0 1</emissive>
          <shader type='vertex'>
            <normal_map>__default__</normal_map>
          </shader>
        </material>
        <cast_shadows>1</cast_shadows>
        <transparency>0</transparency>
      </visual>
      <!-- A sequence of spaced spheres the *width* of the finger from the tip
      towards the base. -->
      <collision name='collision'>
        <pose frame=''>0 -0.0209 0 0 0 0</pose>
        <geometry>
          <sphere>
            <radius>0.008</radius>
          </sphere>
        </geometry>
      </collision>
      <collision name='collision'>
        <pose frame=''>0 -0.0049 0 0 0 0</pose>
        <geometry>
          <sphere>
            <radius>0.008</radius>
          </sphere>
        </geometry>
      </collision>
      <collision name='collision'>
        <pose frame=''>0 0.0112 0 0 0 0</pose>
        <geometry>
          <sphere>
            <radius>0.008</radius>
          </sphere>
        </geometry>
      </collision>
      <collision name='collision'>
        <pose frame=''>0 0.0271 0 0 0 0</pose>
        <geometry>
          <sphere>
            <radius>0.008</radius>
          </sphere>
        </geometry>
      </collision>
      <!-- Two more spheres that form a triangle with the tip-most sphere
           above. -->
      <collision name='collision'>
        <pose frame=''>-0.004 0.0375 0.0060 0 0 0</pose>
        <geometry>
          <sphere>
            <radius>0.004</radius>
          </sphere>
        </geometry>
      </collision>
      <collision name='collision'>
        <pose frame=''>-0.004 0.0375 -0.0060 0 0 0</pose>
        <geometry>
          <sphere>
            <radius>0.004</radius>
          </sphere>
        </geometry>
      </collision>
    </link>
    <link name='right_pusher'>
      <pose frame=''>-0.028 -0.037 0 0 0 -0.909</pose>
      <inertial>
        <mass>0</mass>
        <inertia>
          <ixx>0.0001</ixx>
          <ixy>0</ixy>
          <ixz>0</ixz>
          <iyy>0.0001</iyy>
          <iyz>0</iyz>
          <izz>0.0001</izz>
        </inertia>
        <pose frame=''>0 0 0 0 -0 0</pose>
      </inertial>
      <self_collide>0</self_collide>
      <kinematic>0</kinematic>
      <gravity>1</gravity>
      <visual name='visual'>
        <pose frame=''>0 0 0 0 -0 0</pose>
        <geometry>
          <box>
            <size>0.01 0.0571 0.01</size>
          </box>
        </geometry>
        <material>
          <lighting>1</lighting>
          <script>
            <uri>file://media/materials/scripts/gazebo.material</uri>
            <name>Gazebo/Grey</name>
          </script>
          <ambient>0.3 0.3 0.3 1</ambient>
          <diffuse>0.7 0.7 0.7 1</diffuse>
          <specular>0.01 0.01 0.01 1</specular>
          <emissive>0 0 0 1</emissive>
          <shader type='vertex'>
            <normal_map>__default__</normal_map>
          </shader>
        </material>
        <cast_shadows>1</cast_shadows>
        <transparency>0</transparency>
      </visual>
    </link>
    <joint name='left_finger_push' type='revolute'>
      <parent>left_finger</parent>
      <child>left_pusher</child>
      <pose frame=''>0 -0.057 0 0 -0 0</pose>
      <axis>
        <limit><effort>0</effort></limit>
        <xyz>0 0 1</xyz>
        <use_parent_model_frame>0</use_parent_model_frame>
        <dynamics>
          <spring_reference>0</spring_reference>
          <spring_stiffness>0</spring_stiffness>
          <damping>0</damping>
          <friction>0</friction>
        </dynamics>
      </axis>
      <physics>
        <ode>
          <limit>
            <cfm>0</cfm>
            <erp>0.2</erp>
          </limit>
          <suspension>
            <cfm>0</cfm>
            <erp>0.2</erp>
          </suspension>
        </ode>
      </physics>
    </joint>
    <joint name='left_finger_sliding_joint' type='prismatic'>
      <parent>body</parent>
      <child>left_finger</child>
      <pose frame=''>0 0 0 0 -0 0</pose>
      <axis>
        <xyz>1 0 0</xyz>
        <use_parent_model_frame>0</use_parent_model_frame>
        <!-- Drake attaches an actuator to all and only joints with a nonzero
             effort limit. -->
        <limit>
          <lower>-0.055</lower>
          <upper>0</upper>
          <effort>80</effort>
          <stiffness>15000</stiffness>
          <dissipation>50</dissipation>
        </limit>
        <dynamics>
          <spring_reference>0</spring_reference>
          <spring_stiffness>0</spring_stiffness>
          <damping>0</damping>
          <friction>0</friction>
        </dynamics>
      </axis>
      <physics>
        <ode>
          <limit>
            <cfm>0</cfm>
            <erp>0.2</erp>
          </limit>
          <suspension>
            <cfm>0</cfm>
            <erp>0.2</erp>
          </suspension>
        </ode>
      </physics>
    </joint>
    <joint name='left_rotor_push' type='revolute'>
      <parent>nonphysical_rotor</parent>
      <child>left_pusher</child>
      <pose frame=''>0 0.057 0 0 -0 0</pose>
      <axis>
        <limit><effort>0</effort></limit>
        <xyz>0 0 1</xyz>
        <use_parent_model_frame>0</use_parent_model_frame>
        <dynamics>
          <spring_reference>0</spring_reference>
          <spring_stiffness>0</spring_stiffness>
          <damping>0</damping>
          <friction>0</friction>
        </dynamics>
      </axis>
      <physics>
        <ode>
          <limit>
            <cfm>0</cfm>
            <erp>0.2</erp>
          </limit>
          <suspension>
            <cfm>0</cfm>
            <erp>0.2</erp>
          </suspension>
        </ode>
      </physics>
    </joint>
    <joint name='nonphysical_rotor_mount' type='revolute'>
      <parent>body</parent>
      <child>nonphysical_rotor</child>
      <pose frame=''>0 0 0 0 -0 0</pose>
      <axis>
        <limit><effort>0</effort></limit>
        <xyz>0 0 1</xyz>
        <use_parent_model_frame>0</use_parent_model_frame>
        <dynamics>
          <spring_reference>0</spring_reference>
          <spring_stiffness>0</spring_stiffness>
          <damping>0</damping>
          <friction>0</friction>
        </dynamics>
      </axis>
      <physics>
        <ode>
          <limit>
            <cfm>0</cfm>
            <erp>0.2</erp>
          </limit>
          <suspension>
            <cfm>0</cfm>
            <erp>0.2</erp>
          </suspension>
        </ode>
      </physics>
    </joint>
    <joint name='right_finger_push' type='revolute'>
      <parent>right_finger</parent>
      <child>right_pusher</child>
      <pose frame=''>0 0.057 0 0 -0 0</pose>
      <axis>
        <limit><effort>0</effort></limit>
        <xyz>0 0 1</xyz>
        <use_parent_model_frame>0</use_parent_model_frame>
        <dynamics>
          <spring_reference>0</spring_reference>
          <spring_stiffness>0</spring_stiffness>
          <damping>0</damping>
          <friction>0</friction>
        </dynamics>
      </axis>
      <physics>
        <ode>
          <limit>
            <cfm>0</cfm>
            <erp>0.2</erp>
          </limit>
          <suspension>
            <cfm>0</cfm>
            <erp>0.2</erp>
          </suspension>
        </ode>
      </physics>
    </joint>
    <joint name='right_finger_sliding_joint' type='prismatic'>
      <parent>body</parent>
      <child>right_finger</child>
      <pose frame=''>0 0 0 0 -0 0</pose>
      <axis>
        <xyz>1 0 0</xyz>
        <use_parent_model_frame>0</use_parent_model_frame>
        <limit>
          <effort>0</effort>
        </limit>
        <dynamics>
          <spring_reference>0</spring_reference>
          <spring_stiffness>0</spring_stiffness>
          <damping>0</damping>
          <friction>0</friction>
        </dynamics>
      </axis>
      <physics>
        <ode>
          <limit>
            <cfm>0</cfm>
            <erp>0.2</erp>
          </limit>
          <suspension>
            <cfm>0</cfm>
            <erp>0.2</erp>
          </suspension>
        </ode>
      </physics>
    </joint>
    <joint name='right_rotor_push' type='revolute'>
      <parent>nonphysical_rotor</parent>
      <child>right_pusher</child>
      <pose frame=''>0 -0.057 0 0 -0 0</pose>
      <axis>
        <limit><effort>0</effort></limit>
        <xyz>0 0 1</xyz>
        <use_parent_model_frame>0</use_parent_model_frame>
        <dynamics>
          <spring_reference>0</spring_reference>
          <spring_stiffness>0</spring_stiffness>
          <damping>0</damping>
          <friction>0</friction>
        </dynamics>
      </axis>
      <physics>
        <ode>
          <limit>
            <cfm>0</cfm>
            <erp>0.2</erp>
          </limit>
          <suspension>
            <cfm>0</cfm>
            <erp>0.2</erp>
          </suspension>
        </ode>
      </physics>
    </joint>
    <static>0</static>
    <allow_auto_disable>1</allow_auto_disable>
  </model>
</sdf>
